Workbook

Sheet Exportations Minières 23-24
A1: Année | B1: Type de minerai | C1: Société | D1: Projet | E1: Pays destinataire | F1: Unité | G1: Poids/Volume | H1: Valeur (FCFA) | I1: Valeur (USD) | J1: Prix unitaire (USD) | K1: Unité du prix (USD) | L1: Prix unitaire (FCFA) | M1: Unité du prix (FCFA)
A2: 2023 | B2: Or | C2: SGO | D2: Sabodala | E2: Suisse | F2: Onces | G2: 288697 | H2: 344273384269 | I2: 569681805 | J2: =IFERROR(I2/G2,"NC") -> 1973.2862 | K2: =IF(J2="NC","NC","USD/"&F2) -> USD/Onces | L2: =IFERROR(H2/G2,"NC") -> 1192507.7 | M2: =IF(L2="NC","NC","FCFA/"&F2) -> FCFA/Onces
A3: 2023 | B3: Or | C3: PMC | D3: Mako | E3: Australie | F3: Onces | G3: 119950 | H3: 138107655558 | I3: 228531807 | J3: =IFERROR(I3/G3,"NC") -> 1905.2256 | K3: =IF(J3="NC","NC","USD/"&F3) -> USD/Onces | L3: =IFERROR(H3/G3,"NC") -> 1151376.9 | M3: =IF(L3="NC","NC","FCFA/"&F3) -> FCFA/Onces
A4: 2023 | B4: Or | C4: SGO | D4: Sabodala | E4: Sénégal | F4: Onces | G4: 8000 | H4: 9494006760 | I4: 15710081 | J4: =IFERROR(I4/G4,"NC") -> 1963.7601 | K4: =IF(J4="NC","NC","USD/"&F4) -> USD/Onces | L4: =IFERROR(H4/G4,"NC") -> 1186750.8 | M4: =IF(L4="NC","NC","FCFA/"&F4) -> FCFA/Onces
A5: 2023 | B5: Acide Phosphorique | C5: ICS | D5: Tobène | E5: Inde | F5: MT | G5: 484798 | H5: 286195769501 | I5: 473578644 | J5: =IFERROR(I5/G5,"NC") -> 976.85767 | K5: =IF(J5="NC","NC","USD/"&F5) -> USD/MT | L5: =IFERROR(H5/G5,"NC") -> 590340.24 | M5: =IF(L5="NC","NC","FCFA/"&F5) -> FCFA/MT
A6: 2023 | B6: Acide Phosphorique | C6: ICS | D6: Tobène | E6: Émirats Arabes Unis | F6: MT | G6: 14376 | H6: 8684769776 | I6: 14371007 | J6: =IFERROR(I6/G6,"NC") -> 999.65269 | K6: =IF(J6="NC","NC","USD/"&F6) -> USD/MT | L6: =IFERROR(H6/G6,"NC") -> 604115.87 | M6: =IF(L6="NC","NC","FCFA/"&F6) -> FCFA/MT
A7: 2023 | B7: Acide Phosphorique | C7: ICS | D7: Tobène | E7: Suisse | F7: MT | G7: 9504 | H7: 5852241986 | I7: 9683920 | J7: =IFERROR(I7/G7,"NC") -> 1018.931 | K7: =IF(J7="NC","NC","USD/"&F7) -> USD/MT | L7: =IFERROR(H7/G7,"NC") -> 615766.2 | M7: =IF(L7="NC","NC","FCFA/"&F7) -> FCFA/MT
A8: 2023 | B8: Ciment | C8: CDS | D8: NC | E8: Mali | F8: Tonnes | G8: 867211 | H8: 42392387900 | I8: 70148240 | J8: =IFERROR(I8/G8,"NC") -> 80.889472 | K8: =IF(J8="NC","NC","USD/"&F8) -> USD/Tonnes | L8: =IFERROR(H8/G8,"NC") -> 48883.591 | M8: =IF(L8="NC","NC","FCFA/"&F8) -> FCFA/Tonnes
A9: 2023 | B9: Ciment | C9: CDS | D9: NC | E9: Gambie | F9: Tonnes | G9: 619499 | H9: 30125944745 | I9: 49850507 | J9: =IFERROR(I9/G9,"NC") -> 80.469068 | K9: =IF(J9="NC","NC","USD/"&F9) -> USD/Tonnes | L9: =IFERROR(H9/G9,"NC") -> 48629.529 | M9: =IF(L9="NC","NC","FCFA/"&F9) -> FCFA/Tonnes
A10: 2023 | B10: Ciment | C10: DANGOTE | D10: Pout | E10: Mali | F10: Tonnes | G10: 240860 | H10: 11879649100 | I10: 19657691 | J10: =IFERROR(I10/G10,"NC") -> 81.614594 | K10: =IF(J10="NC","NC","USD/"&F10) -> USD/Tonnes | L10: =IFERROR(H10/G10,"NC") -> 49321.801 | M10: =IF(L10="NC","NC","FCFA/"&F10) -> FCFA/Tonnes
A11: 2023 | B11: Ciment | C11: SOCOCIM | D11: Bargny | E11: Mali | F11: Tonnes | G11: 131698 | H11: 6669016479 | I11: 11035466 | J11: =IFERROR(I11/G11,"NC") -> 83.793725 | K11: =IF(J11="NC","NC","USD/"&F11) -> USD/Tonnes | L11: =IFERROR(H11/G11,"NC") -> 50638.707 | M11: =IF(L11="NC","NC","FCFA/"&F11) -> FCFA/Tonnes
A12: 2023 | B12: Ciment | C12: DANGOTE | D12: Pout | E12: Gambie | F12: Tonnes | G12: 41410 | H12: 1982066100 | I12: 3279798 | J12: =IFERROR(I12/G12,"NC") -> 79.203043 | K12: =IF(J12="NC","NC","USD/"&F12) -> USD/Tonnes | L12: =IFERROR(H12/G12,"NC") -> 47864.431 | M12: =IF(L12="NC","NC","FCFA/"&F12) -> FCFA/Tonnes
A13: 2023 | B13: Ciment | C13: SOCOCIM | D13: Bargny | E13: Gambie | F13: Tonnes | G13: 36362 | H13: 1769500108 | I13: 2928057 | J13: =IFERROR(I13/G13,"NC") -> 80.525191 | K13: =IF(J13="NC","NC","USD/"&F13) -> USD/Tonnes | L13: =IFERROR(H13/G13,"NC") -> 48663.443 | M13: =IF(L13="NC","NC","FCFA/"&F13) -> FCFA/Tonnes
... A43: 2023 | B43: Basalte | C43: COGECA | D43: NC | E43: NC | F43: Tonnes | G43: 22058 | H43: 46887495 | I43: 77586 | J43: =IFERROR(I43/G43,"NC") -> 3.5173633 | K43: =IF(J43="NC","NC","USD/"&F43) -> USD/Tonnes | L43: =IFERROR(H43/G43,"NC") -> 2125.6458 | M43: =IF(L43="NC","NC","FCFA/"&F43) -> FCFA/Tonnes
A44: 2023 | B44: Basalte | C44: TALIX | D44: Diack | E44: Sénégal | F44: Tonnes | G44: NC | H44: 2526487480 | I44: 4180672 | J44: =IFERROR(I44/G44,"NC") -> NC | K44: =IF(J44="NC","NC","USD/"&F44) -> NC | L44: =IFERROR(H44/G44,"NC") -> NC | M44: =IF(L44="NC","NC","FCFA/"&F44) -> NC
A45: 2023 | B45: Basalte | C45: GECAMINE | D45: NC | E45: Gambie | F45: Tonnes | G45: 65839 | H45: 566744852 | I45: 937814 | J45: =IFERROR(I45/G45,"NC") -> 14.24405 | K45: =IF(J45="NC","NC","USD/"&F45) -> USD/Tonnes | L45: =IFERROR(H45/G45,"NC") -> 8608.0416 | M45: =IF(L45="NC","NC","FCFA/"&F45) -> FCFA/Tonnes
A46: 2023 | B46: Basalte | C46: TALIX | D46: Diack | E46: Gambie | F46: Tonnes | G46: NC | H46: 97587866 | I46: 161482 | J46: =IFERROR(I46/G46,"NC") -> NC | K46: =IF(J46="NC","NC","USD/"&F46) -> NC | L46: =IFERROR(H46/G46,"NC") -> NC | M46: =IF(L46="NC","NC","FCFA/"&F46) -> NC
A47: 2023 | B47: Ilmenite 56 | C47: GCO | D47: Diogo | E47: France | F47: Tonnes | G47: 17001 | H47: 2471147154 | I47: 4089098 | J47: =IFERROR(I47/G47,"NC") -> 240.52103 | K47: =IF(J47="NC","NC","USD/"&F47) -> USD/Tonnes | L47: =IFERROR(H47/G47,"NC") -> 145353.05 | M47: =IF(L47="NC","NC","FCFA/"&F47) -> FCFA/Tonnes
A48: 2023 | B48: Argent | C48: SGO | D48: Sabodala | E48: Suisse | F48: Onces | G48: 21822 | H48: 307938113 | I48: 509556 | J48: =IFERROR(I48/G48,"NC") -> 23.350564 | K48: =IF(J48="NC","NC","USD/"&F48) -> USD/Onces | L48: =IFERROR(H48/G48,"NC") -> 14111.361 | M48: =IF(L48="NC","NC","FCFA/"&F48) -> FCFA/Onces
A49: 2023 | B49: Argent | C49: PMC | D49: Mako | E49: Australie | F49: Onces | G49: 8872 | H49: 122375993 | I49: 202500 | J49: =IFERROR(I49/G49,"NC") -> 22.824617 | K49: =IF(J49="NC","NC","USD/"&F49) -> USD/Onces | L49: =IFERROR(H49/G49,"NC") -> 13793.507 | M49: =IF(L49="NC","NC","FCFA/"&F49) -> FCFA/Onces
A50: 2023 | B50: DSP | C50: ICS | D50: Tobène | E50: Mali | F50: MT | G50: 4084 | H50: 358740500 | I50: 593621 | J50: =IFERROR(I50/G50,"NC") -> 145.35284 | K50: =IF(J50="NC","NC","USD/"&F50) -> USD/MT | L50: =IFERROR(H50/G50,"NC") -> 87840.475 | M50: =IF(L50="NC","NC","FCFA/"&F50) -> FCFA/MT
A51: 2023 | B51: Clinker | C51: SOCOCIM | D51: Bargny | E51: Mali | F51: Tonnes | G51: 3599 | H51: 134973750 | I51: 223346 | J51: =IFERROR(I51/G51,"NC") -> 62.057794 | K51: =IF(J51="NC","NC","USD/"&F51) -> USD/Tonnes | L51: =IFERROR(H51/G51,"NC") -> 37503.126 | M51: =IF(L51="NC","NC","FCFA/"&F51) -> FCFA/Tonnes
A52: 2023 | B52: Gypse | C52: ICS | D52: Tobène | E52: Mali | F52: MT | G52: 1412 | H52: 8472900 | I52: 14020 | J52: =IFERROR(I52/G52,"NC") -> 9.9291785 | K52: =IF(J52="NC","NC","USD/"&F52) -> USD/MT | L52: =IFERROR(H52/G52,"NC") -> 6000.6374 | M52: =IF(L52="NC","NC","FCFA/"&F52) -> FCFA/MT
A53: 2023 | B53: Gypse | C53: ICS | D53: Tobène | E53: Guinée-Bissau | F53: MT | G53: 1352 | H53: 8114700 | I53: 13428 | J53: =IFERROR(I53/G53,"NC") -> 9.9319527 | K53: =IF(J53="NC","NC","USD/"&F53) -> USD/MT | L53: =IFERROR(H53/G53,"NC") -> 6001.997 | M53: =IF(L53="NC","NC","FCFA/"&F53) -> FCFA/MT
A54: 2023 | B54: Gypse | C54: ICS | D54: Tobène | E54: Burkina Faso | F54: MT | G54: 100 | H54: 600000 | I54: 993 | J54: =IFERROR(I54/G54,"NC") -> 9.93 | K54: =IF(J54="NC","NC","USD/"&F54) -> USD/MT | L54: =IFERROR(H54/G54,"NC") -> 6000 | M54: =IF(L54="NC","NC","FCFA/"&F54) -> FCFA/MT
A55: 2023 | B55: Rock Phosphate | C55: ICS | D55: Tobène | E55: Inde | F55: MT | G55: 99 | H55: 12309259 | I55: 20369 | J55: =IFERROR(I55/G55,"NC") -> 205.74747 | K55: =IF(J55="NC","NC","USD/"&F55) -> USD/MT | L55: =IFERROR(H55/G55,"NC") -> 124335.95 | M55: =IF(L55="NC","NC","FCFA/"&F55) -> FCFA/MT
A56: 2024 | B56: Or | C56: PMC | D56: Mako | E56: Australie | F56: Onces | G56: 121623 | H56: 176892827875 | I56: 292498604 | J56: =IFERROR(I56/G56,"NC") -> 2404.9613 | K56: =IF(J56="NC","NC","USD/"&F56) -> USD/Onces | L56: =IFERROR(H56/G56,"NC") -> 1454435.7 | M56: =IF(L56="NC","NC","FCFA/"&F56) -> FCFA/Onces
A57: 2024 | B57: Or | C57: SGO | D57: Sabodala | E57: Dubaï | F57: Onces | G57: 116418 | H57: 171988995312 | I57: 287722269 | J57: =IFERROR(I57/G57,"NC") -> 2471.4586 | K57: =IF(J57="NC","NC","USD/"&F57) -> USD/Onces | L57: =IFERROR(H57/G57,"NC") -> 1477340.2 | M57: =IF(L57="NC","NC","FCFA/"&F57) -> FCFA/Onces
A58: 2024 | B58: Or | C58: SGO | D58: Sabodala | E58: Suisse | F58: Onces | G58: 105001 | H58: 153070817850 | I58: 254705218 | J58: =IFERROR(I58/G58,"NC") -> 2425.7409 | K58: =IF(J58="NC","NC","USD/"&F58) -> USD/Onces | L58: =IFERROR(H58/G58,"NC") -> 1457803.4 | M58: =IF(L58="NC","NC","FCFA/"&F58) -> FCFA/Onces
... A94: 2024 | B94: Basalte | C94: GECAMINE | D94: Diack | E94: Gambie | F94: Tonnes | G94: 340661 | H94: 3071169676 | I94: 5065027 | J94: =IFERROR(I94/G94,"NC") -> 14.868233 | K94: =IF(J94="NC","NC","USD/"&F94) -> USD/Tonnes | L94: =IFERROR(H94/G94,"NC") -> 9015.3251 | M94: =IF(L94="NC","NC","FCFA/"&F94) -> FCFA/Tonnes
A95: 2024 | B95: Basalte | C95: TALIX | D95: Diack | E95: Gambie | F95: Tonnes | G95: NC | H95: 358807621 | I95: 591755 | J95: =IFERROR(I95/G95,"NC") -> NC | K95: =IF(J95="NC","NC","USD/"&F95) -> NC | L95: =IFERROR(H95/G95,"NC") -> NC | M95: =IF(L95="NC","NC","FCFA/"&F95) -> NC
A96: 2024 | B96: Basalte | C96: COGECA | D96: NC | E96: Gambie | F96: Tonnes | G96: 25201 | H96: 63184603 | I96: 104206 | J96: =IFERROR(I96/G96,"NC") -> 4.1349946 | K96: =IF(J96="NC","NC","USD/"&F96) -> USD/Tonnes | L96: =IFERROR(H96/G96,"NC") -> 2507.226 | M96: =IF(L96="NC","NC","FCFA/"&F96) -> FCFA/Tonnes
A97: 2024 | B97: Zircon Medium | C97: GCO | D97: Diogo | E97: France | F97: Tonnes | G97: 31443 | H97: 4311499782 | I97: 7118096 | J97: =IFERROR(I97/G97,"NC") -> 226.38094 | K97: =IF(J97="NC","NC","USD/"&F97) -> USD/Tonnes | L97: =IFERROR(H97/G97,"NC") -> 137121.13 | M97: =IF(L97="NC","NC","FCFA/"&F97) -> FCFA/Tonnes
A98: 2024 | B98: Leucoxene | C98: GCO | D98: Diogo | E98: France | F98: Tonnes | G98: 6092 | H98: 4539903428 | I98: 7453711 | J98: =IFERROR(I98/G98,"NC") -> 1223.5245 | K98: =IF(J98="NC","NC","USD/"&F98) -> USD/Tonnes | L98: =IFERROR(H98/G98,"NC") -> 745223.81 | M98: =IF(L98="NC","NC","FCFA/"&F98) -> FCFA/Tonnes
A99: 2024 | B99: Rutile | C99: GCO | D99: Diogo | E99: France | F99: Tonnes | G99: 2640 | H99: 2861618508 | I99: 4714166 | J99: =IFERROR(I99/G99,"NC") -> 1785.6689 | K99: =IF(J99="NC","NC","USD/"&F99) -> USD/Tonnes | L99: =IFERROR(H99/G99,"NC") -> 1083946.4 | M99: =IF(L99="NC","NC","FCFA/"&F99) -> FCFA/Tonnes
A100: 2024 | B100: Ilmenite 56 | C100: GCO | D100: Diogo | E100: France | F100: Tonnes | G100: 20001 | H100: 2761143939 | I100: 4522423 | J100: =IFERROR(I100/G100,"NC") -> 226.10984 | K100: =IF(J100="NC","NC","USD/"&F100) -> USD/Tonnes | L100: =IFERROR(H100/G100,"NC") -> 138050.29 | M100: =IF(L100="NC","NC","FCFA/"&F100) -> FCFA/Tonnes
A101: 2024 | B101: DAP - Sac 50Kg | C101: ICS | D101: Tobène | E101: Mali | F101: MT | G101: 1980 | H101: 792000000 | I101: 1336897 | J101: =IFERROR(I101/G101,"NC") -> 675.20051 | K101: =IF(J101="NC","NC","USD/"&F101) -> USD/MT | L101: =IFERROR(H101/G101,"NC") -> 400000 | M101: =IF(L101="NC","NC","FCFA/"&F101) -> FCFA/MT
A102: 2024 | B102: Argent | C102: PMC | D102: Mako | E102: Australie | F102: Onces | G102: 10095 | H102: 169980320 | I102: 280882 | J102: =IFERROR(I102/G102,"NC") -> 27.823873 | K102: =IF(J102="NC","NC","USD/"&F102) -> USD/Onces | L102: =IFERROR(H102/G102,"NC") -> 16838.07 | M102: =IF(L102="NC","NC","FCFA/"&F102) -> FCFA/Onces
A103: 2024 | B103: Argent | C103: SGO | D103: Sabodala | E103: Dubaï | F103: Onces | G103: 8904 | H103: 156146734 | I103: 249425 | J103: =IFERROR(I103/G103,"NC") -> 28.012691 | K103: =IF(J103="NC","NC","USD/"&F103) -> USD/Onces | L103: =IFERROR(H103/G103,"NC") -> 17536.695 | M103: =IF(L103="NC","NC","FCFA/"&F103) -> FCFA/Onces
A104: 2024 | B104: Argent | C104: SGO | D104: Sabodala | E104: Suisse | F104: Onces | G104: 8181 | H104: 140740539 | I104: 233978 | J104: =IFERROR(I104/G104,"NC") -> 28.600171 | K104: =IF(J104="NC","NC","USD/"&F104) -> USD/Onces | L104: =IFERROR(H104/G104,"NC") -> 17203.342 | M104: =IF(L104="NC","NC","FCFA/"&F104) -> FCFA/Onces
...

Sheet Exportations Hydrocarbures 24
A1: Date | B1: N° de facture | C1: Volumes vendus (barils) | D1: Prix de vente officiel (USD/baril) | E1: Revenus perçus (USD) | F1: Part État - Volume | G1: Part État - Valeur USD | H1: Part PETROSEN - Volume | I1: Part PETROSEN - Valeur USD | J1: Destination
A2: 12/07/2024 | B2: INV-SAN2024.01 | C2: 984195 | D2: 83.63 | E2: 82304291 | F2: 46484 | G2: 3804033 | H2: 177155 | I2: 14814764 | J2: Pays-Bas
A3: 24/07/2024 | B3: INV-SAN2024.02 | C3: 998289 | D3: 83.33 | E3: 83183429 | F3: 47150 | G3: 3844666 | H3: 179692 | I3: 14973016 | J3: Italie
A4: 04/08/2024 | B4: INV-SAN2024.03 | C4: 921461 | D4: 76.47 | E4: 70464123 | F4: 43521 | G4: 3256791 | H4: 157570 | I4: 12049378 | J4: Chine
A5: 22/08/2024 | B5: INV-SAN2024.04 | C5: 997272 | D5: 79.73 | E5: 79510502 | F5: 47102 | G5: 3674906 | H5: 170533 | I5: 13596255 | J5: Espagne
A6: 30/08/2024 | B6: INV-SAN2024.05-P | C6: 947311 | D6: 72.04 | E6: 68244284 | F6: 44742 | G6: 3154192 | H6: 161990 | I6: 11669760 | J6: Chine
A7: 08/09/2024 | B7: INV-SAN2024.06 | C7: 946390 | D7: 72.04 | E7: 68177936 | F7: 44698 | G7: 3151125 | H7: 161833 | I7: 11658449 | J7: Chine
A8: 18/09/2024 | B8: INV-SAN2024.07 | C8: 945349 | D8: 73.22 | E8: 69217508 | F8: 44649 | G8: 3199173 | H8: 161655 | I8: 11836217 | J8: Chine
A9: 28/09/2024 | B9: INV-SAN2024.08 | C9: 947159 | D9: 73.53 | E9: 69641760 | F9: 44735 | G9: 3218782 | H9: 161964 | I9: 11908727 | J9: Chine
A10: 08/10/2024 | B10: INV-SAN2024.09 | C10: 950928 | D10: 74.72 | E10: 71049536 | F10: 44913 | G10: 3283848 | H10: 162609 | I10: 12149494 | J10: Chine
A11: 18/10/2024 | B11: INV-SAN2024.10 | C11: 943708 | D11: 71.91 | E11: 67858267 | F11: 44572 | G11: 3136350 | H11: 161374 | I11: 11603759 | J11: Chine
A12: 30/10/2024 | B12: INV-SAN2024.11 | C12: 991982 | D12: 72.68 | E12: 72096260 | F12: 46852 | G12: 3332227 | H12: 169629 | I12: 12328466 | J12: Chine
A13: 09/11/2024 | B13: INV-SAN2024.12 | C13: 946910 | D13: 70.65 | E13: 66899192 | F13: 44723 | G13: 3092023 | H13: 161922 | I13: 11439789 | J13: Chine
... A17: 09/12/2024 | B17: INV-SAN2024.15-P | C17: 857013 | D17: 69.98 | E17: 59973791 | F17: 40477 | G17: 2771937 | H17: 170845 | I17: 11955733 | J17: Chine

Sheet Prix par Société
A1: Société | B1: Volume 2023 | C1: Volume 2024 | D1: Prix moyen pondéré USD 2023 | E1: Prix moyen pondéré USD 2024 | F1: Prix moyen pondéré FCFA 2023 | G1: Prix moyen pondéré FCFA 2024 | H1: Unité
A2: SGO | B2: =SUMIFS('Exportations Minières 23-24'!$G$2:$G$105,'Exportations Minières 23-24'!$C$2:$C$105,A2,'Exportations Minières 23-24'!$A$2:$A$105,2023) -> 318519 | C2: =SUMIFS('Exportations Minières 23-24'!$G$2:$G$105,'Exportations Minières 23-24'!$C$2:$C$105,A2,'Exportations Minières 23-24'!$A$2:$A$105,2024) -> 238504 | D2: =IFERROR((SUMIFS('Exportations Minières 23-24'!$I$2:$I$105,'Exportations Minières 23-24'!$C$2:$C$105,A2,'Exportations Minières 23-24'!$A$2:$A$105,2023))/B2,"NC") -> 1839.4552 | E2: =IFERROR((SUMIFS('Exportations Minières 23-24'!$I$2:$I$105,'Exportations Minières 23-24'!$C$2:$C$105,A2,'Exportations Minières 23-24'!$A$2:$A$105,2024))/C2,"NC") -> 2276.3178 | F2: =IFERROR((SUMIFS('Exportations Minières 23-24'!$H$2:$H$105,'Exportations Minières 23-24'!$C$2:$C$105,A2,'Exportations Minières 23-24'!$A$2:$A$105,2023))/B2,"NC") -> 1111630.2 | G2: =IFERROR((SUMIFS('Exportations Minières 23-24'!$H$2:$H$105,'Exportations Minières 23-24'!$C$2:$C$105,A2,'Exportations Minières 23-24'!$A$2:$A$105,2024))/C2,"NC") -> 1364156.2 | H2: Onces
A3: PMC | B3: =SUMIFS('Exportations Minières 23-24'!$G$2:$G$105,'Exportations Minières 23-24'!$C$2:$C$105,A3,'Exportations Minières 23-24'!$A$2:$A$105,2023) -> 128822 | C3: =SUMIFS('Exportations Minières 23-24'!$G$2:$G$105,'Exportations Minières 23-24'!$C$2:$C$105,A3,'Exportations Minières 23-24'!$A$2:$A$105,2024) -> 131718 | D3: =IFERROR((SUMIFS('Exportations Minières 23-24'!$I$2:$I$105,'Exportations Minières 23-24'!$C$2:$C$105,A3,'Exportations Minières 23-24'!$A$2:$A$105,2023))/B3,"NC") -> 1775.5842 | E3: =IFERROR((SUMIFS('Exportations Minières 23-24'!$I$2:$I$105,'Exportations Minières 23-24'!$C$2:$C$105,A3,'Exportations Minières 23-24'!$A$2:$A$105,2024))/C3,"NC") -> 2222.7751 | F3: =IFERROR((SUMIFS('Exportations Minières 23-24'!$H$2:$H$105,'Exportations Minières 23-24'!$C$2:$C$105,A3,'Exportations Minières 23-24'!$A$2:$A$105,2023))/B3,"NC") -> 1073031.2 | G3: =IFERROR((SUMIFS('Exportations Minières 23-24'!$H$2:$H$105,'Exportations Minières 23-24'!$C$2:$C$105,A3,'Exportations Minières 23-24'!$A$2:$A$105,2024))/C3,"NC") -> 1344256.7 | H3: Onces
A4: ICS | B4: =SUMIFS('Exportations Minières 23-24'!$G$2:$G$105,'Exportations Minières 23-24'!$C$2:$C$105,A4,'Exportations Minières 23-24'!$A$2:$A$105,2023) -> 563165 | C4: =SUMIFS('Exportations Minières 23-24'!$G$2:$G$105,'Exportations Minières 23-24'!$C$2:$C$105,A4,'Exportations Minières 23-24'!$A$2:$A$105,2024) -> 579703 | D4: =IFERROR((SUMIFS('Exportations Minières 23-24'!$I$2:$I$105,'Exportations Minières 23-24'!$C$2:$C$105,A4,'Exportations Minières 23-24'!$A$2:$A$105,2023))/B4,"NC") -> 942.30967 | E4: =IFERROR((SUMIFS('Exportations Minières 23-24'!$I$2:$I$105,'Exportations Minières 23-24'!$C$2:$C$105,A4,'Exportations Minières 23-24'!$A$2:$A$105,2024))/C4,"NC") -> 921.14825 | F4: =IFERROR((SUMIFS('Exportations Minières 23-24'!$H$2:$H$105,'Exportations Minières 23-24'!$C$2:$C$105,A4,'Exportations Minières 23-24'!$A$2:$A$105,2023))/B4,"NC") -> 569462 | G4: =IFERROR((SUMIFS('Exportations Minières 23-24'!$H$2:$H$105,'Exportations Minières 23-24'!$C$2:$C$105,A4,'Exportations Minières 23-24'!$A$2:$A$105,2024))/C4,"NC") -> 559326.65 | H4: MT
A5: CDS | B5: =SUMIFS('Exportations Minières 23-24'!$G$2:$G$105,'Exportations Minières 23-24'!$C$2:$C$105,A5,'Exportations Minières 23-24'!$A$2:$A$105,2023) -> 1512362 | C5: =SUMIFS('Exportations Minières 23-24'!$G$2:$G$105,'Exportations Minières 23-24'!$C$2:$C$105,A5,'Exportations Minières 23-24'!$A$2:$A$105,2024) -> 1517058 | D5: =IFERROR((SUMIFS('Exportations Minières 23-24'!$I$2:$I$105,'Exportations Minières 23-24'!$C$2:$C$105,A5,'Exportations Minières 23-24'!$A$2:$A$105,2023))/B5,"NC") -> 80.691793 | E5: =IFERROR((SUMIFS('Exportations Minières 23-24'!$I$2:$I$105,'Exportations Minières 23-24'!$C$2:$C$105,A5,'Exportations Minières 23-24'!$A$2:$A$105,2024))/C5,"NC") -> 78.521984 | F5: =IFERROR((SUMIFS('Exportations Minières 23-24'!$H$2:$H$105,'Exportations Minières 23-24'!$C$2:$C$105,A5,'Exportations Minières 23-24'!$A$2:$A$105,2023))/B5,"NC") -> 48764.128 | G5: =IFERROR((SUMIFS('Exportations Minières 23-24'!$H$2:$H$105,'Exportations Minières 23-24'!$C$2:$C$105,A5,'Exportations Minières 23-24'!$A$2:$A$105,2024))/C5,"NC") -> 47611.626 | H5: Tonnes
A6: DANGOTE | B6: =SUMIFS('Exportations Minières 23-24'!$G$2:$G$105,'Exportations Minières 23-24'!$C$2:$C$105,A6,'Exportations Minières 23-24'!$A$2:$A$105,2023) -> 289867 | C6: =SUMIFS('Exportations Minières 23-24'!$G$2:$G$105,'Exportations Minières 23-24'!$C$2:$C$105,A6,'Exportations Minières 23-24'!$A$2:$A$105,2024) -> 141620 | D6: =IFERROR((SUMIFS('Exportations Minières 23-24'!$I$2:$I$105,'Exportations Minières 23-24'!$C$2:$C$105,A6,'Exportations Minières 23-24'!$A$2:$A$105,2023))/B6,"NC") -> 81.192316 | E6: =IFERROR((SUMIFS('Exportations Minières 23-24'!$I$2:$I$105,'Exportations Minières 23-24'!$C$2:$C$105,A6,'Exportations Minières 23-24'!$A$2:$A$105,2024))/C6,"NC") -> 134.44735 | F6: =IFERROR((SUMIFS('Exportations Minières 23-24'!$H$2:$H$105,'Exportations Minières 23-24'!$C$2:$C$105,A6,'Exportations Minières 23-24'!$A$2:$A$105,2023))/B6,"NC") -> 49066.607 | G6: =IFERROR((SUMIFS('Exportations Minières 23-24'!$H$2:$H$105,'Exportations Minières 23-24'!$C$2:$C$105,A6,'Exportations Minières 23-24'!$A$2:$A$105,2024))/C6,"NC") -> 81521.989 | H6: Tonnes
A7: SOCOCIM | B7: =SUMIFS('Exportations Minières 23-24'!$G$2:$G$105,'Exportations Minières 23-24'!$C$2:$C$105,A7,'Exportations Minières 23-24'!$A$2:$A$105,2023) -> 176324 | C7: =SUMIFS('Exportations Minières 23-24'!$G$2:$G$105,'Exportations Minières 23-24'!$C$2:$C$105,A7,'Exportations Minières 23-24'!$A$2:$A$105,2024) -> 134679 | D7: =IFERROR((SUMIFS('Exportations Minières 23-24'!$I$2:$I$105,'Exportations Minières 23-24'!$C$2:$C$105,A7,'Exportations Minières 23-24'!$A$2:$A$105,2023))/B7,"NC") -> 82.958928 | E7: =IFERROR((SUMIFS('Exportations Minières 23-24'!$I$2:$I$105,'Exportations Minières 23-24'!$C$2:$C$105,A7,'Exportations Minières 23-24'!$A$2:$A$105,2024))/C7,"NC") -> 83.192881 | F7: =IFERROR((SUMIFS('Exportations Minières 23-24'!$H$2:$H$105,'Exportations Minières 23-24'!$C$2:$C$105,A7,'Exportations Minières 23-24'!$A$2:$A$105,2023))/B7,"NC") -> 50134.216 | G7: =IFERROR((SUMIFS('Exportations Minières 23-24'!$H$2:$H$105,'Exportations Minières 23-24'!$C$2:$C$105,A7,'Exportations Minières 23-24'!$A$2:$A$105,2024))/C7,"NC") -> 50443.662 | H7: Tonnes
A8: GCO | B8: =SUMIFS('Exportations Minières 23-24'!$G$2:$G$105,'Exportations Minières 23-24'!$C$2:$C$105,A8,'Exportations Minières 23-24'!$A$2:$A$105,2023) -> 502049 | C8: =SUMIFS('Exportations Minières 23-24'!$G$2:$G$105,'Exportations Minières 23-24'!$C$2:$C$105,A8,'Exportations Minières 23-24'!$A$2:$A$105,2024) -> 668144 | D8: =IFERROR((SUMIFS('Exportations Minières 23-24'!$I$2:$I$105,'Exportations Minières 23-24'!$C$2:$C$105,A8,'Exportations Minières 23-24'!$A$2:$A$105,2023))/B8,"NC") -> 463.16961 | E8: =IFERROR((SUMIFS('Exportations Minières 23-24'!$I$2:$I$105,'Exportations Minières 23-24'!$C$2:$C$105,A8,'Exportations Minières 23-24'!$A$2:$A$105,2024))/C8,"NC") -> 419.99388 | F8: =IFERROR((SUMIFS('Exportations Minières 23-24'!$H$2:$H$105,'Exportations Minières 23-24'!$C$2:$C$105,A8,'Exportations Minières 23-24'!$A$2:$A$105,2023))/B8,"NC") -> 279905.32 | G8: =IFERROR((SUMIFS('Exportations Minières 23-24'!$H$2:$H$105,'Exportations Minières 23-24'!$C$2:$C$105,A8,'Exportations Minières 23-24'!$A$2:$A$105,2024))/C8,"NC") -> 255220.5 | H8: Tonnes
A9: SOMIVA | B9: =SUMIFS('Exportations Minières 23-24'!$G$2:$G$105,'Exportations Minières 23-24'!$C$2:$C$105,A9,'Exportations Minières 23-24'!$A$2:$A$105,2023) -> 369936 | C9: =SUMIFS('Exportations Minières 23-24'!$G$2:$G$105,'Exportations Minières 23-24'!$C$2:$C$105,A9,'Exportations Minières 23-24'!$A$2:$A$105,2024) -> 230418 | D9: =IFERROR((SUMIFS('Exportations Minières 23-24'!$I$2:$I$105,'Exportations Minières 23-24'!$C$2:$C$105,A9,'Exportations Minières 23-24'!$A$2:$A$105,2023))/B9,"NC") -> 160.44609 | E9: =IFERROR((SUMIFS('Exportations Minières 23-24'!$I$2:$I$105,'Exportations Minières 23-24'!$C$2:$C$105,A9,'Exportations Minières 23-24'!$A$2:$A$105,2024))/C9,"NC") -> 142.68965 | F9: =IFERROR((SUMIFS('Exportations Minières 23-24'!$H$2:$H$105,'Exportations Minières 23-24'!$C$2:$C$105,A9,'Exportations Minières 23-24'!$A$2:$A$105,2023))/B9,"NC") -> 96961.708 | G9: =IFERROR((SUMIFS('Exportations Minières 23-24'!$H$2:$H$105,'Exportations Minières 23-24'!$C$2:$C$105,A9,'Exportations Minières 23-24'!$A$2:$A$105,2024))/C9,"NC") -> 86435.881 | H9: Tonnes
A10: SEPHOS | B10: =SUMIFS('Exportations Minières 23-24'!$G$2:$G$105,'Exportations Minières 23-24'!$C$2:$C$105,A10,'Exportations Minières 23-24'!$A$2:$A$105,2023) -> 114902 | C10: =SUMIFS('Exportations Minières 23-24'!$G$2:$G$105,'Exportations Minières 23-24'!$C$2:$C$105,A10,'Exportations Minières 23-24'!$A$2:$A$105,2024) -> 177129 | D10: =IFERROR((SUMIFS('Exportations Minières 23-24'!$I$2:$I$105,'Exportations Minières 23-24'!$C$2:$C$105,A10,'Exportations Minières 23-24'!$A$2:$A$105,2023))/B10,"NC") -> 137.52579 | E10: =IFERROR((SUMIFS('Exportations Minières 23-24'!$I$2:$I$105,'Exportations Minières 23-24'!$C$2:$C$105,A10,'Exportations Minières 23-24'!$A$2:$A$105,2024))/C10,"NC") -> 119.25145 | F10: =IFERROR((SUMIFS('Exportations Minières 23-24'!$H$2:$H$105,'Exportations Minières 23-24'!$C$2:$C$105,A10,'Exportations Minières 23-24'!$A$2:$A$105,2023))/B10,"NC") -> 83110.376 | G10: =IFERROR((SUMIFS('Exportations Minières 23-24'!$H$2:$H$105,'Exportations Minières 23-24'!$C$2:$C$105,A10,'Exportations Minières 23-24'!$A$2:$A$105,2024))/C10,"NC") -> 72307.846 | H10: Tonnes
A11: BMCC | B11: =SUMIFS('Exportations Minières 23-24'!$G$2:$G$105,'Exportations Minières 23-24'!$C$2:$C$105,A11,'Exportations Minières 23-24'!$A$2:$A$105,2023) -> 120731 | C11: =SUMIFS('Exportations Minières 23-24'!$G$2:$G$105,'Exportations Minières 23-24'!$C$2:$C$105,A11,'Exportations Minières 23-24'!$A$2:$A$105,2024) -> 147335 | D11: =IFERROR((SUMIFS('Exportations Minières 23-24'!$I$2:$I$105,'Exportations Minières 23-24'!$C$2:$C$105,A11,'Exportations Minières 23-24'!$A$2:$A$105,2023))/B11,"NC") -> 95.98857 | E11: =IFERROR((SUMIFS('Exportations Minières 23-24'!$I$2:$I$105,'Exportations Minières 23-24'!$C$2:$C$105,A11,'Exportations Minières 23-24'!$A$2:$A$105,2024))/C11,"NC") -> 113.05625 | F11: =IFERROR((SUMIFS('Exportations Minières 23-24'!$H$2:$H$105,'Exportations Minières 23-24'!$C$2:$C$105,A11,'Exportations Minières 23-24'!$A$2:$A$105,2023))/B11,"NC") -> 58008.365 | G11: =IFERROR((SUMIFS('Exportations Minières 23-24'!$H$2:$H$105,'Exportations Minières 23-24'!$C$2:$C$105,A11,'Exportations Minières 23-24'!$A$2:$A$105,2024))/C11,"NC") -> 68551.398 | H11: Tonnes
A12: SSPT | B12: =SUMIFS('Exportations Minières 23-24'!$G$2:$G$105,'Exportations Minières 23-24'!$C$2:$C$105,A12,'Exportations Minières 23-24'!$A$2:$A$105,2023) -> 180760 | C12: =SUMIFS('Exportations Minières 23-24'!$G$2:$G$105,'Exportations Minières 23-24'!$C$2:$C$105,A12,'Exportations Minières 23-24'!$A$2:$A$105,2024) -> 156542 | D12: =IFERROR((SUMIFS('Exportations Minières 23-24'!$I$2:$I$105,'Exportations Minières 23-24'!$C$2:$C$105,A12,'Exportations Minières 23-24'!$A$2:$A$105,2023))/B12,"NC") -> 43.271183 | E12: =IFERROR((SUMIFS('Exportations Minières 23-24'!$I$2:$I$105,'Exportations Minières 23-24'!$C$2:$C$105,A12,'Exportations Minières 23-24'!$A$2:$A$105,2024))/C12,"NC") -> 44.082777 | F12: =IFERROR((SUMIFS('Exportations Minières 23-24'!$H$2:$H$105,'Exportations Minières 23-24'!$C$2:$C$105,A12,'Exportations Minières 23-24'!$A$2:$A$105,2023))/B12,"NC") -> 26149.89 | G12: =IFERROR((SUMIFS('Exportations Minières 23-24'!$H$2:$H$105,'Exportations Minières 23-24'!$C$2:$C$105,A12,'Exportations Minières 23-24'!$A$2:$A$105,2024))/C12,"NC") -> 26729.49 | H12: Tonnes
A13: COGECA | B13: =SUMIFS('Exportations Minières 23-24'!$G$2:$G$105,'Exportations Minières 23-24'!$C$2:$C$105,A13,'Exportations Minières 23-24'!$A$2:$A$105,2023) -> 22058 | C13: =SUMIFS('Exportations Minières 23-24'!$G$2:$G$105,'Exportations Minières 23-24'!$C$2:$C$105,A13,'Exportations Minières 23-24'!$A$2:$A$105,2024) -> 25201 | D13: =IFERROR((SUMIFS('Exportations Minières 23-24'!$I$2:$I$105,'Exportations Minières 23-24'!$C$2:$C$105,A13,'Exportations Minières 23-24'!$A$2:$A$105,2023))/B13,"NC") -> 3.5173633 | E13: =IFERROR((SUMIFS('Exportations Minières 23-24'!$I$2:$I$105,'Exportations Minières 23-24'!$C$2:$C$105,A13,'Exportations Minières 23-24'!$A$2:$A$105,2024))/C13,"NC") -> 4.1349946 | F13: =IFERROR((SUMIFS('Exportations Minières 23-24'!$H$2:$H$105,'Exportations Minières 23-24'!$C$2:$C$105,A13,'Exportations Minières 23-24'!$A$2:$A$105,2023))/B13,"NC") -> 2125.6458 | G13: =IFERROR((SUMIFS('Exportations Minières 23-24'!$H$2:$H$105,'Exportations Minières 23-24'!$C$2:$C$105,A13,'Exportations Minières 23-24'!$A$2:$A$105,2024))/C13,"NC") -> 2507.226 | H13: Tonnes
... A15: GECAMINE | B15: =SUMIFS('Exportations Minières 23-24'!$G$2:$G$105,'Exportations Minières 23-24'!$C$2:$C$105,A15,'Exportations Minières 23-24'!$A$2:$A$105,2023) -> 65839 | C15: =SUMIFS('Exportations Minières 23-24'!$G$2:$G$105,'Exportations Minières 23-24'!$C$2:$C$105,A15,'Exportations Minières 23-24'!$A$2:$A$105,2024) -> 340661 | D15: =IFERROR((SUMIFS('Exportations Minières 23-24'!$I$2:$I$105,'Exportations Minières 23-24'!$C$2:$C$105,A15,'Exportations Minières 23-24'!$A$2:$A$105,2023))/B15,"NC") -> 14.24405 | E15: =IFERROR((SUMIFS('Exportations Minières 23-24'!$I$2:$I$105,'Exportations Minières 23-24'!$C$2:$C$105,A15,'Exportations Minières 23-24'!$A$2:$A$105,2024))/C15,"NC") -> 14.868233 | F15: =IFERROR((SUMIFS('Exportations Minières 23-24'!$H$2:$H$105,'Exportations Minières 23-24'!$C$2:$C$105,A15,'Exportations Minières 23-24'!$A$2:$A$105,2023))/B15,"NC") -> 8608.0416 | G15: =IFERROR((SUMIFS('Exportations Minières 23-24'!$H$2:$H$105,'Exportations Minières 23-24'!$C$2:$C$105,A15,'Exportations Minières 23-24'!$A$2:$A$105,2024))/C15,"NC") -> 9015.3251 | H15: Tonnes

Sheet Prix par Substance
A1: Type de minerai | B1: Volume 2023 | C1: Volume 2024 | D1: Prix moyen pondéré USD 2023 | E1: Prix moyen pondéré USD 2024 | F1: Prix moyen pondéré FCFA 2023 | G1: Prix moyen pondéré FCFA 2024 | H1: Unité
A2: Or | B2: =SUMIFS('Exportations Minières 23-24'!$G$2:$G$105,'Exportations Minières 23-24'!$B$2:$B$105,A2,'Exportations Minières 23-24'!$A$2:$A$105,2023) -> 416647 | C2: =SUMIFS('Exportations Minières 23-24'!$G$2:$G$105,'Exportations Minières 23-24'!$B$2:$B$105,A2,'Exportations Minières 23-24'!$A$2:$A$105,2024) -> 343042 | D2: =IFERROR((SUMIFS('Exportations Minières 23-24'!$I$2:$I$105,'Exportations Minières 23-24'!$B$2:$B$105,A2,'Exportations Minières 23-24'!$A$2:$A$105,2023))/B2,"NC") -> 1953.5091 | E2: =IFERROR((SUMIFS('Exportations Minières 23-24'!$I$2:$I$105,'Exportations Minières 23-24'!$B$2:$B$105,A2,'Exportations Minières 23-24'!$A$2:$A$105,2024))/C2,"NC") -> 2433.8888 | F2: =IFERROR((SUMIFS('Exportations Minières 23-24'!$H$2:$H$105,'Exportations Minières 23-24'!$B$2:$B$105,A2,'Exportations Minières 23-24'!$A$2:$A$105,2023))/B2,"NC") -> 1180555.8 | G2: =IFERROR((SUMIFS('Exportations Minières 23-24'!$H$2:$H$105,'Exportations Minières 23-24'!$B$2:$B$105,A2,'Exportations Minières 23-24'!$A$2:$A$105,2024))/C2,"NC") -> 1463239.6 | H2: Onces
A3: Acide Phosphorique | B3: =SUMIFS('Exportations Minières 23-24'!$G$2:$G$105,'Exportations Minières 23-24'!$B$2:$B$105,A3,'Exportations Minières 23-24'!$A$2:$A$105,2023) -> 508678 | C3: =SUMIFS('Exportations Minières 23-24'!$G$2:$G$105,'Exportations Minières 23-24'!$B$2:$B$105,A3,'Exportations Minières 23-24'!$A$2:$A$105,2024) -> 483393 | D3: =IFERROR((SUMIFS('Exportations Minières 23-24'!$I$2:$I$105,'Exportations Minières 23-24'!$B$2:$B$105,A3,'Exportations Minières 23-24'!$A$2:$A$105,2023))/B3,"NC") -> 978.28798 | E3: =IFERROR((SUMIFS('Exportations Minières 23-24'!$I$2:$I$105,'Exportations Minières 23-24'!$B$2:$B$105,A3,'Exportations Minières 23-24'!$A$2:$A$105,2024))/C3,"NC") -> 980.98586 | F3: =IFERROR((SUMIFS('Exportations Minières 23-24'!$H$2:$H$105,'Exportations Minières 23-24'!$B$2:$B$105,A3,'Exportations Minières 23-24'!$A$2:$A$105,2023))/B3,"NC") -> 591204.62 | G3: =IFERROR((SUMIFS('Exportations Minières 23-24'!$H$2:$H$105,'Exportations Minières 23-24'!$B$2:$B$105,A3,'Exportations Minières 23-24'!$A$2:$A$105,2024))/C3,"NC") -> 594793.82 | H3: MT
A4: Ciment | B4: =SUMIFS('Exportations Minières 23-24'!$G$2:$G$105,'Exportations Minières 23-24'!$B$2:$B$105,A4,'Exportations Minières 23-24'!$A$2:$A$105,2023) -> 1974954 | C4: =SUMIFS('Exportations Minières 23-24'!$G$2:$G$105,'Exportations Minières 23-24'!$B$2:$B$105,A4,'Exportations Minières 23-24'!$A$2:$A$105,2024) -> 1793357 | D4: =IFERROR((SUMIFS('Exportations Minières 23-24'!$I$2:$I$105,'Exportations Minières 23-24'!$B$2:$B$105,A4,'Exportations Minières 23-24'!$A$2:$A$105,2023))/B4,"NC") -> 81.001622 | E4: =IFERROR((SUMIFS('Exportations Minières 23-24'!$I$2:$I$105,'Exportations Minières 23-24'!$B$2:$B$105,A4,'Exportations Minières 23-24'!$A$2:$A$105,2024))/C4,"NC") -> 83.289145 | F4: =IFERROR((SUMIFS('Exportations Minières 23-24'!$H$2:$H$105,'Exportations Minières 23-24'!$B$2:$B$105,A4,'Exportations Minières 23-24'!$A$2:$A$105,2023))/B4,"NC") -> 48951.366 | G4: =IFERROR((SUMIFS('Exportations Minières 23-24'!$H$2:$H$105,'Exportations Minières 23-24'!$B$2:$B$105,A4,'Exportations Minières 23-24'!$A$2:$A$105,2024))/C4,"NC") -> 50502.184 | H4: Tonnes
A5: Ilmenite 54 | B5: =SUMIFS('Exportations Minières 23-24'!$G$2:$G$105,'Exportations Minières 23-24'!$B$2:$B$105,A5,'Exportations Minières 23-24'!$A$2:$A$105,2023) -> 292907 | C5: =SUMIFS('Exportations Minières 23-24'!$G$2:$G$105,'Exportations Minières 23-24'!$B$2:$B$105,A5,'Exportations Minières 23-24'!$A$2:$A$105,2024) -> 387783 | D5: =IFERROR((SUMIFS('Exportations Minières 23-24'!$I$2:$I$105,'Exportations Minières 23-24'!$B$2:$B$105,A5,'Exportations Minières 23-24'!$A$2:$A$105,2023))/B5,"NC") -> 303.70133 | E5: =IFERROR((SUMIFS('Exportations Minières 23-24'!$I$2:$I$105,'Exportations Minières 23-24'!$B$2:$B$105,A5,'Exportations Minières 23-24'!$A$2:$A$105,2024))/C5,"NC") -> 242.18189 | F5: =IFERROR((SUMIFS('Exportations Minières 23-24'!$H$2:$H$105,'Exportations Minières 23-24'!$B$2:$B$105,A5,'Exportations Minières 23-24'!$A$2:$A$105,2023))/B5,"NC") -> 183534.53 | G5: =IFERROR((SUMIFS('Exportations Minières 23-24'!$H$2:$H$105,'Exportations Minières 23-24'!$B$2:$B$105,A5,'Exportations Minières 23-24'!$A$2:$A$105,2024))/C5,"NC") -> 147296.34 | H5: Tonnes
A6: Phosphate | B6: =SUMIFS('Exportations Minières 23-24'!$G$2:$G$105,'Exportations Minières 23-24'!$B$2:$B$105,A6,'Exportations Minières 23-24'!$A$2:$A$105,2023) -> 605569 | C6: =SUMIFS('Exportations Minières 23-24'!$G$2:$G$105,'Exportations Minières 23-24'!$B$2:$B$105,A6,'Exportations Minières 23-24'!$A$2:$A$105,2024) -> 147335 | D6: =IFERROR((SUMIFS('Exportations Minières 23-24'!$I$2:$I$105,'Exportations Minières 23-24'!$B$2:$B$105,A6,'Exportations Minières 23-24'!$A$2:$A$105,2023))/B6,"NC") -> 143.24638 | E6: =IFERROR((SUMIFS('Exportations Minières 23-24'!$I$2:$I$105,'Exportations Minières 23-24'!$B$2:$B$105,A6,'Exportations Minières 23-24'!$A$2:$A$105,2024))/C6,"NC") -> 113.05625 | F6: =IFERROR((SUMIFS('Exportations Minières 23-24'!$H$2:$H$105,'Exportations Minières 23-24'!$B$2:$B$105,A6,'Exportations Minières 23-24'!$A$2:$A$105,2023))/B6,"NC") -> 86567.481 | G6: =IFERROR((SUMIFS('Exportations Minières 23-24'!$H$2:$H$105,'Exportations Minières 23-24'!$B$2:$B$105,A6,'Exportations Minières 23-24'!$A$2:$A$105,2024))/C6,"NC") -> 68551.398 | H6: Tonnes
A7: Zircon Premium | B7: =SUMIFS('Exportations Minières 23-24'!$G$2:$G$105,'Exportations Minières 23-24'!$B$2:$B$105,A7,'Exportations Minières 23-24'!$A$2:$A$105,2023) -> 28177 | C7: =SUMIFS('Exportations Minières 23-24'!$G$2:$G$105,'Exportations Minières 23-24'!$B$2:$B$105,A7,'Exportations Minières 23-24'!$A$2:$A$105,2024) -> 39376 | D7: =IFERROR((SUMIFS('Exportations Minières 23-24'!$I$2:$I$105,'Exportations Minières 23-24'!$B$2:$B$105,A7,'Exportations Minières 23-24'!$A$2:$A$105,2023))/B7,"NC") -> 1931.166 | E7: =IFERROR((SUMIFS('Exportations Minières 23-24'!$I$2:$I$105,'Exportations Minières 23-24'!$B$2:$B$105,A7,'Exportations Minières 23-24'!$A$2:$A$105,2024))/C7,"NC") -> 1828.4475 | F7: =IFERROR((SUMIFS('Exportations Minières 23-24'!$H$2:$H$105,'Exportations Minières 23-24'!$B$2:$B$105,A7,'Exportations Minières 23-24'!$A$2:$A$105,2023))/B7,"NC") -> 1167053.4 | G7: =IFERROR((SUMIFS('Exportations Minières 23-24'!$H$2:$H$105,'Exportations Minières 23-24'!$B$2:$B$105,A7,'Exportations Minières 23-24'!$A$2:$A$105,2024))/C7,"NC") -> 1109336.1 | H7: Tonnes
A8: Zircon Standard | B8: =SUMIFS('Exportations Minières 23-24'!$G$2:$G$105,'Exportations Minières 23-24'!$B$2:$B$105,A8,'Exportations Minières 23-24'!$A$2:$A$105,2023) -> 19379 | C8: =SUMIFS('Exportations Minières 23-24'!$G$2:$G$105,'Exportations Minières 23-24'!$B$2:$B$105,A8,'Exportations Minières 23-24'!$A$2:$A$105,2024) -> 27523 | D8: =IFERROR((SUMIFS('Exportations Minières 23-24'!$I$2:$I$105,'Exportations Minières 23-24'!$B$2:$B$105,A8,'Exportations Minières 23-24'!$A$2:$A$105,2023))/B8,"NC") -> 1782.2886 | E8: =IFERROR((SUMIFS('Exportations Minières 23-24'!$I$2:$I$105,'Exportations Minières 23-24'!$B$2:$B$105,A8,'Exportations Minières 23-24'!$A$2:$A$105,2024))/C8,"NC") -> 1719.2661 | F8: =IFERROR((SUMIFS('Exportations Minières 23-24'!$H$2:$H$105,'Exportations Minières 23-24'!$B$2:$B$105,A8,'Exportations Minières 23-24'!$A$2:$A$105,2023))/B8,"NC") -> 1077082.9 | G8: =IFERROR((SUMIFS('Exportations Minières 23-24'!$H$2:$H$105,'Exportations Minières 23-24'!$B$2:$B$105,A8,'Exportations Minières 23-24'!$A$2:$A$105,2024))/C8,"NC") -> 1046555.4 | H8: Tonnes
A9: Ilmenite 58 | B9: =SUMIFS('Exportations Minières 23-24'!$G$2:$G$105,'Exportations Minières 23-24'!$B$2:$B$105,A9,'Exportations Minières 23-24'!$A$2:$A$105,2023) -> 111716 | C9: =SUMIFS('Exportations Minières 23-24'!$G$2:$G$105,'Exportations Minières 23-24'!$B$2:$B$105,A9,'Exportations Minières 23-24'!$A$2:$A$105,2024) -> 153286 | D9: =IFERROR((SUMIFS('Exportations Minières 23-24'!$I$2:$I$105,'Exportations Minières 23-24'!$B$2:$B$105,A9,'Exportations Minières 23-24'!$A$2:$A$105,2023))/B9,"NC") -> 292.29415 | E9: =IFERROR((SUMIFS('Exportations Minières 23-24'!$I$2:$I$105,'Exportations Minières 23-24'!$B$2:$B$105,A9,'Exportations Minières 23-24'!$A$2:$A$105,2024))/C9,"NC") -> 284.28992 | F9: =IFERROR((SUMIFS('Exportations Minières 23-24'!$H$2:$H$105,'Exportations Minières 23-24'!$B$2:$B$105,A9,'Exportations Minières 23-24'!$A$2:$A$105,2023))/B9,"NC") -> 176640.88 | G9: =IFERROR((SUMIFS('Exportations Minières 23-24'!$H$2:$H$105,'Exportations Minières 23-24'!$B$2:$B$105,A9,'Exportations Minières 23-24'!$A$2:$A$105,2024))/C9,"NC") -> 172522.58 | H9: Tonnes
A10: NPK | B10: =SUMIFS('Exportations Minières 23-24'!$G$2:$G$105,'Exportations Minières 23-24'!$B$2:$B$105,A10,'Exportations Minières 23-24'!$A$2:$A$105,2023) -> 47440 | C10: =SUMIFS('Exportations Minières 23-24'!$G$2:$G$105,'Exportations Minières 23-24'!$B$2:$B$105,A10,'Exportations Minières 23-24'!$A$2:$A$105,2024) -> 0 | D10: =IFERROR((SUMIFS('Exportations Minières 23-24'!$I$2:$I$105,'Exportations Minières 23-24'!$B$2:$B$105,A10,'Exportations Minières 23-24'!$A$2:$A$105,2023))/B10,"NC") -> 682.96429 | E10: =IFERROR((SUMIFS('Exportations Minières 23-24'!$I$2:$I$105,'Exportations Minières 23-24'!$B$2:$B$105,A10,'Exportations Minières 23-24'!$A$2:$A$105,2024))/C10,"NC") -> NC | F10: =IFERROR((SUMIFS('Exportations Minières 23-24'!$H$2:$H$105,'Exportations Minières 23-24'!$B$2:$B$105,A10,'Exportations Minières 23-24'!$A$2:$A$105,2023))/B10,"NC") -> 412732.9 | G10: =IFERROR((SUMIFS('Exportations Minières 23-24'!$H$2:$H$105,'Exportations Minières 23-24'!$B$2:$B$105,A10,'Exportations Minières 23-24'!$A$2:$A$105,2024))/C10,"NC") -> NC | H10: MT
A11: Attapulgite | B11: =SUMIFS('Exportations Minières 23-24'!$G$2:$G$105,'Exportations Minières 23-24'!$B$2:$B$105,A11,'Exportations Minières 23-24'!$A$2:$A$105,2023) -> 180760 | C11: =SUMIFS('Exportations Minières 23-24'!$G$2:$G$105,'Exportations Minières 23-24'!$B$2:$B$105,A11,'Exportations Minières 23-24'!$A$2:$A$105,2024) -> 156542 | D11: =IFERROR((SUMIFS('Exportations Minières 23-24'!$I$2:$I$105,'Exportations Minières 23-24'!$B$2:$B$105,A11,'Exportations Minières 23-24'!$A$2:$A$105,2023))/B11,"NC") -> 43.271183 | E11: =IFERROR((SUMIFS('Exportations Minières 23-24'!$I$2:$I$105,'Exportations Minières 23-24'!$B$2:$B$105,A11,'Exportations Minières 23-24'!$A$2:$A$105,2024))/C11,"NC") -> 44.082777 | F11: =IFERROR((SUMIFS('Exportations Minières 23-24'!$H$2:$H$105,'Exportations Minières 23-24'!$B$2:$B$105,A11,'Exportations Minières 23-24'!$A$2:$A$105,2023))/B11,"NC") -> 26149.89 | G11: =IFERROR((SUMIFS('Exportations Minières 23-24'!$H$2:$H$105,'Exportations Minières 23-24'!$B$2:$B$105,A11,'Exportations Minières 23-24'!$A$2:$A$105,2024))/C11,"NC") -> 26729.49 | H11: Tonnes
A12: Leucoxene | B12: =SUMIFS('Exportations Minières 23-24'!$G$2:$G$105,'Exportations Minières 23-24'!$B$2:$B$105,A12,'Exportations Minières 23-24'!$A$2:$A$105,2023) -> 4820 | C12: =SUMIFS('Exportations Minières 23-24'!$G$2:$G$105,'Exportations Minières 23-24'!$B$2:$B$105,A12,'Exportations Minières 23-24'!$A$2:$A$105,2024) -> 6092 | D12: =IFERROR((SUMIFS('Exportations Minières 23-24'!$I$2:$I$105,'Exportations Minières 23-24'!$B$2:$B$105,A12,'Exportations Minières 23-24'!$A$2:$A$105,2023))/B12,"NC") -> 1318.9971 | E12: =IFERROR((SUMIFS('Exportations Minières 23-24'!$I$2:$I$105,'Exportations Minières 23-24'!$B$2:$B$105,A12,'Exportations Minières 23-24'!$A$2:$A$105,2024))/C12,"NC") -> 1223.5245 | F12: =IFERROR((SUMIFS('Exportations Minières 23-24'!$H$2:$H$105,'Exportations Minières 23-24'!$B$2:$B$105,A12,'Exportations Minières 23-24'!$A$2:$A$105,2023))/B12,"NC") -> 797103.95 | G12: =IFERROR((SUMIFS('Exportations Minières 23-24'!$H$2:$H$105,'Exportations Minières 23-24'!$B$2:$B$105,A12,'Exportations Minières 23-24'!$A$2:$A$105,2024))/C12,"NC") -> 745223.81 | H12: Tonnes
A13: Rutile | B13: =SUMIFS('Exportations Minières 23-24'!$G$2:$G$105,'Exportations Minières 23-24'!$B$2:$B$105,A13,'Exportations Minières 23-24'!$A$2:$A$105,2023) -> 3062 | C13: =SUMIFS('Exportations Minières 23-24'!$G$2:$G$105,'Exportations Minières 23-24'!$B$2:$B$105,A13,'Exportations Minières 23-24'!$A$2:$A$105,2024) -> 2640 | D13: =IFERROR((SUMIFS('Exportations Minières 23-24'!$I$2:$I$105,'Exportations Minières 23-24'!$B$2:$B$105,A13,'Exportations Minières 23-24'!$A$2:$A$105,2023))/B13,"NC") -> 1951.0509 | E13: =IFERROR((SUMIFS('Exportations Minières 23-24'!$I$2:$I$105,'Exportations Minières 23-24'!$B$2:$B$105,A13,'Exportations Minières 23-24'!$A$2:$A$105,2024))/C13,"NC") -> 1785.6689 | F13: =IFERROR((SUMIFS('Exportations Minières 23-24'!$H$2:$H$105,'Exportations Minières 23-24'!$B$2:$B$105,A13,'Exportations Minières 23-24'!$A$2:$A$105,2023))/B13,"NC") -> 1179070.2 | G13: =IFERROR((SUMIFS('Exportations Minières 23-24'!$H$2:$H$105,'Exportations Minières 23-24'!$B$2:$B$105,A13,'Exportations Minières 23-24'!$A$2:$A$105,2024))/C13,"NC") -> 1083946.4 | H13: Tonnes
... A27: DSP - Sac 50 Kg | B27: =SUMIFS('Exportations Minières 23-24'!$G$2:$G$105,'Exportations Minières 23-24'!$B$2:$B$105,A27,'Exportations Minières 23-24'!$A$2:$A$105,2023) -> 0 | C27: =SUMIFS('Exportations Minières 23-24'!$G$2:$G$105,'Exportations Minières 23-24'!$B$2:$B$105,A27,'Exportations Minières 23-24'!$A$2:$A$105,2024) -> 1061 | D27: =IFERROR((SUMIFS('Exportations Minières 23-24'!$I$2:$I$105,'Exportations Minières 23-24'!$B$2:$B$105,A27,'Exportations Minières 23-24'!$A$2:$A$105,2023))/B27,"NC") -> NC | E27: =IFERROR((SUMIFS('Exportations Minières 23-24'!$I$2:$I$105,'Exportations Minières 23-24'!$B$2:$B$105,A27,'Exportations Minières 23-24'!$A$2:$A$105,2024))/C27,"NC") -> 139.94062 | F27: =IFERROR((SUMIFS('Exportations Minières 23-24'!$H$2:$H$105,'Exportations Minières 23-24'!$B$2:$B$105,A27,'Exportations Minières 23-24'!$A$2:$A$105,2023))/B27,"NC") -> NC | G27: =IFERROR((SUMIFS('Exportations Minières 23-24'!$H$2:$H$105,'Exportations Minières 23-24'!$B$2:$B$105,A27,'Exportations Minières 23-24'!$A$2:$A$105,2024))/C27,"NC") -> 85000 | H27: MT

Sheet Prix par Société et Substance
A1: Société | B1: Type de minerai | C1: Volume 2023 | D1: Volume 2024 | E1: Prix moyen pondéré USD 2023 | F1: Prix moyen pondéré USD 2024 | G1: Prix moyen pondéré FCFA 2023 | H1: Prix moyen pondéré FCFA 2024 | I1: Unité
A2: SGO | B2: Or | C2: =SUMIFS('Exportations Minières 23-24'!$G$2:$G$105,'Exportations Minières 23-24'!$C$2:$C$105,A2,'Exportations Minières 23-24'!$B$2:$B$105,B2,'Exportations Minières 23-24'!$A$2:$A$105,2023) -> 296697 | D2: =SUMIFS('Exportations Minières 23-24'!$G$2:$G$105,'Exportations Minières 23-24'!$C$2:$C$105,A2,'Exportations Minières 23-24'!$B$2:$B$105,B2,'Exportations Minières 23-24'!$A$2:$A$105,2024) -> 221419 | E2: =IFERROR((SUMIFS('Exportations Minières 23-24'!$I$2:$I$105,'Exportations Minières 23-24'!$C$2:$C$105,A2,'Exportations Minières 23-24'!$B$2:$B$105,B2,'Exportations Minières 23-24'!$A$2:$A$105,2023))/C2,"NC") -> 1973.0293 | F2: =IFERROR((SUMIFS('Exportations Minières 23-24'!$I$2:$I$105,'Exportations Minières 23-24'!$C$2:$C$105,A2,'Exportations Minières 23-24'!$B$2:$B$105,B2,'Exportations Minières 23-24'!$A$2:$A$105,2024))/D2,"NC") -> 2449.7784 | G2: =IFERROR((SUMIFS('Exportations Minières 23-24'!$H$2:$H$105,'Exportations Minières 23-24'!$C$2:$C$105,A2,'Exportations Minières 23-24'!$B$2:$B$105,B2,'Exportations Minières 23-24'!$A$2:$A$105,2023))/C2,"NC") -> 1192352.4 | H2: =IFERROR((SUMIFS('Exportations Minières 23-24'!$H$2:$H$105,'Exportations Minières 23-24'!$C$2:$C$105,A2,'Exportations Minières 23-24'!$B$2:$B$105,B2,'Exportations Minières 23-24'!$A$2:$A$105,2024))/D2,"NC") -> 1468075.5 | I2: Onces
A3: PMC | B3: Or | C3: =SUMIFS('Exportations Minières 23-24'!$G$2:$G$105,'Exportations Minières 23-24'!$C$2:$C$105,A3,'Exportations Minières 23-24'!$B$2:$B$105,B3,'Exportations Minières 23-24'!$A$2:$A$105,2023) -> 119950 | D3: =SUMIFS('Exportations Minières 23-24'!$G$2:$G$105,'Exportations Minières 23-24'!$C$2:$C$105,A3,'Exportations Minières 23-24'!$B$2:$B$105,B3,'Exportations Minières 23-24'!$A$2:$A$105,2024) -> 121623 | E3: =IFERROR((SUMIFS('Exportations Minières 23-24'!$I$2:$I$105,'Exportations Minières 23-24'!$C$2:$C$105,A3,'Exportations Minières 23-24'!$B$2:$B$105,B3,'Exportations Minières 23-24'!$A$2:$A$105,2023))/C3,"NC") -> 1905.2256 | F3: =IFERROR((SUMIFS('Exportations Minières 23-24'!$I$2:$I$105,'Exportations Minières 23-24'!$C$2:$C$105,A3,'Exportations Minières 23-24'!$B$2:$B$105,B3,'Exportations Minières 23-24'!$A$2:$A$105,2024))/D3,"NC") -> 2404.9613 | G3: =IFERROR((SUMIFS('Exportations Minières 23-24'!$H$2:$H$105,'Exportations Minières 23-24'!$C$2:$C$105,A3,'Exportations Minières 23-24'!$B$2:$B$105,B3,'Exportations Minières 23-24'!$A$2:$A$105,2023))/C3,"NC") -> 1151376.9 | H3: =IFERROR((SUMIFS('Exportations Minières 23-24'!$H$2:$H$105,'Exportations Minières 23-24'!$C$2:$C$105,A3,'Exportations Minières 23-24'!$B$2:$B$105,B3,'Exportations Minières 23-24'!$A$2:$A$105,2024))/D3,"NC") -> 1454435.7 | I3: Onces
A4: ICS | B4: Acide Phosphorique | C4: =SUMIFS('Exportations Minières 23-24'!$G$2:$G$105,'Exportations Minières 23-24'!$C$2:$C$105,A4,'Exportations Minières 23-24'!$B$2:$B$105,B4,'Exportations Minières 23-24'!$A$2:$A$105,2023) -> 508678 | D4: =SUMIFS('Exportations Minières 23-24'!$G$2:$G$105,'Exportations Minières 23-24'!$C$2:$C$105,A4,'Exportations Minières 23-24'!$B$2:$B$105,B4,'Exportations Minières 23-24'!$A$2:$A$105,2024) -> 483393 | E4: =IFERROR((SUMIFS('Exportations Minières 23-24'!$I$2:$I$105,'Exportations Minières 23-24'!$C$2:$C$105,A4,'Exportations Minières 23-24'!$B$2:$B$105,B4,'Exportations Minières 23-24'!$A$2:$A$105,2023))/C4,"NC") -> 978.28798 | F4: =IFERROR((SUMIFS('Exportations Minières 23-24'!$I$2:$I$105,'Exportations Minières 23-24'!$C$2:$C$105,A4,'Exportations Minières 23-24'!$B$2:$B$105,B4,'Exportations Minières 23-24'!$A$2:$A$105,2024))/D4,"NC") -> 980.98586 | G4: =IFERROR((SUMIFS('Exportations Minières 23-24'!$H$2:$H$105,'Exportations Minières 23-24'!$C$2:$C$105,A4,'Exportations Minières 23-24'!$B$2:$B$105,B4,'Exportations Minières 23-24'!$A$2:$A$105,2023))/C4,"NC") -> 591204.62 | H4: =IFERROR((SUMIFS('Exportations Minières 23-24'!$H$2:$H$105,'Exportations Minières 23-24'!$C$2:$C$105,A4,'Exportations Minières 23-24'!$B$2:$B$105,B4,'Exportations Minières 23-24'!$A$2:$A$105,2024))/D4,"NC") -> 594793.82 | I4: MT
A5: CDS | B5: Ciment | C5: =SUMIFS('Exportations Minières 23-24'!$G$2:$G$105,'Exportations Minières 23-24'!$C$2:$C$105,A5,'Exportations Minières 23-24'!$B$2:$B$105,B5,'Exportations Minières 23-24'!$A$2:$A$105,2023) -> 1512362 | D5: =SUMIFS('Exportations Minières 23-24'!$G$2:$G$105,'Exportations Minières 23-24'!$C$2:$C$105,A5,'Exportations Minières 23-24'!$B$2:$B$105,B5,'Exportations Minières 23-24'!$A$2:$A$105,2024) -> 1517058 | E5: =IFERROR((SUMIFS('Exportations Minières 23-24'!$I$2:$I$105,'Exportations Minières 23-24'!$C$2:$C$105,A5,'Exportations Minières 23-24'!$B$2:$B$105,B5,'Exportations Minières 23-24'!$A$2:$A$105,2023))/C5,"NC") -> 80.691793 | F5: =IFERROR((SUMIFS('Exportations Minières 23-24'!$I$2:$I$105,'Exportations Minières 23-24'!$C$2:$C$105,A5,'Exportations Minières 23-24'!$B$2:$B$105,B5,'Exportations Minières 23-24'!$A$2:$A$105,2024))/D5,"NC") -> 78.521984 | G5: =IFERROR((SUMIFS('Exportations Minières 23-24'!$H$2:$H$105,'Exportations Minières 23-24'!$C$2:$C$105,A5,'Exportations Minières 23-24'!$B$2:$B$105,B5,'Exportations Minières 23-24'!$A$2:$A$105,2023))/C5,"NC") -> 48764.128 | H5: =IFERROR((SUMIFS('Exportations Minières 23-24'!$H$2:$H$105,'Exportations Minières 23-24'!$C$2:$C$105,A5,'Exportations Minières 23-24'!$B$2:$B$105,B5,'Exportations Minières 23-24'!$A$2:$A$105,2024))/D5,"NC") -> 47611.626 | I5: Tonnes
A6: DANGOTE | B6: Ciment | C6: =SUMIFS('Exportations Minières 23-24'!$G$2:$G$105,'Exportations Minières 23-24'!$C$2:$C$105,A6,'Exportations Minières 23-24'!$B$2:$B$105,B6,'Exportations Minières 23-24'!$A$2:$A$105,2023) -> 289867 | D6: =SUMIFS('Exportations Minières 23-24'!$G$2:$G$105,'Exportations Minières 23-24'!$C$2:$C$105,A6,'Exportations Minières 23-24'!$B$2:$B$105,B6,'Exportations Minières 23-24'!$A$2:$A$105,2024) -> 141620 | E6: =IFERROR((SUMIFS('Exportations Minières 23-24'!$I$2:$I$105,'Exportations Minières 23-24'!$C$2:$C$105,A6,'Exportations Minières 23-24'!$B$2:$B$105,B6,'Exportations Minières 23-24'!$A$2:$A$105,2023))/C6,"NC") -> 81.192316 | F6: =IFERROR((SUMIFS('Exportations Minières 23-24'!$I$2:$I$105,'Exportations Minières 23-24'!$C$2:$C$105,A6,'Exportations Minières 23-24'!$B$2:$B$105,B6,'Exportations Minières 23-24'!$A$2:$A$105,2024))/D6,"NC") -> 134.44735 | G6: =IFERROR((SUMIFS('Exportations Minières 23-24'!$H$2:$H$105,'Exportations Minières 23-24'!$C$2:$C$105,A6,'Exportations Minières 23-24'!$B$2:$B$105,B6,'Exportations Minières 23-24'!$A$2:$A$105,2023))/C6,"NC") -> 49066.607 | H6: =IFERROR((SUMIFS('Exportations Minières 23-24'!$H$2:$H$105,'Exportations Minières 23-24'!$C$2:$C$105,A6,'Exportations Minières 23-24'!$B$2:$B$105,B6,'Exportations Minières 23-24'!$A$2:$A$105,2024))/D6,"NC") -> 81521.989 | I6: Tonnes
A7: SOCOCIM | B7: Ciment | C7: =SUMIFS('Exportations Minières 23-24'!$G$2:$G$105,'Exportations Minières 23-24'!$C$2:$C$105,A7,'Exportations Minières 23-24'!$B$2:$B$105,B7,'Exportations Minières 23-24'!$A$2:$A$105,2023) -> 172725 | D7: =SUMIFS('Exportations Minières 23-24'!$G$2:$G$105,'Exportations Minières 23-24'!$C$2:$C$105,A7,'Exportations Minières 23-24'!$B$2:$B$105,B7,'Exportations Minières 23-24'!$A$2:$A$105,2024) -> 134679 | E7: =IFERROR((SUMIFS('Exportations Minières 23-24'!$I$2:$I$105,'Exportations Minières 23-24'!$C$2:$C$105,A7,'Exportations Minières 23-24'!$B$2:$B$105,B7,'Exportations Minières 23-24'!$A$2:$A$105,2023))/C7,"NC") -> 83.394436 | F7: =IFERROR((SUMIFS('Exportations Minières 23-24'!$I$2:$I$105,'Exportations Minières 23-24'!$C$2:$C$105,A7,'Exportations Minières 23-24'!$B$2:$B$105,B7,'Exportations Minières 23-24'!$A$2:$A$105,2024))/D7,"NC") -> 83.192881 | G7: =IFERROR((SUMIFS('Exportations Minières 23-24'!$H$2:$H$105,'Exportations Minières 23-24'!$C$2:$C$105,A7,'Exportations Minières 23-24'!$B$2:$B$105,B7,'Exportations Minières 23-24'!$A$2:$A$105,2023))/C7,"NC") -> 50397.405 | H7: =IFERROR((SUMIFS('Exportations Minières 23-24'!$H$2:$H$105,'Exportations Minières 23-24'!$C$2:$C$105,A7,'Exportations Minières 23-24'!$B$2:$B$105,B7,'Exportations Minières 23-24'!$A$2:$A$105,2024))/D7,"NC") -> 50443.662 | I7: Tonnes
A8: GCO | B8: Ilmenite 54 | C8: =SUMIFS('Exportations Minières 23-24'!$G$2:$G$105,'Exportations Minières 23-24'!$C$2:$C$105,A8,'Exportations Minières 23-24'!$B$2:$B$105,B8,'Exportations Minières 23-24'!$A$2:$A$105,2023) -> 292907 | D8: =SUMIFS('Exportations Minières 23-24'!$G$2:$G$105,'Exportations Minières 23-24'!$C$2:$C$105,A8,'Exportations Minières 23-24'!$B$2:$B$105,B8,'Exportations Minières 23-24'!$A$2:$A$105,2024) -> 387783 | E8: =IFERROR((SUMIFS('Exportations Minières 23-24'!$I$2:$I$105,'Exportations Minières 23-24'!$C$2:$C$105,A8,'Exportations Minières 23-24'!$B$2:$B$105,B8,'Exportations Minières 23-24'!$A$2:$A$105,2023))/C8,"NC") -> 303.70133 | F8: =IFERROR((SUMIFS('Exportations Minières 23-24'!$I$2:$I$105,'Exportations Minières 23-24'!$C$2:$C$105,A8,'Exportations Minières 23-24'!$B$2:$B$105,B8,'Exportations Minières 23-24'!$A$2:$A$105,2024))/D8,"NC") -> 242.18189 | G8: =IFERROR((SUMIFS('Exportations Minières 23-24'!$H$2:$H$105,'Exportations Minières 23-24'!$C$2:$C$105,A8,'Exportations Minières 23-24'!$B$2:$B$105,B8,'Exportations Minières 23-24'!$A$2:$A$105,2023))/C8,"NC") -> 183534.53 | H8: =IFERROR((SUMIFS('Exportations Minières 23-24'!$H$2:$H$105,'Exportations Minières 23-24'!$C$2:$C$105,A8,'Exportations Minières 23-24'!$B$2:$B$105,B8,'Exportations Minières 23-24'!$A$2:$A$105,2024))/D8,"NC") -> 147296.34 | I8: Tonnes
A9: SOMIVA | B9: Phosphate | C9: =SUMIFS('Exportations Minières 23-24'!$G$2:$G$105,'Exportations Minières 23-24'!$C$2:$C$105,A9,'Exportations Minières 23-24'!$B$2:$B$105,B9,'Exportations Minières 23-24'!$A$2:$A$105,2023) -> 369936 | D9: =SUMIFS('Exportations Minières 23-24'!$G$2:$G$105,'Exportations Minières 23-24'!$C$2:$C$105,A9,'Exportations Minières 23-24'!$B$2:$B$105,B9,'Exportations Minières 23-24'!$A$2:$A$105,2024) -> 0 | E9: =IFERROR((SUMIFS('Exportations Minières 23-24'!$I$2:$I$105,'Exportations Minières 23-24'!$C$2:$C$105,A9,'Exportations Minières 23-24'!$B$2:$B$105,B9,'Exportations Minières 23-24'!$A$2:$A$105,2023))/C9,"NC") -> 160.44609 | F9: =IFERROR((SUMIFS('Exportations Minières 23-24'!$I$2:$I$105,'Exportations Minières 23-24'!$C$2:$C$105,A9,'Exportations Minières 23-24'!$B$2:$B$105,B9,'Exportations Minières 23-24'!$A$2:$A$105,2024))/D9,"NC") -> NC | G9: =IFERROR((SUMIFS('Exportations Minières 23-24'!$H$2:$H$105,'Exportations Minières 23-24'!$C$2:$C$105,A9,'Exportations Minières 23-24'!$B$2:$B$105,B9,'Exportations Minières 23-24'!$A$2:$A$105,2023))/C9,"NC") -> 96961.708 | H9: =IFERROR((SUMIFS('Exportations Minières 23-24'!$H$2:$H$105,'Exportations Minières 23-24'!$C$2:$C$105,A9,'Exportations Minières 23-24'!$B$2:$B$105,B9,'Exportations Minières 23-24'!$A$2:$A$105,2024))/D9,"NC") -> NC | I9: Tonnes
A10: SEPHOS | B10: Phosphate | C10: =SUMIFS('Exportations Minières 23-24'!$G$2:$G$105,'Exportations Minières 23-24'!$C$2:$C$105,A10,'Exportations Minières 23-24'!$B$2:$B$105,B10,'Exportations Minières 23-24'!$A$2:$A$105,2023) -> 114902 | D10: =SUMIFS('Exportations Minières 23-24'!$G$2:$G$105,'Exportations Minières 23-24'!$C$2:$C$105,A10,'Exportations Minières 23-24'!$B$2:$B$105,B10,'Exportations Minières 23-24'!$A$2:$A$105,2024) -> 0 | E10: =IFERROR((SUMIFS('Exportations Minières 23-24'!$I$2:$I$105,'Exportations Minières 23-24'!$C$2:$C$105,A10,'Exportations Minières 23-24'!$B$2:$B$105,B10,'Exportations Minières 23-24'!$A$2:$A$105,2023))/C10,"NC") -> 137.52579 | F10: =IFERROR((SUMIFS('Exportations Minières 23-24'!$I$2:$I$105,'Exportations Minières 23-24'!$C$2:$C$105,A10,'Exportations Minières 23-24'!$B$2:$B$105,B10,'Exportations Minières 23-24'!$A$2:$A$105,2024))/D10,"NC") -> NC | G10: =IFERROR((SUMIFS('Exportations Minières 23-24'!$H$2:$H$105,'Exportations Minières 23-24'!$C$2:$C$105,A10,'Exportations Minières 23-24'!$B$2:$B$105,B10,'Exportations Minières 23-24'!$A$2:$A$105,2023))/C10,"NC") -> 83110.376 | H10: =IFERROR((SUMIFS('Exportations Minières 23-24'!$H$2:$H$105,'Exportations Minières 23-24'!$C$2:$C$105,A10,'Exportations Minières 23-24'!$B$2:$B$105,B10,'Exportations Minières 23-24'!$A$2:$A$105,2024))/D10,"NC") -> NC | I10: Tonnes
A11: BMCC | B11: Phosphate | C11: =SUMIFS('Exportations Minières 23-24'!$G$2:$G$105,'Exportations Minières 23-24'!$C$2:$C$105,A11,'Exportations Minières 23-24'!$B$2:$B$105,B11,'Exportations Minières 23-24'!$A$2:$A$105,2023) -> 120731 | D11: =SUMIFS('Exportations Minières 23-24'!$G$2:$G$105,'Exportations Minières 23-24'!$C$2:$C$105,A11,'Exportations Minières 23-24'!$B$2:$B$105,B11,'Exportations Minières 23-24'!$A$2:$A$105,2024) -> 147335 | E11: =IFERROR((SUMIFS('Exportations Minières 23-24'!$I$2:$I$105,'Exportations Minières 23-24'!$C$2:$C$105,A11,'Exportations Minières 23-24'!$B$2:$B$105,B11,'Exportations Minières 23-24'!$A$2:$A$105,2023))/C11,"NC") -> 95.98857 | F11: =IFERROR((SUMIFS('Exportations Minières 23-24'!$I$2:$I$105,'Exportations Minières 23-24'!$C$2:$C$105,A11,'Exportations Minières 23-24'!$B$2:$B$105,B11,'Exportations Minières 23-24'!$A$2:$A$105,2024))/D11,"NC") -> 113.05625 | G11: =IFERROR((SUMIFS('Exportations Minières 23-24'!$H$2:$H$105,'Exportations Minières 23-24'!$C$2:$C$105,A11,'Exportations Minières 23-24'!$B$2:$B$105,B11,'Exportations Minières 23-24'!$A$2:$A$105,2023))/C11,"NC") -> 58008.365 | H11: =IFERROR((SUMIFS('Exportations Minières 23-24'!$H$2:$H$105,'Exportations Minières 23-24'!$C$2:$C$105,A11,'Exportations Minières 23-24'!$B$2:$B$105,B11,'Exportations Minières 23-24'!$A$2:$A$105,2024))/D11,"NC") -> 68551.398 | I11: Tonnes
A12: GCO | B12: Zircon Premium | C12: =SUMIFS('Exportations Minières 23-24'!$G$2:$G$105,'Exportations Minières 23-24'!$C$2:$C$105,A12,'Exportations Minières 23-24'!$B$2:$B$105,B12,'Exportations Minières 23-24'!$A$2:$A$105,2023) -> 28177 | D12: =SUMIFS('Exportations Minières 23-24'!$G$2:$G$105,'Exportations Minières 23-24'!$C$2:$C$105,A12,'Exportations Minières 23-24'!$B$2:$B$105,B12,'Exportations Minières 23-24'!$A$2:$A$105,2024) -> 39376 | E12: =IFERROR((SUMIFS('Exportations Minières 23-24'!$I$2:$I$105,'Exportations Minières 23-24'!$C$2:$C$105,A12,'Exportations Minières 23-24'!$B$2:$B$105,B12,'Exportations Minières 23-24'!$A$2:$A$105,2023))/C12,"NC") -> 1931.166 | F12: =IFERROR((SUMIFS('Exportations Minières 23-24'!$I$2:$I$105,'Exportations Minières 23-24'!$C$2:$C$105,A12,'Exportations Minières 23-24'!$B$2:$B$105,B12,'Exportations Minières 23-24'!$A$2:$A$105,2024))/D12,"NC") -> 1828.4475 | G12: =IFERROR((SUMIFS('Exportations Minières 23-24'!$H$2:$H$105,'Exportations Minières 23-24'!$C$2:$C$105,A12,'Exportations Minières 23-24'!$B$2:$B$105,B12,'Exportations Minières 23-24'!$A$2:$A$105,2023))/C12,"NC") -> 1167053.4 | H12: =IFERROR((SUMIFS('Exportations Minières 23-24'!$H$2:$H$105,'Exportations Minières 23-24'!$C$2:$C$105,A12,'Exportations Minières 23-24'!$B$2:$B$105,B12,'Exportations Minières 23-24'!$A$2:$A$105,2024))/D12,"NC") -> 1109336.1 | I12: Tonnes
A13: GCO | B13: Zircon Standard | C13: =SUMIFS('Exportations Minières 23-24'!$G$2:$G$105,'Exportations Minières 23-24'!$C$2:$C$105,A13,'Exportations Minières 23-24'!$B$2:$B$105,B13,'Exportations Minières 23-24'!$A$2:$A$105,2023) -> 19379 | D13: =SUMIFS('Exportations Minières 23-24'!$G$2:$G$105,'Exportations Minières 23-24'!$C$2:$C$105,A13,'Exportations Minières 23-24'!$B$2:$B$105,B13,'Exportations Minières 23-24'!$A$2:$A$105,2024) -> 27523 | E13: =IFERROR((SUMIFS('Exportations Minières 23-24'!$I$2:$I$105,'Exportations Minières 23-24'!$C$2:$C$105,A13,'Exportations Minières 23-24'!$B$2:$B$105,B13,'Exportations Minières 23-24'!$A$2:$A$105,2023))/C13,"NC") -> 1782.2886 | F13: =IFERROR((SUMIFS('Exportations Minières 23-24'!$I$2:$I$105,'Exportations Minières 23-24'!$C$2:$C$105,A13,'Exportations Minières 23-24'!$B$2:$B$105,B13,'Exportations Minières 23-24'!$A$2:$A$105,2024))/D13,"NC") -> 1719.2661 | G13: =IFERROR((SUMIFS('Exportations Minières 23-24'!$H$2:$H$105,'Exportations Minières 23-24'!$C$2:$C$105,A13,'Exportations Minières 23-24'!$B$2:$B$105,B13,'Exportations Minières 23-24'!$A$2:$A$105,2023))/C13,"NC") -> 1077082.9 | H13: =IFERROR((SUMIFS('Exportations Minières 23-24'!$H$2:$H$105,'Exportations Minières 23-24'!$C$2:$C$105,A13,'Exportations Minières 23-24'!$B$2:$B$105,B13,'Exportations Minières 23-24'!$A$2:$A$105,2024))/D13,"NC") -> 1046555.4 | I13: Tonnes
