Workbook

Sheet Requete_INFOTITREMINIER OK
A1: entreprise_id | B1: num_titre_minier | C1: nom_perimetre | D1: nm_nature | E1: nm_region | F1: substance_desc | G1: nm_commune | H1: nm_departement | I1: date_signature | J1: date_octroi | L1: superficie_octroye | M1: superficie_exploite | N1: superficie_rendue | O1: superficie_rehabilite | P1: date_fin
A2: 2SBCI | B2: 09142/MIM/DMG | C2: BANDIA | D2: Carrière | E2: THIES | F2: Calcaire | G2: BANDIA | H2: MBOUR | I2: 42886 | J2: 42886 | L2: 0.3 | P2: 44711 | R2: =+VLOOKUP(A2,'[1]Requete_INFOTITREMINIER OK'!$A$1:$M$117,13,0) -> 0 | S2: =N2=R2 -> TRUE
A3: AFRIGEM SL | B3: A010333/MMIAPME/DMG | C3: LINGEKHOTO | D3: Permis de recherche | E3: KEDOUGOU | F3: Or | G3: KEDOUGOU | H3: KEDOUGOU | I3: 40513 | J3: 40513 | L3: 157 | M3: 0 | N3: 120.5 | O3: 0 | P3: 43069 | R3: =+VLOOKUP(A3,'[1]Requete_INFOTITREMINIER OK'!$A$1:$M$117,13,0) -> 120.5 | S3: =N3=R3 -> TRUE
A4: AFRIGEM SL | B4: 010978/MMG/DMG/25/06/2020 | C4: BOUROUBOUROU | D4: Permis de recherche | E4: KEDOUGOU | F4: Or | G4: KEDOUGOU | H4: KEDOUGOU | I4: 40513 | J4: 40513 | L4: 187 | M4: 0 | N4: 110 | O4: 0 | P4: 44625 | R4: =+VLOOKUP(A4,'[1]Requete_INFOTITREMINIER OK'!$A$1:$M$117,13,0) -> 120.5 | S4: =N4=R4 -> FALSE
A5: AFRIGOLD SARL | B5: UTMWGS 84 ZONE 28 | C5: KARAKHAENA | D5: Permis d’exploitation | E5: KEDOUGOU | F5: Or | G5: SARAYA | H5: SARAYA | I5: 42285 | J5: 42402 | L5: 39 | M5: 39 | N5: 0 | O5: 0 | P5: 44228 | R5: =+VLOOKUP(A5,'[1]Requete_INFOTITREMINIER OK'!$A$1:$M$117,13,0) -> 0 | S5: =N5=R5 -> TRUE
A6: AGEM SENEGAL EXPLORATION SUARL | B6: 13984/MIM/DMG | C6: DAORALA | D6: Permis de recherche | E6: KEDOUGOU | F6: Or | G6: MEDINA BAFFE | H6: SARAYA | I6: 38215 | J6: 38415 | L6: 420 | M6: 0 | N6: 184 | O6: 0 | R6: =+VLOOKUP(A6,'[1]Requete_INFOTITREMINIER OK'!$A$1:$M$117,13,0) -> 184 | S6: =N6=R6 -> TRUE
A7: AGEM SENEGAL EXPLORATION SUARL | B7: 012395/MMG/DMG | C7: NOUMOUFOUKHA | D7: Permis de recherche | E7: KEDOUGOU | F7: Or | G7: MEDINA BAFFE | H7: SARAYA | I7: 43231 | J7: 43256 | L7: 79 | M7: 0 | N7: 0 | O7: 0 | P7: 45081 | R7: 0 | S7: =N7=R7 -> TRUE
A8: AGROMINE | B8: 001928MMG | C8: LAMBAYE | D8: Permis de recherche | E8: DIOURBEL | F8: Phosphate de chaux | G8: DIOURBEL | H8: DIOURBEL | I8: 43486 | J8: 43496 | L8: 567 | M8: 0 | N8: 0 | O8: 0 | P8: 401768 | R8: =+VLOOKUP(A8,'[1]Requete_INFOTITREMINIER OK'!$A$1:$M$117,13,0) -> 0 | S8: =N8=R8 -> TRUE
A9: AGROMINE | B9: 025823 | C9: Seune Sèrère | D9: Carrière | E9: THIES | F9: Basalte | G9: KEUR MOUSSA | H9: THIES | J9: 43361 | L9: 0.38 | M9: 0 | N9: 0 | O9: 0 | P9: 45278 | R9: =+VLOOKUP(A9,'[1]Requete_INFOTITREMINIER OK'!$A$1:$M$117,13,0) -> 0 | S9: =N9=R9 -> TRUE
A10: ALBINA SENEGAL SARL | B10: 017130/MMG/DMG | C10: BANDIA | D10: Carrière | E10: THIES | F10: Calcaire | G10: BANDIA | H10: THIES | J10: 43304 | L10: 0.15 | M10: 0.15 | P10: 45129 | R10: =+VLOOKUP(A10,'[1]Requete_INFOTITREMINIER OK'!$A$1:$M$117,13,0) -> 0 | S10: =N10=R10 -> TRUE
A11: AMAFRIQUE SENEGAL | B11: A018603/MMG/DMG | C11: Thilogne | D11: Permis de recherche | E11: MATAM | F11: Phosphate de chaux | G11: AGNAM-CIVOL | H11: MATAM | I11: 42157 | J11: 42200 | L11: 1590 | M11: 0 | N11: 401 | O11: 0 | P11: 44420 | R11: =+VLOOKUP(A11,'[1]Requete_INFOTITREMINIER OK'!$A$1:$M$117,13,0) -> 401 | S11: =N11=R11 -> TRUE
A12: ARDIMINES SARL | B12: 002734 | C12: Tombo | D12: Permis de recherche | E12: KEDOUGOU | F12: Or | G12: TOMBORONKOTO | H12: KEDOUGOU | I12: 42682 | J12: 43510 | L12: 22 | M12: 0 | N12: 0 | O12: 0 | P12: 44971 | R12: =+VLOOKUP(A12,'[1]Requete_INFOTITREMINIER OK'!$A$1:$M$117,13,0) -> 0 | S12: =N12=R12 -> TRUE
A13: ATIC SARL | B13: 09MAI2018009738 | C13: ATIC SILEX | D13: Carrière | E13: THIES | F13: Silex | G13: M’BORO | H13: TIVAOUANE | I13: 43186 | J13: 43229 | L13: 1.2 | M13: 1.2 | N13: 0 | O13: 0 | P13: 401768 | R13: =+VLOOKUP(A13,'[1]Requete_INFOTITREMINIER OK'!$A$1:$M$117,13,0) -> 0 | S13: =N13=R13 -> TRUE
A14: BAMBADJI SA | B14: 012394/ MMG/DMG | C14: BAMBADJI | D14: Permis de recherche | E14: KEDOUGOU | F14: Or | G14: MADINA BAFFE | H14: SARAYA | I14: 43231 | J14: 43256 | L14: 314.5 | M14: 0 | N14: 0 | O14: 0 | P14: 401768 | R14: =+VLOOKUP(A14,'[1]Requete_INFOTITREMINIER OK'!$A$1:$M$117,13,0) -> 0 | S14: =N14=R14 -> TRUE
A15: BAMBUK MINERALS SARL | B15: 014934 | C15: SANGOLA | D15: Permis de recherche | E15: KEDOUGOU | F15: Or | G15: BANDAFASSI | H15: KEDOUGOU | I15: 42529 | J15: 43623 | L15: 381 | M15: 0 | N15: 0 | O15: 0 | P15: 45084 | R15: =+VLOOKUP(A15,'[1]Requete_INFOTITREMINIER OK'!$A$1:$M$117,13,0) -> 0 | S15: =N15=R15 -> TRUE
A16: BAMBUK MINERALS SARL | B16: 023735 | C16: KOULOUNTOU EST | D16: Permis de recherche | E16: KEDOUGOU | F16: Or | G16: TOMBORONKOTO | H16: KEDOUGOU | I16: 42682 | J16: 43410 | L16: 381 | M16: 0 | N16: 0 | O16: 0 | P16: 401768 | R16: =+VLOOKUP(A16,'[1]Requete_INFOTITREMINIER OK'!$A$1:$M$117,13,0) -> 0 | S16: =N16=R16 -> TRUE
A17: BB FIRST COMMODITY HOLDING LIMITED | B17: 00487/MMG/DMG | C17: MADINA FOULBE | D17: Permis de recherche | E17: TAMBACOUNDA | F17: Or | G17: MADINA FOULBE | H17: BAKEL | I17: 40305 | J17: 43115 | L17: 260 | M17: 0 | N17: 65 | O17: 0 | P17: 401768 | R17: =+VLOOKUP(A17,'[1]Requete_INFOTITREMINIER OK'!$A$1:$M$117,13,0) -> 65 | S17: =N17=R17 -> TRUE
A18: BHAIRAVA AGRICOLE SARL | B18: 10566 | C18: KAOUROU | D18: Permis de recherche | E18: KEDOUGOU | F18: Or | G18: Bakel | H18: BAKEL | L18: 144 | R18: =+VLOOKUP(A18,'[1]Requete_INFOTITREMINIER OK'!$A$1:$M$117,13,0) -> #N/A | S18: =N18=R18 -> #N/A
A19: BMCC SA | B19: 001840/MMG/DMG | C19: CHERIF LO NGAKHAM | D19: Permis d’exploitation | E19: DIOURBEL | F19: Phosphates | G19: CHERIF Lo | H19: Diourbel | I19: 43367 | L19: 75 | M19: 5 | N19: 0 | O19: 0 | R19: =+VLOOKUP(A19,'[1]Requete_INFOTITREMINIER OK'!$A$1:$M$117,13,0) -> 0 | S19: =N19=R19 -> TRUE
A20: BOSFOR SARL | B20: 0062254 MEMDMGBD | C20: bandia/thiés | D20: Carrière | E20: THIES | F20: Calcaire | G20: DIASS | H20: MBOUR | J20: 41143 | L20: 0.2 | M20: 0 | O20: 0 | P20: 42969 | R20: =+VLOOKUP(A20,'[1]Requete_INFOTITREMINIER OK'!$A$1:$M$117,13,0) -> 0 | S20: =N20=R20 -> TRUE
A21: BOYA SA | B21: 011843 MIM/DMG | C21: DIAMBA SUD | D21: Permis de recherche | E21: KEDOUGOU | F21: Or | G21: SARAYA | H21: SARAYA | I21: 42102 | J21: 42165 | L21: 71.32 | M21: 0 | N21: 18.02 | O21: 0 | P21: 44391 | R21: =+VLOOKUP(A21,'[1]Requete_INFOTITREMINIER OK'!$A$1:$M$117,13,0) -> 18.02 | S21: =N21=R21 -> TRUE
A22: BOYA SA | B22: 011842/MIM/DMG | C22: DIAMBA NORD | D22: Permis de recherche | E22: KEDOUGOU | F22: Or | G22: SARAYA | H22: SARAYA | I22: 42102 | J22: 42165 | L22: 241.8 | M22: 0 | N22: 80.7 | O22: 0 | P22: 43625 | R22: =+VLOOKUP(A22,'[1]Requete_INFOTITREMINIER OK'!$A$1:$M$117,13,0) -> 18.02 | S22: =N22=R22 -> FALSE
A23: CAYOR PHOSPHATE MINING | B23: 036584 | C23: UTM WGS 84 ZONE 28N | D23: Permis de recherche | E23: LOUGA | F23: Phosphate | G23: NDANDE/ THILOM FALL/ NGOURANE | H23: LOUGA | I23: 41425 | J23: 44741 | L23: 637.48 | R23: =+VLOOKUP(A23,'[1]Requete_INFOTITREMINIER OK'!$A$1:$M$117,13,0) -> 0 | S23: =N23=R23 -> TRUE
A24: CHALLENGER NORD-SUD INTERNATIONAL INC | B24: 025475 | C24: NIAKHENE | D24: Permis de recherche | E24: DIOURBEL | F24: Phosphate de chaux | G24: DIOURBEL | H24: DIOURBEL | I24: 44099 | J24: 44132 | L24: 498 | M24: 0 | N24: 0 | O24: 0 | P24: 45592 | R24: =+VLOOKUP(A24,'[1]Requete_INFOTITREMINIER OK'!$A$1:$M$117,13,0) -> 0 | S24: =N24=R24 -> TRUE
A25: CHALLENGER NORD-SUD INTERNATIONAL INC | B25: A07102/MIM/DMG | C25: Coki | D25: Permis de recherche | E25: LOUGA | F25: Phosphate de chaux | G25: COKI | H25: LOUGA | I25: 42474 | J25: 42506 | L25: 4396 | M25: 0 | N25: 1101 | O25: 0 | P25: 44692 | R25: =+VLOOKUP(A25,'[1]Requete_INFOTITREMINIER OK'!$A$1:$M$117,13,0) -> 0 | S25: =N25=R25 -> FALSE
A26: CHESSER | B26: 006873873 | C26: Bondola | D26: Permis de recherche | E26: KEDOUGOU | F26: Or | G26: Bembou | H26: Kedougou | I26: 44606 | J26: 44623 | L26: 207.17 | M26: 0 | N26: 0 | O26: 0 | R26: =+VLOOKUP(A26,'[1]Requete_INFOTITREMINIER OK'!$A$1:$M$117,13,0) -> #N/A | S26: =N26=R26 -> #N/A
A27: CHESSER | B27: 006873873 | C27: Morichou | D27: Permis de recherche | E27: KEDOUGOU | F27: Or | G27: Sadatou | H27: Kedougou | I27: 44606 | J27: 44623 | L27: 207.17 | M27: 0 | N27: 0 | O27: 0 | R27: =+VLOOKUP(A27,'[1]Requete_INFOTITREMINIER OK'!$A$1:$M$117,13,0) -> #N/A | S27: =N27=R27 -> #N/A
A28: CIMENTS DE L' AFRIQUE SA | B28: 005494 | C28: POUT | D28: Permis d’exploitation | E28: THIES | F28: Calcaire | G28: KEUR MOUSSA | H28: THIES | I28: 42479 | J28: 44279 | L28: 2.77 | M28: 2.77 | N28: 0 | O28: 0 | P28: 46104 | R28: =+VLOOKUP(A28,'[1]Requete_INFOTITREMINIER OK'!$A$1:$M$117,13,0) -> 0 | S28: =N28=R28 -> TRUE
A29: CIMENTS DU SAHEL | B29: 2-N°2000-106 du 22 février 2000 | C29: Argile et latérite Tchiky | D29: Concession minière | E29: THIES | F29: Argile | G29: DIASS | H29: MBOUR | I29: 36574 | J29: 36578 | L29: 2 | M29: 0.3 | N29: 0 | O29: 0.05 | P29: 45710 | R29: =+VLOOKUP(A29,'[1]Requete_INFOTITREMINIER OK'!$A$1:$M$117,13,0) -> 0 | S29: =N29=R29 -> TRUE
A30: CIMENTS DU SAHEL | B30: 3-2015-639 du 15 mai 2015 | C30: Bandia-Kirène | D30: Concession minière | E30: THIES | F30: Calcaire | G30: BANDIA | H30: THIES | I30: 36574 | J30: 42139 | L30: 5.86 | M30: 0 | N30: 0 | O30: 0 | P30: 51271 | R30: =+VLOOKUP(A30,'[1]Requete_INFOTITREMINIER OK'!$A$1:$M$117,13,0) -> 0 | S30: =N30=R30 -> TRUE
A31: COMPAGNIE GENERALE D'EXPLOITATION DE CARRIERE | B31: 007541/MMITPME | C31: BANDIA | D31: Carrière | E31: THIES | F31: Calcaire | G31: BANDIA | H31: THIES | J31: 40032 | L31: 0.05 | M31: 0.05 | P31: 46431 | R31: =+VLOOKUP(A31,'[1]Requete_INFOTITREMINIER OK'!$A$1:$M$117,13,0) -> 0 | S31: =N31=R31 -> TRUE
A32: COMPAGNIE GENERALE D'EXPLOITATION DE CARRIERE | B32: 008569/MEMIMEFP | C32: BANDIA | D32: Carrière | E32: THIES | F32: Calcaire | G32: BANDIA | H32: THIES | J32: 35384 | L32: 0.075 | M32: 0.065 | N32: 0.01 | P32: 46431 | R32: =+VLOOKUP(A32,'[1]Requete_INFOTITREMINIER OK'!$A$1:$M$117,13,0) -> 0 | S32: =N32=R32 -> FALSE
A33: COMPAGNIE GENERALE D'EXPLOITATION DE CARRIERE | B33: 010284 | C33: DIACK | D33: Carrière | E33: THIES | F33: Basalte | G33: N'GOUDIANE | H33: THIES | J33: 43986 | L33: 0.0275 | P33: 45811 | R33: =+VLOOKUP(A33,'[1]Requete_INFOTITREMINIER OK'!$A$1:$M$117,13,0) -> 0 | S33: =N33=R33 -> TRUE
A34: COMPAGNIE GENERALE D'EXPLOITATION DE CARRIERE | B34: 6283/MIM/DMG | C34: DIACK | D34: Carrière | E34: THIES | F34: Basalte | G34: N'GOUDIANE | H34: THIES | J34: 42478 | L34: 0.41 | P34: 46432 | R34: =+VLOOKUP(A34,'[1]Requete_INFOTITREMINIER OK'!$A$1:$M$117,13,0) -> 0 | S34: =N34=R34 -> TRUE
A35: COMPAGNIE GENERALE D'EXPLOITATION DE CARRIERE | B35: 07540/MIMTPME/DMG | C35: DIACK | D35: Carrière | E35: THIES | F35: Basalte | G35: N'GOUDIANE | H35: THIES | J35: 40032 | L35: 0.15 | P35: 46460 | R35: =+VLOOKUP(A35,'[1]Requete_INFOTITREMINIER OK'!$A$1:$M$117,13,0) -> 0 | S35: =N35=R35 -> TRUE
A36: COMPAGNIE GENERALE D'EXPLOITATION DE CARRIERE | B36: 04252/MIMTPME/DMG | C36: DIACK | D36: Carrière | E36: THIES | F36: Basalte | G36: N'GOUDIANE | H36: THIES | J36: 39902 | L36: 0.05 | P36: 46460 | R36: =+VLOOKUP(A36,'[1]Requete_INFOTITREMINIER OK'!$A$1:$M$117,13,0) -> 0 | S36: =N36=R36 -> TRUE
A37: COMPAGNIE GENERALE D'EXPLOITATION DE CARRIERE | B37: 001557/MMG/CAB/CT1 | C37: DIACK | D37: Carrière | E37: THIES | F37: Basalte | G37: N'GOUDIANE | H37: THIES | J37: 43493 | L37: 0.15 | P37: 45318 | R37: =+VLOOKUP(A37,'[1]Requete_INFOTITREMINIER OK'!$A$1:$M$117,13,0) -> 0 | S37: =N37=R37 -> TRUE
A38: COMPAGNIE GENERALE D'EXPLOITATION DE CARRIERE | B38: 0010283 | C38: DIACK | D38: Carrière | E38: THIES | F38: Basalte | G38: N'GOUDIANE | H38: THIES | J38: 43986 | L38: 0.015 | P38: 45811 | R38: =+VLOOKUP(A38,'[1]Requete_INFOTITREMINIER OK'!$A$1:$M$117,13,0) -> 0 | S38: =N38=R38 -> TRUE
A39: CONSULTING BUSINESS AGENCY | B39: A025607/MMG/DMG | C39: MADINA TOUBAKOTA | D39: Permis de recherche | E39: KEDOUGOU | F39: Or | G39: BEMBOU | H39: SARAYA | I39: 43737 | J39: 43780 | L39: 252 | M39: 0 | N39: 0 | O39: 0 | P39: 45240 | R39: =+VLOOKUP(A39,'[1]Requete_INFOTITREMINIER OK'!$A$1:$M$117,13,0) -> #N/A | S39: =N39=R39 -> #N/A
A40: CSE GRANULATS | B40: 008633MMG/DMG | C40: DIACK | D40: Carrière | E40: THIES | F40: Basalte | G40: N’GOUNDIANE | H40: THIES | J40: 43219 | L40: 0.092 | M40: 0.092 | N40: 0 | O40: 0 | P40: 401768 | R40: =+VLOOKUP(A40,'[1]Requete_INFOTITREMINIER OK'!$A$1:$M$117,13,0) -> 0 | S40: =N40=R40 -> TRUE
...

Sheet INFOTITRE
A2: Répartition des titres miniers par région en 2022 | O2: Étiquettes de lignes | P2: Nombre de entreprise_id
A3: Étiquettes de lignes | B3: Nombre de entreprise_id | C3: Nombre de entreprise_id2 | E3: Étiquettes de lignes | F3: Nombre de entreprise_id | O3: 2SBCI | P3: 1
A4: THIES | B4: 66 | C4: 0.54545455 | E4: THIES | F4: =B4 -> 66 | O4: AFRIGEM SL | P4: 2
A5: KEDOUGOU | B5: 34 | C5: 0.28099174 | E5: KEDOUGOU | F5: =B5 -> 34 | O5: AFRIGOLD SARL | P5: 1
A6: TAMBACOUNDA | B6: 7 | C6: 0.05785124 | E6: TAMBACOUNDA | F6: =B6 -> 7 | O6: AGEM SENEGAL EXPLORATION SUARL | P6: 2
A7: DIOURBEL | B7: 5 | C7: 0.041322314 | E7: DIOURBEL | F7: =B7 -> 5 | O7: AGROMINE | P7: 2
A8: MATAM | B8: 3 | C8: 0.024793388 | E8: MATAM | F8: =B8 -> 3 | O8: ALBINA SENEGAL SARL | P8: 1
A9: LOUGA | B9: 3 | C9: 0.024793388 | E9: LOUGA | F9: =B9 -> 3 | O9: AMAFRIQUE SENEGAL | P9: 1
A10: SAINT-LOUIS | B10: 1 | C10: 0.0082644628 | E10: SAINT-LOUIS | F10: =B10 -> 1 | O10: ARDIMINES SARL | P10: 1
A11: KOLDA | B11: 1 | C11: 0.0082644628 | E11: KOLDA | F11: =B11 -> 1 | O11: ATIC SARL | P11: 1
A12: DAKAR | B12: 1 | C12: 0.0082644628 | E12: DAKAR | F12: =B12 -> 1 | O12: BAMBADJI SA | P12: 1
A13: Total général | B13: 121 | C13: 1 | E13: Total général | F13: =SUM(F4:F12) -> 121 | O13: BAMBUK MINERALS SARL | P13: 2
O14: BB FIRST COMMODITY HOLDING LIMITED | P14: 1
O15: BHAIRAVA AGRICOLE SARL | P15: 1
A16: Répartition des titres miniers selon le type par région en 2022 | O16: BMCC SA | P16: 1
A17: Nombre de nm_nature | B17: Étiquettes de colonnes | O17: BOSFOR SARL | P17: 1
A18: Étiquettes de lignes | B18: Carrière | C18: Concession minière | D18: Permis d’exploitation | E18: Permis de recherche | F18: Petite Mine | G18: Total général | O18: BOYA SA | P18: 2
A19: DAKAR | C19: 1 | G19: 1 | O19: CAYOR PHOSPHATE MINING | P19: 1
A20: DIOURBEL | D20: 1 | E20: 4 | G20: 5 | O20: CHALLENGER NORD-SUD INTERNATIONAL INC | P20: 2
A21: KEDOUGOU | C21: 3 | D21: 3 | E21: 27 | F21: 1 | G21: 34 | O21: CHESSER | P21: 2
A22: KOLDA | E22: 1 | G22: 1 | O22: CIMENTS DE L' AFRIQUE SA | P22: 1
A23: LOUGA | E23: 3 | G23: 3 | O23: CIMENTS DU SAHEL | P23: 2
A24: MATAM | C24: 1 | E24: 2 | G24: 3 | O24: COMPAGNIE GENERALE D'EXPLOITATION DE CARRIERE | P24: 8
A25: SAINT-LOUIS | F25: 1 | G25: 1 | O25: CONSULTING BUSINESS AGENCY | P25: 1
A26: TAMBACOUNDA | B26: 3 | E26: 2 | F26: 2 | G26: 7 | O26: CSE GRANULATS | P26: 2
A27: THIES | B27: 44 | C27: 18 | D27: 1 | E27: 1 | F27: 2 | G27: 66 | O27: DALEMA | P27: 1
A28: Total général | B28: 47 | C28: 23 | D28: 5 | E28: 40 | F28: 6 | G28: 121 | O28: DAMASH MINERALS LTD | P28: 1
O29: DANGOTE CEMENT SENEGAL | P29: 2
E30: =E21/E28 -> 0.675 | O30: DIYAN EXPLOITATION MINIERE SUARL | P30: 1
A31: Répartition des titres miniers par type en 2022 | O31: ENTREPRISE MAPATHE NDIOUCK SA | P31: 2
A32: Étiquettes de lignes | B32: Nombre de nm_nature | C32: Nombre de nm_nature2 | O32: ENTREPRISE OUSMANE SOW | P32: 1
A33: Carrière | B33: 47 | C33: 0.38842975 | O33: G.H MINING | P33: 1
A34: Permis de recherche | B34: 40 | C34: 0.33057851 | O34: GAZAL CARRIERES SUARL | P34: 1
A35: Concession minière | B35: 23 | C35: 0.19008264 | O35: GECAMINES | P35: 7
A36: Petite Mine | B36: 6 | C36: 0.049586777 | O36: GLOBAL IMMO SENEGAL SARL | P36: 1
A37: Permis d’exploitation | B37: 5 | C37: 0.041322314 | O37: G-PHOS S.A.U | P37: 1
A38: Total général | B38: 121 | C38: 1 | O38: GRANDE COTE OPERATIONS | P38: 1
O39: GROUPEMENT D'ENTREPRISE SINTRAM HOUAR | P39: 1
A40: Répartition des titres miniers par type en 2022 | O40: HOLDING ATLANTQUE MINING PETROLUM-SA | P40: 1
A41: Nature | B41: Nombre | C41: % | O41: IAMGOLD BOTO S.A | P41: 1
...

Sheet Requete_SONDAGE OK
A1: formulaire_id | B1: entreprise_id | C1: num_titre_minier | D1: nm_nature | E1: sondage_desc | F1: grille_maille_desc | G1: metrage | H1: intervalle | I1: intersection
A2: 1677 | B2: 2SBCI | C2: ………. | D2: Carrière | E2: RAB | F2: 89mm | G2: 17 | H2: 3
B3: AGEM SENEGAL EXPLORATION SUARL | D3: Permis de recherche | E3: RC | G3: 3000
B4: AGROMINE | D4: Permis de recherche | E4: Carotté | G4: 240
B5: ARDIMINES SARL | D5: Permis de recherche | E5: RAB
B6: BAMBADJI SA | D6: Permis de recherche | E6: Carotté | G6: 6122
B7: BAMBADJI SA | D7: Permis de recherche | E7: RC | G7: 16439
B8: BAMBADJI SA | D8: Permis de recherche | E8: Aircore | G8: 2764
B9: BAMBADJI SA | D9: Permis de recherche | E9: Tarrière | G9: 3114
B10: BAMBUK MINERALS SARL | D10: Permis de recherche | E10: RC | G10: =27+30+42+42+47+44+43+40+11+17+32+38+42+42+40+36+36+20+70+72*3+64+76*4+66*2+45+36+48+35+36*3+24+40+33*2+30*4+72+33 -> 2042
B11: BAMBUK MINERALS SARL | D11: Permis de recherche | E11: Tarrière | G11: =9+6+4+12+11+5+4+9+14+18+5+5+8+7+20+10+5 -> 152
B12: BHAIRAVA AGRICOLE SARL | D12: Permis de recherche | E12: Tarrière | G12: 330
B13: BOYA SA | D13: Permis de recherche | E13: RC | G13: 9413
B14: BOYA SA | D14: Permis de recherche | E14: Carotté | G14: 7807
A15: 1580 | B15: CSE GRANULATS | C15: 008633/MMG/DGM | D15: Carrière | E15: Carotté | G15: 21 | H15: 0-0 | I15: 0
A16: 1580 | B16: CSE GRANULATS | C16: 008633/MMG/DGM | D16: Carrière | E16: Destructif | G16: 18 | H16: 0-0 | I16: 0
B17: DAMASH MINERALS LTD | D17: Permis de recherche | E17: RC | G17: 510
B18: DAMASH MINERALS LTD | D18: Permis de recherche | E18: Carotté | G18: 335
B19: HOLDING ATLANTQUE MINING PETROLUM-SA | D19: Permis de recherche | E19: Carotté | G19: 415
B20: HOLDING ATLANTQUE MINING PETROLUM-SA | D20: Permis de recherche | E20: Destructif | G20: 1717
A21: 1395 | B21: INDUSTRIES CHIMIQUES DU SENEGAL | C21: 99 1020 | D21: Concession minière | E21: Carotté | F21: 250*250m | G21: 6111 | H21: 0-0 | I21: 7
B22: INTERNATIONAL MINING COMPANY (IMC) | D22: Permis de recherche | E22: RC | G22: 26898
B23: MASSAWA JERSEY LIMITED | D23: Permis de recherche | E23: RC | G23: 1496
A24: 1400 | B24: PETOWAL MINING COMPANY (PMC) SA | C24: 2016-995 | D24: Concession minière | E24: RC | F24: 10*10 | G24: 25251 | H24: 24 | I24: 0
B25: SABODALA GOLD OPERATIONS | D25: Concession minière | E25: RC | G25: 150659
B26: SABODALA MINING COMPANY | D26: Permis de recherche | E26: RC | G26: 8674
A27: 1460 | B27: SENEGAL MINES | C27: 15M | D27: Concession minière | E27: Carotté | F27: 200 | G27: 30 | H27: 15m | I27: 850000
A28: 1545 | B28: SEN-HMC SUARL | C28: 000363MMG/DMG | D28: Petite mine | E28: Tarrière | F28: 50m*50m | G28: 118 | H28: 0-0 | I28: 0
A29: 1590 | B29: SEPHOS SENEGAL SA | C29: 10357/MMI/PME/DMG | D29: Petite mine | E29: Carotté | F29: 25*25 | G29: 6155 | H29: 0-0 | I29: 0
A30: 1605 | B30: SERIGNE SALIOU MBACKE SUARL | C30: 00489/MMG/DMG | D30: Petite mine | E30: RAB | G30: 6524 | H30: 0-864 | I30: 246
B31: SOCABEG MINING | D31: Permis de recherche | E31: Carotté | G31: 167
B32: SOCABEG MINING | D32: Permis de recherche | E32: Destructif | G32: 681
B33: SOCIETE SENEGALAISE DE NEGOCE INTERNATIONALE (SNEPAC) SARL | D33: Permis de recherche | E33: RC | G33: 4914 | H33: 25 | I33: 3.72
B34: SOCIETE SENEGALAISE DE NEGOCE INTERNATIONALE (SNEPAC) SARL | D34: Permis de recherche | E34: Tarrière | G34: 3193 | H34: 35 | I34: 1.2
B35: SONKO ET FILS SARL | D35: Permis de recherche | E35: Tarrière | G35: =6+12+6+3+6 -> 33
A36: 1680 | B36: SORED-MINES SA | C36: 2007-1327 | D36: Concession minière | E36: RC | G36: 1986 | H36: 0-0 | I36: 0
B37: STRATEX-EMC.SA | D37: Permis de recherche | E37: Tarrière | G37: 8953
G38: =SUM(G2:G37) -> 306299

Sheet SONDAGE
A2: Répartition des entreprises ayant fait des sondages selon le type en 2022
A3: Étiquettes de lignes | B3: Nombre de sondage_desc | C3: Somme de metrage | D3: Somme de metrage2 | G3: Étiquettes de lignes | H3: Nombre de sondage_desc | I3: Nombre de sondage_desc2 | K3: TYPE DE SONDAGE | L3: Nombre | M3: % | N3: METRAGE | O3: %
A4: Aircore | B4: 1 | C4: 2764 | D4: 0.0090238623 | G4: Aircore | H4: 1 | I4: 0.027777778 | K4: RC | L4: 12 | M4: 0.33333333 | N4: 6524 | O4: 0.021299449
A5: Carotté | B5: 10 | C5: 27403 | D5: 0.089464869 | G5: Carotté | H5: 10 | I5: 0.27777778 | K5: Carotté | L5: 10 | M5: 0.27777778 | N5: 27403 | O5: 0.089464869
A6: Destructif | B6: 3 | C6: 2416 | D6: 0.0078877176 | G6: Destructif | H6: 3 | I6: 0.083333333 | K6: Tarrière | L6: 7 | M6: 0.19444444 | N6: 251282 | O6: 0.82038139
A7: RAB | B7: 3 | C7: 6541 | D7: 0.021354951 | G7: RAB | H7: 3 | I7: 0.083333333 | K7: Destructif | L7: 3 | M7: 0.083333333 | N7: 2416 | O7: 0.0078877176
A8: RC | B8: 12 | C8: 251282 | D8: 0.82038139 | G8: RC | H8: 12 | I8: 0.33333333 | K8: RAB | L8: 3 | M8: 0.083333333 | N8: 17 | O8: 5.5501324e-05
A9: Tarrière | B9: 7 | C9: 15893 | D9: 0.051887208 | G9: Tarrière | H9: 7 | I9: 0.19444444 | K9: Aircore | L9: 1 | M9: 0.027777778 | N9: 2764 | O9: 0.0090238623
A10: Total général | B10: 36 | C10: 306299 | D10: 1 | G10: Total général | H10: 36 | I10: 1
A15: Répartition des linéaires de sondage par nature du titre minier 2022
A16: Étiquettes de lignes | B16: Nombre de nm_nature
A17: Permis de recherche | B17: 25
A18: Concession minière | B18: 5
A19: Petite mine | B19: 3
A20: Carrière | B20: 3
A21: Total général | B21: 36
A25: Nombre de nm_nature | B25: Étiquettes de colonnes
A26: Étiquettes de lignes | B26: Carrière | C26: Concession minière | D26: Permis de recherche | E26: Petite mine | F26: Total général
A27: Aircore | D27: 1 | F27: 1
A28: Carotté | B28: 1 | C28: 2 | D28: 6 | E28: 1 | F28: 10
A29: Destructif | B29: 1 | D29: 2 | F29: 3
A30: RAB | B30: 1 | D30: 1 | E30: 1 | F30: 3
A31: RC | C31: 3 | D31: 9 | F31: 12
A32: Tarrière | D32: 6 | E32: 1 | F32: 7
A33: Total général | B33: 3 | C33: 5 | D33: 25 | E33: 3 | F33: 36

Sheet Requete_PRODUCTION_TRANSFOR OK
A1: entreprise_id | B1: Région | C1: produit_desc_ok | D1: qte_prd_vendu_pays | E1: qte_prd_vendu_etrger | F1: qte_prd_immobilise | G1: qte_stock_ouverture | H1: qte_prd_stock_cloture | I1: val_prd_vendu_pays | J1: val_prd_vendu_etrger | K1: val_prd_immobilise | L1: val_prd_stock_ouverture | M1: val_prd_stock_cloture | N1: PRODUCTION EN QUANTITE | O1: PRODUCTION EN VALEUR | Q1: Prix pays | R1: Prix etgr | S1: prix stck ouv | T1: Prix stock Cltur
A2: 2SBCI | B2: =VLOOKUP(A2,'Requete_INFOTITREMINIER OK'!$A$1:$P$122,5,0) -> THIES | C2: Calcaire | D2: 85030 | E2: 0 | F2: 0 | G2: 0 | H2: 0 | I2: 306017.57 | J2: 0 | K2: 0 | L2: 0 | M2: 0 | N2: =+D2+E2+H2-G2 -> 85030 | O2: =+I2+J2+M2-L2 -> 306017.57 | P2: =O2/N2 -> 3.5989365
A3: AFRIGOLD SARL | B3: KEDOUGOU | C3: Or | D3: 0.04847 | E3: 0 | F3: 0 | G3: 0 | H3: 0 | I3: 1614476 | J3: 0 | K3: 0 | L3: 0 | M3: 0 | N3: =+D3+E3+H3-G3 -> 0.04847 | O3: =+I3+J3+M3-L3 -> 1614476 | Q3: =I3/D3 -> 33308768 | R3: =J3/E3 -> #DIV/0! | S3: =L3/G3 -> #DIV/0! | T3: =M3/H3 -> #DIV/0!
A4: ALBINA SENEGAL SARL | B4: THIES | C4: Calcaire | D4: 95809.5 | E4: 0 | F4: 0 | G4: 0 | H4: 0 | I4: 205720.2 | J4: 0 | K4: 0 | L4: 0 | M4: 0 | N4: =+D4+E4+H4-G4 -> 95809.5 | O4: =+I4+J4+M4-L4 -> 205720.2 | P4: =O4/N4 -> 2.1471796 | Q4: =I4/D4 -> 2.1471796 | R4: =J4/E4 -> #DIV/0! | S4: =L4/G4 -> #DIV/0! | T4: =M4/H4 -> #DIV/0!
A5: ATIC SARL | B5: THIES | C5: Silex | D5: 44624 | E5: 0 | F5: 0 | G5: 0 | H5: 0 | I5: 334686 | J5: 0 | K5: 0 | L5: 0 | M5: 0 | N5: =+D5+E5+H5-G5 -> 44624 | O5: =+I5+J5+M5-L5 -> 334686 | P5: =+O5/N5 -> 7.5001345 | Q5: =I5/D5 -> 7.5001345 | R5: =J5/E5 -> #DIV/0! | S5: =L5/G5 -> #DIV/0! | T5: =M5/H5 -> #DIV/0!
A6: BMCC SA | B6: DIOURBEL | C6: Phosphates | D6: 2595 | E6: 49105 | F6: 0 | G6: 549 | H6: 26601 | I6: 149252 | J6: 2483353 | K6: 0 | L6: 13445 | M6: 1346446 | N6: =+D6+E6+H6-G6 -> 77752 | O6: =+I6+J6+M6-L6 -> 3965606 | P6: =+O6/N6 -> 51.003267 | Q6: =I6/D6 -> 57.515222 | R6: =J6/E6 -> 50.572304 | S6: =L6/G6 -> 24.489982 | T6: =M6/H6 -> 50.616368
A7: BOSFOR SARL | B7: THIES | C7: Calcaire | D7: 724174 | E7: 0 | F7: =400457+131471+206999 -> 738927 | G7: =23874+4533 -> 28407 | H7: =10228+7951+24981 -> 43160 | I7: 1954151 | J7: 0 | K7: =240274+723090+931495 -> 1894859 | L7: 145413 | M7: 153082 | N7: =+D7+E7+H7-G7 -> 738927 | O7: =+I7+J7+M7-L7 -> 1961820 | P7: =O7/N7 -> 2.6549578 | Q7: =I7/D7 -> 2.6984551 | R7: =J7/E7 -> #DIV/0! | S7: =L7/G7 -> 5.1189144 | T7: =M7/H7 -> 3.5468489
A8: CIMENTS DU SAHEL | B8: THIES | C8: Ciment | D8: 2401500 | E8: 1112412 | F8: 23334 | G8: 982 | H8: 36378 | I8: 112613674 | J8: 51335300 | K8: 1116653 | L8: 32467 | M8: 1565025 | N8: =+D8+E8+H8-G8 -> 3549308 | O8: =+I8+J8+M8-L8 -> 165481532 | P8: =O8/N8 -> 46.623604 | Q8: =I8/D8 -> 46.893056 | R8: =J8/E8 -> 46.14774 | S8: =L8/G8 -> 33.062118 | T8: =M8/H8 -> 43.021194
A9: COMPAGNIE GENERALE D'EXPLOITATION DE CARRIERE | B9: THIES | C9: Basalte | D9: 2224570 | E9: 14394 | F9: 0 | G9: =L9/7.2 -> 539755.42 | H9: =M9/7.2 -> 543569.31 | I9: 16061313 | J9: 107161 | K9: 0 | L9: 3886239 | M9: 3913699 | N9: =+D9+E9+H9-G9 -> 2242777.9 | O9: =+I9+J9+M9-L9 -> 16195934 | P9: =+O9/N9 -> 7.2213722 | Q9: =I9/D9 -> 7.219963 | R9: =J9/E9 -> 7.4448381 | S9: =L9/G9 -> 7.2 | T9: =M9/H9 -> 7.2
A10: COMPAGNIE GENERALE D'EXPLOITATION DE CARRIERE | B10: THIES | C10: Calcaire | D10: =I10/4.5 -> 49375.204 | I10: =16418122.419-O9 -> 222188.42 | N10: =+D10+E10+H10-G10 -> 49375.204 | O10: =+I10+J10+M10-L10 -> 222188.42 | P10: =O10/N10 -> 4.5 | Q10: =I10/D10 -> 4.5 | R10: =J10/E10 -> #DIV/0! | S10: =L10/G10 -> #DIV/0! | T10: =M10/H10 -> #DIV/0!
A11: CSE GRANULATS | B11: THIES | C11: Basalte | D11: 1236580.2 | E11: 47949.86 | F11: 1412149 | G11: 78819 | H11: 61383 | I11: 8611048.7 | J11: 390487.02 | K11: 55066154 | L11: 634703.08 | M11: 436646.16 | N11: =+D11+E11+H11-G11 -> 1267094.1 | O11: =+I11+J11+M11-L11 -> 8803478.8 | P11: =+O11/N11 -> 6.9477706 | Q11: =I11/D11 -> 6.9635991 | R11: =J11/E11 -> 8.143653 | S11: =L11/G11 -> 8.052666 | T11: =M11/H11 -> 7.1134705
A12: DANGOTE CEMENT SENEGAL | B12: THIES | C12: Ciment | D12: 842075 | E12: 208646 | F12: 0 | G12: 6073 | H12: 27266 | I12: 39627967 | J12: 8959179 | K12: 0 | L12: 184722 | M12: 1063760 | N12: =+D12+E12+H12-G12 -> 1071914 | O12: =+I12+J12+M12-L12 -> 49466184 | P12: =O12/N12 -> 46.14753 | Q12: =I12/D12 -> 47.059902 | R12: =J12/E12 -> 42.939615 | S12: =L12/G12 -> 30.416927 | T12: =M12/H12 -> 39.014157
A13: DIYAN EXPLOITATION MINIERE SUARL | B13: THIES | C13: Silex | N13: =+D13+E13+H13-G13 -> 0 | O13: =+I13+J13+M13-L13 -> 0 | Q13: =I13/D13 -> #DIV/0! | R13: =J13/E13 -> #DIV/0! | S13: =L13/G13 -> #DIV/0! | T13: =M13/H13 -> #DIV/0!
A14: ENTREPRISE MAPATHE NDIOUCK SA | B14: THIES | C14: Silex | D14: 45433 | G14: 1935 | I14: 403499.92 | L14: 17185.137 | N14: =+D14+E14+H14-G14 -> 43498 | O14: =+I14+J14+M14-L14 -> 386314.78 | P14: =+O14/N14 -> 8.8812079 | Q14: =I14/D14 -> 8.8812079 | R14: =J14/E14 -> #DIV/0! | S14: =L14/G14 -> 8.8812078 | T14: =M14/H14 -> #DIV/0!
A15: ENTREPRISE MAPATHE NDIOUCK SA | B15: TAMBACOUNDA | C15: Grès | D15: 62201 | I15: 477353.11 | N15: =+D15+E15+H15-G15 -> 62201 | O15: =+I15+J15+M15-L15 -> 477353.11 | P15: =+O15/N15 -> 7.6743639 | Q15: =I15/D15 -> 7.6743639 | R15: =J15/E15 -> #DIV/0! | S15: =L15/G15 -> #DIV/0! | T15: =M15/H15 -> #DIV/0!
A16: ENTREPRISE OUSMANE SOW | B16: THIES | C16: Grès | D16: =9765+7845 -> 17610 | I16: =54922.81+44127.9 -> 99050.71 | N16: =+D16+E16+H16-G16 -> 17610 | O16: =+I16+J16+M16-L16 -> 99050.71 | P16: =+O16/N16 -> 5.6246854 | Q16: =I16/D16 -> 5.6246854 | R16: =J16/E16 -> #DIV/0! | S16: =L16/G16 -> #DIV/0! | T16: =M16/H16 -> #DIV/0!
A17: ENTREPRISE OUSMANE SOW | B17: THIES | C17: Latérite | N17: =+D17+E17+H17-G17 -> 0 | O17: =+I17+J17+M17-L17 -> 0 | Q17: =I17/D17 -> #DIV/0! | R17: =J17/E17 -> #DIV/0! | S17: =L17/G17 -> #DIV/0! | T17: =M17/H17 -> #DIV/0!
A18: G.H MINING | B18: TAMBACOUNDA | C18: Manganèse | D18: 0 | E18: 31093.338 | F18: 0 | G18: 1300 | H18: 6297.512 | I18: 0 | J18: 1263388 | K18: 0 | L18: 0 | M18: 0 | N18: =+D18+E18+H18-G18 -> 36090.85 | O18: =+I18+J18+M18-L18 -> 1263388 | Q18: =I18/D18 -> #DIV/0! | R18: =J18/E18 -> 40.632112 | S18: =L18/G18 -> 0 | T18: =M18/H18 -> 0
A19: GAZAL CARRIERES | B19: THIES | C19: Calcaire | D19: 117568 | E19: 0 | F19: 0 | G19: 0 | H19: 0 | I19: 534400 | J19: 0 | K19: 0 | L19: 0 | M19: 0 | N19: =+D19+E19+H19-G19 -> 117568 | O19: =+I19+J19+M19-L19 -> 534400 | P19: =O19/N19 -> 4.5454545 | Q19: =I19/D19 -> 4.5454545 | R19: =J19/E19 -> #DIV/0! | S19: =L19/G19 -> #DIV/0! | T19: =M19/H19 -> #DIV/0!
A20: GECAMINES | B20: THIES | C20: Calcaire | D20: =110593+6694+153506+258+178082+106396 -> 555529 | F20: 0 | G20: 0 | H20: 0 | I20: =657483+37673+134004+1480+707190+858211 -> 2396041 | K20: 0 | N20: =+D20+E20+H20-G20 -> 555529 | O20: =+I20+J20+M20-L20 -> 2396041 | Q20: =I20/D20 -> 4.31308 | R20: =J20/E20 -> #DIV/0! | S20: =L20/G20 -> #DIV/0! | T20: =M20/H20 -> #DIV/0!
A21: GECAMINES | B21: THIES | C21: Basalte | D21: 2306764 | E21: 93421 | F21: 0 | G21: 0 | H21: 0 | I21: 17227606 | J21: 736942 | K21: 0 | L21: 3677029 | M21: 3043077 | N21: =+D21+E21+H21-G21 -> 2400185 | O21: =+I21+J21+M21-L21 -> 17330596 | P21: =+O21/N21 -> 7.2205251 | Q21: =I21/D21 -> 7.4683002 | R21: =J21/E21 -> 7.8883977 | S21: =L21/G21 -> #DIV/0! | T21: =M21/H21 -> #DIV/0!
A22: GLOBAL IMMO SENEGAL SARL | B22: THIES | C22: Silex | D22: 292997 | I22: 2137633.4 | N22: =+D22+E22+H22-G22 -> 292997 | O22: =+I22+J22+M22-L22 -> 2137633.4 | P22: =+O22/N22 -> 7.2957519 | Q22: =I22/D22 -> 7.2957519 | R22: =J22/E22 -> #DIV/0! | S22: =L22/G22 -> #DIV/0! | T22: =M22/H22 -> #DIV/0!
A23: GRANDE COTE OPERATIONS | B23: THIES | C23: Ilménite | D23: 0 | E23: 526747 | F23: 0 | G23: =29059+2426+0 -> 31485 | H23: =865+1633 -> 2498 | I23: 0 | J23: 109536232 | K23: 0 | L23: 2176655 | M23: 217218 | N23: =+D23+E23+H23-G23 -> 497760 | O23: =+I23+J23+M23-L23 -> 107576795 | Q23: =I23/D23 -> #DIV/0! | R23: =J23/E23 -> 207.94847 | S23: =L23/G23 -> 69.133079 | T23: =M23/H23 -> 86.956765
A24: GRANDE COTE OPERATIONS | B24: THIES | C24: Zircon | D24: =0 -> 0 | E24: 90745 | F24: 0 | G24: 8549 | H24: 1869 | I24: 0 | J24: 88151983 | K24: 0 | L24: 1516900 | M24: 334527 | N24: =+D24+E24+H24-G24 -> 84065 | O24: =+I24+J24+M24-L24 -> 86969610 | P24: =O24/N24 -> 1034.552 | Q24: =I24/D24 -> #DIV/0! | R24: =J24/E24 -> 971.42524 | S24: =L24/G24 -> 177.43596 | T24: =M24/H24 -> 178.98716
A25: GRANDE COTE OPERATIONS | B25: THIES | C25: Rutile | D25: 0 | E25: 4160 | F25: 0 | G25: 34 | H25: 77 | I25: 0 | J25: 5290813 | K25: 0 | L25: 12483 | M25: 35816 | N25: =+D25+E25+H25-G25 -> 4203 | O25: =+I25+J25+M25-L25 -> 5314146 | Q25: =I25/D25 -> #DIV/0! | R25: =J25/E25 -> 1271.83 | S25: =L25/G25 -> 367.14706 | T25: =M25/H25 -> 465.14286
A26: GRANDE COTE OPERATIONS | B26: THIES | C26: Leucoxene | D26: 0 | E26: 6340 | F26: 0 | G26: 75 | H26: 19 | I26: 0 | J26: 5532815 | K26: 0 | L26: 19731 | M26: 6682 | N26: =+D26+E26+H26-G26 -> 6284 | O26: =+I26+J26+M26-L26 -> 5519766 | Q26: =I26/D26 -> #DIV/0! | R26: =J26/E26 -> 872.68375 | S26: =L26/G26 -> 263.08 | T26: =M26/H26 -> 351.68421
A27: GROUPEMENT D'ENTREPRISE SINTRAM HOUAR | B27: THIES | C27: Basalte | D27: 53521 | E27: 0 | F27: 0 | G27: 0 | H27: 0 | I27: 182334 | J27: 0 | K27: 0 | L27: 0 | M27: 0 | N27: =+D27+E27+H27-G27 -> 53521 | O27: =+I27+J27+M27-L27 -> 182334 | P27: =+O27/N27 -> 3.4067749 | Q27: =I27/D27 -> 3.4067749 | R27: =J27/E27 -> #DIV/0! | S27: =L27/G27 -> #DIV/0! | T27: =M27/H27 -> #DIV/0!
A28: INCA SARL | B28: THIES | C28: Calcaire | N28: =+D28+E28+H28-G28 -> 0 | O28: =+I28+J28+M28-L28 -> 0 | P28: =O28/N28 -> #DIV/0! | R28: =J28/E28 -> #DIV/0! | S28: =L28/G28 -> #DIV/0! | T28: =M28/H28 -> #DIV/0!
A29: INDUSTRIES CHIMIQUES DU SENEGAL | B29: THIES | C29: Phosphates | D29: 0 | E29: 0 | F29: 0 | G29: 180608 | H29: 33590 | I29: 0 | J29: 0 | K29: 0 | L29: 4946108 | M29: 1053777 | N29: =G29-H29 -> 147018 | O29: =L29-M29 -> 3892331 | P29: =+O29/N29 -> 26.4752 | Q29: =I29/D29 -> #DIV/0! | R29: =J29/E29 -> #DIV/0! | S29: =L29/G29 -> 27.385874 | T29: =M29/H29 -> 31.371748
A30: INDUSTRIES CHIMIQUES DU SENEGAL | B30: THIES | C30: Acide phosphorique | D30: 7 | E30: 558410 | F30: 0 | G30: 56345 | H30: 43178 | I30: 6289 | J30: 533842674 | K30: 0 | L30: 16652848 | M30: 18650398 | N30: =+D30+E30+H30-G30 -> 545250 | O30: =+I30+J30+M30-L30 -> 535846513 | P30: =+O30/N30 -> 982.75381 | Q30: =I30/D30 -> 898.42857 | R30: =J30/E30 -> 956.00486 | S30: =L30/G30 -> 295.55148 | T30: =M30/H30 -> 431.94215
A31: INDUSTRIES CHIMIQUES DU SENEGAL | B31: THIES | C31: Engrais | D31: 76545 | E31: 12318 | F31: 0 | G31: 31084 | H31: 25222 | I31: 27574026 | J31: 3328965 | K31: 0 | L31: 7024386 | M31: 6142778 | N31: =+D31+E31+H31-G31 -> 83001 | O31: =+I31+J31+M31-L31 -> 30021383 | P31: =+O31/N31 -> 361.69905 | Q31: =I31/D31 -> 360.23288 | R31: =J31/E31 -> 270.25207 | S31: =L31/G31 -> 225.98076 | T31: =M31/H31 -> 243.54841
A32: KUTLU GABANE HOLDING S.A | B32: THIES | C32: Basalte | D32: 117925.4 | E32: 0 | F32: 0 | G32: 0 | H32: 0 | I32: 963311.8 | J32: 0 | K32: 0 | L32: 0 | M32: 0 | N32: =+D32+E32+H32-G32 -> 117925.4 | O32: =+I32+J32+M32-L32 -> 963311.8 | P32: =+O32/N32 -> 8.1688237 | Q32: =I32/D32 -> 8.1688237 | R32: =J32/E32 -> #DIV/0! | S32: =L32/G32 -> #DIV/0! | T32: =M32/H32 -> #DIV/0!
A33: PETOWAL MINING COMPANY (PMC) SA | B33: KEDOUGOU | C33: Argent | E33: 0.35442419 | J33: 152394.41 | N33: =+D33+E33+H33-G33 -> 0.35442419 | O33: =+I33+J33+M33-L33 -> 152394.41 | Q33: =I33/D33 -> #DIV/0! | R33: =J33/E33 -> 429977.45 | S33: =L33/G33 -> #DIV/0! | T33: =M33/H33 -> #DIV/0!
A34: PETOWAL MINING COMPANY (PMC) SA | B34: KEDOUGOU | C34: Or | D34: 0 | E34: 4.0319337 | F34: 0 | G34: 0.13974758 | H34: 0.12304505 | I34: 0 | J34: 147862816 | K34: 0 | L34: 2874527 | M34: 2730952 | N34: =+D34+E34+H34-G34 -> 4.0152312 | O34: =+I34+J34+M34-L34 -> 147719241 | Q34: =I34/D34 -> #DIV/0! | R34: =J34/E34 -> 36672928 | S34: =L34/G34 -> 20569423 | T34: =M34/H34 -> 22194733
A35: PROCHIMAT SA | B35: THIES | C35: Attapulgite | D35: 1775 | E35: 9235 | G35: 309 | H35: 240 | I35: 129907 | J35: =575697.785+43946.217 -> 619644 | L35: 2096.228 | M35: 34922.894 | N35: =+D35+E35+H35-G35 -> 10941 | O35: =+I35+J35+M35-L35 -> 782377.67 | Q35: =I35/D35 -> 73.187042 | R35: =J35/E35 -> 67.097347 | S35: =L35/G35 -> 6.7839094 | T35: =M35/H35 -> 145.51206
A36: ROYAL SENEGAL MINES ET EQUIPEMENTS | B36: THIES | C36: Calcaire | D36: 57288 | E36: 0 | F36: 0 | G36: 0 | H36: 0 | I36: 260400 | J36: 0 | K36: 0 | L36: 0 | M36: 0 | N36: =+D36+E36+H36-G36 -> 57288 | O36: =+I36+J36+M36-L36 -> 260400 | P36: =O36/N36 -> 4.5454545 | Q36: =I36/D36 -> 4.5454545 | R36: =J36/E36 -> #DIV/0! | S36: =L36/G36 -> #DIV/0! | T36: =M36/H36 -> #DIV/0!
A37: SABODALA GOLD OPERATIONS | B37: KEDOUGOU | C37: Or | D37: 0.25 | E37: 10.64 | F37: 0 | G37: 0.3 | H37: 0.27 | I37: 9028238 | J37: 383558467 | K37: 0 | L37: 1055660 | M37: 2080075 | N37: =+D37+E37+H37-G37 -> 10.86 | O37: =+I37+J37+M37-L37 -> 393611120 | Q37: =I37/D37 -> 36112952 | R37: =J37/E37 -> 36048728 | S37: =L37/G37 -> 3518866.7 | T37: =M37/H37 -> 7703981.5
A38: SABODALA GOLD OPERATIONS | B38: KEDOUGOU | C38: Argent | D38: 0 | E38: 0.85 | F38: 0 | G38: 0 | H38: 0 | I38: 0 | J38: 374908 | K38: 0 | L38: 0 | M38: 0 | N38: =+D38+E38+H38-G38 -> 0.85 | O38: =+I38+J38+M38-L38 -> 374908 | Q38: =I38/D38 -> #DIV/0! | R38: =J38/E38 -> 441068.24 | S38: =L38/G38 -> #DIV/0! | T38: =M38/H38 -> #DIV/0!
A39: SENEGAL MINES | B39: THIES | C39: Hormite | D39: 0 | E39: 20360 | G39: =4599+386 -> 4985 | H39: =1020+386 -> 1406 | I39: 0 | J39: 1335507 | L39: =204952+26315 -> 231267 | M39: =55097+30902 -> 85999 | N39: =+D39+E39+H39-G39 -> 16781 | O39: =+I39+J39+M39-L39 -> 1190239 | R39: =J39/E39 -> 65.594646 | S39: =L39/G39 -> 46.392578 | T39: =M39/H39 -> 61.165718
A40: SENEGAL MINES | B40: THIES | C40: Attapulgite | D40: 80.14 | E40: 9150 | G40: 335 | H40: 694 | I40: 6345 | J40: 430330 | L40: 60416 | M40: 18195 | N40: =+D40+E40+H40-G40 -> 9589.14 | O40: =+I40+J40+M40-L40 -> 394454 | Q40: =I40/D40 -> 79.173946 | R40: =J40/E40 -> 47.030601 | S40: =L40/G40 -> 180.34627 | T40: =M40/H40 -> 26.217579
...

Sheet PRODUCTION
A3: Étiquettes de lignes | B3: Somme de PRODUCTION EN QUANTITE | E3: Étiquettes de lignes | F3: Somme de qte_brute | K3: Substance | L3: 2019 | M3: 2020 | N3: 2021 | O3: 2020/ 2021
A4: Argent | B4: 1.2044242 | E4: Argile | F4: 556799 | K4: Argent | L4: 0.5 | M4: 1 | N4: 1.3 | O4: 31,8%
A5: Attapulgite | B5: 165559.5 | E5: Calcaire | F5: 5193843 | K5: Argile | L5: 433483 | M5: 418052 | N5: 670650 | O5: 60,4%
A6: Basalte | B6: 6352766.3 | E6: Latérite | F6: 224778 | K6: Attapulgite | L6: 197673 | M6: 201919 | N6: 193438 | O6: -4,2%
A7: Calcaire | B7: 2416753.7 | E7: Marne | F7: 1990935 | K7: Basalte | L7: 3613673 | M7: 3700409 | N7: 5415020 | O7: 46,3%
A8: Grès | B8: 79811 | E8: Phosphate de chaux | F8: 1771000 | K8: Calcaire | L8: 5944543 | M8: 6558606 | N8: 7471837 | O8: 13,9%
A9: Hormite | B9: 16781 | E9: Total général | F9: 9737355 | K9: Grès | N9: 86431
A10: Ilménite | B10: 497760 | K10: Hormite | L10: 11213 | M10: 29603 | N10: 18988 | O10: -35,9%
A11: Latérite | B11: 0 | K11: Ilménite | L11: 492282 | M11: 521440 | N11: 543062 | O11: 4,1%
A12: Leucoxene | B12: 6284 | F12: 5193843 | K12: Latérite | L12: 139552 | M12: 260571 | N12: 293165 | O12: 12,5%
A13: Manganèse | B13: 36090.85 | K13: Leucoxène | L13: 6515 | M13: 5501 | N13: 6985 | O13: 27,0%
A14: Minéraux lourds | B14: 9099 | K14: Manganèse | L14: 4368 | M14: 15376 | N14: 9236 | O14: -39,9%
A15: Or | B15: 14.946701 | F15: =+F12/B29 -> 0.68244885 | K15: Marne | L15: 1617455 | M15: 1845762 | N15: 1965915 | O15: 6,5%
A16: Phosphates | B16: 1088462 | K16: Minéraux lourds | M16: 682 | N16: 1812 | O16: 165,7%
A17: Rutile | B17: 4203 | K17: Or | L17: 13 | M17: 12.4 | N17: 16.2 | O17: 35,0%
A18: Silex | B18: 884708.31 | K18: Phosphates | L18: 2295975 | M18: 2230504 | N18: 2500344 | O18: 12,1%
A19: Zircon | B19: 84065 | K19: Rutile | L19: 3614 | M19: 4044 | N19: 4431 | O19: 9,6%
A20: Total général | B20: 11642360 | K20: Silex | L20: 98355 | M20: 297611 | N20: 888095 | O20: 298,4%
K21: Zircon | L21: 80721 | M21: 84376 | N21: 90706 | O21: 7,5%
L22: =SUM(L17:L21) -> 2478678 | M22: =SUM(M17:M21) -> 2616547.4 | N22: =SUM(N17:N21) -> 3483592.2 | O22: =SUM(O17:O21) -> 0
A24: Production par substance (en tonnes) 2022
A25: Argent | B25: =+B4 -> 1.2044242 | E25: Substance | F25: 2019 | G25: 2020 | H25: 2021 | I25: 2022
A26: Argile | B26: =+F4 -> 556799 | E26: Argent | F26: 0.5 | G26: 1 | H26: 1.3 | I26: =+B25 -> 1.2044242 | J26: =+I26/H26-1 -> -0.073519853
A27: Attapulgite | B27: =+B5 -> 165559.5 | E27: Argile | F27: 433483 | G27: 418052 | H27: 670650 | I27: =+B26 -> 556799 | J27: =+I27/H27-1 -> -0.16976217
A28: Basalte | B28: =+B6 -> 6352766.3 | E28: Attapulgite | F28: 197673 | G28: 201919 | H28: 193438 | I28: =+B27 -> 165559.5 | J28: =+I28/H28-1 -> -0.14412111
A29: Calcaire | B29: =+B7+F5 -> 7610596.7 | E29: Basalte | F29: 3613673 | G29: 3700409 | H29: 5415020 | I29: =+B28 -> 6352766.3 | J29: =+I29/H29-1 -> 0.17317505
A30: Grès | B30: =+B8 -> 79811 | E30: Calcaire | F30: 5944543 | G30: 6558606 | H30: 7471837 | I30: =+B29 -> 7610596.7 | J30: =+I30/H30-1 -> 0.018571029
A31: Hormite | B31: =+B9 -> 16781 | E31: Grès | H31: 86431 | I31: =+B30 -> 79811 | J31: =+I31/H31-1 -> -0.076592889
A32: Ilménite | B32: =+B10 -> 497760 | E32: Hormite | F32: 11213 | G32: 29603 | H32: 18988 | I32: =+B31 -> 16781 | J32: =+I32/H32-1 -> -0.1162313
A33: Latérite | B33: =+B11+F6 -> 224778 | E33: Ilménite | F33: 492282 | G33: 521440 | H33: 543062 | I33: =+B32 -> 497760 | J33: =+I33/H33-1 -> -0.083419573
A34: Leucoxène | B34: =+B12 -> 6284 | E34: Latérite | F34: 139552 | G34: 260571 | H34: 293165 | I34: =+B33 -> 224778 | J34: =+I34/H34-1 -> -0.23327137
A35: Manganèse | B35: =+B13 -> 36090.85 | E35: Leucoxène | F35: 6515 | G35: 5501 | H35: 6985 | I35: =+B34 -> 6284 | J35: =+I35/H35-1 -> -0.10035791
A36: Marne | B36: =+F7 -> 1990935 | E36: Manganèse | F36: 4368 | G36: 15376 | H36: 9236 | I36: =+B35 -> 36090.85 | J36: =+I36/H36-1 -> 2.9076278
A37: Minéraux lourds | B37: =+B14 -> 9099 | E37: Marne | F37: 1617455 | G37: 1845762 | H37: 1965915 | I37: =+B36 -> 1990935 | J37: =+I37/H37-1 -> 0.012726898
A38: Or | B38: =+B15 -> 14.946701 | E38: Minéraux lourds | G38: 682 | H38: 1812 | I38: =+B37 -> 9099 | J38: =+I38/H38-1 -> 4.0215232
A39: Phosphates | B39: =+B16+F8 -> 2859462 | E39: Or | F39: 13 | G39: 12.4 | H39: 16.2 | I39: =+B38 -> 14.946701 | J39: =+I39/H39-1 -> -0.077364122
A40: Rutile | B40: =+B17 -> 4203 | E40: Phosphates | F40: 2295975 | G40: 2230504 | H40: 2500344 | I40: =+B39 -> 2859462 | J40: =+I40/H40-1 -> 0.14362744
A41: Silex | B41: =+B18 -> 884708.31 | E41: Rutile | F41: 3614 | G41: 4044 | H41: 4431 | I41: =+B40 -> 4203 | J41: =+I41/H41-1 -> -0.051455653
A42: Zircon | B42: =+B19 -> 84065 | E42: Silex | F42: 98355 | G42: 297611 | H42: 888095 | I42: =+B41 -> 884708.31 | J42: =+I42/H42-1 -> -0.0038134321
B43: =SUM(B25:B42) -> 21379715 | E43: Zircon | F43: 80721 | G43: 84376 | H43: 90706 | I43: =+B42 -> 84065 | J43: =+I43/H43-1 -> -0.073214561
...

Sheet Requete_PRODUCTIONELECTRICIT OK
A1: entreprise_id | B1: electrc_propr_consommtn | C1: qte_electrc_autoconsom | D1: estimatn_autoconsommtn | E1: vendu_electrc_ind | F1: qte_electrc_vendu | G1: solaire_ind | H1: fuel_ind | I1: fuel_qte | J1: fuel_unite_mesr | K1: diesel_ind | L1: diesel_qte | M1: diesel_unite_mesr | N1: charbon_ind | O1: charbon_qte | P1: charbon_unite_mesr | Q1: gaz_nat_ind | R1: gaz_nat_qte | S1: gaz_nat_unite_mesr | T1: autre_source | U1: autre_ind | V1: autre_qte | W1: autre_unite_mesr | X1: autre_unite_mesr_desc | Y1: Prix Implicite
A2: BOSFOR SARL | B2: 1 | C2: 2329600 | D2: 262000 | E2: 2 | F2: 0 | G2: 2 | H2: 2 | I2: 0 | J2: 1 | K2: 1 | L2: 400000 | M2: 1 | N2: 2 | O2: 0 | P2: 1 | Q2: 2 | R2: 0 | S2: 1 | U2: 2 | V2: 0 | W2: 1 | Y2: =D2/C2 -> 0.11246566
A3: INDUSTRIES CHIMIQUES DU SENEGAL | B3: 1 | C3: 265237763 | D3: 7172899 | E3: 1 | F3: 15554000 | G3: 2 | H3: 1 | I3: 787 | J3: 2 | K3: 1 | L3: 26623457 | M3: 2 | N3: 1 | O3: 151162 | P3: 1 | Q3: 2 | R3: 0 | S3: 1 | U3: 2 | V3: 0 | W3: 1 | Y3: =D3/C3 -> 0.02704328
A4: CIMENTS DU SAHEL | B4: 1 | C4: 226156533 | D4: 27100412 | E4: 2 | F4: 0 | G4: 2 | H4: 1 | I4: 26706426 | J4: 1 | K4: 1 | L4: 32938142 | M4: 1 | N4: 2 | O4: 0 | P4: 1 | Q4: 2 | R4: 0 | S4: 1 | U4: 2 | V4: 0 | W4: 1 | Y4: =D4/C4 -> 0.11983033
A5: GRANDE COTE OPERATIONS | B5: 3 | C5: 134248000 | D5: 15033200 | E5: 2 | F5: 0 | G5: 2 | H5: 2 | I5: 0 | J5: 1 | K5: 2 | L5: 0 | M5: 1 | N5: 2 | O5: 0 | P5: 1 | Q5: 2 | R5: 0 | S5: 1 | U5: 2 | V5: 0 | W5: 1 | Y5: =D5/C5 -> 0.11198081
A6: SORED-MINES SA | B6: 1 | C6: 8885368 | D6: =+C6*0.11 -> 977390.48 | E6: 2 | F6: 0 | G6: 2 | H6: 2 | I6: 0 | J6: 1 | K6: 1 | L6: 2221342 | M6: 1 | N6: 2 | O6: 0 | P6: 1 | Q6: 2 | R6: 0 | S6: 1 | U6: 2 | V6: 0 | W6: 1 | Y6: =D6/C6 -> 0.11
A7: SABODALA GOLD OPERATIONS | C7: 143556211 | D7: 14341000 | E7: 2 | F7: 0 | G7: 2 | H7: 2 | I7: 0 | J7: 1 | K7: 2 | L7: 0 | M7: 1 | N7: 2 | O7: 0 | P7: 1 | Q7: 2 | R7: 0 | S7: 1 | U7: 2 | V7: 0 | W7: 1 | Y7: =D7/C7 -> 0.099898151
A8: DANGOTE CEMENT SENEGAL | B8: 1 | C8: 100528139 | D8: 11359680 | E8: 2 | F8: 0 | G8: 1 | H8: 2 | I8: 0 | J8: 1 | K8: 1 | L8: 721980 | M8: 1 | N8: 1 | O8: 72783 | P8: 1 | Q8: 2 | R8: 0 | S8: 1 | U8: 2 | V8: 0 | W8: 1 | Y8: =D8/C8 -> 0.113
A9: PETOWAL MINING COMPANY (PMC) SA | B9: 1 | C9: 83628875 | D9: 9455753 | E9: 2 | F9: 0 | G9: 2 | H9: 2 | I9: 0 | J9: 1 | K9: 1 | L9: 21486676 | M9: 1 | N9: 2 | O9: 0 | P9: 1 | Q9: 2 | R9: 0 | S9: 1 | U9: 2 | V9: 0 | W9: 1 | Y9: =D9/C9 -> 0.11306804
A10: GECAMINES | B10: 1 | C10: 4375380 | D10: 809445 | E10: 2 | F10: 0 | G10: 2 | H10: 2 | I10: 0 | J10: 1 | K10: 1 | L10: 1458460 | M10: 1 | N10: 2 | O10: 0 | P10: 1 | Q10: 2 | R10: 0 | S10: 1 | U10: 2 | V10: 0 | W10: 1 | Y10: =D10/C10 -> 0.18499993
A12: Carrières | C12: =(C10+C2)/1000 -> 6704.98 | D12: =(D10+D2)/1000 -> 1071.445 | L12: =D12/$D$15 -> 0.026210292
A13: Minéraux lourds | C13: =C5/1000 -> 134248 | D13: =D5/1000 -> 15033.2 | L13: =D13/$D$15 -> 0.36775062
A14: Or | C14: =(C6+C7+C9)/1000 -> 236070.45 | D14: =(D6+D7+D9)/1000 -> 24774.143 | L14: =D14/$D$15 -> 0.60603908
A15: TOTAL | C15: =SUM(C12:C14) -> 377023.43 | D15: =SUM(D12:D14) -> 40878.788 | L15: =D15/$D$15 -> 1
C16: =C15/1000 -> 377.02343
C17: 352.2 | D17: =C16/C17-1 -> 0.070481073
A19: Type d'activité | B19: Electricité produite en quantité (MWH) | C19: Electricité produite en valeur | D19: Pourcentage par type d'activité
C20: ( en million FCFA)
A21: Carrière | B21: 4 345 | C21: 809.4 | D21: =+C21/$C$24 -> 0.019800022
A22: Minéraux lourds | B22: 134 248 | C22: 15033.2 | D22: =+C22/$C$24 -> 0.36775103
A23: Or | B23: 236 074,5 | C23: 25036.143 | D23: =+C23/$C$24 -> 0.61244895
A24: TOTAL | C24: =SUM(C21:C23) -> 40878.743

Sheet Requete_PRODUCTION CIMICS ok
A1: entreprise_id | B1: Région | C1: substance_desc | D1: qte_brute | E1: cout_production | F1: qte_transforme | G1: Cout de production/qte
A2: CIMENTS DU SAHEL | B2: THIES | C2: Argile | D2: 400578 | E2: 1321908 | F2: 400578 | G2: =+E2/D2 -> 3.3000015
A3: DANGOTE CEMENT SENEGAL | B3: THIES | C3: Argile | D3: 156221 | E3: 388947 | F3: 168001 | G3: =+E3/D3 -> 2.4897229
A4: CIMENTS DU SAHEL | B4: THIES | C4: Calcaire | D4: 2902226 | E4: 6094674 | F4: 2902226 | G4: =+E4/D4 -> 2.0999998
A5: DANGOTE CEMENT SENEGAL | B5: THIES | C5: Calcaire | D5: 1388347 | E5: 2244819 | F5: 1388347 | G5: =+E5/D5 -> 1.6169005
A6: CIMENTS DU SAHEL | B6: THIES | C6: Latérite | D6: 82473 | E6: 247419 | F6: 82473 | G6: =+E6/D6 -> 3
A7: DANGOTE CEMENT SENEGAL | B7: THIES | C7: Latérite | D7: 40864 | E7: 84608 | F7: 40864 | G7: =+E7/D7 -> 2.0704777
A8: INDUSTRIES CHIMIQUES DU SENEGAL | B8: THIES | C8: Phosphate de chaux | D8: 1771000 | E8: 56393616 | F8: 1987798 | G8: =+E8/D8 -> 31.84281
A9: SOCOCIM INDUSTRIES | B9: DAKAR | C9: Marne | D9: 1990935 | E9: 4370102 | F9: 1990935 | G9: =+E9/D9 -> 2.1949998
A10: SOCOCIM INDUSTRIES | B10: DAKAR | C10: Calcaire | D10: =140987+762283 -> 903270 | E10: 1982677 | F10: =140987+762283 -> 903270 | G10: =+E10/D10 -> 2.1949993
A11: SOCOCIM INDUSTRIES | B11: DAKAR | C11: Latérite | D11: 101441 | E11: 395011 | F11: =101441 -> 101441 | G11: =+E11/D11 -> 3.8939975
D12: =+SUBTOTAL(9,D2:D11) -> 9737355 | E12: =+SUBTOTAL(9,E2:E11) -> 73523781 | F12: =+SUBTOTAL(9,F2:F11) -> 9965933
D13: =SUBTOTAL(9,D2:D12) -> 9737355
C14: Charges/tonnes
C15: CA/Tonnes
B16: CA/Tonnes | C16: QUANTITE | D16: VALEUR | E16: CA/Qte
B17: Ciment | C17: =+'Requete_PRODUCTION_TRANSFOR OK'!N48 -> 3370695.1 | D17: ='Requete_PRODUCTION_TRANSFOR OK'!O48 -> 159971636 | E17: =D17/C17 -> 47.459539
B18: Clincker | C18: =+'Requete_PRODUCTION_TRANSFOR OK'!N49 -> 22019.16 | D18: ='Requete_PRODUCTION_TRANSFOR OK'!O49 -> 836567 | E18: =D18/C18 -> 37.992685
D19: =SUBTOTAL(9,D17:D18) -> 160808203
B20: Charges/tonnes | D20: =D17*0.01 -> 1599716.4
B21: ='Charge rectifiées OK T'!BU53 -> 1.6378472e+08 | C21: =D19-B21 -> -2976517.1 | D21: =D19*0.01 -> 1608082
D24: 7610596.7

Sheet Requete_exportationdetail OK
A1: entreprise_id | B1: produit_desc | C1: exportation_id | D1: produit_id | E1: pays_id | F1: Pays | G1: qte_vendu_pays | H1: val_produit | K1: produit_desc | L1: (Plusieurs éléments)
A2: BMCC SA | B2: Phosphates | C2: 418 | D2: 11 | E2: 81 | F2: Inde | G2: 23001 | H2: 1023137
A3: BMCC SA | B3: Phosphates | C3: 419 | D3: 11 | E3: 81 | F3: Inde | G3: 26105 | H3: 1460215 | K3: Étiquettes de lignes | L3: Somme de qte_vendu_pays | M3: Somme de val_produit | P3: Étiquettes de lignes | Q3: Somme de qte_vendu_pays | R3: Somme de val_produit
A4: CIMENTS DU SAHEL | B4: Ciment | C4: 373 | D4: 46 | E4: 31 | F4: Burkina Faso | G4: 400 | H4: 18200 | K4: Emirat Arabe Unis | L4: 528.89 | M4: 295007440 | P4: Acide phosphorique | Q4: 558410.08 | R4: 533842674
A5: CIMENTS DU SAHEL | B5: Ciment | C5: 374 | D5: 46 | E5: 68 | F5: Gambie | G5: 485904 | H5: 21800120 | K5: France | L5: 529590.76 | M5: 163306124 | P5: Argent | Q5: 0.85 | R5: 374907
A6: CIMENTS DU SAHEL | B6: Ciment | C6: 375 | D6: 46 | E6: 74 | F6: Guinée | G6: 110 | H6: 4785 | K6: Australie | L6: 684.03193 | M6: 148742351 | P6: Attapulgite | Q6: 161515.8 | R6: 4422520
A7: CIMENTS DU SAHEL | B7: Ciment | C7: 376 | D7: 46 | E7: 75 | F7: Guinée-Bissau | G7: 2930 | H7: 134463 | K7: Suisse | L7: 148212.33 | M7: 94910043 | P7: Basalte | Q7: 47949.86 | R7: 390487.02
A8: CIMENTS DU SAHEL | B8: Ciment | C8: 377 | D8: 46 | E8: 111 | F8: Mali | G8: 586238 | H8: 27805009 | K8: Liban | L8: 182942 | M8: 21366392 | P8: Ciment | Q8: 1502608.9 | R8: 68535819
A9: CIMENTS DU SAHEL | B9: Ciment | C9: 378 | D9: 46 | E9: 116 | F9: Mauritanie | G9: 36830 | H9: 1572723 | K9: Norvège | L9: 101873 | M9: 17675149 | P9: Clinker | Q9: 13645.85 | R9: 504795
A10: CSE GRANULATS | B10: Basalte | C10: 417 | D10: 37 | E10: 68 | F10: Gambie | G10: 47949.86 | H10: 390487.02 | K10: Maurice | L10: 0.27 | M10: 9648371 | P10: Engrais | Q10: 12318 | R10: 3328965
A11: DANGOTE CEMENT SENEGAL | B11: Ciment | C11: 415 | D11: 46 | E11: 31 | F11: Burkina Faso | G11: 3396 | H11: 130813 | K11: Chine | L11: 49007.888 | M11: 8487014.9 | P11: Ilménite | Q11: 526747 | R11: 109536229
A12: DANGOTE CEMENT SENEGAL | B12: Ciment | C12: 412 | D12: 46 | E12: 68 | F12: Gambie | G12: 65923 | H12: 2585006 | K12: États-Unis | L12: 31246 | M12: 8049524 | P12: Leucoxene | Q12: 6340 | R12: 5532814
A13: DANGOTE CEMENT SENEGAL | B13: Ciment | C13: 413 | D13: 46 | E13: 75 | F13: Guinée-Bissau | G13: 13462 | H13: 532510 | K13: Espagne | L13: 8360 | M13: 6660472 | P13: Manganèse | Q13: 31093.338 | R13: 1263388
A14: DANGOTE CEMENT SENEGAL | B14: Ciment | C14: 414 | D14: 46 | E14: 111 | F14: Mali | G14: 125865 | H14: 5710850 | K14: Belgique | L14: 29318.253 | M14: 3764950 | P14: Minéraux lourds | Q14: 9097.55 | R14: 2225608.9
A15: G.H MINING | B15: Manganèse | C15: 403 | D15: 8 | E15: 39 | F15: Chine | G15: 31093.338 | H15: 1263388 | K15: Panamá | L15: 40461 | M15: 3434732 | P15: Or | Q15: 14.671934 | R15: 531398667
A16: GRANDE COTE OPERATIONS | B16: Leucoxene | F16: Afrique du Sud | G16: 100 | H16: 76434 | K16: Inde | L16: 49424 | M16: 2876373 | P16: Phosphates | Q16: 464970 | R16: 47999622
A17: GRANDE COTE OPERATIONS | B17: Zircon | C17: 385 | D17: 18 | E17: 5 | F17: Allemagne | G17: 66 | H17: 82182 | K17: Allemagne | L17: 1784 | M17: 2231046 | P17: Rutile | Q17: 4160 | R17: 5290812
A18: GRANDE COTE OPERATIONS | B18: Zircon | F18: Allemagne | G18: 1678 | H18: 2119199 | K18: Pays-Bas | L18: 35791.962 | M18: 1858458 | P18: Zircon | Q18: 90613 | R18: 87993881
A19: GRANDE COTE OPERATIONS | B19: Leucoxene | F19: Allemagne | G19: 40 | H19: 29665 | K19: Japon | L19: 1379 | M19: 1638316 | P19: Total général | Q19: 3429484.9 | R19: 1.4026412e+09
A20: GRANDE COTE OPERATIONS | B20: Zircon | C20: 390 | D20: 18 | F20: Angleterre | G20: 160 | H20: 205256 | K20: Royaume-Uni | L20: 63922.825 | M20: 1436607
A21: GRANDE COTE OPERATIONS | B21: Rutile | F21: Angleterre | G21: 100 | H21: 131315 | K21: Corée du Sud | L21: 1020 | M21: 955701 | P21: SUBSTANCES | Q21: 2021 | S21: 2022
A22: GRANDE COTE OPERATIONS | B22: Leucoxene | F22: Angleterre | G22: 120 | H22: 87598 | K22: Italie | L22: 661 | M22: 805311 | Q22: Quantite | R22: Valeur (Milliers FCFA) | S22: Quantite | T22: Valeur (Milliers FCFA)
A23: GRANDE COTE OPERATIONS | B23: Zircon | C23: 386 | D23: 18 | E23: 12 | F23: Australie | G23: 680 | H23: 879535 | K23: Salvador | L23: 5500 | M23: 785469 | P23: Acide phosphorique | Q23: 497897 | R23: 291874254 | S23: =+VLOOKUP(P23,$P$4:$R$18,2,0) -> 558410.08 | T23: =+VLOOKUP(P23,$P$4:$R$18,3,0) -> 533842674
A24: GRANDE COTE OPERATIONS | B24: Zircon | F24: Brésil | G24: 140 | H24: 176061 | K24: Turquie | L24: 595 | M24: 738090 | P24: Argent | Q24: 1.3179 | R24: 582754 | S24: =+VLOOKUP(P24,$P$4:$R$18,2,0) -> 0.85 | T24: =+VLOOKUP(P24,$P$4:$R$18,3,0) -> 374907
A25: GRANDE COTE OPERATIONS | B25: Zircon | C25: 383 | D25: 18 | E25: 39 | F25: Chine | G25: 1553 | H25: 1972278 | K25: Mali | L25: 8816 | M25: 594500 | P25: Attapulgite | Q25: 182379.62 | R25: 8082682.2 | S25: =+VLOOKUP(P25,$P$4:$R$18,2,0) -> 161515.8 | T25: =+VLOOKUP(P25,$P$4:$R$18,3,0) -> 4422520
A26: GRANDE COTE OPERATIONS | B26: Zircon | F26: Chine | G26: 368 | H26: 436921 | K26: Angleterre | L26: 380 | M26: 424169 | P26: Basalte | Q26: 36437 | R26: 364715.65 | S26: =+VLOOKUP(P26,$P$4:$R$18,2,0) -> 47949.86 | T26: =+VLOOKUP(P26,$P$4:$R$18,3,0) -> 390487.02
A27: GRANDE COTE OPERATIONS | B27: Rutile | F27: Chine | G27: 80 | H27: 96661 | K27: Gambie | L27: 47949.86 | M27: 390487.02 | P27: Ciment | Q27: 1793708.3 | R27: 71599992 | S27: =+VLOOKUP(P27,$P$4:$R$18,2,0) -> 1502608.9 | T27: =+VLOOKUP(P27,$P$4:$R$18,3,0) -> 68535819
A28: GRANDE COTE OPERATIONS | B28: Leucoxene | F28: Chine | G28: 400 | H28: 303853 | K28: Lituanie | L28: 2690 | M28: 317593 | P28: Clinker | Q28: 341082.58 | R28: 8910597 | S28: =+VLOOKUP(P28,$P$4:$R$18,2,0) -> 13645.85 | T28: =+VLOOKUP(P28,$P$4:$R$18,3,0) -> 504795
A29: GRANDE COTE OPERATIONS | B29: Zircon | F29: Chine | G29: 6416 | H29: 2188305 | K29: Brésil | L29: 140 | M29: 176061 | P29: Engrais | Q29: 255148 | R29: 30336436 | S29: =+VLOOKUP(P29,$P$4:$R$18,2,0) -> 12318 | T29: =+VLOOKUP(P29,$P$4:$R$18,3,0) -> 3328965
A30: GRANDE COTE OPERATIONS | B30: Rutile | F30: Corée du Sud | G30: 580 | H30: 634237 | K30: Afrique du Sud | L30: 100 | M30: 76434 | P30: Hormite | Q30: 15363.21 | R30: 134354.48 | S30: 0 | T30: 0
A31: GRANDE COTE OPERATIONS | B31: Leucoxene | F31: Corée du Sud | G31: 400 | H31: 298442 | K31: Taiwan | L31: 60 | M31: 66222 | P31: Ilménite | Q31: 556405.92 | R31: 78636154 | S31: =+VLOOKUP(P31,$P$4:$R$18,2,0) -> 526747 | T31: =+VLOOKUP(P31,$P$4:$R$18,3,0) -> 109536229
A32: GRANDE COTE OPERATIONS | B32: Ilménite | F32: Corée du Sud | G32: 40 | H32: 23022 | K32: Cote d'ivore | L32: 64 | M32: 5536 | P32: Leucoxene | Q32: 6960 | R32: 3595901 | S32: =+VLOOKUP(P32,$P$4:$R$18,2,0) -> 6340 | T32: =+VLOOKUP(P32,$P$4:$R$18,3,0) -> 5532814
A33: GRANDE COTE OPERATIONS | B33: Rutile | F33: Emirat Arabe Unis | G33: 60 | H33: 63698 | K33: Total général | L33: 1342502.1 | M33: 7.9642894e+08 | P33: Manganèse | Q33: 9396 | R33: 518248 | S33: =+VLOOKUP(P33,$P$4:$R$18,2,0) -> 31093.338 | T33: =+VLOOKUP(P33,$P$4:$R$18,3,0) -> 1263388
A34: GRANDE COTE OPERATIONS | B34: Rutile | F34: Emirat Arabe Unis | G34: 20 | H34: 26978 | P34: Minéraux lourds | Q34: 0 | R34: 0 | S34: =+VLOOKUP(P34,$P$4:$R$18,2,0) -> 9097.55 | T34: =+VLOOKUP(P34,$P$4:$R$18,3,0) -> 2225608.9
A35: GRANDE COTE OPERATIONS | B35: Leucoxene | F35: Emirat Arabe Unis | G35: 440 | H35: 341151 | P35: Or | Q35: 15.8735 | R35: 505067362 | S35: =+VLOOKUP(P35,$P$4:$R$18,2,0) -> 14.671934 | T35: =+VLOOKUP(P35,$P$4:$R$18,3,0) -> 531398667
A36: GRANDE COTE OPERATIONS | B36: Zircon | C36: 382 | D36: 18 | E36: 60 | F36: Espagne | G36: 1763 | H36: 2159428 | P36: Phosphates | Q36: 562863 | R36: 23565975 | S36: =+VLOOKUP(P36,$P$4:$R$18,2,0) -> 464970 | T36: =+VLOOKUP(P36,$P$4:$R$18,3,0) -> 47999622
A37: GRANDE COTE OPERATIONS | B37: Zircon | F37: Espagne | G37: 3591 | H37: 4215746 | P37: Rutile | Q37: 4462 | R37: 3629678 | S37: =+VLOOKUP(P37,$P$4:$R$18,2,0) -> 4160 | T37: =+VLOOKUP(P37,$P$4:$R$18,3,0) -> 5290812
A38: GRANDE COTE OPERATIONS | B38: Rutile | F38: Espagne | G38: 60 | H38: 64976 | P38: Zircon | Q38: 90198.732 | R38: 61742607 | S38: =+VLOOKUP(P38,$P$4:$R$18,2,0) -> 90613 | T38: =+VLOOKUP(P38,$P$4:$R$18,3,0) -> 87993881
A39: GRANDE COTE OPERATIONS | B39: Zircon | C39: 381 | D39: 18 | E39: 62 | F39: États-Unis | G39: 2241 | H39: 2673377 | P39: TOTAL | Q39: =SUM(Q23:Q38) -> 4352318.6 | R39: =SUM(R23:R38) -> 1.0886417e+09 | S39: =SUM(S23:S38) -> 3429484.9 | T39: =SUM(T23:T38) -> 1.4026412e+09
A40: GRANDE COTE OPERATIONS | B40: Ilménite | C40: 394 | D40: 22 | E40: 62 | F40: États-Unis | G40: 29005 | H40: 5376147
...

Sheet EXPORTATION
A3: Étiquettes de lignes | B3: Somme de qte_vendu_pays | C3: Somme de val_produit
A4: Argent | B4: 0.85 | C4: 374907
A5: Attapulgite | B5: 161515.8 | C5: 4422520 | F5: Or | G5: 531398667
A6: Basalte | B6: 47949.86 | C6: 390487.02 | F6: Ilménite | G6: 109536229
A7: Ilménite | B7: 526747 | C7: 109536229 | F7: Zircon | G7: 87993881
A8: Leucoxene | B8: 6340 | C8: 5532814 | F8: Phosphates | G8: 47999622
A9: Manganèse | B9: 31093.338 | C9: 1263388 | F9: Leucoxene | G9: 5532814
A10: Minéraux lourds | B10: 9097.55 | C10: 2225608.9 | F10: Rutile | G10: 5290812
A11: Or | B11: 14.671934 | C11: 531398667 | F11: Attapulgite | G11: 4422520
A12: Phosphates | B12: 464970 | C12: 47999622 | F12: Minéraux lourds | G12: 2225608.9
A13: Rutile | B13: 4160 | C13: 5290812 | F13: Manganèse | G13: 1263388
A14: Zircon | B14: 90613 | C14: 87993881 | F14: Basalte | G14: 390487.02
A15: Total général | B15: 1342502.1 | C15: 7.9642894e+08 | D15: 685.9 | F15: Argent | G15: 374907
B16: 1464483 | D16: =796.4/D15-1 -> 0.1611022
B17: =+B15/B16-1 -> -0.083292828
A19: Répartition des exportations par substance en 2022 (en valeur)
A20: SUBSTANCES | B20: MONTANT (milliers FCFA) | C20: %
A21: Or | B21: =VLOOKUP(A21,$A$4:$C$14,3,0) -> 531398667 | C21: =+B21/$B$32 -> 0.66722672 | D21: =+A21 -> Or | E21: =+C21 -> 0.66722672
A22: Ilménite | B22: =VLOOKUP(A22,$A$4:$C$14,3,0) -> 109536229 | C22: =+B22/$B$32 -> 0.13753422 | D22: Ilménite, Rutile et Leucoxène | E22: =+C22+C26+C25 -> 0.15112441
A23: Zircon | B23: =VLOOKUP(A23,$A$4:$C$14,3,0) -> 87993881 | C23: =+B23/$B$32 -> 0.11048554 | D23: =+A23 -> Zircon | E23: =+C23 -> 0.11048554
A24: Phosphates | B24: =VLOOKUP(A24,$A$4:$C$14,3,0) -> 47999622 | C24: =+B24/$B$32 -> 0.060268556 | D24: =+A24 -> Phosphates | E24: =+C24 -> 0.060268556
A25: Leucoxene | B25: =VLOOKUP(A25,$A$4:$C$14,3,0) -> 5532814 | C25: =+B25/$B$32 -> 0.0069470279 | D25: Autres produits | E25: =1-SUM(E21:E24) -> 0.010894771
A26: Rutile | B26: =VLOOKUP(A26,$A$4:$C$14,3,0) -> 5290812 | C26: =+B26/$B$32 -> 0.006643169
A27: Attapulgite | B27: =VLOOKUP(A27,$A$4:$C$14,3,0) -> 4422520 | C27: =+B27/$B$32 -> 0.0055529374
A28: Minéraux lourds | B28: =VLOOKUP(A28,$A$4:$C$14,3,0) -> 2225608.9 | C28: =+B28/$B$32 -> 0.0027944852
A29: Manganèse | B29: =VLOOKUP(A29,$A$4:$C$14,3,0) -> 1263388 | C29: =+B29/$B$32 -> 0.001586316
A30: Basalte | B30: =VLOOKUP(A30,$A$4:$C$14,3,0) -> 390487.02 | C30: =+B30/$B$32 -> 0.00049029738
A31: Argent | B31: =VLOOKUP(A31,$A$4:$C$14,3,0) -> 374907 | C31: =+B31/$B$32 -> 0.00047073503
A32: TOTAL | B32: =SUM(B21:B31) -> 7.9642894e+08 | C32: =+B32/$B$32 -> 1
A34: produit_desc | B34: (Plusieurs éléments)
A35: Répartition des exportations des produits miniers par pays en 2022
A36: Étiquettes de lignes | B36: Somme de qte_vendu_pays | C36: Somme de val_produit | D36: Somme de val_produit2
A37: Emirat Arabe Unis | B37: 528.89 | C37: 295007440 | D37: 0.37041276
A38: France | B38: 529590.76 | C38: 163306124 | D38: 0.20504795
A39: Australie | B39: 684.03193 | C39: 148742351 | D39: 0.18676161
A40: Suisse | B40: 148212.33 | C40: 94910043 | D40: 0.11916951
A41: Liban | B41: 182942 | C41: 21366392 | D41: 0.026827744
A42: Norvège | B42: 101873 | C42: 17675149 | D42: 0.022193002
A43: Maurice | B43: 0.27 | C43: 9648371 | D43: 0.012114541
A44: Chine | B44: 49007.888 | C44: 8487014.9 | D44: 0.010656337
...

Sheet Charge rectifiées OK
