Workbook

Sheet Titres_Declare
A1: Code | B1: Entreprise Titulaire | C1: Type | D1: Substances | E1: Statut | F1: Région | G1: Date Octroi | H1: Date Expiration | I1: Année Octroi | J1: Correspondance RBE | K1: Score Matching | L1: Année 1re Décl. RBE | M1: Déclaré (0/1)
A2: 02001 | B2: COMPAGNIE SENEGALAISE DES PHOSPHATES DE TAIBA | C2: CM | D2: phosphate de chaux | E2: Active | F2: Thiès | G2: 01/01/1959 | H2: 01/01/2034 | I2: 1959 | M2: 0 — NON
A3: 02002 | B3: PROCHIMAT | C3: CM | D3: phosphate de chaux | E3: Active | F3: Thiès | G3: 21/03/2015 | H3: 01/01/2052 | I3: 2015 | M3: 0 — NON
A4: 02003 | B4: ENTREPRISE DE GENIE CIVIL CONCASSEUR BASALTE NDIAMBOUR (EGCCBN) SUARL | C4: AECPP | D4: basalte | E4: Active | F4: Thiès | G4: 04/10/2019 | H4: 02/10/2029 | I4: 2019 | M4: 0 — NON
A5: 02004 | B5: SOCIETE SENEGALAISE DES PHOSPHATES DE THIES | C5: CM | D5: argile industrielle, attapulgite, sépiolite | E5: Active | F5: Thiès | G5: 19/04/1985 | I5: 1985 | J5: SOCIETE SENEGALAISE DE PHOSPHATES DE THIES (SSPT) | K5: 93.3 | L5: 2023 | M5: 1 — OUI
A6: 02005 | B6: SOCIETE SENEGALAISE DES PHOSPHATES DE THIES | C6: CM | D6: Argile, attapulgite, sépiolite | E6: Active | F6: Thiès | G6: 19/04/1985 | I6: 1985 | J6: SOCIETE SENEGALAISE DE PHOSPHATES DE THIES (SSPT) | K6: 93.3 | L6: 2023 | M6: 1 — OUI
A7: 02006 | B7: SOCIETE SENEGALAISE DES PHOSPHATES DE THIES | C7: CM | D7: argile industrielle, attapulgite, sépiolite | E7: Renouvellement en Cours | F7: Thiès | G7: 12/01/1998 | H7: 11/01/2023 | I7: 1998 | J7: SOCIETE SENEGALAISE DE PHOSPHATES DE THIES (SSPT) | K7: 93.3 | L7: 2023 | M7: 1 — OUI
A8: 02007 | B8: SOCIETE SENEGALAISE DES PHOSPHATES DE THIES | C8: CM | D8: Argile, attapulgite, sépiolite | E8: Active | F8: Thiès | G8: 19/04/1985 | I8: 1985 | J8: SOCIETE SENEGALAISE DE PHOSPHATES DE THIES (SSPT) | K8: 93.3 | L8: 2023 | M8: 1 — OUI
A9: 02008 | B9: COMPAGNIE GENERALE D'EXPLOITATION DE CARRIERE | C9: AECPP | D9: basalte | E9: Active | F9: Thiès | G9: 30/05/1983 | H9: 20/09/2026 | I9: 1983 | M9: 0 — NON
A10: 02009 | B10: GECAMINES.SA | C10: AECPP | D10: basalte | E10: Active | F10: Thiès | G10: 22/06/2009 | H10: 21/06/2025 | I10: 2009 | M10: 0 — NON
A11: 02010 | B11: COMPAGNIE SAHELIENNE D'ENTREPRISE GRANULATS | C11: AECPP | D11: basalte | E11: Avertissement Renouvellement | F11: Thiès | G11: 18/10/1995 | H11: 13/01/2025 | I11: 1995 | M11: 0 — NON
A12: 02011 | B12: GECAMINES.SA | C12: AECPP | D12: calcaire | E12: Active | F12: Thiès | G12: 07/10/2021 | H12: 06/10/2026 | I12: 2021 | M12: 0 — NON
A13: 02013 | B13: COMPAGNIE GENERALE D'EXPLOITATION DE CARRIERE | C13: AECPP | D13: calcaire | E13: Active | F13: Thiès | G13: 15/11/1996 | H13: 09/04/2026 | I13: 1996 | M13: 0 — NON
A14: 02014 | B14: SENEGAL MINES | C14: CM | D14: Argile, attapulgite | E14: Avertissement Renouvellement | F14: Thiès | G14: 26/05/1988 | H14: 26/05/2013 | I14: 1988 | M14: 0 — NON
A15: 02015 | B15: INDUSTRIES CHIMIQUES DU SENEGAL | C15: CM | D15: phosphate de chaux | E15: Active | F15: Thiès | G15: 16/10/2009 | H15: 19/10/2024 | I15: 2009 | M15: 0 — NON
A16: 02016 | B16: INDUSTRIES CHIMIQUES DU SENEGAL | C16: CM | D16: phosphate de chaux | E16: Renouvellement en Cours | F16: Thiès | G16: 19/10/1999 | H16: 18/10/2024 | I16: 1999 | M16: 0 — NON
A17: 02017 | B17: CIMENTS DU SAHEL | C17: CM | D17: calcaire | E17: Active | F17: Thiès | G17: 22/02/2000 | H17: 21/02/2025 | I17: 2000 | J17: LES CIMENTS DU SAHEL | K17: 88.9 | L17: 2021 | M17: 1 — OUI
A18: 02018 | B18: CIMENTS DU SAHEL | C18: CM | D18: Argile | E18: Active | F18: Thiès | G18: 16/10/2009 | H18: 22/02/2025 | I18: 2009 | J18: LES CIMENTS DU SAHEL | K18: 88.9 | L18: 2021 | M18: 1 — OUI
A19: 02019 | B19: SOCIETE DE RECHERCHE ET DE DEVELOPPEMENT DES MINES SA (SORED-MINES) | C19: CM | D19: Au, substance connexes | E19: Renouvellement en Cours | F19: Kedougou | G19: 02/11/2007 | H19: 02/11/2017 | I19: 2007 | M19: 0 — NON
A20: 02022 | B20: SABODALA GOLD OPERATIONS SA (SGO) | C20: CM | D20: Au | E20: Active | F20: Kedougou | G20: 09/06/2005 | H20: 21/04/2040 | I20: 2005 | J20: SABODALA GOLD OPERATIONS | K20: 92.3 | L20: 2022 | M20: 1 — OUI
A21: 02024 | B21: GECAMINES.SA | C21: AECPP | D21: calcaire | E21: Active | F21: Thiès | G21: 09/09/2010 | H21: 12/05/2026 | I21: 2010 | M21: 0 — NON
A22: 02025 | B22: SOCIETE DE COMMERCIALISATION DU CIMENT (SOCOCIM) INDUSTRIES | C22: CM | D22: calcaire | E22: Active | F22: Dakar | G22: 16/10/2009 | H22: 19/04/2031 | I22: 2009 | M22: 0 — NON
A23: 02026 | B23: SOCIETE DE COMMERCIALISATION DU CIMENT (SOCOCIM) INDUSTRIES | C23: CM | D23: calcaire | E23: Active | F23: Thiès | G23: 19/04/2006 | H23: 19/04/2033 | I23: 2006 | M23: 0 — NON
A24: 02027 | B24: SOCIETE DE COMMERCIALISATION DU CIMENT (SOCOCIM) INDUSTRIES | C24: CM | D24: calcaire | E24: Active | F24: Thiès | G24: 19/04/2006 | H24: 18/04/2031 | I24: 2006 | M24: 0 — NON
A25: 02028 | B25: GRANDE COTE OPERATIONS SA | C25: CM | D25: ML | E25: Active | F25: Thiès | G25: 16/10/2009 | H25: 02/11/2032 | I25: 2009 | J25: GRANDE COTE OPERATIONS | K25: 100 | L25: 2021 | M25: 1 — OUI
A26: 02029 | B26: LIBASSE NIANG | C26: AECPP | D26: grès | E26: Renouvellement en Cours | F26: Thiès | G26: 03/11/2006 | H26: 10/04/2021 | I26: 2006 | M26: 0 — NON
A27: 02034 | B27: DANGOTE INDUSTRIES SENEGAL SA | C27: CM | D27: argile industrielle, calcaire, latérite | E27: Active | F27: Thiès | G27: 12/12/2008 | H27: 11/12/2033 | I27: 2008 | M27: 0 — NON
A28: 02035 | B28: COMPAGNIE GENERALE D'EXPLOITATION DE CARRIERE | C28: AECPP | D28: basalte | E28: Active | F28: Thiès | G28: 30/06/2008 | H28: 16/04/2026 | I28: 2008 | M28: 0 — NON
A29: 02036 | B29: CARRIERE ABDOU FATTAH SA | C29: AECPP | D29: calcaire | E29: Active | F29: Thiès | G29: 23/11/2006 | H29: 28/09/2025 | I29: 2006 | M29: 0 — NON
A30: 02037 | B30: COMPAGNIE GENERALE D'EXPLOITATION DE CARRIERE | C30: AECPP | D30: basalte | E30: Active | F30: Thiès | G30: 07/08/2009 | H30: 13/11/2026 | I30: 2009 | M30: 0 — NON
A31: 02041 | B31: COMPAGNIE GENERALE D'EXPLOITATION DE CARRIERE | C31: AECPP | D31: calcaire | E31: Active | F31: Thiès | G31: 07/08/2009 | H31: 07/04/2026 | I31: 2009 | M31: 0 — NON
A32: 02059 | B32: MINING RESEARCH COMPANY S.L | C32: PR | D32: Au | E32: Renouvellement en Cours | F32: Kedougou | G32: 04/02/2019 | H32: 03/02/2023 | I32: 2019 | M32: 0 — NON
A33: 02060 | B33: SYPROM SA | C33: AECPP | D33: grès | E33: Active | F33: Dakar | G33: 20/06/2002 | H33: 22/06/2025 | I33: 2002 | J33: SYPROM | K33: 100 | L33: 2022 | M33: 1 — OUI
A34: 02062 | B34: ENTREPRISE MAPATHE NDIOUCK | C34: AEPM | D34: Sl | E34: Renouvellement en Cours | F34: Thiès | G34: 02/07/2018 | H34: 01/07/2023 | I34: 2018 | M34: 0 — NON
A35: 02063 | B35: DIAKHA GOLD MINES | C35: AEMSM | D35: Au | E35: Avertissement Renouvellement | F35: Kedougou | G35: 29/07/2010 | H35: 02/03/2024 | I35: 2010 | M35: 0 — NON
A36: 02068 | B36: SOCIETE DES MINES DU SENEGAL (SODEMINES) | C36: PR | D36: Au | E36: Renouvellement en Cours | F36: Kedougou | G36: 01/02/2012 | H36: 02/11/2021 | I36: 2012 | J36: SOCIETE DES MINES DU SENEGAL (SODEMINES) | K36: 100 | L36: 2022 | M36: 1 — OUI
A37: 02072 | B37: SOCIETE D'ETUDES ET DE REALISATION DES PHOSPHATES DE MATAM (SERPM) | C37: CM | D37: phosphate de chaux | E37: Active | F37: Matam | G37: 08/06/2011 | H37: 08/06/2036 | I37: 2011 | M37: 0 — NON
A38: 02075 | B38: SERIGNE SALIOU MBACKE SARL | C38: AEPM | D38: Au | E38: Active | F38: Kedougou | G38: 27/01/2012 | H38: 13/01/2028 | I38: 2012 | M38: 0 — NON
A39: 02078 | B39: SOCIETE DES MINES DU SENEGAL (SODEMINES) | C39: PR | D39: Au | E39: Renouvellement en Cours | F39: Kedougou | G39: 22/05/2012 | H39: 02/11/2021 | I39: 2012 | J39: SOCIETE DES MINES DU SENEGAL (SODEMINES) | K39: 100 | L39: 2022 | M39: 1 — OUI
A40: 02079 | B40: GH MINING SARL | C40: PR | D40: Mn | E40: Transformation en Cours | F40: Tambacounda | G40: 10/01/2012 | H40: 27/01/2021 | I40: 2012 | M40: 0 — NON
...

Sheet Permis
A1: Code | B1: Nom | C1: Parties | D1: Juridiction | E1: Type | F1: Substances | G1: Statut | H1: Région | I1: Demande faite | J1: Octroyé | K1: Expire le | L1: Renouvelé | M1: superficie
A2: 02231 | B2: Taiba | C2: AFRICA TRADE AND INVESTMENT CONSULTING SARL | D2: Sénégal | E2: AEHTR | F2: Sl | G2: Active | H2: Thiès | I2: 43165 | J2: 43229 | K2: 46881 | L2: 45055 | M2: 0.0795 Ha
A3: 03563 | B3: KIDIRA | C3: AFRICA TRADE AND INVESTMENT CONSULTING SARL | D3: Sénégal | E3: AECPP | F3: basalte | G3: Active | H3: Tambacounda | I3: 44215 | J3: 44862 | K3: 46687 | M3: 34.7200 Ha
A4: 03831 | C4: AFRICA TRADE AND INVESTMENT CONSULTING SARL | D4: Sénégal | E4: AECPP | F4: basalte | G4: Active | H4: Thiès | I4: 45085 | J4: 45184 | K4: 47010 | M4: 30.0634 Ha
A5: 04124 | C5: SURVEY SERVICES SUARL | D5: Sénégal | E5: AEMSM | F5: Au | G5: Active | H5: Kedougou | I5: 45316 | J5: 45329 | K5: 46424 | M5: 49.9886 Ha
A6: 03785 | C6: 3T SARL | D6: Sénégal | E6: AEMSM | F6: Au | G6: Active | H6: Kedougou | I6: 45083 | J6: 45090 | K6: 46185 | M6: 49.6480 Ha
A7: 03608 | B7: GUETIE | C7: ABANDOUR GEOLINK | D7: Sénégal | E7: PR | F7: Cu | G7: Active | H7: Tambacounda | I7: 44127 | J7: 44747 | K7: 46208 | M7: 95.0099 km²
A8: 03346 | B8: ICS MBORO | C8: ADAMA UNIVERSAL IMMOBILIER ET AFFAIRES | D8: Sénégal | E8: AEHTR | F8: Sl | G8: Active | H8: Thiès | I8: 44455 | J8: 44476 | K8: 46301
A9: 03492 | B9: ICS | C9: ADICO SARL | D9: Sénégal | E9: AEHTR | F9: Sl | G9: Active | H9: Thiès | I9: 44781 | J9: 44811 | K9: 46636
A10: 04410 | C10: ADICO SARL | D10: Sénégal | E10: AECPT | F10: sable de dune | G10: Active | H10: Thiès | I10: 45850.398 | J10: 45957 | K10: 46321 | M10: 1.8545 Ha
A11: 04252 | B11: BARIBARIE 1 | C11: AFG RESSOURCES | D11: Sénégal | E11: PR | F11: Li | G11: Active | H11: Kedougou | I11: 44841 | J11: 44959 | K11: 46419 | M11: 98.9681 km²
A12: 04063 | C12: AFRICA GLOBAL GEOINGENIERIE SARL | D12: Sénégal | E12: AEMSM | F12: Au | G12: Active | H12: Kedougou | I12: 45098 | J12: 45289 | K12: 46384 | M12: 49.3027 Ha
A13: 04342 | C13: AFRICA SERVICES GROUP SUARL | D13: Sénégal | E13: AECPT | F13: sable de dune | G13: Active | H13: Dakar | I13: 45805 | J13: 45807 | K13: 46171 | M13: 2.4073 Ha
A14: 04393 | C14: AFRICA SERVICES GROUP SUARL | D14: Sénégal | E14: AECPT | F14: sable de dune | G14: Active | H14: Dakar | I14: 45972.643 | J14: 45989 | K14: 46353 | M14: 1.8200 Ha
A15: 03507 | C15: AFRICA TRADING EQUIPEMENT CONSTRUCTION SUARL | D15: Sénégal | E15: AEHTR | F15: Sl | G15: Active | H15: Thiès | I15: 44447 | J15: 44608 | K15: 46433
A16: 04267 | C16: AFRICAN BUILDERS SARL | D16: Sénégal | E16: AECPP | F16: Argile, latérite | G16: Active | H16: Thiès | I16: 45047 | J16: 45090 | K16: 46916 | M16: 48.6722 Ha
A17: 02146 | B17: KARAKAENA | C17: AFRIGOLD SARL | D17: Sénégal | E17: PE | F17: Au | G17: Active | H17: Kedougou | I17: 42097 | J17: 44228 | K17: 46053 | M17: 38.6940 km²
A18: 03855 | B18: Kéniéba | C18: AFRIK'MINES SUARL | D18: Sénégal | E18: AEPM | F18: Au | G18: Active | H18: Tambacounda | I18: 45098 | J18: 45145 | K18: 46971 | M18: 4.9545 km²
A19: 04066 | C19: AFRIK'MINES SUARL | D19: Sénégal | E19: AEPM | F19: Mn | G19: Active | H19: Tambacounda | I19: 45099 | J19: 45308 | K19: 47134 | M19: 4.9978 km²
A20: 04248 | B20: Kolia | C20: AFRIQUE MINES COMPANY PLUS | D20: Sénégal | E20: AEMSM | F20: Au | G20: Active | H20: Kedougou | I20: 44998 | J20: 45099 | K20: 46194 | M20: 45.6814 Ha
A21: 02215 | B21: NOUMOUFOUKHA | C21: AGEM | D21: Sénégal | E21: PR | F21: Au, substances connexes | G21: Active | H21: Kedougou | I21: 43038 | J21: 43256 | K21: 45813 | M21: 60.0113 km²
A22: DPR22102018 | B22: DAORALA | C22: AGEM EXPLORATION SENEGAL | D22: Sénégal | E22: PR | F22: Au | G22: Active | H22: Kedougou | I22: 44252 | J22: 44405 | K22: 45865 | M22: 83.4261 km²
A23: 02165 | B23: Pout | C23: AGROMINE SUARL | D23: Sénégal | E23: AECPP | F23: basalte | G23: Active | H23: Thiès | I23: 42422 | J23: 43362 | K23: 46643 | L23: 44818 | M23: 38.5224 Ha
A24: 02273 | B24: LAMBAYE | C24: AGROMINE SUARL | D24: Sénégal | E24: PR | F24: phosphate de chaux | G24: Renouvellement en Cours | H24: Diourbel | I24: 43357 | J24: 43496 | K24: 46053 | M24: 421.8438 km²
A25: 04268 | B25: MAMANKANTI | C25: AIR DYNAMICS SOLUTIONS SENEGAL | D25: Sénégal | E25: PR | F25: Au | G25: Active | H25: Kedougou | I25: 45369 | J25: 45380 | K25: 46840 | M25: 18.6813 km²
A26: 03672 | C26: AL JABER BTP SAU | D26: Sénégal | E26: AEHTR | F26: Sl | G26: Active | H26: Thiès | I26: 44834 | J26: 44957 | K26: 46782
A27: 02188 | C27: ALBINA SENEGAL | D27: Sénégal | E27: AECPP | F27: calcaire | G27: Active | H27: Thiès | I27: 42786 | J27: 43304 | K27: 46957 | M27: 15.0505 Ha
A28: 03864 | B28: Périmètre 2 | C28: ALIM GOLD SARL | D28: Sénégal | E28: AEMSM | F28: Au | G28: Active | H28: Kedougou | I28: 45152 | J28: 45194 | K28: 46289 | M28: 43.9332 Ha
A29: 04090 | B29: Périmètre 3 | C29: ALIM GOLD SARL | D29: Sénégal | E29: AEMSM | F29: Au | G29: Active | H29: Kedougou | I29: 45306 | J29: 45349 | K29: 46444 | M29: 49.5800 Ha
A30: 03452 | B30: ICS | C30: ALWAR PRODUCTION GROUP | D30: Sénégal | E30: AEHTR | F30: Sl | G30: Active | I30: 44357 | J30: 44614 | K30: 46439
A31: 04395 | C31: AMAFRIQUE SENEGAL | D31: Sénégal | E31: AP | F31: phosphate de chaux | G31: Active | H31: Matam | I31: 45973.532 | J31: 46113 | K31: 46295 | M31: 4.9794 km²
A32: 03424 | B32: ICS | C32: AMATH NDIAYE INTERNATIONALE PRESTIGE SUARL | D32: Sénégal | E32: AEHTR | F32: Sl | G32: Active | H32: Thiès | I32: 44532 | J32: 44594 | K32: 46419
A33: 03925 | C33: AMCI GOLD MINE SARL | D33: Sénégal | E33: AEMSM | F33: Au | G33: Active | H33: Tambacounda | I33: 45117 | J33: 45121 | K33: 46216 | M33: 49.3363 Ha
A34: 03971 | B34: Périmètre 2 | C34: AMCI GOLD MINE SARL | D34: Sénégal | E34: AEMSM | F34: Au | G34: Active | H34: Tambacounda | I34: 45117 | J34: 45121 | K34: 46216 | M34: 48.7346 Ha
A35: 03973 | B35: Périmètre 4 | C35: AMCI GOLD MINE SARL | D35: Sénégal | E35: AEMSM | F35: Au | G35: Active | H35: Tambacounda | I35: 45117 | J35: 45121 | K35: 46216 | M35: 49.9278 Ha
A36: 03751 | B36: Périmètre 3 | C36: AMCI GOLD MINE SARL | D36: Sénégal | E36: AEMSM | F36: Au | G36: Active | H36: Kedougou | I36: 45029 | J36: 45090 | K36: 46185 | M36: 38.7250 Ha
A37: 03921 | B37: Périmètre 4 | C37: AMFICI GOLD | D37: Sénégal | E37: AEMSM | F37: Au | G37: Active | H37: Kedougou | I37: 45190 | J37: 45196 | K37: 46291 | M37: 38.7200 Ha
A38: 03922 | B38: Périmètre 3 | C38: AMFICI GOLD | D38: Sénégal | E38: AEMSM | F38: Au | G38: Active | H38: Kedougou | I38: 45190 | J38: 45196 | K38: 46291 | M38: 35.0200 Ha
A39: 03264 | B39: Packi | C39: AMIN TRANS SUARL | D39: Sénégal | E39: AECPP | F39: grès, latérite | G39: Active | H39: Thiès | I39: 44379 | J39: 44439 | K39: 46264 | M39: 1.9792 Ha
A40: 03347 | B40: ICS MBORO | C40: AMIN TRANS SUARL | D40: Sénégal | E40: AEHTR | F40: Sl | G40: Active | H40: Thiès | I40: 44404 | J40: 44172 | K40: 45997
...

Sheet Sous-traitant
A1: Entreprise | B1: Colonne1 | C1: Email | D1: Profile | E1: Pays
A2: CHEIKH FALL | B2: =UPPER(Tableau3[[#This Row],[Entreprise]]) -> CHEIKH FALL | C2: cheikhomar2003@yahoo.fr | D2: Sous-traitants | E2: Sénégal
A3: FORADRILL-SENEGAL | B3: =UPPER(Tableau3[[#This Row],[Entreprise]]) -> FORADRILL-SENEGAL | C3: ghazmohamad@yahoo.fr | D3: Sous-traitants | E3: Sénégal
A4: AMS Senegal SUARL | B4: =UPPER(Tableau3[[#This Row],[Entreprise]]) -> AMS SENEGAL SUARL | C4: amssenegal@outlook.com | D4: Sous-traitants | E4: Sénégal
A5: African Underground Mining Services Senegal SUARL | B5: =UPPER(Tableau3[[#This Row],[Entreprise]]) -> AFRICAN UNDERGROUND MINING SERVICES SENEGAL SUARL | C5: mark.mclaskey@amsgh.com | D5: Sous-traitants | E5: Sénégal
A6: KEKENDO AFRICA ENGINEERING | B6: =UPPER(Tableau3[[#This Row],[Entreprise]]) -> KEKENDO AFRICA ENGINEERING | C6: kagny.lamine@kekendoafricapoly.com | D6: Sous-traitants | E6: Sénégal
A7: CORICA MINING SERVICES SARL | B7: =UPPER(Tableau3[[#This Row],[Entreprise]]) -> CORICA MINING SERVICES SARL | C7: abdoulaye.diallo@corica.com | D7: Sous-traitants | E7: Sénégal
A8: CHALLENGE 2000 SARL | B8: =UPPER(Tableau3[[#This Row],[Entreprise]]) -> CHALLENGE 2000 SARL | C8: lamine.diagne@challenge2000.sn | D8: Sous-traitants | E8: Sénégal
A9: EIFFAGE SENEGAL SAS | B9: =UPPER(Tableau3[[#This Row],[Entreprise]]) -> EIFFAGE SENEGAL SAS | C9: dame.sene@eiffage.com | D9: Sous-traitants | E9: Sénégal
A10: GLOBAL AFRICINVEST | B10: =UPPER(Tableau3[[#This Row],[Entreprise]]) -> GLOBAL AFRICINVEST | C10: lamine.globalai@gmail.com | D10: Sous-traitants | E10: Sénégal
A11: MCI SENEGAL SAS | B11: =UPPER(Tableau3[[#This Row],[Entreprise]]) -> MCI SENEGAL SAS | C11: gaelle.ndiaye@mci-int.com | D11: Sous-traitants | E11: Sénégal
A12: Africa Power Services Senegal | B12: =UPPER(Tableau3[[#This Row],[Entreprise]]) -> AFRICA POWER SERVICES SENEGAL | C12: juridique@delmasip.com | D12: Sous-traitants | E12: Sénégal
A13: Lycopodium Minerals Canada LTD | B13: =UPPER(Tableau3[[#This Row],[Entreprise]]) -> LYCOPODIUM MINERALS CANADA LTD | C13: khuram.mushtaq@lycopodium.com | D13: Sous-traitants | E13: Canada
... A42: CJ ICM LOGISTICS BELGIUM BV | B42: =UPPER(Tableau3[[#This Row],[Entreprise]]) -> CJ ICM LOGISTICS BELGIUM BV | C42: ilidia.rocha@cj-icm.com | D42: Sous-traitants | E42: Belgique

Sheet Merge
A1: Code | B1: Nom | C1: Parties | D1: Déclare | E1: Profile | F1: Juridiction | G1: Contact | H1: Type | I1: Substances | J1: Statut | K1: Région | L1: Demande faite | M1: Octroyé | N1: Expire le | O1: Renouvelé | P1: superficie
A2: 02231 | B2: Taiba | C2: AFRICA TRADE AND INVESTMENT CONSULTING SARL | D2: =IF(COUNTIF(RBE!$C$1:$C$629,A2)>0,"Existe","Absent") -> Absent | E2: Permis | F2: Sénégal | H2: AEHTR | I2: Sl | J2: Active | K2: Thiès | L2: 43165 | M2: 43229 | N2: 46881 | O2: 45055 | P2: 0.0795 Ha
A3: 03563 | B3: KIDIRA | C3: AFRICA TRADE AND INVESTMENT CONSULTING SARL (100%) | D3: =IF(COUNTIF(RBE!$C$1:$C$629,A3)>0,"Existe","Absent") -> Absent | E3: Permis | F3: Sénégal | H3: AECPP | I3: basalte | J3: Active | K3: Tambacounda | L3: 44215 | M3: 44862 | N3: 46687 | P3: 34.7200 Ha
A4: 03831 | C4: AFRICA TRADE AND INVESTMENT CONSULTING SARL (100%) | D4: =IF(COUNTIF(RBE!$C$1:$C$629,A4)>0,"Existe","Absent") -> Absent | E4: Permis | F4: Sénégal | H4: AECPP | I4: basalte | J4: Active | K4: Thiès | L4: 45085 | M4: 45184 | N4: 47010 | P4: 30.0634 Ha
A5: 04124 | C5: SURVEY SERVICES SUARL | D5: =IF(COUNTIF(RBE!$C$1:$C$629,A5)>0,"Existe","Absent") -> Absent | E5: Permis | F5: Sénégal | H5: AEMSM | I5: Au | J5: Active | K5: Kedougou | L5: 45316 | M5: 45329 | N5: 46424 | P5: 49.9886 Ha
A6: 03785 | C6: 3T SARL (100%) | D6: =IF(COUNTIF(RBE!$C$1:$C$629,A6)>0,"Existe","Absent") -> Absent | E6: Permis | F6: Sénégal | H6: AEMSM | I6: Au | J6: Active | K6: Kedougou | L6: 45083 | M6: 45090 | N6: 46185 | P6: 49.6480 Ha
A7: 03608 | B7: GUETIE | C7: ABANDOUR GEOLINK (100%) | D7: =IF(COUNTIF(RBE!$C$1:$C$629,A7)>0,"Existe","Absent") -> Absent | E7: Permis | F7: Sénégal | H7: PR | I7: Cu | J7: Active | K7: Tambacounda | L7: 44127 | M7: 44747 | N7: 46208 | P7: 95.0099 km²
A8: 03346 | B8: ICS MBORO | C8: ADAMA UNIVERSAL IMMOBILIER ET AFFAIRES (100%) | D8: =IF(COUNTIF(RBE!$C$1:$C$629,A8)>0,"Existe","Absent") -> Absent | E8: Permis | F8: Sénégal | H8: AEHTR | I8: Sl | J8: Active | K8: Thiès | L8: 44455 | M8: 44476 | N8: 46301
A9: 03492 | B9: ICS | C9: ADICO SARL (100%) | D9: =IF(COUNTIF(RBE!$C$1:$C$629,A9)>0,"Existe","Absent") -> Absent | E9: Permis | F9: Sénégal | H9: AEHTR | I9: Sl | J9: Active | K9: Thiès | L9: 44781 | M9: 44811 | N9: 46636
A10: 04410 | C10: ADICO SARL (100%) | D10: =IF(COUNTIF(RBE!$C$1:$C$629,A10)>0,"Existe","Absent") -> Absent | E10: Permis | F10: Sénégal | H10: AECPT | I10: sable de dune | J10: Active | K10: Thiès | L10: 45850.398 | M10: 45957 | N10: 46321 | P10: 1.8545 Ha
A11: 04252 | B11: BARIBARIE 1 | C11: AFG RESSOURCES (100%) | D11: =IF(COUNTIF(RBE!$C$1:$C$629,A11)>0,"Existe","Absent") -> Absent | E11: Permis | F11: Sénégal | H11: PR | I11: Li | J11: Active | K11: Kedougou | L11: 44841 | M11: 44959 | N11: 46419 | P11: 98.9681 km²
A12: 04063 | C12: AFRICA GLOBAL GEOINGENIERIE SARL | D12: =IF(COUNTIF(RBE!$C$1:$C$629,A12)>0,"Existe","Absent") -> Absent | E12: Permis | F12: Sénégal | H12: AEMSM | I12: Au | J12: Active | K12: Kedougou | L12: 45098 | M12: 45289 | N12: 46384 | P12: 49.3027 Ha
A13: 04342 | C13: AFRICA SERVICES GROUP SUARL (100%) | D13: =IF(COUNTIF(RBE!$C$1:$C$629,A13)>0,"Existe","Absent") -> Absent | E13: Permis | F13: Sénégal | H13: AECPT | I13: sable de dune | J13: Active | K13: Dakar | L13: 45805 | M13: 45807 | N13: 46171 | P13: 2.4073 Ha
A14: 04393 | C14: AFRICA SERVICES GROUP SUARL (100%) | D14: =IF(COUNTIF(RBE!$C$1:$C$629,A14)>0,"Existe","Absent") -> Absent | E14: Permis | F14: Sénégal | H14: AECPT | I14: sable de dune | J14: Active | K14: Dakar | L14: 45972.643 | M14: 45989 | N14: 46353 | P14: 1.8200 Ha
A15: 03507 | C15: AFRICA TRADING EQUIPEMENT CONSTRUCTION SUARL (100%) | D15: =IF(COUNTIF(RBE!$C$1:$C$629,A15)>0,"Existe","Absent") -> Absent | E15: Permis | F15: Sénégal | H15: AEHTR | I15: Sl | J15: Active | K15: Thiès | L15: 44447 | M15: 44608 | N15: 46433
A16: 04267 | C16: AFRICAN BUILDERS SARL (100%) | D16: =IF(COUNTIF(RBE!$C$1:$C$629,A16)>0,"Existe","Absent") -> Absent | E16: Permis | F16: Sénégal | H16: AECPP | I16: Argile, latérite | J16: Active | K16: Thiès | L16: 45047 | M16: 45090 | N16: 46916 | P16: 48.6722 Ha
A17: 02146 | B17: KARAKAENA | C17: AFRIGOLD SARL (90%) | D17: =IF(COUNTIF(RBE!$C$1:$C$629,A17)>0,"Existe","Absent") -> Absent | E17: Permis | F17: Sénégal | H17: PE | I17: Au | J17: Active | K17: Kedougou | L17: 42097 | M17: 44228 | N17: 46053 | P17: 38.6940 km²
A18: 03855 | B18: Kéniéba | C18: AFRIK'MINES SUARL (100%) | D18: =IF(COUNTIF(RBE!$C$1:$C$629,A18)>0,"Existe","Absent") -> Absent | E18: Permis | F18: Sénégal | H18: AEPM | I18: Au | J18: Active | K18: Tambacounda | L18: 45098 | M18: 45145 | N18: 46971 | P18: 4.9545 km²
A19: 04066 | C19: AFRIK'MINES SUARL (100%) | D19: =IF(COUNTIF(RBE!$C$1:$C$629,A19)>0,"Existe","Absent") -> Absent | E19: Permis | F19: Sénégal | H19: AEPM | I19: Mn | J19: Active | K19: Tambacounda | L19: 45099 | M19: 45308 | N19: 47134 | P19: 4.9978 km²
A20: 04248 | B20: Kolia | C20: AFRIQUE MINES COMPANY PLUS (100%) | D20: =IF(COUNTIF(RBE!$C$1:$C$629,A20)>0,"Existe","Absent") -> Absent | E20: Permis | F20: Sénégal | H20: AEMSM | I20: Au | J20: Active | K20: Kedougou | L20: 44998 | M20: 45099 | N20: 46194 | P20: 45.6814 Ha
A21: 02215 | B21: NOUMOUFOUKHA | C21: AGEM (100%) | D21: =IF(COUNTIF(RBE!$C$1:$C$629,A21)>0,"Existe","Absent") -> Absent | E21: Permis | F21: Sénégal | H21: PR | I21: Au, substances connexes | J21: Active | K21: Kedougou | L21: 43038 | M21: 43256 | N21: 45813 | P21: 60.0113 km²
A22: DPR22102018 | B22: DAORALA | C22: AGEM EXPLORATION SENEGAL (100%) | D22: =IF(COUNTIF(RBE!$C$1:$C$629,A22)>0,"Existe","Absent") -> Absent | E22: Permis | F22: Sénégal | H22: PR | I22: Au | J22: Active | K22: Kedougou | L22: 44252 | M22: 44405 | N22: 45865 | P22: 83.4261 km²
A23: 02165 | B23: Pout | C23: AGROMINE SUARL (100%) | D23: =IF(COUNTIF(RBE!$C$1:$C$629,A23)>0,"Existe","Absent") -> Absent | E23: Permis | F23: Sénégal | H23: AECPP | I23: basalte | J23: Active | K23: Thiès | L23: 42422 | M23: 43362 | N23: 46643 | O23: 44818 | P23: 38.5224 Ha
A24: 02273 | B24: LAMBAYE | C24: AGROMINE SUARL (100%) | D24: =IF(COUNTIF(RBE!$C$1:$C$629,A24)>0,"Existe","Absent") -> Absent | E24: Permis | F24: Sénégal | H24: PR | I24: phosphate de chaux | J24: Renouvellement en Cours | K24: Diourbel | L24: 43357 | M24: 43496 | N24: 46053 | P24: 421.8438 km²
A25: 04268 | B25: MAMANKANTI | C25: AIR DYNAMICS SOLUTIONS SENEGAL (100%) | D25: =IF(COUNTIF(RBE!$C$1:$C$629,A25)>0,"Existe","Absent") -> Absent | E25: Permis | F25: Sénégal | H25: PR | I25: Au | J25: Active | K25: Kedougou | L25: 45369 | M25: 45380 | N25: 46840 | P25: 18.6813 km²
A26: 03672 | C26: AL JABER BTP SAU (100%) | D26: =IF(COUNTIF(RBE!$C$1:$C$629,A26)>0,"Existe","Absent") -> Absent | E26: Permis | F26: Sénégal | H26: AEHTR | I26: Sl | J26: Active | K26: Thiès | L26: 44834 | M26: 44957 | N26: 46782
A27: 02188 | C27: ALBINA SENEGAL (100%) | D27: =IF(COUNTIF(RBE!$C$1:$C$629,A27)>0,"Existe","Absent") -> Absent | E27: Permis | F27: Sénégal | H27: AECPP | I27: calcaire | J27: Active | K27: Thiès | L27: 42786 | M27: 43304 | N27: 46957 | P27: 15.0505 Ha
A28: 03864 | B28: Périmètre 2 | C28: ALIM GOLD SARL (100%) | D28: =IF(COUNTIF(RBE!$C$1:$C$629,A28)>0,"Existe","Absent") -> Absent | E28: Permis | F28: Sénégal | H28: AEMSM | I28: Au | J28: Active | K28: Kedougou | L28: 45152 | M28: 45194 | N28: 46289 | P28: 43.9332 Ha
A29: 04090 | B29: Périmètre 3 | C29: ALIM GOLD SARL (100%) | D29: =IF(COUNTIF(RBE!$C$1:$C$629,A29)>0,"Existe","Absent") -> Absent | E29: Permis | F29: Sénégal | H29: AEMSM | I29: Au | J29: Active | K29: Kedougou | L29: 45306 | M29: 45349 | N29: 46444 | P29: 49.5800 Ha
A30: 03452 | B30: ICS | C30: ALWAR PRODUCTION GROUP (100%) | D30: =IF(COUNTIF(RBE!$C$1:$C$629,A30)>0,"Existe","Absent") -> Absent | E30: Permis | F30: Sénégal | H30: AEHTR | I30: Sl | J30: Active | L30: 44357 | M30: 44614 | N30: 46439
A31: 04395 | C31: AMAFRIQUE SENEGAL (100%) | D31: =IF(COUNTIF(RBE!$C$1:$C$629,A31)>0,"Existe","Absent") -> Absent | E31: Permis | F31: Sénégal | H31: AP | I31: phosphate de chaux | J31: Active | K31: Matam | L31: 45973.532 | M31: 46113 | N31: 46295 | P31: 4.9794 km²
A32: 03424 | B32: ICS | C32: AMATH NDIAYE INTERNATIONALE PRESTIGE SUARL (100%) | D32: =IF(COUNTIF(RBE!$C$1:$C$629,A32)>0,"Existe","Absent") -> Absent | E32: Permis | F32: Sénégal | H32: AEHTR | I32: Sl | J32: Active | K32: Thiès | L32: 44532 | M32: 44594 | N32: 46419
A33: 03925 | C33: AMCI GOLD MINE SARL | D33: =IF(COUNTIF(RBE!$C$1:$C$629,A33)>0,"Existe","Absent") -> Absent | E33: Permis | F33: Sénégal | H33: AEMSM | I33: Au | J33: Active | K33: Tambacounda | L33: 45117 | M33: 45121 | N33: 46216 | P33: 49.3363 Ha
A34: 03971 | B34: Périmètre 2 | C34: AMCI GOLD MINE SARL | D34: =IF(COUNTIF(RBE!$C$1:$C$629,A34)>0,"Existe","Absent") -> Absent | E34: Permis | F34: Sénégal | H34: AEMSM | I34: Au | J34: Active | K34: Tambacounda | L34: 45117 | M34: 45121 | N34: 46216 | P34: 48.7346 Ha
A35: 03973 | B35: Périmètre 4 | C35: AMCI GOLD MINE SARL | D35: =IF(COUNTIF(RBE!$C$1:$C$629,A35)>0,"Existe","Absent") -> Absent | E35: Permis | F35: Sénégal | H35: AEMSM | I35: Au | J35: Active | K35: Tambacounda | L35: 45117 | M35: 45121 | N35: 46216 | P35: 49.9278 Ha
A36: 03751 | B36: Périmètre 3 | C36: AMCI GOLD MINE SARL (100%) | D36: =IF(COUNTIF(RBE!$C$1:$C$629,A36)>0,"Existe","Absent") -> Absent | E36: Permis | F36: Sénégal | H36: AEMSM | I36: Au | J36: Active | K36: Kedougou | L36: 45029 | M36: 45090 | N36: 46185 | P36: 38.7250 Ha
A37: 03921 | B37: Périmètre 4 | C37: AMFICI GOLD (100%) | D37: =IF(COUNTIF(RBE!$C$1:$C$629,A37)>0,"Existe","Absent") -> Absent | E37: Permis | F37: Sénégal | H37: AEMSM | I37: Au | J37: Active | K37: Kedougou | L37: 45190 | M37: 45196 | N37: 46291 | P37: 38.7200 Ha
A38: 03922 | B38: Périmètre 3 | C38: AMFICI GOLD (100%) | D38: =IF(COUNTIF(RBE!$C$1:$C$629,A38)>0,"Existe","Absent") -> Absent | E38: Permis | F38: Sénégal | H38: AEMSM | I38: Au | J38: Active | K38: Kedougou | L38: 45190 | M38: 45196 | N38: 46291 | P38: 35.0200 Ha
A39: 03264 | B39: Packi | C39: AMIN TRANS SUARL (100%) | D39: =IF(COUNTIF(RBE!$C$1:$C$629,A39)>0,"Existe","Absent") -> Absent | E39: Permis | F39: Sénégal | H39: AECPP | I39: grès, latérite | J39: Active | K39: Thiès | L39: 44379 | M39: 44439 | N39: 46264 | P39: 1.9792 Ha
A40: 03347 | B40: ICS MBORO | C40: AMIN TRANS SUARL (100%) | D40: =IF(COUNTIF(RBE!$C$1:$C$629,A40)>0,"Existe","Absent") -> Absent | E40: Permis | F40: Sénégal | H40: AEHTR | I40: Sl | J40: Active | K40: Thiès | L40: 44404 | M40: 44172 | N40: 45997
...

Sheet Feuil1
A3: Étiquettes de lignes | B3: Nombre de Denomination Sociale2
A4: YOUSRIYA NASSIF LOZA | B4: 6
A5: XINJIN ZIRCONIUM INDUSTRY | B5: 1
A6: 2025 | B6: 1
A7: YELLOW GROUND SENEGAL SAS | B7: 5
A8: 2025 | B8: 5
A9: AMADOU DIOP GUEYE | B9: 5
A10: AGRO SENEGAL EXPORTS | B10: 2
A11: 2022 | B11: 2
A12: AL MAKHTOUM GENERAL TRADING | B12: 1
A13: 2022 | B13: 1
A14: ALLIANCE GOLD | B14: 2
A15: 2022 | B15: 2
... A1741: Total général | B1741: 628

Sheet RBE
A1: Région | B1: Denomination Sociale | C1: Denomination Sociale2 | D1: déclarant | E1: Prénom et Nom Bénéficiaire | F1: Date d'acquisition | G1: Année | H1: % Action Direct | I1: % Voix Direct | J1: Nationalite | K1: Pays de résidence | L1: Est Une PPE | M1: Fonction PPE | N1: NomPPE | O1: Greffe | P1: Regions
A2: Dakar | B2: 2S GOLD | C2: 2S GOLD | D2: =VLOOKUP(RBE!C2,Permis[[#This Row],[Parties]],1,0) -> #N/A | E2: ALEXANDRE BRINGER | F2: 2021-11-16 15:40:33.487 | G2: =LEFT(TRIM(F2),4) -> 2021 | H2: 20 | I2: NULL | J2: SÉNÉGAL | K2: SÉNÉGAL | L2: NULL | M2: 0 | N2: NULL | O2: Greffe | P2: Dakar | Q2: =IF(J2=K2,0,1) -> 0 | R2: =ISBLANK(K2) -> FALSE
A3: Dakar | B3: ABA SERVICES | C3: ABA SERVICES | D3: =VLOOKUP(RBE!C3,Permis[[#This Row],[Parties]],1,0) -> #N/A | E3: ALFRED SYMPA | F3: 2021-11-17 15:38:42.123 | G3: =LEFT(TRIM(F3),4) -> 2021 | H3: 100 | I3: NULL | J3: ALBANIE | K3: ALBANIE | L3: NULL | M3: 0 | N3: NULL | O3: Greffe | P3: Dakar | Q3: =IF(J3=K3,0,1) -> 0 | R3: =ISBLANK(K3) -> FALSE
A4: Dakar | B4: ABABACAR DIOP TRANSPORTS SARL | C4: ABABACAR DIOP TRANSPORTS SARL | D4: =VLOOKUP(RBE!C4,Permis[[#This Row],[Parties]],1,0) -> #N/A | E4: ALIKO DANGOTE | F4: 2021-12-24 11:36:59.230 | G4: =LEFT(TRIM(F4),4) -> 2021 | H4: 25 | I4: NULL | J4: SÉNÉGAL | K4: SÉNÉGAL | L4: NULL | M4: 0 | N4: NULL | O4: Greffe | P4: Dakar | Q4: =IF(J4=K4,0,1) -> 0 | R4: =ISBLANK(K4) -> FALSE
A5: Dakar | B5: ABANDOUR GEOLINK | C5: ABANDOUR GEOLINK | D5: =VLOOKUP(RBE!C5,Permis[[#This Row],[Parties]],1,0) -> #N/A | E5: ALIOU CAMARA | F5: 2021-12-24 11:36:59.230 | G5: =LEFT(TRIM(F5),4) -> 2021 | H5: 25 | I5: NULL | J5: SÉNÉGAL | K5: SÉNÉGAL | L5: NULL | M5: 0 | N5: NULL | O5: Greffe | P5: Dakar | Q5: =IF(J5=K5,0,1) -> 0 | R5: =ISBLANK(K5) -> FALSE
A6: Dakar | B6: ABANDOUR GEOLINK | C6: ABANDOUR GEOLINK | D6: =VLOOKUP(RBE!C6,Permis[[#This Row],[Parties]],1,0) -> #N/A | E6: ALIOU CISSE | F6: 2021-12-21 15:13:29.357 | G6: =LEFT(TRIM(F6),4) -> 2021 | H6: 30 | I6: NULL | J6: SÉNÉGAL | K6: SÉNÉGAL | L6: NULL | M6: 0 | N6: NULL | O6: Greffe | P6: Dakar | Q6: =IF(J6=K6,0,1) -> 0 | R6: =ISBLANK(K6) -> FALSE
A7: Dakar | B7: AD GLOD | C7: AD GLOD | D7: =VLOOKUP(RBE!C7,Permis[[#This Row],[Parties]],1,0) -> #N/A | E7: ALIOU DIOUF | F7: 2021-12-21 15:13:29.357 | G7: =LEFT(TRIM(F7),4) -> 2021 | H7: 70 | I7: NULL | J7: SÉNÉGAL | K7: SÉNÉGAL | L7: NULL | M7: 0 | N7: NULL | O7: Greffe | P7: Dakar | Q7: =IF(J7=K7,0,1) -> 0 | R7: =ISBLANK(K7) -> FALSE
A8: Dakar | B8: AD GLOD | C8: AD GLOD | D8: =VLOOKUP(RBE!C8,Permis[[#This Row],[Parties]],1,0) -> #N/A | E8: ALIOU NDIAYE | F8: 2021-12-13 15:49:50.663 | G8: =LEFT(TRIM(F8),4) -> 2021 | H8: 50 | I8: 50 | J8: SÉNÉGAL | K8: SÉNÉGAL | L8: SENEGAL | M8: 0 | N8: CHEIKHOUNA THIOUNE | O8: Greffe | P8: Dakar | Q8: =IF(J8=K8,0,1) -> 0 | R8: =ISBLANK(K8) -> FALSE
A9: Dakar | B9: AD GLOD | C9: AD GLOD | D9: =VLOOKUP(RBE!C9,Permis[[#This Row],[Parties]],1,0) -> #N/A | E9: ALIOU SOUARE | F9: 2021-12-13 15:49:50.663 | G9: =LEFT(TRIM(F9),4) -> 2021 | H9: 50 | I9: 50 | J9: SÉNÉGAL | K9: SÉNÉGAL | L9: SÉNÉGAL | M9: 0 | N9: CHEIKHOUNA THIOUNE | O9: Greffe | P9: Dakar | Q9: =IF(J9=K9,0,1) -> 0 | R9: =ISBLANK(K9) -> FALSE
A10: Dakar | B10: " ADAMA UNIVERSAL IMMOBILIER ET AFFAIRES " ADA-SUARL | C10: ADAMA UNIVERSAL IMMOBILIER ET AFFAIRES ADA-SUARL | D10: =VLOOKUP(RBE!C10,Permis[[#This Row],[Parties]],1,0) -> #N/A | E10: ABABACAR DIOP | F10: 2021-06-28 13:12:04.777 | G10: =LEFT(TRIM(F10),4) -> 2021 | H10: 99.99 | I10: 99.99 | J10: NIGÉRIA | K10: NIGÉRIA | L10: NULL | M10: 0 | N10: NULL | O10: Greffe | P10: Dakar | Q10: =IF(J10=K10,0,1) -> 0 | R10: =ISBLANK(K10) -> FALSE
A11: Dakar | B11: ADJAF UNIVERSEL | C11: ADJAF UNIVERSEL | D11: =VLOOKUP(RBE!C11,Permis[[#This Row],[Parties]],1,0) -> #N/A | E11: ALIOUNE CISSE | F11: 2021-12-24 11:36:59.230 | G11: =LEFT(TRIM(F11),4) -> 2021 | H11: 25 | I11: NULL | J11: SÉNÉGAL | K11: SÉNÉGAL | L11: NULL | M11: 0 | N11: NULL | O11: Greffe | P11: Dakar | Q11: =IF(J11=K11,0,1) -> 0 | R11: =ISBLANK(K11) -> FALSE
A12: Dakar | B12: "AFIA SERVICES" | C12: AFIA SERVICES | D12: =VLOOKUP(RBE!C12,Permis[[#This Row],[Parties]],1,0) -> #N/A | E12: ADAMA CISSOKHO | F12: 2021-11-16 15:40:33.487 | G12: =LEFT(TRIM(F12),4) -> 2021 | H12: 20 | I12: NULL | J12: SÉNÉGAL | K12: SÉNÉGAL | L12: NULL | M12: 0 | N12: NULL | O12: Greffe | P12: Dakar | Q12: =IF(J12=K12,0,1) -> 0 | R12: =ISBLANK(K12) -> FALSE
A13: Dakar | B13: AFRICA A WAY | C13: AFRICA A WAY | D13: =VLOOKUP(RBE!C13,Permis[[#This Row],[Parties]],1,0) -> #N/A | E13: ALIOUNE CISSE | F13: 2021-12-24 11:36:59.230 | G13: =LEFT(TRIM(F13),4) -> 2021 | H13: 25 | I13: NULL | J13: SÉNÉGAL | K13: SÉNÉGAL | L13: NULL | M13: 0 | N13: NULL | O13: Greffe | P13: Dakar | Q13: =IF(J13=K13,0,1) -> 0 | R13: =ISBLANK(K13) -> FALSE
A14: Dakar | B14: AFRICA A WAY | C14: AFRICA A WAY | D14: =VLOOKUP(RBE!C14,Permis[[#This Row],[Parties]],1,0) -> #N/A | E14: ALIOUNE CISSE | F14: 2021-07-02 09:29:40.887 | G14: =LEFT(TRIM(F14),4) -> 2021 | H14: NULL | I14: NULL | J14: CANADA | K14: CANADA | L14: NULL | M14: 0 | N14: NULL | O14: Greffe | P14: Dakar | Q14: =IF(J14=K14,0,1) -> 0 | R14: =ISBLANK(K14) -> FALSE
A15: Dakar | B15: AFRICA CONSULTING BUSINESS (ACB) | C15: AFRICA CONSULTING BUSINESS (ACB) | D15: =VLOOKUP(RBE!C15,Permis[[#This Row],[Parties]],1,0) -> #N/A | E15: ALIOUNE DIALLO | F15: 2021-11-19 15:35:36.977 | G15: =LEFT(TRIM(F15),4) -> 2021 | H15: 100 | I15: 100 | J15: SÉNÉGAL | K15: SÉNÉGAL | L15: NULL | M15: 0 | N15: NULL | O15: Greffe | P15: Dakar | Q15: =IF(J15=K15,0,1) -> 0 | R15: =ISBLANK(K15) -> FALSE
A16: Dakar | B16: AFRICA GLOBAL GEOINGENIERIE (A2G) | C16: AFRICA GLOBAL GEOINGENIERIE (A2G) | D16: =VLOOKUP(RBE!C16,Permis[[#This Row],[Parties]],1,0) -> #N/A | E16: ALIOUNE TELEMAQUE SOW | F16: 2022-02-21 15:55:15.067 | G16: =LEFT(TRIM(F16),4) -> 2022 | H16: 100 | I16: NULL | J16: SÉNÉGAL | K16: SÉNÉGAL | L16: NULL | M16: 0 | N16: NULL | O16: Greffe | P16: Dakar | Q16: =IF(J16=K16,0,1) -> 0 | R16: =ISBLANK(K16) -> FALSE
A17: Dakar | B17: AFRICA GLOBAL GEOINGENIERIE (A2G) | C17: AFRICA GLOBAL GEOINGENIERIE (A2G) | D17: =VLOOKUP(RBE!C17,Permis[[#This Row],[Parties]],1,0) -> #N/A | E17: ALIOUNEDIOP FAYE | F17: 2022-05-18 14:06:56.020 | G17: =LEFT(TRIM(F17),4) -> 2022 | H17: NULL | I17: 2 | J17: SÉNÉGAL | K17: SÉNÉGAL | L17: NULL | M17: 0 | N17: NULL | O17: Greffe | P17: Dakar | Q17: =IF(J17=K17,0,1) -> 0 | R17: =ISBLANK(K17) -> FALSE
A18: Dakar | B18: AFRICA TRADE AND INVESTMENT CONSULTING (ATIC-SARL) | C18: AFRICA TRADE AND INVESTMENT CONSULTING (ATIC-SARL) | D18: =VLOOKUP(RBE!C18,Permis[[#This Row],[Parties]],1,0) -> #N/A | E18: ALLE THIAM | F18: 2022-11-11 14:48:03.010 | G18: =LEFT(TRIM(F18),4) -> 2022 | H18: 100 | I18: 100 | J18: SÉNÉGAL | K18: SÉNÉGAL | L18: NULL | M18: 0 | N18: NULL | O18: Greffe | P18: Dakar | Q18: =IF(J18=K18,0,1) -> 0 | R18: =ISBLANK(K18) -> FALSE
A19: Dakar | B19: Africa Traiding-Equipement et Transport (AF-TECO) | C19: Africa Traiding-Equipement et Transport (AF-TECO) | D19: =VLOOKUP(RBE!C19,Permis[[#This Row],[Parties]],1,0) -> #N/A | E19: ALPHA MOUSSA KANE | F19: 2022-12-02 09:59:34.317 | G19: =LEFT(TRIM(F19),4) -> 2022 | H19: 40 | I19: 40 | J19: SÉNÉGAL | K19: SÉNÉGAL | L19: NULL | M19: 0 | N19: NULL | O19: Greffe | P19: Dakar | Q19: =IF(J19=K19,0,1) -> 0 | R19: =ISBLANK(K19) -> FALSE
A20: Dakar | B20: AFRICA VISION MINING ( AVM-SARL) | C20: AFRICA VISION MINING ( AVM-SARL) | D20: =VLOOKUP(RBE!C20,Permis[[#This Row],[Parties]],1,0) -> #N/A | E20: AMADOU AIDARA | F20: 2022-05-18 14:06:56.020 | G20: =LEFT(TRIM(F20),4) -> 2022 | H20: NULL | I20: 2 | J20: SÉNÉGAL | K20: SÉNÉGAL | L20: NULL | M20: 0 | N20: NULL | O20: Greffe | P20: Dakar | Q20: =IF(J20=K20,0,1) -> 0 | R20: =ISBLANK(K20) -> FALSE
A21: Dakar | B21: AFRICA VISION MINING ( AVM-SARL) | C21: AFRICA VISION MINING ( AVM-SARL) | D21: =VLOOKUP(RBE!C21,Permis[[#This Row],[Parties]],1,0) -> #N/A | E21: AMADOU APITHY | F21: 2022-07-28 13:22:53.183 | G21: =LEFT(TRIM(F21),4) -> 2022 | H21: 100 | I21: NULL | J21: SÉNÉGAL | K21: SÉNÉGAL | L21: NULL | M21: 0 | N21: NULL | O21: Greffe | P21: Dakar | Q21: =IF(J21=K21,0,1) -> 0 | R21: =ISBLANK(K21) -> FALSE
A22: Dakar | B22: AFRICAN BUILDERS SARL | C22: AFRICAN BUILDERS SARL | D22: =VLOOKUP(RBE!C22,Permis[[#This Row],[Parties]],1,0) -> #N/A | E22: AMADOU BA | F22: 2022-12-02 09:59:34.317 | G22: =LEFT(TRIM(F22),4) -> 2022 | H22: 40 | I22: 40 | J22: SÉNÉGAL | K22: SÉNÉGAL | L22: NULL | M22: 0 | N22: NULL | O22: Greffe | P22: Dakar | Q22: =IF(J22=K22,0,1) -> 0 | R22: =ISBLANK(K22) -> FALSE
A23: Dakar | B23: AFRICAN BUILDERS SARL | C23: AFRICAN BUILDERS SARL | D23: =VLOOKUP(RBE!C23,Permis[[#This Row],[Parties]],1,0) -> #N/A | E23: AMADOU DIALLO | F23: 2022-12-02 09:59:34.317 | G23: =LEFT(TRIM(F23),4) -> 2022 | H23: 30 | I23: 30 | J23: SÉNÉGAL | K23: SÉNÉGAL | L23: NULL | M23: 0 | N23: NULL | O23: Greffe | P23: Dakar | Q23: =IF(J23=K23,0,1) -> 0 | R23: =ISBLANK(K23) -> FALSE
A24: Dakar | B24: AFRICAN BUILDERS SARL | C24: AFRICAN BUILDERS SARL | D24: =VLOOKUP(RBE!C24,Permis[[#This Row],[Parties]],1,0) -> #N/A | E24: AMADOU DIANE | F24: 2022-09-30 08:41:23.457 | G24: =LEFT(TRIM(F24),4) -> 2022 | H24: 24 | I24: NULL | J24: SÉNÉGAL | K24: SÉNÉGAL | L24: NULL | M24: 0 | N24: NULL | O24: Greffe | P24: Dakar | Q24: =IF(J24=K24,0,1) -> 0 | R24: =ISBLANK(K24) -> FALSE
A25: Dakar | B25: AFRICAN BUILDERS SARL | C25: AFRICAN BUILDERS SARL | D25: =VLOOKUP(RBE!C25,Permis[[#This Row],[Parties]],1,0) -> #N/A | E25: AMADOU DIANGO | F25: 2022-09-30 08:41:23.457 | G25: =LEFT(TRIM(F25),4) -> 2022 | H25: 5 | I25: NULL | J25: SÉNÉGAL | K25: SÉNÉGAL | L25: NULL | M25: 0 | N25: NULL | O25: Greffe | P25: Dakar | Q25: =IF(J25=K25,0,1) -> 0 | R25: =ISBLANK(K25) -> FALSE
A26: Dakar | B26: AGEM SENEGAL EXPLORATION | C26: AGEM SENEGAL EXPLORATION | D26: =VLOOKUP(RBE!C26,Permis[[#This Row],[Parties]],1,0) -> #N/A | E26: AMADOU DIOP | F26: 2022-09-30 08:41:23.457 | G26: =LEFT(TRIM(F26),4) -> 2022 | H26: 11 | I26: NULL | J26: SÉNÉGAL | K26: SÉNÉGAL | L26: NULL | M26: 0 | N26: NULL | O26: Greffe | P26: Dakar | Q26: =IF(J26=K26,0,1) -> 0 | R26: =ISBLANK(K26) -> FALSE
A27: Dakar | B27: AGRO SENEGAL EXPORTS | C27: AGRO SENEGAL EXPORTS | D27: =VLOOKUP(RBE!C27,Permis[[#This Row],[Parties]],1,0) -> #N/A | E27: AMADOU DIOP GUEYE | F27: 2022-09-30 08:41:23.457 | G27: =LEFT(TRIM(F27),4) -> 2022 | H27: 23 | I27: NULL | J27: SÉNÉGAL | K27: SÉNÉGAL | L27: NULL | M27: 0 | N27: NULL | O27: Greffe | P27: Dakar | Q27: =IF(J27=K27,0,1) -> 0 | R27: =ISBLANK(K27) -> FALSE
A28: Dakar | B28: AGRO SENEGAL EXPORTS | C28: AGRO SENEGAL EXPORTS | D28: =VLOOKUP(RBE!C28,Permis[[#This Row],[Parties]],1,0) -> #N/A | E28: AMADOU DIOP GUEYE | F28: 2022-09-30 08:41:23.457 | G28: =LEFT(TRIM(F28),4) -> 2022 | H28: 11 | I28: NULL | J28: SÉNÉGAL | K28: SÉNÉGAL | L28: NULL | M28: 0 | N28: NULL | O28: Greffe | P28: Dakar | Q28: =IF(J28=K28,0,1) -> 0 | R28: =ISBLANK(K28) -> FALSE
A29: Dakar | B29: AL MAKHTOUM GENERAL TRADING | C29: AL MAKHTOUM GENERAL TRADING | D29: =VLOOKUP(RBE!C29,Permis[[#This Row],[Parties]],1,0) -> #N/A | E29: AMADOU DIOP GUEYE | F29: 2022-09-30 08:41:23.457 | G29: =LEFT(TRIM(F29),4) -> 2022 | H29: 11 | I29: NULL | J29: SÉNÉGAL | K29: SÉNÉGAL | L29: NULL | M29: 0 | N29: NULL | O29: Greffe | P29: Dakar | Q29: =IF(J29=K29,0,1) -> 0 | R29: =ISBLANK(K29) -> FALSE
A30: Dakar | B30: ALLIANCE GOLD | C30: ALLIANCE GOLD | D30: =VLOOKUP(RBE!C30,Permis[[#This Row],[Parties]],1,0) -> #N/A | E30: AMADOU DIOP GUEYE | F30: 2022-09-30 16:34:27.577 | G30: =LEFT(TRIM(F30),4) -> 2022 | H30: NULL | I30: NULL | J30: CANADA | K30: CANADA | L30: NULL | M30: 0 | N30: NULL | O30: Greffe | P30: Dakar | Q30: =IF(J30=K30,0,1) -> 0 | R30: =ISBLANK(K30) -> FALSE
A31: Dakar | B31: ALLIANCE GOLD | C31: ALLIANCE GOLD | D31: =VLOOKUP(RBE!C31,Permis[[#This Row],[Parties]],1,0) -> #N/A | E31: AMADOU DIOP GUEYE | F31: 2022-11-17 15:32:59.050 | G31: =LEFT(TRIM(F31),4) -> 2022 | H31: 100 | I31: 100 | J31: SÉNÉGAL | K31: SÉNÉGAL | L31: NULL | M31: 0 | N31: NULL | O31: Greffe | P31: Dakar | Q31: =IF(J31=K31,0,1) -> 0 | R31: =ISBLANK(K31) -> FALSE
A32: Dakar | B32: ALPHA OMEGA | C32: ALPHA OMEGA | D32: =VLOOKUP(RBE!C32,Permis[[#This Row],[Parties]],1,0) -> #N/A | E32: AMADOU GAYE | F32: 2022-01-12 13:28:08.260 | G32: =LEFT(TRIM(F32),4) -> 2022 | H32: 30 | I32: 30 | J32: SÉNÉGAL | K32: SÉNÉGAL | L32: NULL | M32: 0 | N32: NULL | O32: Greffe | P32: Dakar | Q32: =IF(J32=K32,0,1) -> 0 | R32: =ISBLANK(K32) -> FALSE
A33: Dakar | B33: AMATH NDIAYE INTERNATIONAL PRESTIGE (ANIP) | C33: AMATH NDIAYE INTERNATIONAL PRESTIGE (ANIP) | D33: =VLOOKUP(RBE!C33,Permis[[#This Row],[Parties]],1,0) -> #N/A | E33: AMADOU MALICK SONKO | F33: 2022-01-12 13:28:08.260 | G33: =LEFT(TRIM(F33),4) -> 2022 | H33: 30 | I33: 30 | J33: SÉNÉGAL | K33: SÉNÉGAL | L33: NULL | M33: 0 | N33: NULL | O33: Greffe | P33: Dakar | Q33: =IF(J33=K33,0,1) -> 0 | R33: =ISBLANK(K33) -> FALSE
A34: Dakar | B34: AMICALE DES ORPAILLEURS DE KEDOUGOU | C34: AMICALE DES ORPAILLEURS DE KEDOUGOU | D34: =VLOOKUP(RBE!C34,Permis[[#This Row],[Parties]],1,0) -> #N/A | E34: AMADOU RACINE SOW | F34: 2022-05-24 13:56:54.337 | G34: =LEFT(TRIM(F34),4) -> 2022 | H34: 100 | I34: 100 | J34: SÉNÉGAL | K34: SÉNÉGAL | L34: NULL | M34: 0 | N34: NULL | O34: Greffe | P34: Dakar | Q34: =IF(J34=K34,0,1) -> 0 | R34: =ISBLANK(K34) -> FALSE
A35: Dakar | B35: AMSA GROUP AFRICA SA | C35: AMSA GROUP AFRICA SA | D35: =VLOOKUP(RBE!C35,Permis[[#This Row],[Parties]],1,0) -> #N/A | E35: AMADOU THIAM | F35: 2022-10-05 13:25:42.720 | G35: =LEFT(TRIM(F35),4) -> 2022 | H35: NULL | I35: NULL | J35: ALLEMAGNE | K35: ALLEMAGNE | L35: NULL | M35: 0 | N35: NULL | O35: Greffe | P35: Dakar | Q35: =IF(J35=K35,0,1) -> 0 | R35: =ISBLANK(K35) -> FALSE
A36: Dakar | B36: ARC EN CIEL | C36: ARC EN CIEL | D36: =VLOOKUP(RBE!C36,Permis[[#This Row],[Parties]],1,0) -> #N/A | E36: AMADOU THIAM | F36: 2022-08-08 09:56:35.827 | G36: =LEFT(TRIM(F36),4) -> 2022 | H36: 100 | I36: 100 | J36: SÉNÉGAL | K36: SÉNÉGAL | L36: NULL | M36: 0 | N36: NULL | O36: Greffe | P36: Dakar | Q36: =IF(J36=K36,0,1) -> 0 | R36: =ISBLANK(K36) -> FALSE
A37: Dakar | B37: ARDIMINES SARL | C37: ARDIMINES SARL | D37: =VLOOKUP(RBE!C37,Permis[[#This Row],[Parties]],1,0) -> #N/A | E37: AMADOU YERO DIALLO | F37: 2022-01-19 14:56:56.897 | G37: =LEFT(TRIM(F37),4) -> 2022 | H37: 100 | I37: 100 | J37: SÉNÉGAL | K37: SÉNÉGAL | L37: NULL | M37: 0 | N37: NULL | O37: Greffe | P37: Dakar | Q37: =IF(J37=K37,0,1) -> 0 | R37: =ISBLANK(K37) -> FALSE
A38: Dakar | B38: ARDIMINES SARL | C38: ARDIMINES SARL | D38: =VLOOKUP(RBE!C38,Permis[[#This Row],[Parties]],1,0) -> #N/A | E38: AMATH NDIAYE | F38: 2022-09-08 15:17:23.333 | G38: =LEFT(TRIM(F38),4) -> 2022 | H38: NULL | I38: NULL | J38: CANADA | K38: CANADA | L38: NULL | M38: 0 | N38: NULL | O38: Greffe | P38: Dakar | Q38: =IF(J38=K38,0,1) -> 0 | R38: =ISBLANK(K38) -> FALSE
A39: Dakar | B39: AREZKI-SA | C39: AREZKI-SA | D39: =VLOOKUP(RBE!C39,Permis[[#This Row],[Parties]],1,0) -> #N/A | E39: AMETH DIAMANKA | F39: 2022-07-08 14:32:33.017 | G39: =LEFT(TRIM(F39),4) -> 2022 | H39: 100 | I39: 100 | J39: SÉNÉGAL | K39: SÉNÉGAL | L39: NULL | M39: 0 | N39: NULL | O39: Greffe | P39: Dakar | Q39: =IF(J39=K39,0,1) -> 0 | R39: =ISBLANK(K39) -> FALSE
A40: Dakar | B40: AREZKI-SA | C40: AREZKI-SA | D40: =VLOOKUP(RBE!C40,Permis[[#This Row],[Parties]],1,0) -> #N/A | E40: AMINATA BAIDY SOW | F40: 2022-03-15 14:29:25.337 | G40: =LEFT(TRIM(F40),4) -> 2022 | H40: 100 | I40: 100 | J40: SÉNÉGAL | K40: SÉNÉGAL | L40: NULL | M40: 0 | N40: NULL | O40: Greffe | P40: Dakar | Q40: =IF(J40=K40,0,1) -> 0 | R40: =ISBLANK(K40) -> FALSE
...

Sheet 00
A1: Entreprises Déclarantes dans RBE
A2: 2S GOLD
A3: ABA SERVICES
A4: ABABACAR DIOP TRANSPORTS SARL
A5: ABANDOUR GEOLINK
A6: AD GLOD
A7: ADAMA UNIVERSAL IMMOBILIER ET AFFAIRES ADA-SUARL
A8: ADJAF UNIVERSEL
A9: AFIA SERVICES
A10: AFRICA A WAY
A11: AFRICA CONSULTING BUSINESS (ACB)
A12: AFRICA GLOBAL GEOINGENIERIE (A2G)
... A319: Total général

Sheet 01
A1: Entreprises ayant des titres miniers
A2: AFRICA TRADE AND INVESTMENT CONSULTING SARL (100%)
A3: SURVEY SERVICES SUARL
A4: 3T SARL (100%)
A5: ABANDOUR GEOLINK (100%)
A6: ADAMA UNIVERSAL IMMOBILIER ET AFFAIRES (100%)
A7: ADICO SARL (100%)
A8: AFG RESSOURCES (100%)
A9: AFRICA GLOBAL GEOINGENIERIE SARL
A10: AFRICA SERVICES GROUP SUARL (100%)
A11: AFRICA TRADING EQUIPEMENT CONSTRUCTION SUARL (100%)
A12: AFRICAN BUILDERS SARL (100%)
... A415: Total général

Sheet 02
A1: Entreprises sous traitant
A2: AECI SENEGAL
A3: Africa Power Services Senegal
A4: African Underground Mining Services Senegal SUARL
A5: AMS Senegal SUARL
A6: BAUER
A7: BOSFOR SARL
A8: CADEX SENEGAL
A9: CHALLENGE 2000 SARL
A10: CHEIKH FALL
A11: CJ ICM LOGISTICS BELGIUM BV
A12: CORICA MINING SERVICES SARL
... A43: Total général

Sheet 03
A2: Parties | B2: (Tous)
A4: Nombre de Parties
A5: 595

Sheet Feuil18
A3: Étiquettes de lignes | B3: Étiquettes de lignes
A4: AFRICA TRADE AND INVESTMENT CONSULTING SARL | B4: AFRICA TRADE AND INVESTMENT CONSULTING SARL
A5: SURVEY SERVICES SUARL | B5: SURVEY SERVICES SUARL
A6: 3T SARL | B6: 3T SARL
A7: ABANDOUR GEOLINK | B7: ABANDOUR GEOLINK
A8: ADAMA UNIVERSAL IMMOBILIER ET AFFAIRES | B8: ADAMA UNIVERSAL IMMOBILIER ET AFFAIRES
A9: ADICO SARL | B9: ADICO SARL
A10: AFG RESSOURCES | B10: AFG RESSOURCES
A11: AFRICA GLOBAL GEOINGENIERIE SARL | B11: AFRICA GLOBAL GEOINGENIERIE SARL
A12: AFRICA SERVICES GROUP SUARL | B12: AFRICA SERVICES GROUP SUARL
A13: AFRICA TRADING EQUIPEMENT CONSTRUCTION SUARL | B13: AFRICA TRADING EQUIPEMENT CONSTRUCTION SUARL
A14: AFRICAN BUILDERS SARL | B14: AFRICAN BUILDERS SARL
... A71: CILAGE MINE SUARL | B71: CILAGE MINE
A72: CIMENTS DE L'AFRIQUE | B72: CIMENTS DE L'AFRIQUE | C72: CIMAF
A73: CIMENTS DE L'AFRIQUE (90%) | B73: CIMENTS DE L'AFRIQUE
A74: CIMENTS DU SAHEL | B74: CIMENTS DU SAHEL | C74: CDS
A75: CK CARRIERE | B75: CK CARRIERE
A76: CK CARRIRES SA | B76: CK CARRIERE
A77: COMMUNE DE BOKHOL | B77: COMMUNE DE BOKHOL
A78: COMMUNE DE KEUR MADIABEL | B78: COMMUNE DE KEUR MADIABEL
A79: COMMUNE DE NGUIDILLE | B79: COMMUNE DE NGUIDILLE
A80: COMMUNE DE PIRE | B80: COMMUNE DE PIRE
A81: COMMUNE DE ROSS-BETHIO | B81: COMMUNE DE ROSS-BETHIO
A82: COMMUNE GANDON | B82: COMMUNE GANDON
A83: COMPAGNIE SENEGALAISE DES PHOSPHATES DE TAIBA | B83: COMPAGNIE SENEGALAISE DES PHOSPHATES DE TAIBA
A84: COMPAGNIE DES SABLES DU SENEGAL | B84: COMPAGNIE DES SABLES DU SENEGAL
A85: COMPAGNIE GENERALE D'EXPLOITATION DE CARRIERE | B85: COMPAGNIE GENERALE D'EXPLOITATION DE CARRIERE | C85: COGECA
A86: COMPAGNIE SAHELIENNE D'ENTREPRISE GRANULATS | B86: COMPAGNIE SAHELIENNE D'ENTREPRISE GRANULATS | C86: CSE
A87: COMPAGNY SAKHO - C.S | B87: COMPAGNY SAKHO - C.S
A88: COMPTOIR COMMERCIAL BALLA AICHA CCBA SUARL | B88: COMPTOIR COMMERCIAL BALLA AICHA CCBA SUARL
A89: COMPTOIR D'OR DE LA REGION SARL | B89: COMPTOIR D'OR DE LA REGION SARL
A90: COMPTOIRE COMMERCIAL DAOUDA DIA SUARL | B90: COMPTOIRE COMMERCIAL DAOUDA DIA SUARL
A91: CONSORTIUM PETROMIR & PETROLINE | B91: CONSORTIUM PETROMIR & PETROLINE
A92: CONSORTIUM SENEGALAISE D' INDUSTRIE ET DE COMMERCE | B92: CONSORTIUM SENEGALAISE D' INDUSTRIE ET DE COMMERCE
A93: CONSTRUCTION GESTION INNOVATION IMMOBILIERE | B93: CONSTRUCTION GESTION INNOVATION IMMOBILIERE
A94: CSE GRANULATS SA | B94: CSE GRANULATS SA
A95: DAME DIAKHATE | B95: DAME DIAKHATE
A96: DAMOUNGHAYE SUARL | B96: DAMOUNGHAYE SUARL
A97: DANGOTE CEMENT SENEGAL SA | B97: DANGOTE CEMENT SENEGAL SA
A98: DANGOTE INDUSTRIES SENEGAL SA | B98: DANGOTE INDUSTRIES SENEGAL SA
...
