Workbook
Name \a: #N/A
Name \Convergence: 1000000
Name \i: #REF!
Name \IterationCount: 0
Name \PM: #REF!
Name \r: #REF!
Name \W: #REF!
Name \WorstStream: " "
Name _____________Inv27: #REF!
Name ____________Inv27: #REF!
Name ___________Inv27: #REF!
Name __________Inv27: #REF!
Name _________Inv27: #REF!
Name ________ABN1: #REF!
Name ________ADN1: #REF!
Name ________AIN1: #REF!
Name ________AJN1: #REF!
Name ________AZN1: #REF!
Name ________BCN1: #REF!
Name ________BDN1: #REF!
Name ________BEN1: #REF!
Name ________BFN1: #REF!
Name ________BHN1: #REF!
Name ________BIN1: #REF!
Name ________BJN1: #REF!
Name ________BKN1: #REF!
Name ________BSN1: #REF!
Name ________BUN1: #REF!
Name ________DAN1: #REF!
Name ________DCN1: #REF!
Name ________DGN1: #REF!
Name ________DIN1: #REF!
Name ________DJN1: #REF!
Name ________DKN1: #REF!
Name ________DLN1: #REF!
Name ________DMN1: #REF!
Name ________DNN1: #REF!
Name ________DPN1: #REF!
Name ________DTN1: #REF!
Name ________DVN1: #REF!
Name ________Inv27: #REF!
Name ________SAN1: #REF!
Name ________SCN1: #REF!
Name ________SLN1: #REF!
Name ________SQN1: #REF!
Name ________SRN1: #REF!
Name ________TFN1: #REF!
Name ________TQN1: #REF!
Name ________TTN1: #REF!
Name ________UAN1: #REF!
Name ________UCN1: #REF!
Name ________UEN1: #REF!
Name ________ULN1: #REF!
Name ________UNN1: #REF!
Name _______ABN1: #REF!
Name _______ADN1: #REF!
Name _______AIN1: #REF!
Name _______AJN1: #REF!
Name _______AZN1: #REF!
Name _______BCN1: #REF!

Sheet Page de garde
A1: DA
B5: REPUBLIQUE | I5: DU SENEGAL
B7: MINISTERE | I7: DES FINANCES ET DU BUDGET
B9: DIRECTION | I9: DIRECTION GENERALE DES IMPÔTS ET DES DOMAINES
B17: CENTRE DE DEPOT : Direction des Grandes Entreprises
A23: ETATS FINANCIERS NORMALISES
A24: SYSTÈME COMPTABLE (SYSCOHADA)
B27: EXERCICE CLOS LE : | M27: 45657
A30: DESIGNATION DE L'ENTREPRISE
C35: DENOMINATION SOCIALE : | L35: Sabodala Gold Operations S.A
C36: (ou nom et prénoms de l'exploitant)
C41: SIGLE USUEL : | H41: SGO
C46: ADRESSE COMPLETE : | J46: Route du Méridien Président, Immeuble 2k Plaza
C51: N° D'IDENTIFICATION FISCALE : | N51: 002850023
C55: SYSTEME NORMAL
C59: Documents déposés | V59: Réservé à la Direction Générale des Impôts
C62: Fiche d'identification et renseignements divers | S62: X | V62: Date de dépôt
C64: Bilan | S64: X
C66: Compte de résultat | S66: X | V66: Nom de l'agent de DGI ayant réceptionné le dépôt
C68: Tableau des flux de trésorerie | S68: X
C70: Notes annexes | S70: X | V70: Signature de l'agent et cachet du service
C72: Nombre de pages déposées par exemplaire
C73: Nombre d'exemplaires déposés | R73: 5

Sheet Fiche de renseignement R1
A1: Fiche R1
I4: Dénomination sociale de l’entreprise | J4: =+'Page de garde'!L35 -> Sabodala Gold Operations S.A
I7: Adresse de l'entreprise | J7: ='Page de garde'!J46 -> Route du Méridien Président, Immeuble 2k Plaza | AC7: Sigle usuel | AD7: =+'Page de garde'!H41 -> SGO
I10: N° d'identification fiscale | J10: ='Page de garde'!N51 -> 002850023 | U10: Exercice clos le | V10: =+'Page de garde'!M27 -> 45657 | AG10: Durée (en mois) | AH10: 12
B13: ZA | E13: EXERCICE COMPTABLE | W13: DU | Y13: 45292 | AF13: AU | AH13: 45657
B16: ZB | E16: DATE D'ARRETE EFFECTIF DES COMPTES | U16: =+V10 -> 45657
B20: ZC | E20: EXERCICE PRECEDENT CLOS LE | Q20: 45657 | AK20: DUREE EXERCICE PRECEDENT EN MOIS : | AL20: 12
B24: ZD | F24: SN | I24: SNDKR-2008-B1711 | W24: 002850023
F25: Greffe | I25: N° registre du Commerce | W25: N° répertoire des entreprises
B28: ZE | G28: 20950 | S28: 28457 | AE28: 006 002 Extraction d’autres
G29: N° de caisse sociale | S29: N° Code employeur | AE29: Code activité principale
B32: ZF | D32: =+J4 -> Sabodala Gold Operations S.A | AE32: =+AD7 -> SGO
D33: Désignation de l'entreprise | AE33: Sigle
B36: ZG | G36: 33 864 25 25 | Q36: 33 864 25 26 | Y36: 221 | AA36: 38385 Dakar Yoff | AE36: Dakar
G37: N° de téléphone | Q37: Télécopie | Y37: Code | AA37: Boîte postale | AE37: Ville
B40: ZH | D40: Route du Méridien Pdt - Immeuble 2K Plaza
D41: Adresse géographique complète (Immeuble, rue, quartier, ville, pays)
B44: ZI | D44: Industries extractives
D45: Désignation précise de l'activité principale exercée par l'entreprise
D48: Malick SOURANG - Responsable Financier
D49: Nom, adresse et qualité de personne à contacter en cas de demande d'informations complémentaires
D52: Malick SOURANG - Responsable Financier
D53: Nom du professionnel salarié de l'entreprise ou Nom, adresse et téléphone du cabinet comptable ou du professionnel INSCRIT A L'ORDRE NATIONAL DES EXPERTS COMPTABLES ET DES COMPTABLES AGREES ayant établi les états financiers.
D56: ERSNT & YOUNG - Commissaire aux comptes
D57: Noms et adresses du ou des commissaires au comptes
E64: Non assujettie | K64: Non (refus) | O64: Oui avec réserves | S64: X | T64: Oui sans réserves | Z64: Non assujettie | AF64: X | AG64: Non | AL64: Oui
C66: Etats financiers certifiés (cocher la case) | X66: Etats financiers approuvés par l'Assemblée Générale (cocher la case)
D69: Abdoul Aziz SY | T69: Domiciliations bancaires
D70: Nom du signataire des états financiers | T70: Banque | AD70: Numéro de compte
T71: SG PARIS CC USD | AD71: FR7630003033920302029993378
D72: Directeur Général | T72: SG PARIS CC EUR | AD72: FR7630003033920302029993378
D73: Qualité du signataire des états financiers | T73: SGBS DAKAR | AD73: SN011 01005 005001566924 66
T74: BICIS DAKAR | AD74: SN010 01528 000581200010 85
D75: 45777 | T75: CBAO DAKAR | AD75: SN012 01203 036184218501 85
D76: Date de signature | T76: CITIBANK | AD76: SN141 01001 000100180001 35
T77: SGBS DAKAR | AD77: SN011 01005 005000578086 29
T78: CITIBANK | AD78: SN141 01001 000100180025 60
T79: CITIBANK | AD79: SN141 01001 000100189001 01
D83: Signature

Sheet Activités de l'entreprise R2
A1: Fiche R2
B4: Désignation de l'entreprise : | C4: ='Fiche de renseignement R1'!$J$4 -> Sabodala Gold Operations S.A
B5: Adresse de l'entreprise :
B6: ='Fiche de renseignement R1'!J7 -> Route du Méridien Président, Immeuble 2k Plaza | L6: Sigle usuel : | M6: ='Fiche de renseignement R1'!AD7 -> SGO
B7: N° d'identification : | L7: Exercice clos le :
B8: =+'Fiche de renseignement R1'!J10 -> 002850023 | K8: ='Fiche de renseignement R1'!V10 -> 45657 | M8: Durée (en mois) | N8: ='Fiche de renseignement R1'!AH10 -> 12
A10: FICHE D'IDENTIFICATION ET RENSEIGNEMENTS DIVERS 2
L12: Contrôle de l'entreprise (cocher la case)
A14: ZK | B14: Forme juridique (1) | F14: 0 | G14: 1 | K14: ZQ | L14: Entreprise sous contrôle public
A16: ZL | B16: Régime fiscal (1) | F16: 1 | K16: ZR | L16: Entreprise sous contrôle privé national
A18: ZM | B18: Pays du siège social (1) | F18: 0 | G18: 7 | K18: ZS | L18: Entreprise sous contrôle privé étranger | Q18: X
A20: ZN | B20: Nbre d'établissements dans le pays | F20: 0 | G20: 1
A22: ZO | B22: Nbre d'établissements hors du pays | F22: 0 | G22: 0
B23: pour lesquels une comptabilité distincte est tenue
A25: ZP | B25: 1ère année exercice dans le pays | E25: 2 | F25: 0 | G25: 0 | H25: 8
A28: ACTIVITE DE L'ENTREPRISE
B30: DESIGNATION DE L'ACTIVITE (2) | C30: Code nomenclature d'activité (1) | K30: Valeur Ajoutée (VA) HT | M30: % activité dans le CA HT ou la VA
B33: Exploitation minière | F33: 6 | G33: 0 | H33: 0 | I33: 2 | L33: 3.3716269e+11 | M33: 1
M36: =+L36/$L$59 -> 0
M39: =+L39/$L$59 -> 0
M42: =+L42/$L$59 -> 0
M45: =+L45/$L$59 -> 0
M48: =+L48/$L$59 -> 0
M51: =+L51/$L$59 -> 0
M54: =+L54/$L$59 -> 0
B57: Divers
I59: TOTAL | L59: =SUM(L32:L56) -> 3.3716269e+11 | M59: =SUM(M32:M57) -> 1
B62: (1) Se réréfer aux tables des codes
B63: (2) Lister de manière précise les activités dans l'ordre décroissant du CAHT, ou de la valeur ajoutée (V.A.)
B64: (3) Rayer la mention inutile (utiliser de préférence la V.A.)

Sheet Dirigeants R3
A1: Fiche R3
A3: Désignation de l'entreprise | B3: ='Fiche de renseignement R1'!$J$4 -> Sabodala Gold Operations S.A
A4: Adresse de l'entreprise | B4: ='Activités de l''entreprise R2'!B6 -> Route du Méridien Président, Immeuble 2k Plaza | D4: Sigle usuel | E4: ='Activités de l''entreprise R2'!M6 -> SGO
A5: N° d'identification fiscale | B5: ='Activités de l''entreprise R2'!B8 -> 002850023 | C5: Exercice clos le | D5: ='Activités de l''entreprise R2'!K8 -> 45657 | E5: Durée (en mois) | F5: ='Activités de l''entreprise R2'!N8 -> 12
A7: FICHE D'IDENTIFICATION ET RENSEIGNEMENTS DIVERS 3
A9: DIRIGEANTS (1)
A11: Nom | B11: Prénoms | C11: Qualité | D11: N° d'identification fiscale | E11: Adressse (BP, ville, pays)
A12: SY | B12: ABDOUL AZIZ | C12: Directeur Général | E12: Dakar - Sénégal
A27: (1) Dirigeants = Président Directeur Général, Directeur Général, Adminsitrateur Général, Gérant, Autres.
A29: MEMBRES DU CONSEIL D'ADMINISTRATION
A31: Nom | B31: Prénoms | C31: Qualité | E31: Adressse (BP, ville, pays)
A32: Sabodala Gold Mauritius Limited représentée par : Abdoul Aziz SY | C32: Administrateur | E32: 6 CIO Kross Border Trust Services Limited St Louis Business Centre, Cnr Desroches & S. Louis Streets, Port Louis, Ile Maurice
A33: Etat du Sénégal représenté par Monsieur Moctar Kettani DOUCOURE | C33: Administrateur | E33: s/c Ministère des Finances et du Budget, Dakar, Sénégal
A34: TOURE | B34: Elhadj Ngagne Demba | C34: Administrateur | E34: s/c de la Société des Mines du Sénégal
A35: GASSAMA | B35: IBRAHIMA | C35: Administrateur | E35: s/c Ministère des Mines et de la Géologie - Pôle Urbain de Diamniadio, Dakar, Sénégal
A36: NDIAYE | B36: Mamadou Diagna | C36: Administrateur | E36: Immeuble Atlantis, Plateau, Dakar, Sénégal
A37: SY | B37: Abdoul Aziz | C37: Administrateur | E37: Villa AD34, Sicap Keur Gorgui, BP 25670, Dakar, Sénégal
A38: BERNASCONI | B38: Pascal | C38: Administrateur, Président du CA | E38: Abidjan, Côte d'Ivoire
A39: MANJENGWA | B39: Lawrence | C39: Administrateur | E39: Zimbabwé
A40: KOFFI | B40: Céline Aka | C40: Administrateur | E40: Cote d'Ivoire
A41: MBODJI | B41: Ibrahima | C41: Administrateur | E41: Dakar - Sénégal
A42: SANFO | B42: Zakaria | C42: Administrateur | E42: Dakar - Sénégal

Sheet Tableau des Notes R4
A1: FICHE R4
A2: Désignation entité : | B2: =+'Fiche de renseignement R1'!$J$4 -> Sabodala Gold Operations S.A | D2: Excercice clos le : | E2: =+'Fiche de renseignement R1'!$V$10 -> 45657
D3: Durée en mois : | E3: =+'Fiche de renseignement R1'!$AH$10 -> 12
A4: Numéro d'identification : | B4: =+'Fiche de renseignement R1'!$J$10 -> 002850023
A6: FICHE RECAPITULATIVE DES NOTES ANNEXES PRESENTEES
A8: NOTES | B8: INTITULES | C8: A | D8: N/A
A9: NOTE 1 | B9: DETTES GARANTIES PAR DES SURETES REELLES | C9: x
A10: NOTE 2 | B10: INFORMATIONS OBLIGATOIRES | C10: x
A11: NOTE 3A | B11: IMMOBILISATION BRUTE | C11: x
A12: NOTE 3B | B12: BIENS PRIS EN LOCATION ACQUISITION | C12: x
A13: NOTE 3C | B13: IMMOBILISATIONS : AMORTISSEMENTS | C13: x
A14: NOTE 3D | B14: IMMOBILISATIONS : PLUS-VALUES ET MOINS VALUES DE CESSION | C14: x
A15: NOTE 3E | B15: INFORMATIONS SUR LES REEVALUATIONS EFFECTUEES PAR L'ENTITE | D15: x
A16: NOTE 3F | B16: TABLEAU D'ETALEMENT DES CHARGES IMMOBILISEES | D16: x
A17: NOTE 4 | B17: IMMOBILISATIONS FINANCIERES | C17: x
A18: NOTE 5 | B18: ACTIF CIRCULANT HAO | D18: x
A19: NOTE 6 | B19: STOCKS ET ENCOURS | C19: x
A20: NOTE 7 | B20: CLIENTS PRODUITS A RECEVOIR | C20: x
A21: NOTE 8 | B21: AUTRES CREANCES | C21: x
A22: NOTE 9 | B22: TITRES DE PLACEMENT | D22: x
A23: NOTE 10 | B23: VALEURS A ENCAISSER | C23: x
A24: NOTE 11 | B24: DISPONIBILITES | C24: x
A25: NOTE 12 | B25: ECARTS DE CONVERSION | C25: x
A26: NOTE 13 | B26: CAPITAL : VALEUR NOMINALE DES ACTIONS OU PARTS | C26: x
A27: NOTE 14 | B27: PRIMES ET RESERVES | C27: x
A28: NOTE 15A | B28: SUBVENTIONS ET PROVISIONS REGLEMENTEES | D28: x
A29: NOTE 15B | B29: AUTRES FONDS PROPRES | D29: x
A30: NOTE 16A | B30: DETTES FINANCIERES ET RESSOURCES ASSIMILEES | C30: x
A31: NOTE 16B | B31: ENGAGEMENTS DE RETRAITE ET AVANTAGES ASSIMILES (METHODE ACTURIELLE) | D31: x
A32: NOTE 16B bis | B32: ENGAGEMENTS DE RETRAITE ET AVANTAGES ASSIMILES (METHODE ACTURIELLE) | D32: x
A33: NOTE 16C | B33: ACTIFS ET PASSIFS EVENTUELS | D33: x
A34: NOTE 17 | B34: FOURNISSEURS D'EXPLOITATION | C34: x
A35: NOTE 18 | B35: DETTES FISCALES ET SOCIALES | C35: x
A36: NOTE 19 | B36: AUTRES DETTES ET PROVISIONS POUR RISQUES A COURT TERME | C36: x
A37: NOTE 20 | B37: BANQUES, CREDIT D'ESCOMPTE ET TRESORERIE | C37: x
A38: NOTE 21 | B38: CHIFFRE D'AFFAIRES ET AUTRES PRODUITS | C38: x
A39: NOTE 22 | B39: ACHATS | C39: x
A40: NOTE 23 | B40: TRANSPORTS | C40: x
A41: NOTE 24 | B41: SERVICES EXTERIEURS | C41: x
A42: NOTE 25 | B42: IMPOTS ET TAXES | C42: x
...

Sheet BILAN PAYSAGE
A1: BILAN PAYSAGE
A3: Désignation entité : | D3: =+'Tableau des Notes R4'!B2 -> Sabodala Gold Operations S.A | I3: Excercice clos le : | J3: =+'Fiche de renseignement R1'!$V$10 -> 45657
I4: Durée en mois : | J4: =+'Fiche de renseignement R1'!$AH$10 -> 12
A5: Numéro d'identification : | D5: =+'Fiche de renseignement R1'!$J$10 -> 002850023
A7: REF | B7: ACTIF | C7: Note | E7: Exercice au 31/12/N | G7: Exercice au 31/12/N-1 | H7: REF | I7: PASSIF | J7: Note | K7: Exercice au 31/12/N | L7: Exercice au 31/12/N-1
D8: Brut | E8: Amorts et Dépréc. | F8: Net | G8: Net | K8: Net | L8: Net
A9: AD | B9: IMMOBILISATIONS INCORPORELLES | C9: 3 | D9: 5.948758e+11 | E9: 3.4595603e+11 | F9: 2.4891977e+11 | G9: 2.8127399e+11 | H9: CA | I9: CAPITAL | J9: 13 | K9: 10500000 | L9: 10500000
A10: AE | B10: Frais de développement et de prospection | D10: 5.5825964e+11 | E10: 3.4391615e+11 | F10: 2.1434349e+11 | G10: 2.5711648e+11 | H10: CB | I10: Apporteurs capital non appelé | J10: 13 | K10: 0 | L10: 0
A11: AF | B11: Brevets, licences, logiciels et droits similaires | D11: 2.1875373e+09 | E11: 2.0398808e+09 | F11: 1.4765655e+08 | G11: 1.7882297e+08 | H11: CD | I11: Primes liées au capital social | J11: 14 | K11: 50704413696 | L11: 50704413696
A12: AG | B12: Fonds commercial et droit au bail | D12: 0 | E12: 0 | F12: 0 | G12: 0 | H12: CE | I12: Ecarts de réévaluation | J12: 3e | K12: 0 | L12: 0
A13: AH | B13: Autres immobilisations incorporelles | D13: 3.4428619e+10 | E13: 0 | F13: 3.4428619e+10 | G13: 2.397869e+10 | H13: CF | I13: Réserves indisponibles | J13: 14 | K13: 2100000 | L13: 2000000
A14: AI | B14: IMMOBILISATIONS CORPORELLES | C14: 3 | D14: 5.1222627e+11 | E14: 2.1067302e+11 | F14: 3.0155326e+11 | G14: 2.4705803e+11 | H14: CG | I14: Réserves libres | J14: 14 | K14: 0 | L14: 0
A15: AJ | B15: Terrains (1) (1) dont placement en net ………../………… | D15: 0 | E15: 0 | F15: 0 | H15: CH | I15: Report à nouveau (+ ou -) | J15: 14 | K15: 4.2060701e+11 | L15: 348511721438
A16: AK | B16: Bâtiments (1) dont placement en net ………../………… | D16: 4.5086893e+10 | E16: 2.5813226e+10 | F16: 1.9273667e+10 | G16: 1.3954137e+10 | H16: CJ | I16: Résutat net de l'exercice (bénéfice + ou perte -) | K16: 57851662541 | L16: 1.3709634e+11
A17: AL | B17: Aménagements, agencements et installations | D17: 3.1715697e+11 | E17: 1.2433049e+11 | F17: 1.9282648e+11 | G17: 1.859635e+11 | H17: CL | I17: Subventions d'investissement | J17: 15 | K17: 0 | L17: 0
A18: AM | B18: Matériel, mobilier et actifs biologiques | D18: 1.4333245e+11 | E18: 5.5154109e+10 | F18: 8.8178344e+10 | G18: 3.5474848e+10 | H18: CM | I18: Provisions réglementées et fonds assimilés | J18: 15 | K18: 0 | L18: 0
A19: AN | B19: Matériel de transport | D19: 6.3593049e+09 | E19: 5.3751946e+09 | F19: 9.8411035e+08 | G19: 1.3637898e+09 | H19: CP | I19: TOTAL CAPITAUX PROPRES ET RESSOURCES ASSIMILEES | K19: 5.2917569e+11 | L19: 5.3632498e+11
A20: AP | B20: Avances & acomptes versés sur immobilisations | C20: 3 | D20: 2.9065658e+08 | E20: 0 | F20: 2.9065658e+08 | G20: 1.0301753e+10 | H20: DA | I20: Emprunts et dettes financières diverses | J20: 16 | K20: 4.1732566e+10 | L20: 3.9946905e+10
A21: AQ | B21: IMMOBILISATIONS FINANCIERES | C21: 4 | D21: 407226428 | E21: 0 | F21: 407226428 | G21: 431226428 | H21: DB | I21: Dettes de location acquisition | J21: 16 | K21: 6.0241819e+08 | L21: 5.6499704e+08
A22: AR | B22: Titres de participation | D22: 0 | E22: 0 | F22: 0 | G22: 0 | H22: DC | I22: Provisions pour risques et charges | J22: 16 | K22: 3.7765366e+10 | L22: 3.3349151e+10
A23: AS | B23: Autres immobilisations financières | D23: 407226428 | E23: 0 | F23: 407226428 | G23: 431226428 | H23: DD | I23: TOTAL DETTES FINANCIERES ET RESSOURCES ASSIMILEES | K23: 8.010035e+10 | L23: 7.3861053e+10
A24: AZ | B24: TOTAL ACTIF IMMOBILISE | D24: 1.1075093e+12 | E24: 5.5662905e+11 | F24: 5.5088025e+11 | G24: 5.2876325e+11 | H24: DF | I24: TOTAL RESSOURCES STABLES | K24: 6.0927604e+11 | L24: 6.1018603e+11
A25: BA | B25: ACTIF CIRCULANT H.A.O. | C25: 5 | D25: 0 | E25: 0 | F25: 0 | G25: 0 | H25: DH | I25: Dettes circulantes HAO | J25: 5 | K25: 0 | L25: 0
A26: BB | B26: STOCKS ET ENCOURS | C26: 6 | D26: 1.5771953e+11 | E26: 9.6629245e+09 | F26: 1.4805661e+11 | G26: 1.1986613e+11 | H26: DI | I26: Clients, avances reçues | J26: 7 | K26: 0 | L26: 0
A27: BG | B27: CREANCES ET EMPLOIS ASSIMILES | D27: 4.6729739e+10 | E27: 0 | F27: 4.6729739e+10 | G27: 6.639748e+10 | H27: DJ | I27: Fournisseurs d'exploitation | J27: 17 | K27: 4.5625346e+10 | L27: 4.4185646e+10
A28: BH | B28: Fournisseurs, avances versées | C28: 17 | D28: 3.6960548e+09 | E28: 0 | F28: 3.6960548e+09 | G28: 4.5610626e+09 | H28: DK | I28: Dettes fiscales et sociales | J28: 18 | K28: 3.8694253e+10 | L28: 7.2919235e+10
A29: BI | B29: Clients | C29: 7 | D29: 2.2384217e+08 | E29: 0 | F29: 2.2384217e+08 | G29: 4.4494604e+09 | H29: DM | I29: Autres dettes | J29: 19 | K29: 6.8376294e+10 | L29: 4.3101673e+10
A30: BJ | B30: Autres créances | C30: 8 | D30: 4.2809842e+10 | E30: 0 | F30: 4.2809842e+10 | G30: 5.7386957e+10 | H30: DN | I30: Provisions pour risques à court terme | J30: 19 | K30: 4.9123551e+09 | L30: 3.5306801e+09
A31: BK | B31: TOTAL ACTIF CIRCULANT | D31: 2.0444927e+11 | E31: 9.6629245e+09 | F31: 1.9478635e+11 | G31: 1.8626361e+11 | H31: DP | I31: TOTAL PASSIF CIRCULANT | K31: 1.5760825e+11 | L31: 1.6373723e+11
A32: BQ | B32: Titres de placement | C32: 9 | D32: 0 | E32: 0 | F32: 0 | G32: 0 | K32: 0 | L32: 0
A33: BR | B33: Valeurs à encaisser | C33: 10 | D33: 1729831521 | E33: 0 | F33: 1729831521 | G33: 945599580 | H33: DQ | I33: Banques, crédits d'escompte | J33: 20 | K33: 0 | L33: 0
A34: BS | B34: Banques, chèques postaux, caisse et assimilés | C34: 11 | D34: 1.9217116e+10 | E34: 0 | F34: 1.9217116e+10 | G34: 5.4227066e+10 | H34: DR | I34: Banques, établissements financiers et crédits de trésorerie | J34: 20 | K34: 8000000000 | L34: 154577
A35: BT | B35: TOTAL TRESORERIE - ACTIF | D35: 2.0946947e+10 | E35: 0 | F35: 2.0946947e+10 | G35: 5.5172666e+10 | H35: DT | I35: TOTAL TRESORERIE - PASSIF | K35: 8000000000 | L35: 154577
A36: BU | B36: Ecarts de conversion - Actif | C36: 12 | D36: 8.2707414e+09 | E36: 0 | F36: 8.2707414e+09 | G36: 4.6132099e+09 | H36: DV | I36: Ecarts de conversion - Passif | J36: 12 | K36: 0 | L36: 8.8931858e+08
A37: BZ | B37: TOTAL GENERAL | D37: 1.3411763e+12 | E37: 5.6629197e+11 | F37: 774884286268 | G37: 7.7481274e+11 | H37: DZ | I37: TOTAL GENERAL | K37: 774884286268 | L37: 7.7481274e+11

Sheet COMPTE DE RESULTAT
A1: COMPTE DE RESULTAT
A3: Désignation entité :Sabodala Gold Operations S.A | D3: Excercice clos le : | E3: =+'Fiche de renseignement R1'!$V$10 -> 45657
D4: Durée en mois : | E4: =+'Fiche de renseignement R1'!$AH$10 -> 12
A5: Numéro d'identification : | B5: =+'Fiche de renseignement R1'!$J$10 -> 002850023
A7: REF | B7: LIBELLES | D7: NOTE | E7: 31/12/N | F7: 31/12/N-1
A8: TA | B8: Ventes de marchandises A | C8: + | D8: 21 | E8: 0 | F8: 0
A9: RA | B9: Achats de marchandises | C9: - | D9: 22 | E9: 0 | F9: 0
A10: RB | B10: Variation de stocks de marchandises | C10: -/+ | D10: 6 | E10: 0 | F10: 0
A11: XA | B11: MARGE BRUTE SUR MARCHANDISES (somme TA à RB) | E11: 0 | F11: 0
A12: TB | B12: Ventes de produits fabriqués B | C12: + | D12: 21 | E12: 3.3716269e+11 | F12: 3.5407533e+11
A13: TC | B13: Travaux, services vendus C | C13: + | D13: 21 | E13: 0 | F13: 0
A14: TD | B14: Produits accessoires D | C14: + | D14: 21 | E14: 0 | F14: 0
A15: XB | B15: CHIFFRE D'AFFAIRES (A + B + C + D) | E15: 337162693235 | F15: 3.5407533e+11
A16: TE | B16: Production stockée (ou destockage) | C16: -/+ | D16: 6 | E16: 1.7407545e+10 | F16: 2.6055476e+10
A17: TF | B17: Production immobilisée | D17: 21 | E17: 0 | F17: 0
A18: TG | B18: Subventions d'exploitation | D18: 21 | E18: 0 | F18: 0
A19: TH | B19: Autres produits | C19: + | D19: 21 | E19: 9.7362148e+09 | F19: 2.444924e+10
A20: TI | B20: Transferts de charges d'exploitation | C20: + | D20: 12 | E20: 2.0101757e+10 | F20: 2.0280953e+10
A21: RC | B21: Achats de matières premières et fournitures liées | C21: - | D21: 22 | E21: 0 | F21: 0
A22: RD | B22: Variation de stocks de stocks de matières premières et fournitures liées | C22: -/+ | D22: 6 | E22: 0 | F22: 0
A23: RE | B23: Autres achats | C23: - | D23: 22 | E23: -9.8270284e+10 | F23: -7.136424e+10
A24: RF | B24: Variation de stocks d'autres approvisionnements | C24: -/+ | D24: 6 | E24: 1.0999104e+10 | F24: 1.2174809e+09
A25: RG | B25: Transports | C25: - | D25: 23 | E25: -2.5246668e+09 | F25: -1.8888878e+09
A26: RH | B26: Services extérieurs | C26: - | D26: 24 | E26: -2.8766951e+10 | F26: -2.5755498e+10
A27: RI | B27: Impôts et taxes | C27: - | D27: 25 | E27: -2.315184e+10 | F27: -44009458558
A28: RJ | B28: Autres charges | C28: - | D28: 26 | E28: -1.1879175e+10 | F28: -1.1186585e+10
A29: XC | B29: VALEUR AJOUTEE (XB + RA + RB) + (somme TE à RJ) | E29: 2.308144e+11 | F29: 2.7187381e+11
A30: RK | B30: Charges de personnel | C30: - | D30: 27 | E30: -5.1202887e+10 | F30: -3.6700823e+10
A31: XD | B31: EXCEDENT BRUT D'EXPLOITATION (XC + RK) | E31: 1.7961151e+11 | F31: 2.3517299e+11
A32: TJ | B32: Reprises d'amortissements, provisions et dépréciations | C32: + | D32: 28 | E32: 1.7207649e+09 | F32: 1.0232607e+09
A33: RL | B33: Dotations aux amortissements, aux provisions et dépréciations | C33: - | D33: 3C & 28 | E33: -9.7413143e+10 | F33: -6.1139751e+10
A34: XE | B34: RESULTAT D'EXPLOITATION (XD + TJ + RL) | E34: 8.3919133e+10 | F34: 1.750565e+11
A35: TK | B35: Revenus financiers et assimilés | C35: + | D35: 29 | E35: 0 | F35: 0
A36: TL | B36: Reprises de provisions et dépréciations financières | C36: + | D36: 28 | E36: 3.5406524e+09 | F36: 1.3394153e+10
A37: TM | B37: Tranferts de charges financières | C37: + | D37: 12 | E37: 0 | F37: 0
A38: RM | B38: Frais financiers et charges assimilées | C38: - | D38: 29 | E38: -3.4265364e+09 | F38: -1.5562051e+09
A39: RN | B39: Dotations aux provisions et aux dépréciations financières | C39: - | D39: 3C & 28 | E39: -4.5016509e+09 | F39: -1.6223677e+09
A40: XF | B40: RESULTAT FINANCIER (somme TK à RN) | E40: -4.3875349e+09 | F40: 1.021558e+10
A41: XG | B41: RESULTAT DES ACTIVITES ORDINAIRES (XE + XF) | E41: 7.9531598e+10 | F41: 1.8527208e+11
A42: TN | B42: Produits des cessions d'immobilisations | C42: + | D42: 3D | E42: 0 | F42: 0
...

Sheet FLUX DE TRESORERIE
A1: FLUX DE TRESORERIE
A3: Désignation entité :Sabodala Gold Operations S.A | D3: Excercice clos le : | E3: =+'Fiche de renseignement R1'!$V$10 -> 45657
D4: Durée en mois : | E4: =+'Fiche de renseignement R1'!$AH$10 -> 12
A5: Numéro d'identification : | B5: =+'Fiche de renseignement R1'!$J$10 -> 002850023
A7: REF | B7: LIBELLES | D7: NOTE | E7: 31/12/N | F7: 31/12/N-1
A8: ZA | B8: Trésorerie nette au 1er janvier (Trésorerie actif N-1 - Trésorerie passif N-1) | C8: A | E8: 5.5172511e+10 | F8: 5.7322902e+10
B9: Flux de trésorerie provenant des activités opérationnelles
A10: FA | B10: Capacité d'Autofinancement Globale (CAFG) | E10: 1.5538605e+11 | F10: 1.8583984e+11
A11: FB | B11: - Variation d'actif circulant HAO (1) | E11: 0 | F11: 0
A12: FC | B12: - Variation des stocks | E12: -2.8190477e+10 | F12: -2.4811423e+10
A13: FD | B13: - Variation des créances | E13: 1.9667741e+10 | F13: -1.9999458e+10
A14: FE | B14: + Variation du passif circulant (1) | E14: -2.8515051e+10 | F14: -1.1381167e+09
B15: Variation du BF lié aux activités opérationnelles (FB + FC + FD + FE) : …………………………………………….. | E15: =SUM(E11:E14) -> -3.7037787e+10 | F15: -4.5948998e+10
A16: ZB | B16: Flux de trésorerie provenant des activités opérationnelles (somme FA à FE) | C16: B | E16: 1.1834827e+11 | F16: 1.3989084e+11
B17: Flux de trésorerie provenant des activités d'investissement
A18: FF | B18: - Décaissements liés aux acquisitions d'immobilisations incorporelles | E18: -3.3600447e+10 | F18: -4.4383364e+10
A19: FG | B19: - Décaissements liés aux acquisitions d'immobilisations corporelles | E19: -8.1927164e+10 | F19: -1.1158633e+11
A20: FH | B20: - Décaissements liés aux acquisitions d'immobilisations financières | E20: 0 | F20: -53831204
A21: FI | B21: + Encaissements liés aux cessions d'immobilisations incorporelles et corporelles | E21: 0 | F21: 0
A22: FJ | B22: + Encaissements liés aux cessions d'immobilisations financières | E22: 24000000 | F22: 0
A23: ZC | B23: Flux de trésorerie provenant des activités d'investissement (somme FF à FJ) | C23: C | E23: -1.1550361e+11 | F23: -1.5602352e+11
B24: Flux de trésorerie provenant du financement par les capitaux propres
A25: FK | B25: + Augmentations de capital par apports nouveaux | E25: 0
A26: FL | B26: + Subventions d'investissements reçues | E26: 0 | F26: 0
A27: FM | B27: - Prélèvements sur le capital | E27: 0 | F27: 0
A28: FN | B28: - Dividendes versés | E28: -44387621281 | F28: -2.6462868e+10
A29: ZD | B29: Flux de trésorerie provenant des capitaux propres (somme FK à FN) | C29: D | E29: -44387621281 | F29: -2.6462868e+10
B30: Flux de trésorerie provenant du financement par les capitaux étrangers
A31: FO | B31: + Emprunts | E31: 0 | F31: 4.0445163e+10
A32: FP | B32: + Autres dettes financières | E32: 2.4174025e+09 | F32: 0
A33: FQ | B33: - Remboursements des emprunts et autres dettes financières | E33: -3100000000
A34: ZE | B34: Flux de trésorerie provenant des capitaux étrangers (somme FO à FQ) | C34: E | E34: -6.8259753e+08 | F34: 4.0445163e+10
A35: ZF | B35: Flux de trésorerie provenant des activités de financement (D + E) | C35: F | E35: -4.5070219e+10 | F35: 1.3982295e+10
A36: ZG | B36: VARIATION DE LA TRESORERIE NETTE DE LA PERIODE (B + C + F) | C36: G | E36: -4.2225564e+10 | F36: -2.1503907e+09
A37: ZH | B37: Trésorerie nette au 31 décembre (G + A) Contrôle : Trésorerie actif N - Trésorerie passif N | C37: H | E37: 1.2946947e+10 | F37: 5.5172511e+10
B38: Contrôle

Sheet Note 1
A1: NOTE 1 : DETTES GARANTIES PAR DES SURETES REELLES
A3: Désignation entité : | D3: Excercice clos le : | E3: =+'Fiche de renseignement R1'!$V$10 -> 45657
A4: =+'Fiche de renseignement R1'!$J$4 -> Sabodala Gold Operations S.A | D4: Durée en mois : | E4: =+'Fiche de renseignement R1'!$AH$10 -> 12
A5: Numéro d'identification : | B5: =+'Fiche de renseignement R1'!$J$10 -> 002850023
A7: LIBELLES | B7: Note | C7: Montant brut | D7: SURETES REELLES
D8: Hypothèques | E8: Nantissements | F8: Gages
F9: Autres
A10: Dettes financières et ressources assimilées :
A11: Emprunts obligataires convertibles
A12: Autres emprunts obligataires
A13: Emprunts et dettes des établissements de crédit
A14: Autres dettes financières
A15: SOUS TOTAL (1) | C15: =SUM(C11:C14) -> 0 | D15: =SUM(D11:D14) -> 0 | E15: =SUM(E11:E14) -> 0 | F15: =SUM(F11:F14) -> 0
A17: Dettes de location-acquisition :
A18: Dettes de crédit-bail immobilier
A19: Dettes de crédit-bail mobilier
A20: Dettes sur contrats de location-vente
A21: Dettes sur contrats de location-acquisition
A22: SOUS TOTAL (2) | C22: =SUM(C18:C21) -> 0 | D22: =SUM(D18:D21) -> 0 | E22: =SUM(E18:E21) -> 0 | F22: =SUM(F18:F21) -> 0
A24: Dettes du passif circulant :
A25: Fournisseurs et comptes rattachés
A26: Clients
A27: Personnel
A28: Sécurité sociale et organismes sociaux
A29: Etat
A30: Organismes internationaux
A31: Associés et groupe
A32: Créditeurs divers
A33: SOUS TOTAL (3) | C33: =SUM(C25:C32) -> 0 | D33: =SUM(D25:D32) -> 0 | E33: =SUM(E25:E32) -> 0 | F33: =SUM(F25:F32) -> 0
A34: TOTAL (1) + (2) + (3) | C34: =+C15+C22+C33 -> 0 | D34: =+D15+D22+D33 -> 0 | E34: =+E15+E22+E33 -> 0 | F34: =+F15+F22+F33 -> 0
A35: ENGAGEMENTS FINANCIERS | E35: Engagements donnés | F35: Engagements reçus
A36: Engagements consentis à des entités liées
A37: Primes de remboursement non échus
A38: Avals, cautions, garanties
A39: Hypothèques, nantissements, gages, autres
A40: Effets escomptés non échus
A41: Créances commerciales et professionnelles cédées
A42: Abandons de créances conditionnels
A43: TOTAL | E43: =SUM(E36:E42) -> 0 | F43: =SUM(F36:F42) -> 0
A44: Commentaire :
...

Sheet Note 2
A1: NOTE 2 : INFORMATIONS OBLIGATOIRES
A3: Désignation entité : | C3: Excercice clos le : | D3: =+'Note 1'!E3 -> 45657
A4: =+'Note 1'!A4 -> Sabodala Gold Operations S.A | C4: Durée en mois : | D4: =+'Note 1'!E4 -> 12
A5: Numéro d'identification : | B5: =+'Note 1'!B5 -> 002850023
A7: A - DECLARATION DE CONFORMITE AU SYSCOHADA
A8: Les états financiers sont établis en conformité avec le Système comptable OHADA et l'Acte uniforme relatif au droit comptable et à l'information financière.
A9: B - REGLES ET METHODES COMPTABLES
A10: L’entreprise tient sa comptabilité suivant les prescriptions du système comptable OHADA, adaptées à l’activité de Sabodala gold Operations S.A. (« SGO »). Le système normal est appliqué. La comptabilité est tenue de façon chronologique sur un système informatique permettant d’éditer le Grand-Livre, la Balance Générale. Les pièces comptables sont numérotées. Les principes de prudence, de transparence, d’importance significative, d’intangibilité du bilan, du coût historique, de la continuité d’exploitation, de la permanence des méthodes, ainsi que de la spécialisation des exercices sont respectés. La comptabilité est tenue en anglais et en US dollars, en raison de l’utilisation depuis le 1er octobre 2011 du système d’information intégré Pronto. Ce dernier est spécifique au secteur minier. Une balance et un Grand Livre en Francs CFA sont préparés. Les opérations en monnaies étrangères effectuées par SGO sont comptabilisées en appliquant le cours de change en vigueur à la date de l’opération. Lorsque le règlement survient durant l’exercice au cours duquel l’opération a été conclue, la différence de change entre le montant enregistré initialement et le montant effectif du règlement constitue un gain ou une perte entrant dans la formation du résultat de l’exercice. A la date de clôture, les éléments en monnaies étrangères (fournisseurs d’exploitation et d’investissement, clients, dépôts en devises, …) sont évalués en utilisant le cours de change du jour de la transaction. La perte de change latente en résultant est prise en compte dans la détermination du résultat de l’exercice par le biais des provisions pour Risques et Charges. Les gains de change latents ne sont pas enregistrés dans le compte de résultat.
A11: C - DEROGATION AUX POSTULATS ET CONVENTIONS COMPTABLES
A12: Respect de tous les postulats et conventions comptables sans aucune dérogation
A13: D - INFORMATIONS COMPLEMENTAIRES RELATIVES AU BILAN, AU COMPTE DE RESULTAT ET AU TABLEAU DES FLUX DE TRESORERIE
A14: • Distribution de dividendes Sur décision de l’Assemblée Générale réunit à la date du 27 juin 2024, approuvant la proposition du Conseil d’Administration, un montant de FCFA 65 milliards du bénéfice réalisé de l’exercice 2023 a été distribué en dividendes aux actionnaires. • Mise en service de la nouvelle usine de traitement du minerai réfractaire (STP/BIOX) En avril 2024, la société a lancé la production au sein de sa nouvelle usine dédiée au traitement du minerai réfractaire, dénommée STP (Sulfide Treatment Process), basée sur la technologie BIOX (bio-oxydation). Ce projet stratégique d'un cout d'environ 290 millions de Dollars US a été mis en œuvre dans le but d’améliorer significativement le taux de récupération des minerais réfractaires, qui représentaient une part importante des réserves de l’entreprise mais dont le traitement demeurait peu efficient avec l’ancienne usine CIL. La nouvelle unité vient ainsi compléter les capacités existantes et renforcer la performance globale de l’outil industriel. Dotée d’une capacité annuelle de traitement de 1 200 000 de tonnes, l’usine BIOX marque une étape clé dans l’optimisation de l’exploitation des ressources minières de la société.

Sheet Note 3A
A1: NOTE 3A : IMMOBILISATION BRUTE
A3: Désignation entité : | E3: Excercice clos le : | F3: ='Note 1'!E3 -> 45657
A4: Sabodala Gold Operations S.A | E4: Durée en mois : | F4: 12
A5: Numéro d'identification : | B5: 002850023
A7: SITUATIONS ET MOUVEMENTS | B7: Montant brut à l'ouverture de l'exercice | C7: Acquisitions Apports Créations | D7: Virements de poste à poste | E7: Suite à une réévaluation pratiquée au cours de l'exercice | F7: Cessions Scissions Hors service | G7: Virements de poste à poste | H7: Montant brut à la clôture de l'exercice
A10: IMMOBILISATIONS INCORPORELLES | B10: =SUM(B11:B14) -> 5.6873242e+11 | C10: =SUM(C11:C14) -> 3.3600447e+10 | D10: =SUM(D11:D14) -> 2.3353161e+10 | E10: =SUM(E11:E14) -> 0 | F10: =SUM(F11:F14) -> -5.3165345e+08 | G10: =SUM(G11:G14) -> -3.0278576e+10 | H10: =SUM(H11:H14) -> 5.948758e+11
A11: Frais de développement et de prospection | B11: 5.425858e+11 | C11: 1.6780475e+10 | D11: 1.1123262e+10 | G11: -1.2229899e+10 | H11: =SUM(B11:G11) -> 5.5825964e+11
A12: Brevets, licences, logiciels et droits similaires | B12: 2.167926e+09 | C12: 19611269 | H12: =SUM(B12:G12) -> 2.1875373e+09
A13: Fonds commercial et droit au bail
A14: Autres immobilisations incorporelles | B14: 2.397869e+10 | C14: 1.6800361e+10 | D14: 1.2229899e+10 | F14: -5.3165345e+08 | G14: -1.8048678e+10 | H14: =SUM(B14:G14) -> 3.4428619e+10
A15: IMMOBILISATIONS CORPORELLES | B15: =SUM(B16:B22) -> 4.4053869e+11 | C15: =SUM(C16:C22) -> 8.2585601e+10 | D15: =SUM(D16:D22) -> 7.419232e+10 | F15: =SUM(F16:F22) -> -2.8415843e+10 | G15: =SUM(G16:G22) -> -5.6965152e+10 | H15: =SUM(H16:H22) -> 5.1193562e+11
A16: Terrains hors immeuble de placement
A17: Terrains immeuble de placement
A18: Bâtiments hors immeuble de placement | B18: 3.6103518e+10 | C18: 1.1278017e+09 | D18: 7.8555735e+09 | H18: =SUM(B18:G18) -> 4.5086893e+10
A19: Bâtiments immeuble de placement
A20: Aménagements, agencements et installations | B20: 2.9679388e+11 | C20: 5.6574242e+10 | D20: 1.0301753e+10 | F20: -3.2665852e+09 | G20: -4.3246327e+10 | H20: =SUM(B20:G20) -> 3.1715697e+11
A21: Matériel, mobilier et actifs biologiques | B21: 9.8497144e+10 | C21: 1.074863e+10 | D21: 5.6034994e+10 | F21: -2.1948315e+10 | H21: =SUM(B21:G21) -> 1.4333245e+11
A22: Matériel de transport | B22: 9.1441464e+09 | C22: 1.4134928e+10 | F22: -3.2009435e+09 | G22: -1.3718825e+10 | H22: =SUM(B22:G22) -> 6.3593049e+09
A23: AVANCES ET ACOMPTES VERSES SUR IMMOBILISATIONS | B23: =SUM(B24:B25) -> 1.0301753e+10 | C23: =SUM(C24:C25) -> 290656582 | D23: =SUM(D24:D25) -> -1.0301753e+10 | E23: =SUM(E24:E25) -> 0 | F23: =SUM(F24:F25) -> 0 | G23: =SUM(G24:G25) -> 0 | H23: =SUM(H24:H25) -> 290656582
A24: Immobilisations incorporelles
A25: Immoblisations corporelles | B25: 1.0301753e+10 | C25: 290656582 | D25: -1.0301753e+10 | H25: =SUM(B25:G25) -> 290656582
A26: IMMOBILISATIONS FINANCIERES | B26: =SUM(B27:B28) -> 431226428 | C26: =SUM(C27:C28) -> 0 | D26: =SUM(D27:D28) -> 0 | E26: =SUM(E27:E28) -> 0 | F26: =SUM(F27:F28) -> -24000000 | G26: =SUM(G27:G28) -> 0 | H26: =SUM(H27:H28) -> 407226428
A27: Titres de placement
A28: Autres immobilisations financières | B28: 431226428 | F28: -24000000 | H28: =SUM(B28:G28) -> 407226428
A29: TOTAL GENERAL | B29: =B26+B23+B15+B10 -> 1.0200041e+12 | C29: =C26+C23+C15+C10 -> 1.1647671e+11 | D29: =D26+D23+D15+D10 -> 8.7243728e+10 | E29: =E26+E23+E15+E10 -> 0 | F29: =F26+F23+F15+F10 -> -2.8971497e+10 | G29: =G26+G23+G15+G10 -> -8.7243728e+10 | H29: =H26+H23+H15+H10 -> 1.1075093e+12
A30: Commentaire :
A31: Immobilisations incorporelles Les immobilisations incorporelles sont principalement constituées des frais de prospection et des coûts de recherche et développement liés à l’exploration minière. Elles sont évaluées au coût historique et amorties en fonction de l’estimation de la production attendue. Immobilisations corporelles Également évaluées au coût historique, les immobilisations corporelles comprennent plusieurs catégories d’actifs. La Société applique la méthode d’amortissement linéaire pour le mobilier de bureau, les véhicules et les équipements mobiles. Les autres immobilisations corporelles sont amorties sur la base de la production. Bâtiments : ils englobent principalement les bureaux administratifs et le village permanent destiné à l’hébergement du personnel. Installations et agencements : ils incluent essentiellement l’usine de traitement, y compris les travaux liés à son extension. Matériel : cette catégorie regroupe les installations et équipements techniques nécessaires aux opérations. Principales acquisitions de l'exercice : Coûts de décapage : +16 831 M FCFA, correspondant aux travaux dans les fosses de Massawa Nord, Kiesta (mise en exploitation en cours d'année), Massawa Centre, Bambaraya, Niakafiri, ainsi qu’une capitalisation marginale à Sabodala. Frais de recherche et développement : +16 780 M FCFA.Logiciels : +19,6 M FCFA.Autres immobilisations incorporelles : +16 800 M FCFA, correspondant à un reclassement de coûts d’exploration en cours vers la rubrique "Autres immobilisations en cours".Bâtiments : +8 983 M FCFA.Agencements, aménagements et installations : +20 363 M FCFA, comprenant : La poursuite et l’achèvement en avril 2024 (date de démarrage de la production) des travaux de construction et d’installation de la nouvelle usine BIOX (traitement de l’or réfractaire). Un montant initial de 43 425 M FCFA, précédemment enregistré dans la rubrique "Bâtiment", a été reclassé comme suit : infrastructures (+1 926 M FCFA), équipements (+39 816 M FCFA), mobiliers et autres matériels (+973 M FCFA). Le projet d'installation du système solaire est en cours : les nouvelles dépenses liées à sa mise en œuvre, ainsi que d'autres coûts rattachés à l'usine BIOX, s’élèvent à 27 689 M FCFA. Le montant de l’actif de démantèlement a été réévalué à la hausse pour un total de +949 M FCFA.Matériel, mobilier et actifs biologiques : +44 835 M FCFA. Matériel roulant : -2 785 M FCFA (sorties nettes). Les sorties d’immobilisations s’élèvent à 28 947 M FCFA en valeur brute. Le détail de ces mouvements figure dans la Note 3D des états financiers.

Sheet Note 3B
A1: NOTE 3B : BIENS PRIS EN LOCATION ACQUISITION
A3: Désignation entité : | G3: Excercice clos le : | H3: ='Note 1'!E3 -> 45657
A4: Sabodala Gold Operations S.A | G4: Durée en mois : | H4: 12
A5: Numéro d'identification : | B5: 002850023
A7: SITUATIONS ET MOUVEMENTS | B7: NATURE DU CONTRAT (I; M; A) | C7: A | D7: AUGMENTATIONS B | G7: DIMINUTIONS C | I7: D = A +B - C
C8: Montant brut à l'ouverture de l'exercice | D8: Acquisitions Apports Créations | E8: Virements de poste à poste | F8: Suite à une réévaluation pratiquée au cours de l'exercice | G8: Cessions Scissions Hors service | H8: Virements de poste à poste | I8: Montant brut à l'ouverture de l'exercice
B9: [1]
A10: Brevets, licences, logiciels et droits similaires
A11: Fonds commercial et droit au bail
A12: Autres immobilisations incorporelles
A13: SOUS TOTAL : IMMOBILISATIONS INCORPORELLES
A14: Terrains
A15: Bâtiments
A16: Aménagements, agencements et installations
A17: Matériel, mobilier et actifs biologiques | B17: M | C17: 1.7291333e+10 | G17: -8.077149e+09 | I17: 9.2141843e+09
A18: Matériel de transport
A19: SOUS TOTAL : IMMOBILISATIONS CORPORELLES | C19: 1.7291333e+10 | G19: -8.077149e+09 | I19: 9.2141843e+09
A21: TOTAL GENERAL | C21: 1.7291333e+10 | G21: -8.077149e+09 | I21: 9.2141843e+09
A22: [1] I : crédit-bail immobilier; M : crédit-bail mobilier; A : autres contrats (dédoubler le poste si montants significatifs)
A23: Commentaire :
A24: Contrat de location financement avec option d’achat signé en Novembre 2008 entre SGMC, Société Générale Branche de Londres et SGO pour l’utilisation de biens d’équipements industriels sur le site de Sabodala.

Sheet Note 3C
A1: NOTE 3C : IMMOBILISATIONS (AMORTISSEMENTS)
A3: Désignation entité : | D3: Excercice clos le : | E3: ='Note 1'!E3 -> 45657
A4: Sabodala Gold Operations S.A | D4: Durée en mois : | E4: 12
A5: Numéro d'identification : | B5: 002850023
A7: SITUATIONS ET MOUVEMENTS | B7: A | C7: B | D7: C | E7: D = A +B - C
B8: Amortissements cumulés à l'ouverture de l'exercice | C8: Augmentations : Dotations de l'exercice | D8: Diminutions : Amortissements relatifs aux éléments sortis de l'actif | E8: Cumul des amortissements à la clôture de l'exercice
A10: Frais de développement et de prospection | B10: 2.8546932e+11 | C10: 5.8446828e+10 | E10: 3.4391615e+11
A11: Brevets, licences, logiciels et droits similaires | B11: 1.9891031e+09 | C11: 50777693 | E11: 2.0398808e+09
A12: Fonds commercial et droit au bail
A13: Autres immobilisations incorporelles
A14: SOUS TOTAL : IMMOBILISATIONS INCORPORELLES | B14: 2.8745843e+11 | C14: 5.8497605e+10 | D14: 0 | E14: 3.4595603e+11
A15: Terrains hors immeuble de placement
A16: Terrains immeuble de placement
A17: Bâtiments hors immeuble de placement | B17: 2.214938e+10 | C17: 3.6638455e+09 | E17: 2.5813226e+10
A18: Bâtiments immeuble de placement
A19: Aménagements, agencements et installations | B19: 1.1083038e+11 | C19: 1.6521435e+10 | D19: -3.0213288e+09 | E19: 1.2433049e+11
A20: Matériel, mobilier et actifs biologiques | B20: 6.3022296e+10 | C20: 1.4038748e+10 | D20: -2.1906935e+10 | E20: 5.5154109e+10
A21: Matériel de transport | B21: 7.7803566e+09 | C21: 7.3305659e+08 | D21: -3.1382186e+09 | E21: 5.3751946e+09
A22: SOUS TOTAL : IMMOBILISATIONS CORPORELLES | B22: 2.0378241e+11 | C22: 3.4957085e+10 | D22: -2.8066483e+10 | E22: 2.1067302e+11
A24: TOTAL GENERAL | B24: 4.9124084e+11 | C24: 9.3454691e+10 | D24: -2.8066483e+10 | E24: 5.5662905e+11
A25: Commentaire :
A26: Les immobilisations incorporelles de SGO sont constituées principalement des frais de prospection minière et des coûts de Recherche et Développement dans le cadre de l’exploration minière. Elles sont évaluées au coût historique et font l’objet d’un amortissement en fonction de l’estimation de la production. Les immobilisations corporelles sont également évaluées au coût historique. La Société utilise la méthode de l’amortissement linéaire pour le mobilier de bureau, les véhicules et les équipements mobiles. Les autres immobilisations corporelles sont amorties en fonction de l’estimation de la production.
A27: Les taux d'amortissement pratiqués sont les suivants : Installations et aménagements : 3 à 5 ans Matériel et outillage : 4 ans Matériel de transport : 3 à 5 ans Mobilier, matériel de bureau : 3 à 5 ans Il y a eu une hausse des dotations de l'exercice en relation avec l'entrée en production de Niakafiri Est - kiesta - BIOX. Les amortissements des couts de décapage s'élévent à 29 224 M FCFA dont 28 737 relatifs au Pit de Sabodala dont les reserves sont presques épuisées, 125 M FCFA à celui de BAMBARAYA et Kiesta pour 362 M FCFA

Sheet Note 3D
A1: NOTE 3D : IMMOBILISATIONS (PLUS-VALUES ET MOINS VALUES DE CESSION)
A3: Désignation entité : | D3: Excercice clos le : | E3: ='Note 1'!E3 -> 45657
A4: Sabodala Gold Operations S.A | D4: Durée en mois : | E4: 12
A5: Numéro d'identification : | B5: 002850023
B7: MONTANT BRUT | C7: AMORTISSEMENTS | D7: VALEUR COMPTABLE NETTE | E7: PRIX DE CESSION | F7: PLUS VALUE OU MOINS VALUE
C8: PRATIQUES
B9: A | C9: B | D9: C = A - B | E9: D | F9: E = D - C
A10: Frais de développement et de prospection
A11: Brevets, licences, logiciels et droits similaires
A12: Fonds commercial et droit au bail
A13: Autres immobilisations incorporelles | B13: 5.3165345e+08 | D13: 5.3165345e+08 | F13: -5.3165345e+08
A14: SOUS TOTAL : IMMOBILISATIONS INCORPORELLES | B14: 5.3165345e+08 | D14: 5.3165345e+08 | F14: -5.3165345e+08
A15: Terrains
A16: Bâtiments
A17: Aménagements, agencements et installations | B17: 3.2665852e+09 | C17: -3.0213288e+09 | D17: 2.4525646e+08 | F17: -2.4525646e+08
A18: Matériel, mobilier et actifs biologiques | B18: 2.1948315e+10 | C18: -2.1906935e+10 | D18: 41379351 | F18: -41379351
A19: Matériel de transport | B19: 3.2009435e+09 | C19: -3.1382186e+09 | D19: 62724901 | F19: -62724901
A20: SOUS TOTAL : IMMOBILISATIONS CORPORELLES | B20: 2.8415843e+10 | C20: -2.8066483e+10 | D20: 3.4936071e+08 | F20: -3.4936071e+08
A21: Titres de participation
A22: Autres immobilisations financières
A23: SOUS TOTAL : IMMOBILISATIONS FINANCIERES
A25: TOTAL GENERAL | B25: 2.8947497e+10 | C25: -2.8066483e+10 | D25: 8.8101416e+08 | F25: -8.8101416e+08
A26: Commentaire :
A27: La sortie d'actif pour un montant XOF de 349M correspond a des installations pour 3 266 M, des materiels et mobiliers actifs pour 21 948M et des materiels de transport pour 3 220M en valeurs brutes.
A28: La sortie de 531M correspond à des Couts d'exploration (en cours) dont les zones d'interventions sont abandonnées 410M FCFA (Mining Lease ) et 121M FCFA Soukhoto East

Sheet Note 3E
A1: NOTE 3E : INFORMATIONS SUR LES REEVALUATIONS EFFECTUEES PAR L'ENTITE
A3: Désignation entité : | C3: Excercice clos le : | D3: =+'Note 1'!E3 -> 45657
A4: =+'Note 1'!A4 -> Sabodala Gold Operations S.A | C4: Durée en mois : | D4: =+'Note 1'!E4 -> 12
A5: Numéro d'identification : | B5: =+'Note 1'!B5 -> 002850023
A7: Nature et date des réévaluations :
A13: Eléments réévalués par postes du bilan | B13: Montants coûts historiques | C13: Amortissements supplémentaires
A22: Méthode de réévaluation utilisée :
A24: Traitement fiscal de l'écart de réévaluation
A25: et des amortissements supplémentaires :
A27: Montant de l'écart incorporé au capital :

Sheet Note 4
A1: NOTE 4 : IMMOBILISATIONS FINANCIERES
A3: Désignation entité : | E3: Excercice clos le : | F3: =+'Note 1'!E3 -> 45657
E4: Durée en mois : | F4: =+'Note 1'!E4 -> 12
A5: Numéro d'identification : | B5: =+'Note 1'!B5 -> 002850023
A7: SITUATIONS ET MOUVEMENTS | B7: ANNEE N | C7: ANNEE N-1 | D7: Variation en % | E7: Créances à un an au plus | F7: Créances à plus d'un an et à deux ans au plus | G7: Créances à plus de deux ans
A9: Titres de participation
A10: Prêts et créances
A11: Prêt au personnel
A12: Créances sur l'Etat
A13: Titres immobilisés
A14: Dépôts et cautionnements | B14: 407226428 | C14: 431226428 | D14: =(B14-C14)/C14 -> -0.055655216 | G14: 407226428
A15: Intérêts courus
A16: TOTAL BRUT | B16: 407226428 | C16: 431226428 | D16: -0.055655216 | G16: 407226428
A17: Dépréciations titres de participation
A18: Dépréciations autres immobilisations
A19: TOTAL NET DE DEPRECIATION
A21: Liste des filiales et participations :
A23: Dénomination sociale | B23: Localisation (ville/pays) | C23: Valeur d'acquisition | E23: % détenu | F23: Montant des capitaux propres filiale | G23: Résultat dernier exercice filiale
A32: Commentaire :
A33: Provision pour réhabilitation des sites miniers versée auprès de la Caisse de Dépots et Consignations (CDC) pour un montant XOF 326 millions. Dépôts et cautionnement auprès des fournisseurs pour un montant XOF de 81 millions.

Sheet Note 5
A1: NOTE 5 : ACTIF CIRCULANT HAO
A3: Désignation entité : | E3: Excercice clos le : | F3: =+'Note 1'!E3 -> 45657
E4: Durée en mois : | F4: =+'Note 1'!E4 -> 12
A5: Numéro d'identification : | B5: =+'Note 1'!B5 -> 002850023
