Workbook

Sheet Modèle
A1: Nom | B1: Unité | C1: Année 1 | D1: Année 2 | E1: Année 3 | F1: Année 4 | G1: Année 5 | H1: Année 6 | I1: Année 7 | J1: Année 8 | K1: Année 9 | L1: Année 10 | M1: Année 11 | N1: SOMME | O1: VAN
A3: I. PRODUCTION
A4: Production d'or | B4: oz | E4: 250000 | F4: 250000 | G4: 250000 | H4: 250000 | I4: 250000 | J4: 250000 | K4: 250000 | L4: 250000 | N4: =SUM($C4:$M4) -> 2000000
A5: Cours de l'or | B5: USD/oz | E5: 1300 | F5: 1300 | G5: 1300 | H5: 1300 | I5: 1300 | J5: 1300 | K5: 1300 | L5: 1300
A6: Chiffre d'affaires | B6: USD | C6: =C$4*C$5 -> 0 | D6: =D$4*D$5 -> 0 | E6: =E$4*E$5 -> 325000000 | F6: =F$4*F$5 -> 325000000 | G6: =G$4*G$5 -> 325000000 | H6: =H$4*H$5 -> 325000000 | I6: =I$4*I$5 -> 325000000 | J6: =J$4*J$5 -> 325000000 | ... M6: =M$4*M$5 -> 0 | N6: =SUM($C6:$M6) -> 2600000000 | O6: =$C6+NPV(10%,$D6:$M6) -> 1.5762282e+09
A8: II. DEPENSES D'INVESTISSEMENT (CAPEX)
A9: Coûts des construction industrielles | B9: USD | C9: 50000000 | D9: 100000000 | N9: =SUM($C9:$M9) -> 150000000 | O9: =$C9+NPV(10%,$D9:$M9) -> 1.4090909e+08
A10: Coûts des biens d'équipement | B10: USD | D10: 50000000 | E10: 5000000 | F10: 5000000 | G10: 5000000 | H10: 5000000 | I10: 5000000 | J10: 5000000 | K10: 5000000 | L10: 5000000 | N10: =SUM($C10:$M10) -> 90000000 | O10: =$C10+NPV(10%,$D10:$M10) -> 69704210
A11: Coûts de réhabilitation du site | B11: USD | M11: 10000000 | N11: =SUM($C11:$M11) -> 10000000 | O11: =$C11+NPV(10%,$D11:$M11) -> 9090909.1
A12: Total des dépenses d'investissement | B12: USD | C12: =SUM(C$9:C$11) -> 50000000 | D12: =SUM(D$9:D$11) -> 150000000 | E12: =SUM(E$9:E$11) -> 5000000 | F12: =SUM(F$9:F$11) -> 5000000 | G12: =SUM(G$9:G$11) -> 5000000 | H12: =SUM(H$9:H$11) -> 5000000 | I12: =SUM(I$9:I$11) -> 5000000 | J12: =SUM(J$9:J$11) -> 5000000 | ... M12: =SUM(M$9:M$11) -> 10000000 | N12: =SUM($C12:$M12) -> 250000000 | O12: =$C12+NPV(10%,$D12:$M12) -> 2.1446873e+08
A14: III. COÛTS D'EXPLOITATION (OPEX)
A15: Coût moyen d'exploitation | B15: USD/oz | E15: 700 | F15: 700 | G15: 700 | H15: 700 | I15: 700 | J15: 700 | K15: 700 | L15: 700
A16: Total des coûts d'exploitation | B16: USD | C16: =C$4*C$15 -> 0 | D16: =D$4*D$15 -> 0 | E16: =E$4*E$15 -> 175000000 | F16: =F$4*F$15 -> 175000000 | G16: =G$4*G$15 -> 175000000 | H16: =H$4*H$15 -> 175000000 | I16: =I$4*I$15 -> 175000000 | J16: =J$4*J$15 -> 175000000 | ... M16: =M$4*M$15 -> 0 | N16: =SUM($C16:$M16) -> 1400000000 | O16: =$C16+NPV(10%,$D16:$M16) -> 8.4873826e+08
A18: IV. FLUX NETS DE TRESORERIE AVANT IMPÔTS
A19: Flux nets de trésorerie avant impôts | B19: USD | C19: =C$6-C$12-C$16 -> -50000000 | D19: =D$6-D$12-D$16 -> -150000000 | E19: =E$6-E$12-E$16 -> 145000000 | F19: =F$6-F$12-F$16 -> 145000000 | G19: =G$6-G$12-G$16 -> 145000000 | H19: =H$6-H$12-H$16 -> 145000000 | I19: =I$6-I$12-I$16 -> 145000000 | J19: =J$6-J$12-J$16 -> 145000000 | ... M19: =M$6-M$12-M$16 -> -10000000 | N19: =SUM($C19:$M19) -> 950000000 | O19: =$C19+NPV(10%,$D19:$M19) -> 5.130212e+08
A20: Taux de rendement interne avant impôts | B20: % | C20: =IF(ISNUMBER(IRR($C19:C19)),IF(IRR($C19:C19)>0,IRR($C19:C19),""),"") | D20: =IF(ISNUMBER(IRR($C19:D19)),IF(IRR($C19:D19)>0,IRR($C19:D19),""),"") | E20: =IF(ISNUMBER(IRR($C19:E19)),IF(IRR($C19:E19)>0,IRR($C19:E19),""),"") | F20: =IF(ISNUMBER(IRR($C19:F19)),IF(IRR($C19:F19)>0,IRR($C19:F19),""),"") -> 0.23743596 | G20: =IF(ISNUMBER(IRR($C19:G19)),IF(IRR($C19:G19)>0,IRR($C19:G19),""),"") -> 0.43121332 | H20: =IF(ISNUMBER(IRR($C19:H19)),IF(IRR($C19:H19)>0,IRR($C19:H19),""),"") -> 0.52174773 | I20: =IF(ISNUMBER(IRR($C19:I19)),IF(IRR($C19:I19)>0,IRR($C19:I19),""),"") -> 0.5678591 | J20: =IF(ISNUMBER(IRR($C19:J19)),IF(IRR($C19:J19)>0,IRR($C19:J19),""),"") -> 0.59275422 | ... M20: =IF(ISNUMBER(IRR($C19:M19)),IF(IRR($C19:M19)>0,IRR($C19:M19),""),"") -> 0.614484
A22: V. DROITS FIXES
A23: Droits fixes | B23: USD | C23: 100000 | N23: =SUM($C23:$M23) -> 100000 | O23: =$C23+NPV(10%,$D23:$M23) -> 100000
A25: VI. REDEVANCE SUPERFICAIRE
A26: Superficie de la mine | B26: km² | C26: 100 | D26: 100 | E26: 100 | F26: 100 | G26: 100 | H26: 100 | I26: 100 | J26: 100 | K26: 100 | L26: 100 | M26: 100
A27: Montant de la redevance superfiaire | B27: USD/km² | C27: 100 | D27: 100 | E27: 100 | F27: 100 | G27: 100 | H27: 100 | I27: 100 | J27: 100 | K27: 100 | L27: 100 | M27: 100
A28: Redevance superficiaire | B28: USD | C28: =C$26*C$27 -> 10000 | D28: =D$26*D$27 -> 10000 | E28: =E$26*E$27 -> 10000 | F28: =F$26*F$27 -> 10000 | G28: =G$26*G$27 -> 10000 | H28: =H$26*H$27 -> 10000 | I28: =I$26*I$27 -> 10000 | J28: =J$26*J$27 -> 10000 | ... M28: =M$26*M$27 -> 10000 | N28: =SUM($C28:$M28) -> 110000 | O28: =$C28+NPV(10%,$D28:$M28) -> 71445.671
A30: VII. REDEVANCE MINIERE
A31: Taux de la redevance minière | B31: % | C31: =IF(ISNUMBER(C5),IF(C$5<1300,3%,IF(C$5<1500,4%,5%)),"") | D31: =IF(ISNUMBER(D5),IF(D$5<1300,3%,IF(D$5<1500,4%,5%)),"") | E31: =IF(ISNUMBER(E5),IF(E$5<1300,3%,IF(E$5<1500,4%,5%)),"") -> 0.04 | F31: =IF(ISNUMBER(F5),IF(F$5<1300,3%,IF(F$5<1500,4%,5%)),"") -> 0.04 | G31: =IF(ISNUMBER(G5),IF(G$5<1300,3%,IF(G$5<1500,4%,5%)),"") -> 0.04 | H31: =IF(ISNUMBER(H5),IF(H$5<1300,3%,IF(H$5<1500,4%,5%)),"") -> 0.04 | I31: =IF(ISNUMBER(I5),IF(I$5<1300,3%,IF(I$5<1500,4%,5%)),"") -> 0.04 | J31: =IF(ISNUMBER(J5),IF(J$5<1300,3%,IF(J$5<1500,4%,5%)),"") -> 0.04 | ... M31: =IF(ISNUMBER(M5),IF(M$5<1300,3%,IF(M$5<1500,4%,5%)),"")
A32: Redevance minière | B32: USD | C32: =IF(ISNUMBER(C31),C$6*C$31,0) -> 0 | D32: =IF(ISNUMBER(D31),D$6*D$31,0) -> 0 | E32: =IF(ISNUMBER(E31),E$6*E$31,0) -> 13000000 | F32: =IF(ISNUMBER(F31),F$6*F$31,0) -> 13000000 | G32: =IF(ISNUMBER(G31),G$6*G$31,0) -> 13000000 | H32: =IF(ISNUMBER(H31),H$6*H$31,0) -> 13000000 | I32: =IF(ISNUMBER(I31),I$6*I$31,0) -> 13000000 | J32: =IF(ISNUMBER(J31),J$6*J$31,0) -> 13000000 | ... M32: =IF(ISNUMBER(M31),M$6*M$31,0) -> 0 | N32: =SUM($C32:$M32) -> 104000000 | O32: =$C32+NPV(10%,$D32:$M32) -> 63049128
A34: +. LA TAXE SUR LA RENTE
A35: Taux de revalorisation des pertes | B35: % | C35: 0.02 | D35: 0.02 | E35: 0.02 | F35: 0.02 | G35: 0.02 | H35: 0.02 | I35: 0.02 | J35: 0.02 | K35: 0.02 | L35: 0.02 | M35: 0.02
A36: Flux nets de trésorerie revalorisés | B36: USD | C36: =IF(C19<0,C19*(1+C35),C19) -> -51000000 | D36: =IF(D19<0,D19*(1+D35),D19) -> -153000000 | E36: =IF(E19<0,E19*(1+E35),E19) -> 145000000 | F36: =IF(F19<0,F19*(1+F35),F19) -> 145000000 | G36: =IF(G19<0,G19*(1+G35),G19) -> 145000000 | H36: =IF(H19<0,H19*(1+H35),H19) -> 145000000 | I36: =IF(I19<0,I19*(1+I35),I19) -> 145000000 | J36: =IF(J19<0,J19*(1+J35),J19) -> 145000000 | ... M36: =IF(M19<0,M19*(1+M35),M19) -> -10200000 | N36: =SUM($C36:$M36) -> 945800000 | O36: =$C36+NPV(10%,$D36:$M36) -> 5.0921682e+08
A37: Taux de rendement interne | B37: % | C37: =IF(ISNUMBER(IRR($C36:C36)),IF(IRR($C36:C36)>0,IRR($C36:C36),""),"") | D37: =IF(ISNUMBER(IRR($C36:D36)),IF(IRR($C36:D36)>0,IRR($C36:D36),""),"") | E37: =IF(ISNUMBER(IRR($C36:E36)),IF(IRR($C36:E36)>0,IRR($C36:E36),""),"") | F37: =IF(ISNUMBER(IRR($C36:F36)),IF(IRR($C36:F36)>0,IRR($C36:F36),""),"") -> 0.22342633 | G37: =IF(ISNUMBER(IRR($C36:G36)),IF(IRR($C36:G36)>0,IRR($C36:G36),""),"") -> 0.41772238 | H37: =IF(ISNUMBER(IRR($C36:H36)),IF(IRR($C36:H36)>0,IRR($C36:H36),""),"") -> 0.5089236 | I37: =IF(ISNUMBER(IRR($C36:I36)),IF(IRR($C36:I36)>0,IRR($C36:I36),""),"") -> 0.55558431 | J37: =IF(ISNUMBER(IRR($C36:J36)),IF(IRR($C36:J36)>0,IRR($C36:J36),""),"") -> 0.58089254 | ... M37: =IF(ISNUMBER(IRR($C36:M36)),IF(IRR($C36:M36)>0,IRR($C36:M36),""),"") -> 0.60312112
A38: Seuil de déclenchement de la taxe sur la rente | B38: % | C38: 0.15 | D38: 0.15 | E38: 0.15 | F38: 0.15 | G38: 0.15 | H38: 0.15 | I38: 0.15 | J38: 0.15 | K38: 0.15 | L38: 0.15 | M38: 0.15
A39: Report des pertes revalorisées | D39: =IF(C40<0,C40,0) -> -51000000 | E39: =IF(D40<0,D40,0) -> -204000000 | F39: =IF(E40<0,E40,0) -> -59000000 | G39: =IF(F40<0,F40,0) -> 0 | H39: =IF(G40<0,G40,0) -> 0 | I39: =IF(H40<0,H40,0) -> 0 | J39: =IF(I40<0,I40,0) -> 0 | K39: =IF(J40<0,J40,0) -> 0 | ... M39: =IF(L40<0,L40,0) -> 0
A40: Flux nets de trésorerie après report des pertes revalorisées | B40: USD | C40: =C36+C39 -> -51000000 | D40: =D36+D39 -> -204000000 | E40: =E36+E39 -> -59000000 | F40: =F36+F39 -> 86000000 | G40: =G36+G39 -> 145000000 | H40: =H36+H39 -> 145000000 | I40: =I36+I39 -> 145000000 | J40: =J36+J39 -> 145000000 | ... M40: =M36+M39 -> -10200000 | N40: =SUM($C40:$M40) -> 631800000 | O40: =$C40+NPV(10%,$D40:$M40) -> 2.4993057e+08
A41: Taux de la taxe sur la rente | B41: % | C41: 0.2 | D41: 0.2 | E41: 0.2 | F41: 0.2 | G41: 0.2 | H41: 0.2 | I41: 0.2 | J41: 0.2 | K41: 0.2 | L41: 0.2 | M41: 0.2
A42: Taxe sur la rente | B42: USD | C42: =IF(C37<C38,0,IF(C40<0,0,C40*C41)) -> 0 | D42: =IF(D37<D38,0,IF(D40<0,0,D40*D41)) -> 0 | E42: =IF(E37<E38,0,IF(E40<0,0,E40*E41)) -> 0 | F42: =IF(F37<F38,0,IF(F40<0,0,F40*F41)) -> 17200000 | G42: =IF(G37<G38,0,IF(G40<0,0,G40*G41)) -> 29000000 | H42: =IF(H37<H38,0,IF(H40<0,0,H40*H41)) -> 29000000 | I42: =IF(I37<I38,0,IF(I40<0,0,I40*I41)) -> 29000000 | J42: =IF(J37<J38,0,IF(J40<0,0,J40*J41)) -> 29000000 | ... M42: =IF(M37<M38,0,IF(M40<0,0,M40*M41)) -> 0 | N42: =SUM($C42:$M42) -> 191200000 | O42: =$C42+NPV(10%,$D42:$M42) -> 1.078156e+08
A44: VIII. IMPÔT SUR LES SOCIETES (IS)
A45: Bénéfice avant report des pertes | B45: USD | C45: =C$6-C$16-C$23-C$28-C$32-C$42-'Amortissements et Emprunt'!C$25-'Amortissements et Emprunt'!C$119-'Amortissements et Emprunt'!C133-'Amortissements et Emprunt'!C$157 -> -7610000 | D45: =D$6-D$16-D$23-D$28-D$32-D$42-'Amortissements et Emprunt'!D$25-'Amortissements et Emprunt'!D$119-'Amortissements et Emprunt'!D133-'Amortissements et Emprunt'!D$157 -> -44510000 | E45: =E$6-E$16-E$23-E$28-E$32-E$42-'Amortissements et Emprunt'!E$25-'Amortissements et Emprunt'!E$119-'Amortissements et Emprunt'!E133-'Amortissements et Emprunt'!E$157 -> 100490000 | F45: =F$6-F$16-F$23-F$28-F$32-F$42-'Amortissements et Emprunt'!F$25-'Amortissements et Emprunt'!F$119-'Amortissements et Emprunt'!F133-'Amortissements et Emprunt'!F$157 -> 88890000 | G45: =G$6-G$16-G$23-G$28-G$32-G$42-'Amortissements et Emprunt'!G$25-'Amortissements et Emprunt'!G$119-'Amortissements et Emprunt'!G133-'Amortissements et Emprunt'!G$157 -> 80170000 | H45: =H$6-H$16-H$23-H$28-H$32-H$42-'Amortissements et Emprunt'!H$25-'Amortissements et Emprunt'!H$119-'Amortissements et Emprunt'!H133-'Amortissements et Emprunt'!H$157 -> 81630000 | I45: =I$6-I$16-I$23-I$28-I$32-I$42-'Amortissements et Emprunt'!I$25-'Amortissements et Emprunt'!I$119-'Amortissements et Emprunt'!I133-'Amortissements et Emprunt'!I$157 -> 87990000 | J45: =J$6-J$16-J$23-J$28-J$32-J$42-'Amortissements et Emprunt'!J$25-'Amortissements et Emprunt'!J$119-'Amortissements et Emprunt'!J133-'Amortissements et Emprunt'!J$157 -> 87990000 | ... M45: =M$6-M$16-M$23-M$28-M$32-M$42-'Amortissements et Emprunt'!M$25-'Amortissements et Emprunt'!M$119-'Amortissements et Emprunt'!M133-'Amortissements et Emprunt'!M$157 -> -25450000 | N45: =SUM($C45:$M45) -> 624590000 | O45: =$C45+NPV(10%,$D45:$M45) -> 3.701608e+08
A46: Report des pertes | B46: USD | D46: =IF(C47<0,C47,0) -> -7610000 | E46: =IF(D47<0,D47,0) -> -52120000 | F46: =IF(E47<0,E47,0) -> 0 | G46: =IF(F47<0,F47,0) -> 0 | H46: =IF(G47<0,G47,0) -> 0 | I46: =IF(H47<0,H47,0) -> 0 | J46: =IF(I47<0,I47,0) -> 0 | K46: =IF(J47<0,J47,0) -> 0 | ... M46: =IF(L47<0,L47,0) -> 0
A47: Bénéfice fiscal | B47: USD | C47: =C$45+C$46 -> -7610000 | D47: =D$45+D$46 -> -52120000 | E47: =E$45+E$46 -> 48370000 | F47: =F$45+F$46 -> 88890000 | G47: =G$45+G$46 -> 80170000 | H47: =H$45+H$46 -> 81630000 | I47: =I$45+I$46 -> 87990000 | J47: =J$45+J$46 -> 87990000 | ... M47: =M$45+M$46 -> -25450000 | N47: =SUM($C47:$M47) -> 564860000 | O47: =$C47+NPV(10%,$D47:$M47) -> 3.2016824e+08
A48: Taux de l'impôt sur les sociétés | B48: % | C48: 0.3 | D48: 0.3 | E48: 0.3 | F48: 0.3 | G48: 0.3 | H48: 0.3 | I48: 0.3 | J48: 0.3 | K48: 0.3 | L48: 0.3 | M48: 0.3
A49: Impôt sur les sociétés | B49: USD | C49: =IF(C$47>0,C$47*C$48,0) -> 0 | D49: =IF(D$47>0,D$47*D$48,0) -> 0 | E49: =IF(E$47>0,E$47*E$48,0) -> 14511000 | F49: =IF(F$47>0,F$47*F$48,0) -> 26667000 | G49: =IF(G$47>0,G$47*G$48,0) -> 24051000 | H49: =IF(H$47>0,H$47*H$48,0) -> 24489000 | I49: =IF(I$47>0,I$47*I$48,0) -> 26397000 | J49: =IF(J$47>0,J$47*J$48,0) -> 26397000 | ... M49: =IF(M$47>0,M$47*M$48,0) -> 0 | N49: =SUM($C49:$M49) -> 195012000 | O49: =$C49+NPV(10%,$D49:$M49) -> 1.1549164e+08
...

Sheet Amortissements et Emprunt
A1: Nom | B1: Unité | C1: Année 1 | D1: Année 2 | E1: Année 3 | F1: Année 4 | G1: Année 5 | H1: Année 6 | I1: Année 7 | J1: Année 8 | K1: Année 9 | L1: Année 10 | M1: Année 11
A3: Durée restante maximum | B3: Années | C3: 11 | D3: 10 | E3: 9 | F3: 8 | G3: 7 | H3: 6 | I3: 5 | J3: 4 | K3: 3 | L3: 2 | M3: 1
A5: I. AMORTISSEMENTS DES CONSTRUCTIONS INDUSTRIELLES
A6: Durée d'amortissement linéaire | B6: Années | C6: 10
A7: Coefficient d'amortissement dégressif | B7: Coefficient | C7: 1
A9: Immobilisations de l'année A1
A10: Durée restante | B10: Années | C10: =IF($C$6<C$3,$C$6,C$3) -> 10 | D10: =IF(C10=0,0,IF(C10-1<D$3,C10-1,D$3)) -> 9 | E10: =IF(D10=0,0,IF(D10-1<E$3,D10-1,E$3)) -> 8 | F10: =IF(E10=0,0,IF(E10-1<F$3,E10-1,F$3)) -> 7 | G10: =IF(F10=0,0,IF(F10-1<G$3,F10-1,G$3)) -> 6 | H10: =IF(G10=0,0,IF(G10-1<H$3,G10-1,H$3)) -> 5 | I10: =IF(H10=0,0,IF(H10-1<I$3,H10-1,I$3)) -> 4 | J10: =IF(I10=0,0,IF(I10-1<J$3,I10-1,J$3)) -> 3 | K10: =IF(J10=0,0,IF(J10-1<K$3,J10-1,K$3)) -> 2 | ... M10: =IF(L10=0,0,IF(L10-1<M$3,L10-1,M$3)) -> 0
A11: Base amortissable | B11: USD | C11: =Modèle!C$9 -> 50000000 | D11: =C15 -> 45000000 | E11: =D15 -> 40000000 | F11: =E15 -> 35000000 | G11: =F15 -> 30000000 | H11: =G15 -> 25000000 | I11: =H15 -> 20000000 | J11: =I15 -> 15000000 | K11: =J15 -> 10000000 | ... M11: =L15 -> 0
A12: Inverse de la durée restante | B12: % | C12: =IF(C10=0,0,1/C10) -> 0.1 | D12: =IF(D10=0,0,1/D10) -> 0.11111111 | E12: =IF(E10=0,0,1/E10) -> 0.125 | F12: =IF(F10=0,0,1/F10) -> 0.14285714 | G12: =IF(G10=0,0,1/G10) -> 0.16666667 | H12: =IF(H10=0,0,1/H10) -> 0.2 | I12: =IF(I10=0,0,1/I10) -> 0.25 | J12: =IF(J10=0,0,1/J10) -> 0.33333333 | ... M12: =IF(M10=0,0,1/M10) -> 0
A13: Taux dégressif | B13: % | C13: =IF(C10=0,0,IF($C$7*1/$C$6>C12,$C$7*1/$C$6,C12)) -> 0.1 | D13: =IF(D10=0,0,IF($C$7*1/$C$6>D12,$C$7*1/$C$6,D12)) -> 0.11111111 | E13: =IF(E10=0,0,IF($C$7*1/$C$6>E12,$C$7*1/$C$6,E12)) -> 0.125 | F13: =IF(F10=0,0,IF($C$7*1/$C$6>F12,$C$7*1/$C$6,F12)) -> 0.14285714 | G13: =IF(G10=0,0,IF($C$7*1/$C$6>G12,$C$7*1/$C$6,G12)) -> 0.16666667 | H13: =IF(H10=0,0,IF($C$7*1/$C$6>H12,$C$7*1/$C$6,H12)) -> 0.2 | I13: =IF(I10=0,0,IF($C$7*1/$C$6>I12,$C$7*1/$C$6,I12)) -> 0.25 | J13: =IF(J10=0,0,IF($C$7*1/$C$6>J12,$C$7*1/$C$6,J12)) -> 0.33333333 | ... M13: =IF(M10=0,0,IF($C$7*1/$C$6>M12,$C$7*1/$C$6,M12)) -> 0
A14: Charge d'amortissement | B14: USD | C14: =C11*C13 -> 5000000 | D14: =D11*D13 -> 5000000 | E14: =E11*E13 -> 5000000 | F14: =F11*F13 -> 5000000 | G14: =G11*G13 -> 5000000 | H14: =H11*H13 -> 5000000 | I14: =I11*I13 -> 5000000 | J14: =J11*J13 -> 5000000 | ... M14: =M11*M13 -> 0
A15: Amortissement restant | B15: USD | C15: =C11-C14 -> 45000000 | D15: =D11-D14 -> 40000000 | E15: =E11-E14 -> 35000000 | F15: =F11-F14 -> 30000000 | G15: =G11-G14 -> 25000000 | H15: =H11-H14 -> 20000000 | I15: =I11-I14 -> 15000000 | J15: =J11-J14 -> 10000000 | ... M15: =M11-M14 -> 0
A17: Immobilisations de l'année A2
A18: Durée restante | B18: Années | D18: =IF($C$6<D$3,$C$6,D$3) -> 10 | E18: =IF(D18=0,0,IF(D18-1<E$3,D18-1,E$3)) -> 9 | F18: =IF(E18=0,0,IF(E18-1<F$3,E18-1,F$3)) -> 8 | G18: =IF(F18=0,0,IF(F18-1<G$3,F18-1,G$3)) -> 7 | H18: =IF(G18=0,0,IF(G18-1<H$3,G18-1,H$3)) -> 6 | I18: =IF(H18=0,0,IF(H18-1<I$3,H18-1,I$3)) -> 5 | J18: =IF(I18=0,0,IF(I18-1<J$3,I18-1,J$3)) -> 4 | K18: =IF(J18=0,0,IF(J18-1<K$3,J18-1,K$3)) -> 3 | L18: =IF(K18=0,0,IF(K18-1<L$3,K18-1,L$3)) -> 2 | M18: =IF(L18=0,0,IF(L18-1<M$3,L18-1,M$3)) -> 1
A19: Base amortissable | B19: USD | D19: =Modèle!D$9 -> 100000000 | E19: =D23 -> 90000000 | F19: =E23 -> 80000000 | G19: =F23 -> 70000000 | H19: =G23 -> 60000000 | I19: =H23 -> 50000000 | J19: =I23 -> 40000000 | K19: =J23 -> 30000000 | L19: =K23 -> 20000000 | M19: =L23 -> 10000000
A20: Inverse de la durée restante | B20: % | D20: =IF(D18=0,0,1/D18) -> 0.1 | E20: =IF(E18=0,0,1/E18) -> 0.11111111 | F20: =IF(F18=0,0,1/F18) -> 0.125 | G20: =IF(G18=0,0,1/G18) -> 0.14285714 | H20: =IF(H18=0,0,1/H18) -> 0.16666667 | I20: =IF(I18=0,0,1/I18) -> 0.2 | J20: =IF(J18=0,0,1/J18) -> 0.25 | K20: =IF(K18=0,0,1/K18) -> 0.33333333 | ... M20: =IF(M18=0,0,1/M18) -> 1
A21: Taux dégressif | B21: % | D21: =IF(D18=0,0,IF($C$7*1/$C$6>D20,$C$7*1/$C$6,D20)) -> 0.1 | E21: =IF(E18=0,0,IF($C$7*1/$C$6>E20,$C$7*1/$C$6,E20)) -> 0.11111111 | F21: =IF(F18=0,0,IF($C$7*1/$C$6>F20,$C$7*1/$C$6,F20)) -> 0.125 | G21: =IF(G18=0,0,IF($C$7*1/$C$6>G20,$C$7*1/$C$6,G20)) -> 0.14285714 | H21: =IF(H18=0,0,IF($C$7*1/$C$6>H20,$C$7*1/$C$6,H20)) -> 0.16666667 | I21: =IF(I18=0,0,IF($C$7*1/$C$6>I20,$C$7*1/$C$6,I20)) -> 0.2 | J21: =IF(J18=0,0,IF($C$7*1/$C$6>J20,$C$7*1/$C$6,J20)) -> 0.25 | K21: =IF(K18=0,0,IF($C$7*1/$C$6>K20,$C$7*1/$C$6,K20)) -> 0.33333333 | ... M21: =IF(M18=0,0,IF($C$7*1/$C$6>M20,$C$7*1/$C$6,M20)) -> 1
A22: Charge d'amortissement | B22: USD | D22: =D19*D21 -> 10000000 | E22: =E19*E21 -> 10000000 | F22: =F19*F21 -> 10000000 | G22: =G19*G21 -> 10000000 | H22: =H19*H21 -> 10000000 | I22: =I19*I21 -> 10000000 | J22: =J19*J21 -> 10000000 | K22: =K19*K21 -> 10000000 | ... M22: =M19*M21 -> 10000000
A23: Amortissement restant | B23: USD | D23: =D19-D22 -> 90000000 | E23: =E19-E22 -> 80000000 | F23: =F19-F22 -> 70000000 | G23: =G19-G22 -> 60000000 | H23: =H19-H22 -> 50000000 | I23: =I19-I22 -> 40000000 | J23: =J19-J22 -> 30000000 | K23: =K19-K22 -> 20000000 | ... M23: =M19-M22 -> 0
A25: Amortissements des constructions industrielles | B25: USD | C25: =C$14+C$22 -> 5000000 | D25: =D$14+D$22 -> 15000000 | E25: =E$14+E$22 -> 15000000 | F25: =F$14+F$22 -> 15000000 | G25: =G$14+G$22 -> 15000000 | H25: =H$14+H$22 -> 15000000 | I25: =I$14+I$22 -> 15000000 | J25: =J$14+J$22 -> 15000000 | ... M25: =M$14+M$22 -> 10000000
A27: II. AMORTISSEMENTS DES BIENS D'EQUIPEMENT
A28: Durée d'amortissement linéaire | B28: Années | C28: 5
A29: Coefficient d'amortissement dégressif | B29: Coefficient | C29: 2
A31: Immobilisations de l'année A1
A32: Durée restante | B32: Années | C32: =IF($C$28<C$3,$C$28,C$3) -> 5 | D32: =IF(C32=0,0,IF(C32-1<D$3,C32-1,D$3)) -> 4 | E32: =IF(D32=0,0,IF(D32-1<E$3,D32-1,E$3)) -> 3 | F32: =IF(E32=0,0,IF(E32-1<F$3,E32-1,F$3)) -> 2 | G32: =IF(F32=0,0,IF(F32-1<G$3,F32-1,G$3)) -> 1 | H32: =IF(G32=0,0,IF(G32-1<H$3,G32-1,H$3)) -> 0 | I32: =IF(H32=0,0,IF(H32-1<I$3,H32-1,I$3)) -> 0 | J32: =IF(I32=0,0,IF(I32-1<J$3,I32-1,J$3)) -> 0 | K32: =IF(J32=0,0,IF(J32-1<K$3,J32-1,K$3)) -> 0 | ... M32: =IF(L32=0,0,IF(L32-1<M$3,L32-1,M$3)) -> 0
A33: Base amortissable | B33: USD | C33: =Modèle!C$10 -> 0 | D33: =C37 -> 0 | E33: =D37 -> 0 | F33: =E37 -> 0 | G33: =F37 -> 0 | H33: =G37 -> 0 | I33: =H37 -> 0 | J33: =I37 -> 0 | K33: =J37 -> 0 | ... M33: =L37 -> 0
A34: Inverse de la durée restante | B34: % | C34: =IF(C32=0,0,1/C32) -> 0.2 | D34: =IF(D32=0,0,1/D32) -> 0.25 | E34: =IF(E32=0,0,1/E32) -> 0.33333333 | F34: =IF(F32=0,0,1/F32) -> 0.5 | G34: =IF(G32=0,0,1/G32) -> 1 | H34: =IF(H32=0,0,1/H32) -> 0 | I34: =IF(I32=0,0,1/I32) -> 0 | J34: =IF(J32=0,0,1/J32) -> 0 | ... M34: =IF(M32=0,0,1/M32) -> 0
A35: Taux dégressif | B35: % | C35: =IF(C32=0,0,IF($C$29*1/$C$28>C34,$C$29*1/$C$28,C34)) -> 0.4 | D35: =IF(D32=0,0,IF($C$29*1/$C$28>D34,$C$29*1/$C$28,D34)) -> 0.4 | E35: =IF(E32=0,0,IF($C$29*1/$C$28>E34,$C$29*1/$C$28,E34)) -> 0.4 | F35: =IF(F32=0,0,IF($C$29*1/$C$28>F34,$C$29*1/$C$28,F34)) -> 0.5 | G35: =IF(G32=0,0,IF($C$29*1/$C$28>G34,$C$29*1/$C$28,G34)) -> 1 | H35: =IF(H32=0,0,IF($C$29*1/$C$28>H34,$C$29*1/$C$28,H34)) -> 0 | I35: =IF(I32=0,0,IF($C$29*1/$C$28>I34,$C$29*1/$C$28,I34)) -> 0 | J35: =IF(J32=0,0,IF($C$29*1/$C$28>J34,$C$29*1/$C$28,J34)) -> 0 | ... M35: =IF(M32=0,0,IF($C$29*1/$C$28>M34,$C$29*1/$C$28,M34)) -> 0
A36: Charge d'amortissement | B36: USD | C36: =C33*C35 -> 0 | D36: =D33*D35 -> 0 | E36: =E33*E35 -> 0 | F36: =F33*F35 -> 0 | G36: =G33*G35 -> 0 | H36: =H33*H35 -> 0 | I36: =I33*I35 -> 0 | J36: =J33*J35 -> 0 | ... M36: =M33*M35 -> 0
A37: Amortissement restant | B37: USD | C37: =C33-C36 -> 0 | D37: =D33-D36 -> 0 | E37: =E33-E36 -> 0 | F37: =F33-F36 -> 0 | G37: =G33-G36 -> 0 | H37: =H33-H36 -> 0 | I37: =I33-I36 -> 0 | J37: =J33-J36 -> 0 | ... M37: =M33-M36 -> 0
A39: Immobilisations de l'année A2
A40: Durée restante | B40: Années | D40: =IF($C$28<D$3,$C$28,D$3) -> 5 | E40: =IF(D40=0,0,IF(D40-1<E$3,D40-1,E$3)) -> 4 | F40: =IF(E40=0,0,IF(E40-1<F$3,E40-1,F$3)) -> 3 | G40: =IF(F40=0,0,IF(F40-1<G$3,F40-1,G$3)) -> 2 | H40: =IF(G40=0,0,IF(G40-1<H$3,G40-1,H$3)) -> 1 | I40: =IF(H40=0,0,IF(H40-1<I$3,H40-1,I$3)) -> 0 | J40: =IF(I40=0,0,IF(I40-1<J$3,I40-1,J$3)) -> 0 | K40: =IF(J40=0,0,IF(J40-1<K$3,J40-1,K$3)) -> 0 | L40: =IF(K40=0,0,IF(K40-1<L$3,K40-1,L$3)) -> 0 | M40: =IF(L40=0,0,IF(L40-1<M$3,L40-1,M$3)) -> 0
A41: Base amortissable | B41: USD | D41: =Modèle!D$10 -> 50000000 | E41: =D45 -> 30000000 | F41: =E45 -> 18000000 | G41: =F45 -> 10800000 | H41: =G45 -> 5400000 | I41: =H45 -> 0 | J41: =I45 -> 0 | K41: =J45 -> 0 | L41: =K45 -> 0 | M41: =L45 -> 0
A42: Inverse de la durée restante | B42: % | D42: =IF(D40=0,0,1/D40) -> 0.2 | E42: =IF(E40=0,0,1/E40) -> 0.25 | F42: =IF(F40=0,0,1/F40) -> 0.33333333 | G42: =IF(G40=0,0,1/G40) -> 0.5 | H42: =IF(H40=0,0,1/H40) -> 1 | I42: =IF(I40=0,0,1/I40) -> 0 | J42: =IF(J40=0,0,1/J40) -> 0 | K42: =IF(K40=0,0,1/K40) -> 0 | ... M42: =IF(M40=0,0,1/M40) -> 0
A43: Taux dégressif | B43: % | D43: =IF(D40=0,0,IF($C$29*1/$C$28>D42,$C$29*1/$C$28,D42)) -> 0.4 | E43: =IF(E40=0,0,IF($C$29*1/$C$28>E42,$C$29*1/$C$28,E42)) -> 0.4 | F43: =IF(F40=0,0,IF($C$29*1/$C$28>F42,$C$29*1/$C$28,F42)) -> 0.4 | G43: =IF(G40=0,0,IF($C$29*1/$C$28>G42,$C$29*1/$C$28,G42)) -> 0.5 | H43: =IF(H40=0,0,IF($C$29*1/$C$28>H42,$C$29*1/$C$28,H42)) -> 1 | I43: =IF(I40=0,0,IF($C$29*1/$C$28>I42,$C$29*1/$C$28,I42)) -> 0 | J43: =IF(J40=0,0,IF($C$29*1/$C$28>J42,$C$29*1/$C$28,J42)) -> 0 | K43: =IF(K40=0,0,IF($C$29*1/$C$28>K42,$C$29*1/$C$28,K42)) -> 0 | ... M43: =IF(M40=0,0,IF($C$29*1/$C$28>M42,$C$29*1/$C$28,M42)) -> 0
A44: Charge d'amortissement | B44: USD | D44: =D41*D43 -> 20000000 | E44: =E41*E43 -> 12000000 | F44: =F41*F43 -> 7200000 | G44: =G41*G43 -> 5400000 | H44: =H41*H43 -> 5400000 | I44: =I41*I43 -> 0 | J44: =J41*J43 -> 0 | K44: =K41*K43 -> 0 | ... M44: =M41*M43 -> 0
A45: Amortissement restant | B45: USD | D45: =D41-D44 -> 30000000 | E45: =E41-E44 -> 18000000 | F45: =F41-F44 -> 10800000 | G45: =G41-G44 -> 5400000 | H45: =H41-H44 -> 0 | I45: =I41-I44 -> 0 | J45: =J41-J44 -> 0 | K45: =K41-K44 -> 0 | ... M45: =M41-M44 -> 0
A47: Immobilisations de l'année A3
A48: Durée restante | B48: Années | E48: =IF($C$28<E$3,$C$28,E$3) -> 5 | F48: =IF(E48=0,0,IF(E48-1<F$3,E48-1,F$3)) -> 4 | G48: =IF(F48=0,0,IF(F48-1<G$3,F48-1,G$3)) -> 3 | H48: =IF(G48=0,0,IF(G48-1<H$3,G48-1,H$3)) -> 2 | I48: =IF(H48=0,0,IF(H48-1<I$3,H48-1,I$3)) -> 1 | J48: =IF(I48=0,0,IF(I48-1<J$3,I48-1,J$3)) -> 0 | K48: =IF(J48=0,0,IF(J48-1<K$3,J48-1,K$3)) -> 0 | L48: =IF(K48=0,0,IF(K48-1<L$3,K48-1,L$3)) -> 0 | M48: =IF(L48=0,0,IF(L48-1<M$3,L48-1,M$3)) -> 0
A49: Base amortissable | B49: USD | E49: =Modèle!E$10 -> 5000000 | F49: =E53 -> 3000000 | G49: =F53 -> 1800000 | H49: =G53 -> 1080000 | I49: =H53 -> 540000 | J49: =I53 -> 0 | K49: =J53 -> 0 | L49: =K53 -> 0 | M49: =L53 -> 0
...
