Workbook

Sheet Index
A1: Feuille | B1: Fichier source | C1: Feuille d'origine
A2: 01_02_Rente_min | B2: 02-Rente-miniere.xlsx | C2: Modèle
A3: 02_03_Impots_su | B3: 03-Impots-sur-la-production.xlsx | C3: Modèle
A4: 03_04_Charges_d_1 | B4: 04-Charges-d-amortissement.xlsx | C4: Modèle
A5: 03_04_Charges_d_2 | B5: 04-Charges-d-amortissement.xlsx | C5: Amortissements
A6: 04_05_Charges_f_1 | B6: 05-Charges-financieres (1).xlsx | C6: Modèle
A7: 04_05_Charges_f_2 | B7: 05-Charges-financieres (1).xlsx | C7: Amortissements et Emprunt
A8: 05_05_Charges_f_1 | B8: 05-Charges-financieres.xlsx | C8: Modèle
A9: 05_05_Charges_f_2 | B9: 05-Charges-financieres.xlsx | C9: Amortissements et Emprunt
A10: 06_06_IS_IMF_1 | B10: 06-IS-IMF.xlsx | C10: Modèle
A11: 06_06_IS_IMF_2 | B11: 06-IS-IMF.xlsx | C11: Amortissements et Emprunt
A12: 07_07_TEMI_1 | B12: 07-TEMI.xlsx | C12: Modèle
... A20: 10_10_Illustrat_3 | B20: 10-Illustrations-graphiques.xlsx | C20: Graphiques

Sheet 01_02_Rente_min
A1: Nom | B1: Unité | C1: Année 1 | D1: Année 2 | E1: Année 3 | F1: Année 4 | G1: Année 5 | H1: Année 6 | I1: Année 7 | J1: Année 8 | K1: Année 9 | L1: Année 10 | M1: Année 11 | N1: SOMME | O1: VAN
A3: I. PRODUCTION
A4: Production d'or | B4: oz | E4: 250000 | F4: 250000 | G4: 250000 | H4: 250000 | I4: 250000 | J4: 250000 | K4: 250000 | L4: 250000 | N4: =SUM($C4:$M4)
A5: Cours de l'or | B5: USD/oz | E5: 1300 | F5: 1300 | G5: 1300 | H5: 1300 | I5: 1300 | J5: 1300 | K5: 1300 | L5: 1300
A6: Chiffre d'affaires | B6: USD | C6: =C$4*C$5 | D6: =D$4*D$5 | E6: =E$4*E$5 | F6: =F$4*F$5 | G6: =G$4*G$5 | H6: =H$4*H$5 | I6: =I$4*I$5 | J6: =J$4*J$5 | ... M6: =M$4*M$5 | N6: =SUM($C6:$M6) | O6: =$C6+NPV(10%,$D6:$M6)
A8: II. DEPENSES D'INVESTISSEMENT (CAPEX)
A9: Coûts des construction industrielles | B9: USD | C9: 50000000 | D9: 100000000 | N9: =SUM($C9:$M9) | O9: =$C9+NPV(10%,$D9:$M9)
A10: Coûts des biens d'équipement | B10: USD | D10: 50000000 | E10: 5000000 | F10: 5000000 | G10: 5000000 | H10: 5000000 | I10: 5000000 | J10: 5000000 | K10: 5000000 | L10: 5000000 | N10: =SUM($C10:$M10) | O10: =$C10+NPV(10%,$D10:$M10)
A11: Coûts de réhabilitation du site | B11: USD | M11: 10000000 | N11: =SUM($C11:$M11) | O11: =$C11+NPV(10%,$D11:$M11)
A12: Total des dépenses d'investissement | B12: USD | C12: =SUM(C$9:C$11) | D12: =SUM(D$9:D$11) | E12: =SUM(E$9:E$11) | F12: =SUM(F$9:F$11) | G12: =SUM(G$9:G$11) | H12: =SUM(H$9:H$11) | I12: =SUM(I$9:I$11) | J12: =SUM(J$9:J$11) | ... M12: =SUM(M$9:M$11) | N12: =SUM($C12:$M12) | O12: =$C12+NPV(10%,$D12:$M12)
A14: III. COÛTS D'EXPLOITATION (OPEX)
A15: Coût moyen d'exploitation | B15: USD/oz | E15: 700 | F15: 700 | G15: 700 | H15: 700 | I15: 700 | J15: 700 | K15: 700 | L15: 700
A16: Total des coûts d'exploitation | B16: USD | C16: =C$4*C$15 | D16: =D$4*D$15 | E16: =E$4*E$15 | F16: =F$4*F$15 | G16: =G$4*G$15 | H16: =H$4*H$15 | I16: =I$4*I$15 | J16: =J$4*J$15 | ... M16: =M$4*M$15 | N16: =SUM($C16:$M16) | O16: =$C16+NPV(10%,$D16:$M16)
A18: IV. FLUX NETS DE TRESORERIE AVANT IMPÔTS
A19: Flux nets de trésorerie avant impôts | B19: USD | C19: =C$6-C$12-C$16 | D19: =D$6-D$12-D$16 | E19: =E$6-E$12-E$16 | F19: =F$6-F$12-F$16 | G19: =G$6-G$12-G$16 | H19: =H$6-H$12-H$16 | I19: =I$6-I$12-I$16 | J19: =J$6-J$12-J$16 | ... M19: =M$6-M$12-M$16 | N19: =SUM($C19:$M19) | O19: =$C19+NPV(10%,$D19:$M19)
A20: Taux de rendement interne avant impôts | B20: % | C20: =IF(ISNUMBER(IRR($C19:C19)),IF(IRR($C19:C19)>0,IRR($C19:C19),""),"") | D20: =IF(ISNUMBER(IRR($C19:D19)),IF(IRR($C19:D19)>0,IRR($C19:D19),""),"") | E20: =IF(ISNUMBER(IRR($C19:E19)),IF(IRR($C19:E19)>0,IRR($C19:E19),""),"") | F20: =IF(ISNUMBER(IRR($C19:F19)),IF(IRR($C19:F19)>0,IRR($C19:F19),""),"") | G20: =IF(ISNUMBER(IRR($C19:G19)),IF(IRR($C19:G19)>0,IRR($C19:G19),""),"") | H20: =IF(ISNUMBER(IRR($C19:H19)),IF(IRR($C19:H19)>0,IRR($C19:H19),""),"") | I20: =IF(ISNUMBER(IRR($C19:I19)),IF(IRR($C19:I19)>0,IRR($C19:I19),""),"") | J20: =IF(ISNUMBER(IRR($C19:J19)),IF(IRR($C19:J19)>0,IRR($C19:J19),""),"") | ... M20: =IF(ISNUMBER(IRR($C19:M19)),IF(IRR($C19:M19)>0,IRR($C19:M19),""),"")
A23: V. IMPOT SUR LA PRODUCTION
A24: Droit fixes | B24: USD | C24: 100000
A25: Redevance superficiaire | B25: USD | C25: =100*100 | D25: =100*100 | E25: =100*100 | F25: =100*100 | G25: =100*100 | H25: =100*100 | I25: =100*100 | J25: =100*100 | ... M25: =100*100
A26: Redevance minière | B26: USD | E26: =E6*0.04 | F26: =F6*0.04 | G26: =G6*0.04 | H26: =H6*0.04 | I26: =I6*0.04 | J26: =J6*0.04 | K26: =K6*0.04 | L26: =L6*0.04 | M26: =M6*0.04

Sheet 02_03_Impots_su
A1: Nom | B1: Unité | C1: Année 1 | D1: Année 2 | E1: Année 3 | F1: Année 4 | G1: Année 5 | H1: Année 6 | I1: Année 7 | J1: Année 8 | K1: Année 9 | L1: Année 10 | M1: Année 11 | N1: SOMME | O1: VAN
A3: I. PRODUCTION
A4: Production d'or | B4: oz | E4: 250000 | F4: 250000 | G4: 250000 | H4: 250000 | I4: 250000 | J4: 250000 | K4: 250000 | L4: 250000 | N4: =SUM($C4:$M4)
A5: Cours de l'or | B5: USD/oz | E5: 1300 | F5: 1300 | G5: 1300 | H5: 1300 | I5: 1300 | J5: 1300 | K5: 1300 | L5: 1300
A6: Chiffre d'affaires | B6: USD | C6: =C$4*C$5 | D6: =D$4*D$5 | E6: =E$4*E$5 | F6: =F$4*F$5 | G6: =G$4*G$5 | H6: =H$4*H$5 | I6: =I$4*I$5 | J6: =J$4*J$5 | ... M6: =M$4*M$5 | N6: =SUM($C6:$M6) | O6: =$C6+NPV(10%,$D6:$M6)
A8: II. DEPENSES D'INVESTISSEMENT (CAPEX)
A9: Coûts des construction industrielles | B9: USD | C9: 50000000 | D9: 100000000 | N9: =SUM($C9:$M9) | O9: =$C9+NPV(10%,$D9:$M9)
A10: Coûts des biens d'équipement | B10: USD | D10: 50000000 | E10: 5000000 | F10: 5000000 | G10: 5000000 | H10: 5000000 | I10: 5000000 | J10: 5000000 | K10: 5000000 | L10: 5000000 | N10: =SUM($C10:$M10) | O10: =$C10+NPV(10%,$D10:$M10)
A11: Coûts de réhabilitation du site | B11: USD | M11: 10000000 | N11: =SUM($C11:$M11) | O11: =$C11+NPV(10%,$D11:$M11)
A12: Total des dépenses d'investissement | B12: USD | C12: =SUM(C$9:C$11) | D12: =SUM(D$9:D$11) | E12: =SUM(E$9:E$11) | F12: =SUM(F$9:F$11) | G12: =SUM(G$9:G$11) | H12: =SUM(H$9:H$11) | I12: =SUM(I$9:I$11) | J12: =SUM(J$9:J$11) | ... M12: =SUM(M$9:M$11) | N12: =SUM($C12:$M12) | O12: =$C12+NPV(10%,$D12:$M12)
A14: III. COÛTS D'EXPLOITATION (OPEX)
A15: Coût moyen d'exploitation | B15: USD/oz | E15: 700 | F15: 700 | G15: 700 | H15: 700 | I15: 700 | J15: 700 | K15: 700 | L15: 700
A16: Total des coûts d'exploitation | B16: USD | C16: =C$4*C$15 | D16: =D$4*D$15 | E16: =E$4*E$15 | F16: =F$4*F$15 | G16: =G$4*G$15 | H16: =H$4*H$15 | I16: =I$4*I$15 | J16: =J$4*J$15 | ... M16: =M$4*M$15 | N16: =SUM($C16:$M16) | O16: =$C16+NPV(10%,$D16:$M16)
A18: IV. FLUX NETS DE TRESORERIE AVANT IMPÔTS
A19: Flux nets de trésorerie avant impôts | B19: USD | C19: =C$6-C$12-C$16 | D19: =D$6-D$12-D$16 | E19: =E$6-E$12-E$16 | F19: =F$6-F$12-F$16 | G19: =G$6-G$12-G$16 | H19: =H$6-H$12-H$16 | I19: =I$6-I$12-I$16 | J19: =J$6-J$12-J$16 | ... M19: =M$6-M$12-M$16 | N19: =SUM($C19:$M19) | O19: =$C19+NPV(10%,$D19:$M19)
A20: Taux de rendement interne avant impôts | B20: % | C20: =IF(ISNUMBER(IRR($C19:C19)),IF(IRR($C19:C19)>0,IRR($C19:C19),""),"") | D20: =IF(ISNUMBER(IRR($C19:D19)),IF(IRR($C19:D19)>0,IRR($C19:D19),""),"") | E20: =IF(ISNUMBER(IRR($C19:E19)),IF(IRR($C19:E19)>0,IRR($C19:E19),""),"") | F20: =IF(ISNUMBER(IRR($C19:F19)),IF(IRR($C19:F19)>0,IRR($C19:F19),""),"") | G20: =IF(ISNUMBER(IRR($C19:G19)),IF(IRR($C19:G19)>0,IRR($C19:G19),""),"") | H20: =IF(ISNUMBER(IRR($C19:H19)),IF(IRR($C19:H19)>0,IRR($C19:H19),""),"") | I20: =IF(ISNUMBER(IRR($C19:I19)),IF(IRR($C19:I19)>0,IRR($C19:I19),""),"") | J20: =IF(ISNUMBER(IRR($C19:J19)),IF(IRR($C19:J19)>0,IRR($C19:J19),""),"") | ... M20: =IF(ISNUMBER(IRR($C19:M19)),IF(IRR($C19:M19)>0,IRR($C19:M19),""),"")
A22: V. DROITS FIXES
A23: Droits fixes | B23: USD | C23: 100000 | N23: =SUM($C23:$M23) | O23: =$C23+NPV(10%,$D23:$M23)
A25: VI. REDEVANCE SUPERFICAIRE
A26: Superficie de la mine | B26: km² | C26: 100 | D26: 100 | E26: 100 | F26: 100 | G26: 100 | H26: 100 | I26: 100 | J26: 100 | K26: 100 | L26: 100 | M26: 100
A27: Montant de la redevance superfiaire | B27: USD/km² | C27: 100 | D27: 100 | E27: 100 | F27: 100 | G27: 100 | H27: 100 | I27: 100 | J27: 100 | K27: 100 | L27: 100 | M27: 100
A28: Redevance superficiaire | B28: USD | C28: =C$26*C$27 | D28: =D$26*D$27 | E28: =E$26*E$27 | F28: =F$26*F$27 | G28: =G$26*G$27 | H28: =H$26*H$27 | I28: =I$26*I$27 | J28: =J$26*J$27 | ... M28: =M$26*M$27 | N28: =SUM($C28:$M28) | O28: =$C28+NPV(10%,$D28:$M28)
A30: VII. REDEVANCE MINIERE
A31: Taux de la redevance minière | B31: % | C31: =IF(ISNUMBER(C5),IF(C$5<1300,3%,IF(C$5<1500,4%,5%)),"") | D31: =IF(ISNUMBER(D5),IF(D$5<1300,3%,IF(D$5<1500,4%,5%)),"") | E31: =IF(ISNUMBER(E5),IF(E$5<1300,3%,IF(E$5<1500,4%,5%)),"") | F31: =IF(ISNUMBER(F5),IF(F$5<1300,3%,IF(F$5<1500,4%,5%)),"") | G31: =IF(ISNUMBER(G5),IF(G$5<1300,3%,IF(G$5<1500,4%,5%)),"") | H31: =IF(ISNUMBER(H5),IF(H$5<1300,3%,IF(H$5<1500,4%,5%)),"") | I31: =IF(ISNUMBER(I5),IF(I$5<1300,3%,IF(I$5<1500,4%,5%)),"") | J31: =IF(ISNUMBER(J5),IF(J$5<1300,3%,IF(J$5<1500,4%,5%)),"") | ... M31: =IF(ISNUMBER(M5),IF(M$5<1300,3%,IF(M$5<1500,4%,5%)),"")
A32: Redevance minière | B32: USD | C32: =IF(ISNUMBER(C31),C$6*C$31,0) | D32: =IF(ISNUMBER(D31),D$6*D$31,0) | E32: =IF(ISNUMBER(E31),E$6*E$31,0) | F32: =IF(ISNUMBER(F31),F$6*F$31,0) | G32: =IF(ISNUMBER(G31),G$6*G$31,0) | H32: =IF(ISNUMBER(H31),H$6*H$31,0) | I32: =IF(ISNUMBER(I31),I$6*I$31,0) | J32: =IF(ISNUMBER(J31),J$6*J$31,0) | ... M32: =IF(ISNUMBER(M31),M$6*M$31,0) | N32: =SUM($C32:$M32) | O32: =$C32+NPV(10%,$D32:$M32)

Sheet 03_04_Charges_d_1
A1: Nom | B1: Unité | C1: Année 1 | D1: Année 2 | E1: Année 3 | F1: Année 4 | G1: Année 5 | H1: Année 6 | I1: Année 7 | J1: Année 8 | K1: Année 9 | L1: Année 10 | M1: Année 11 | N1: SOMME | O1: VAN
A3: I. PRODUCTION
A4: Production d'or | B4: oz | E4: 250000 | F4: 250000 | G4: 250000 | H4: 250000 | I4: 250000 | J4: 250000 | K4: 250000 | L4: 250000 | N4: =SUM($C4:$M4)
A5: Cours de l'or | B5: USD/oz | E5: 1300 | F5: 1300 | G5: 1300 | H5: 1300 | I5: 1300 | J5: 1300 | K5: 1300 | L5: 1300
A6: Chiffre d'affaires | B6: USD | C6: =C$4*C$5 | D6: =D$4*D$5 | E6: =E$4*E$5 | F6: =F$4*F$5 | G6: =G$4*G$5 | H6: =H$4*H$5 | I6: =I$4*I$5 | J6: =J$4*J$5 | ... M6: =M$4*M$5 | N6: =SUM($C6:$M6) | O6: =$C6+NPV(10%,$D6:$M6)
A8: II. DEPENSES D'INVESTISSEMENT (CAPEX)
A9: Coûts des construction industrielles | B9: USD | C9: 50000000 | D9: 100000000 | N9: =SUM($C9:$M9) | O9: =$C9+NPV(10%,$D9:$M9)
A10: Coûts des biens d'équipement | B10: USD | D10: 50000000 | E10: 5000000 | F10: 5000000 | G10: 5000000 | H10: 5000000 | I10: 5000000 | J10: 5000000 | K10: 5000000 | L10: 5000000 | N10: =SUM($C10:$M10) | O10: =$C10+NPV(10%,$D10:$M10)
A11: Coûts de réhabilitation du site | B11: USD | M11: 10000000 | N11: =SUM($C11:$M11) | O11: =$C11+NPV(10%,$D11:$M11)
A12: Total des dépenses d'investissement | B12: USD | C12: =SUM(C$9:C$11) | D12: =SUM(D$9:D$11) | E12: =SUM(E$9:E$11) | F12: =SUM(F$9:F$11) | G12: =SUM(G$9:G$11) | H12: =SUM(H$9:H$11) | I12: =SUM(I$9:I$11) | J12: =SUM(J$9:J$11) | ... M12: =SUM(M$9:M$11) | N12: =SUM($C12:$M12) | O12: =$C12+NPV(10%,$D12:$M12)
A14: III. COÛTS D'EXPLOITATION (OPEX)
A15: Coût moyen d'exploitation | B15: USD/oz | E15: 700 | F15: 700 | G15: 700 | H15: 700 | I15: 700 | J15: 700 | K15: 700 | L15: 700
A16: Total des coûts d'exploitation | B16: USD | C16: =C$4*C$15 | D16: =D$4*D$15 | E16: =E$4*E$15 | F16: =F$4*F$15 | G16: =G$4*G$15 | H16: =H$4*H$15 | I16: =I$4*I$15 | J16: =J$4*J$15 | ... M16: =M$4*M$15 | N16: =SUM($C16:$M16) | O16: =$C16+NPV(10%,$D16:$M16)
A18: IV. FLUX NETS DE TRESORERIE AVANT IMPÔTS
A19: Flux nets de trésorerie avant impôts | B19: USD | C19: =C$6-C$12-C$16 | D19: =D$6-D$12-D$16 | E19: =E$6-E$12-E$16 | F19: =F$6-F$12-F$16 | G19: =G$6-G$12-G$16 | H19: =H$6-H$12-H$16 | I19: =I$6-I$12-I$16 | J19: =J$6-J$12-J$16 | ... M19: =M$6-M$12-M$16 | N19: =SUM($C19:$M19) | O19: =$C19+NPV(10%,$D19:$M19)
A20: Taux de rendement interne avant impôts | B20: % | C20: =IF(ISNUMBER(IRR($C19:C19)),IF(IRR($C19:C19)>0,IRR($C19:C19),""),"") | D20: =IF(ISNUMBER(IRR($C19:D19)),IF(IRR($C19:D19)>0,IRR($C19:D19),""),"") | E20: =IF(ISNUMBER(IRR($C19:E19)),IF(IRR($C19:E19)>0,IRR($C19:E19),""),"") | F20: =IF(ISNUMBER(IRR($C19:F19)),IF(IRR($C19:F19)>0,IRR($C19:F19),""),"") | G20: =IF(ISNUMBER(IRR($C19:G19)),IF(IRR($C19:G19)>0,IRR($C19:G19),""),"") | H20: =IF(ISNUMBER(IRR($C19:H19)),IF(IRR($C19:H19)>0,IRR($C19:H19),""),"") | I20: =IF(ISNUMBER(IRR($C19:I19)),IF(IRR($C19:I19)>0,IRR($C19:I19),""),"") | J20: =IF(ISNUMBER(IRR($C19:J19)),IF(IRR($C19:J19)>0,IRR($C19:J19),""),"") | ... M20: =IF(ISNUMBER(IRR($C19:M19)),IF(IRR($C19:M19)>0,IRR($C19:M19),""),"")
A22: V. DROITS FIXES
A23: Droits fixes | B23: USD | C23: 100000 | N23: =SUM($C23:$M23) | O23: =$C23+NPV(10%,$D23:$M23)
A25: VI. REDEVANCE SUPERFICAIRE
A26: Superficie de la mine | B26: km² | C26: 100 | D26: 100 | E26: 100 | F26: 100 | G26: 100 | H26: 100 | I26: 100 | J26: 100 | K26: 100 | L26: 100 | M26: 100
A27: Montant de la redevance superfiaire | B27: USD/km² | C27: 100 | D27: 100 | E27: 100 | F27: 100 | G27: 100 | H27: 100 | I27: 100 | J27: 100 | K27: 100 | L27: 100 | M27: 100
A28: Redevance superficiaire | B28: USD | C28: =C$26*C$27 | D28: =D$26*D$27 | E28: =E$26*E$27 | F28: =F$26*F$27 | G28: =G$26*G$27 | H28: =H$26*H$27 | I28: =I$26*I$27 | J28: =J$26*J$27 | ... M28: =M$26*M$27 | N28: =SUM($C28:$M28) | O28: =$C28+NPV(10%,$D28:$M28)
A30: VII. REDEVANCE MINIERE
A31: Taux de la redevance minière | B31: % | C31: =IF(ISNUMBER(C5),IF(C$5<1300,3%,IF(C$5<1500,4%,5%)),"") | D31: =IF(ISNUMBER(D5),IF(D$5<1300,3%,IF(D$5<1500,4%,5%)),"") | E31: =IF(ISNUMBER(E5),IF(E$5<1300,3%,IF(E$5<1500,4%,5%)),"") | F31: =IF(ISNUMBER(F5),IF(F$5<1300,3%,IF(F$5<1500,4%,5%)),"") | G31: =IF(ISNUMBER(G5),IF(G$5<1300,3%,IF(G$5<1500,4%,5%)),"") | H31: =IF(ISNUMBER(H5),IF(H$5<1300,3%,IF(H$5<1500,4%,5%)),"") | I31: =IF(ISNUMBER(I5),IF(I$5<1300,3%,IF(I$5<1500,4%,5%)),"") | J31: =IF(ISNUMBER(J5),IF(J$5<1300,3%,IF(J$5<1500,4%,5%)),"") | ... M31: =IF(ISNUMBER(M5),IF(M$5<1300,3%,IF(M$5<1500,4%,5%)),"")
A32: Redevance minière | B32: USD | C32: =IF(ISNUMBER(C31),C$6*C$31,0) | D32: =IF(ISNUMBER(D31),D$6*D$31,0) | E32: =IF(ISNUMBER(E31),E$6*E$31,0) | F32: =IF(ISNUMBER(F31),F$6*F$31,0) | G32: =IF(ISNUMBER(G31),G$6*G$31,0) | H32: =IF(ISNUMBER(H31),H$6*H$31,0) | I32: =IF(ISNUMBER(I31),I$6*I$31,0) | J32: =IF(ISNUMBER(J31),J$6*J$31,0) | ... M32: =IF(ISNUMBER(M31),M$6*M$31,0) | N32: =SUM($C32:$M32) | O32: =$C32+NPV(10%,$D32:$M32)

Sheet 03_04_Charges_d_2
A1: Nom | B1: Unité | C1: Année 1 | D1: Année 2 | E1: Année 3 | F1: Année 4 | G1: Année 5 | H1: Année 6 | I1: Année 7 | J1: Année 8 | K1: Année 9 | L1: Année 10 | M1: Année 11
A3: Durée restante maximum | B3: Années | C3: 11 | D3: 10 | E3: 9 | F3: 8 | G3: 7 | H3: 6 | I3: 5 | J3: 4 | K3: 3 | L3: 2 | M3: 1
A5: I. AMORTISSEMENTS DES CONSTRUCTIONS INDUSTRIELLES
A6: Durée d'amortissement linéaire | B6: Années | C6: 10
A7: Coefficient d'amortissement dégressif | B7: Coefficient | C7: 1
A9: Immobilisations de l'année A1
A10: Durée restante | B10: Années | C10: =IF($C$6<C$3,$C$6,C$3) | D10: =IF(C10=0,0,IF(C10-1<D$3,C10-1,D$3)) | E10: =IF(D10=0,0,IF(D10-1<E$3,D10-1,E$3)) | F10: =IF(E10=0,0,IF(E10-1<F$3,E10-1,F$3)) | G10: =IF(F10=0,0,IF(F10-1<G$3,F10-1,G$3)) | H10: =IF(G10=0,0,IF(G10-1<H$3,G10-1,H$3)) | I10: =IF(H10=0,0,IF(H10-1<I$3,H10-1,I$3)) | J10: =IF(I10=0,0,IF(I10-1<J$3,I10-1,J$3)) | K10: =IF(J10=0,0,IF(J10-1<K$3,J10-1,K$3)) | ... M10: =IF(L10=0,0,IF(L10-1<M$3,L10-1,M$3))
A11: Base amortissable | B11: USD | C11: =Modèle!C$9 | D11: =C15 | E11: =D15 | F11: =E15 | G11: =F15 | H11: =G15 | I11: =H15 | J11: =I15 | K11: =J15 | ... M11: =L15
A12: Inverse de la durée restante | B12: % | C12: =IF(C10=0,0,1/C10) | D12: =IF(D10=0,0,1/D10) | E12: =IF(E10=0,0,1/E10) | F12: =IF(F10=0,0,1/F10) | G12: =IF(G10=0,0,1/G10) | H12: =IF(H10=0,0,1/H10) | I12: =IF(I10=0,0,1/I10) | J12: =IF(J10=0,0,1/J10) | ... M12: =IF(M10=0,0,1/M10)
A13: Taux dégressif | B13: % | C13: =IF(C10=0,0,IF($C$7*1/$C$6>C12,$C$7*1/$C$6,C12)) | D13: =IF(D10=0,0,IF($C$7*1/$C$6>D12,$C$7*1/$C$6,D12)) | E13: =IF(E10=0,0,IF($C$7*1/$C$6>E12,$C$7*1/$C$6,E12)) | F13: =IF(F10=0,0,IF($C$7*1/$C$6>F12,$C$7*1/$C$6,F12)) | G13: =IF(G10=0,0,IF($C$7*1/$C$6>G12,$C$7*1/$C$6,G12)) | H13: =IF(H10=0,0,IF($C$7*1/$C$6>H12,$C$7*1/$C$6,H12)) | I13: =IF(I10=0,0,IF($C$7*1/$C$6>I12,$C$7*1/$C$6,I12)) | J13: =IF(J10=0,0,IF($C$7*1/$C$6>J12,$C$7*1/$C$6,J12)) | ... M13: =IF(M10=0,0,IF($C$7*1/$C$6>M12,$C$7*1/$C$6,M12))
A14: Charge d'amortissement | B14: USD | C14: =C11*C13 | D14: =D11*D13 | E14: =E11*E13 | F14: =F11*F13 | G14: =G11*G13 | H14: =H11*H13 | I14: =I11*I13 | J14: =J11*J13 | ... M14: =M11*M13
A15: Amortissement restant | B15: USD | C15: =C11-C14 | D15: =D11-D14 | E15: =E11-E14 | F15: =F11-F14 | G15: =G11-G14 | H15: =H11-H14 | I15: =I11-I14 | J15: =J11-J14 | ... M15: =M11-M14
A17: Immobilisations de l'année A2
A18: Durée restante | B18: Années | D18: =IF($C$6<D$3,$C$6,D$3) | E18: =IF(D18=0,0,IF(D18-1<E$3,D18-1,E$3)) | F18: =IF(E18=0,0,IF(E18-1<F$3,E18-1,F$3)) | G18: =IF(F18=0,0,IF(F18-1<G$3,F18-1,G$3)) | H18: =IF(G18=0,0,IF(G18-1<H$3,G18-1,H$3)) | I18: =IF(H18=0,0,IF(H18-1<I$3,H18-1,I$3)) | J18: =IF(I18=0,0,IF(I18-1<J$3,I18-1,J$3)) | K18: =IF(J18=0,0,IF(J18-1<K$3,J18-1,K$3)) | L18: =IF(K18=0,0,IF(K18-1<L$3,K18-1,L$3)) | M18: =IF(L18=0,0,IF(L18-1<M$3,L18-1,M$3))
A19: Base amortissable | B19: USD | D19: =Modèle!D$9 | E19: =D23 | F19: =E23 | G19: =F23 | H19: =G23 | I19: =H23 | J19: =I23 | K19: =J23 | L19: =K23 | M19: =L23
A20: Inverse de la durée restante | B20: % | D20: =IF(D18=0,0,1/D18) | E20: =IF(E18=0,0,1/E18) | F20: =IF(F18=0,0,1/F18) | G20: =IF(G18=0,0,1/G18) | H20: =IF(H18=0,0,1/H18) | I20: =IF(I18=0,0,1/I18) | J20: =IF(J18=0,0,1/J18) | K20: =IF(K18=0,0,1/K18) | ... M20: =IF(M18=0,0,1/M18)
A21: Taux dégressif | B21: % | D21: =IF(D18=0,0,IF($C$7*1/$C$6>D20,$C$7*1/$C$6,D20)) | E21: =IF(E18=0,0,IF($C$7*1/$C$6>E20,$C$7*1/$C$6,E20)) | F21: =IF(F18=0,0,IF($C$7*1/$C$6>F20,$C$7*1/$C$6,F20)) | G21: =IF(G18=0,0,IF($C$7*1/$C$6>G20,$C$7*1/$C$6,G20)) | H21: =IF(H18=0,0,IF($C$7*1/$C$6>H20,$C$7*1/$C$6,H20)) | I21: =IF(I18=0,0,IF($C$7*1/$C$6>I20,$C$7*1/$C$6,I20)) | J21: =IF(J18=0,0,IF($C$7*1/$C$6>J20,$C$7*1/$C$6,J20)) | K21: =IF(K18=0,0,IF($C$7*1/$C$6>K20,$C$7*1/$C$6,K20)) | ... M21: =IF(M18=0,0,IF($C$7*1/$C$6>M20,$C$7*1/$C$6,M20))
A22: Charge d'amortissement | B22: USD | D22: =D19*D21 | E22: =E19*E21 | F22: =F19*F21 | G22: =G19*G21 | H22: =H19*H21 | I22: =I19*I21 | J22: =J19*J21 | K22: =K19*K21 | ... M22: =M19*M21
A23: Amortissement restant | B23: USD | D23: =D19-D22 | E23: =E19-E22 | F23: =F19-F22 | G23: =G19-G22 | H23: =H19-H22 | I23: =I19-I22 | J23: =J19-J22 | K23: =K19-K22 | ... M23: =M19-M22
A25: Amortissements des constructions industrielles | B25: USD | C25: =C$14+C$22 | D25: =D$14+D$22 | E25: =E$14+E$22 | F25: =F$14+F$22 | G25: =G$14+G$22 | H25: =H$14+H$22 | I25: =I$14+I$22 | J25: =J$14+J$22 | ... M25: =M$14+M$22
A27: II. AMORTISSEMENTS DES BIENS D'EQUIPEMENT
A28: Durée d'amortissement linéaire | B28: Années | C28: 5
A29: Coefficient d'amortissement dégressif | B29: Coefficient | C29: 2
A31: Immobilisations de l'année A1
A32: Durée restante | B32: Années | C32: =IF($C$28<C$3,$C$28,C$3) | D32: =IF(C32=0,0,IF(C32-1<D$3,C32-1,D$3)) | E32: =IF(D32=0,0,IF(D32-1<E$3,D32-1,E$3)) | F32: =IF(E32=0,0,IF(E32-1<F$3,E32-1,F$3)) | G32: =IF(F32=0,0,IF(F32-1<G$3,F32-1,G$3)) | H32: =IF(G32=0,0,IF(G32-1<H$3,G32-1,H$3)) | I32: =IF(H32=0,0,IF(H32-1<I$3,H32-1,I$3)) | J32: =IF(I32=0,0,IF(I32-1<J$3,I32-1,J$3)) | K32: =IF(J32=0,0,IF(J32-1<K$3,J32-1,K$3)) | ... M32: =IF(L32=0,0,IF(L32-1<M$3,L32-1,M$3))
A33: Base amortissable | B33: USD | C33: =Modèle!C$10 | D33: =C37 | E33: =D37 | F33: =E37 | G33: =F37 | H33: =G37 | I33: =H37 | J33: =I37 | K33: =J37 | ... M33: =L37
A34: Inverse de la durée restante | B34: % | C34: =IF(C32=0,0,1/C32) | D34: =IF(D32=0,0,1/D32) | E34: =IF(E32=0,0,1/E32) | F34: =IF(F32=0,0,1/F32) | G34: =IF(G32=0,0,1/G32) | H34: =IF(H32=0,0,1/H32) | I34: =IF(I32=0,0,1/I32) | J34: =IF(J32=0,0,1/J32) | ... M34: =IF(M32=0,0,1/M32)
A35: Taux dégressif | B35: % | C35: =IF(C32=0,0,IF($C$29*1/$C$28>C34,$C$29*1/$C$28,C34)) | D35: =IF(D32=0,0,IF($C$29*1/$C$28>D34,$C$29*1/$C$28,D34)) | E35: =IF(E32=0,0,IF($C$29*1/$C$28>E34,$C$29*1/$C$28,E34)) | F35: =IF(F32=0,0,IF($C$29*1/$C$28>F34,$C$29*1/$C$28,F34)) | G35: =IF(G32=0,0,IF($C$29*1/$C$28>G34,$C$29*1/$C$28,G34)) | H35: =IF(H32=0,0,IF($C$29*1/$C$28>H34,$C$29*1/$C$28,H34)) | I35: =IF(I32=0,0,IF($C$29*1/$C$28>I34,$C$29*1/$C$28,I34)) | J35: =IF(J32=0,0,IF($C$29*1/$C$28>J34,$C$29*1/$C$28,J34)) | ... M35: =IF(M32=0,0,IF($C$29*1/$C$28>M34,$C$29*1/$C$28,M34))
A36: Charge d'amortissement | B36: USD | C36: =C33*C35 | D36: =D33*D35 | E36: =E33*E35 | F36: =F33*F35 | G36: =G33*G35 | H36: =H33*H35 | I36: =I33*I35 | J36: =J33*J35 | ... M36: =M33*M35
A37: Amortissement restant | B37: USD | C37: =C33-C36 | D37: =D33-D36 | E37: =E33-E36 | F37: =F33-F36 | G37: =G33-G36 | H37: =H33-H36 | I37: =I33-I36 | J37: =J33-J36 | ... M37: =M33-M36
A39: Immobilisations de l'année A2
A40: Durée restante | B40: Années | D40: =IF($C$28<D$3,$C$28,D$3) | E40: =IF(D40=0,0,IF(D40-1<E$3,D40-1,E$3)) | F40: =IF(E40=0,0,IF(E40-1<F$3,E40-1,F$3)) | G40: =IF(F40=0,0,IF(F40-1<G$3,F40-1,G$3)) | H40: =IF(G40=0,0,IF(G40-1<H$3,G40-1,H$3)) | I40: =IF(H40=0,0,IF(H40-1<I$3,H40-1,I$3)) | J40: =IF(I40=0,0,IF(I40-1<J$3,I40-1,J$3)) | K40: =IF(J40=0,0,IF(J40-1<K$3,J40-1,K$3)) | L40: =IF(K40=0,0,IF(K40-1<L$3,K40-1,L$3)) | M40: =IF(L40=0,0,IF(L40-1<M$3,L40-1,M$3))
A41: Base amortissable | B41: USD | D41: =Modèle!D$10 | E41: =D45 | F41: =E45 | G41: =F45 | H41: =G45 | I41: =H45 | J41: =I45 | K41: =J45 | L41: =K45 | M41: =L45
A42: Inverse de la durée restante | B42: % | D42: =IF(D40=0,0,1/D40) | E42: =IF(E40=0,0,1/E40) | F42: =IF(F40=0,0,1/F40) | G42: =IF(G40=0,0,1/G40) | H42: =IF(H40=0,0,1/H40) | I42: =IF(I40=0,0,1/I40) | J42: =IF(J40=0,0,1/J40) | K42: =IF(K40=0,0,1/K40) | ... M42: =IF(M40=0,0,1/M40)
A43: Taux dégressif | B43: % | D43: =IF(D40=0,0,IF($C$29*1/$C$28>D42,$C$29*1/$C$28,D42)) | E43: =IF(E40=0,0,IF($C$29*1/$C$28>E42,$C$29*1/$C$28,E42)) | F43: =IF(F40=0,0,IF($C$29*1/$C$28>F42,$C$29*1/$C$28,F42)) | G43: =IF(G40=0,0,IF($C$29*1/$C$28>G42,$C$29*1/$C$28,G42)) | H43: =IF(H40=0,0,IF($C$29*1/$C$28>H42,$C$29*1/$C$28,H42)) | I43: =IF(I40=0,0,IF($C$29*1/$C$28>I42,$C$29*1/$C$28,I42)) | J43: =IF(J40=0,0,IF($C$29*1/$C$28>J42,$C$29*1/$C$28,J42)) | K43: =IF(K40=0,0,IF($C$29*1/$C$28>K42,$C$29*1/$C$28,K42)) | ... M43: =IF(M40=0,0,IF($C$29*1/$C$28>M42,$C$29*1/$C$28,M42))
A44: Charge d'amortissement | B44: USD | D44: =D41*D43 | E44: =E41*E43 | F44: =F41*F43 | G44: =G41*G43 | H44: =H41*H43 | I44: =I41*I43 | J44: =J41*J43 | K44: =K41*K43 | ... M44: =M41*M43
A45: Amortissement restant | B45: USD | D45: =D41-D44 | E45: =E41-E44 | F45: =F41-F44 | G45: =G41-G44 | H45: =H41-H44 | I45: =I41-I44 | J45: =J41-J44 | K45: =K41-K44 | ... M45: =M41-M44
A47: Immobilisations de l'année A3
A48: Durée restante | B48: Années | E48: =IF($C$28<E$3,$C$28,E$3) | F48: =IF(E48=0,0,IF(E48-1<F$3,E48-1,F$3)) | G48: =IF(F48=0,0,IF(F48-1<G$3,F48-1,G$3)) | H48: =IF(G48=0,0,IF(G48-1<H$3,G48-1,H$3)) | I48: =IF(H48=0,0,IF(H48-1<I$3,H48-1,I$3)) | J48: =IF(I48=0,0,IF(I48-1<J$3,I48-1,J$3)) | K48: =IF(J48=0,0,IF(J48-1<K$3,J48-1,K$3)) | L48: =IF(K48=0,0,IF(K48-1<L$3,K48-1,L$3)) | M48: =IF(L48=0,0,IF(L48-1<M$3,L48-1,M$3))
A49: Base amortissable | B49: USD | E49: =Modèle!E$10 | F49: =E53 | G49: =F53 | H49: =G53 | I49: =H53 | J49: =I53 | K49: =J53 | L49: =K53 | M49: =L53
...

Sheet 04_05_Charges_f_1
A1: Nom | B1: Unité | C1: Année 1 | D1: Année 2 | E1: Année 3 | F1: Année 4 | G1: Année 5 | H1: Année 6 | I1: Année 7 | J1: Année 8 | K1: Année 9 | L1: Année 10 | M1: Année 11 | N1: SOMME | O1: VAN
A3: I. PRODUCTION
A4: Production d'or | B4: oz | E4: 250000 | F4: 250000 | G4: 250000 | H4: 250000 | I4: 250000 | J4: 250000 | K4: 250000 | L4: 250000 | N4: =SUM($C4:$M4)
A5: Cours de l'or | B5: USD/oz | E5: 1300 | F5: 1300 | G5: 1300 | H5: 1300 | I5: 1300 | J5: 1300 | K5: 1300 | L5: 1300
A6: Chiffre d'affaires | B6: USD | C6: =C$4*C$5 | D6: =D$4*D$5 | E6: =E$4*E$5 | F6: =F$4*F$5 | G6: =G$4*G$5 | H6: =H$4*H$5 | I6: =I$4*I$5 | J6: =J$4*J$5 | ... M6: =M$4*M$5 | N6: =SUM($C6:$M6) | O6: =$C6+NPV(10%,$D6:$M6)
A8: II. DEPENSES D'INVESTISSEMENT (CAPEX)
A9: Coûts des construction industrielles | B9: USD | C9: 50000000 | D9: 100000000 | N9: =SUM($C9:$M9) | O9: =$C9+NPV(10%,$D9:$M9)
A10: Coûts des biens d'équipement | B10: USD | D10: 50000000 | E10: 5000000 | F10: 5000000 | G10: 5000000 | H10: 5000000 | I10: 5000000 | J10: 5000000 | K10: 5000000 | L10: 5000000 | N10: =SUM($C10:$M10) | O10: =$C10+NPV(10%,$D10:$M10)
A11: Coûts de réhabilitation du site | B11: USD | M11: 10000000 | N11: =SUM($C11:$M11) | O11: =$C11+NPV(10%,$D11:$M11)
A12: Total des dépenses d'investissement | B12: USD | C12: =SUM(C$9:C$11) | D12: =SUM(D$9:D$11) | E12: =SUM(E$9:E$11) | F12: =SUM(F$9:F$11) | G12: =SUM(G$9:G$11) | H12: =SUM(H$9:H$11) | I12: =SUM(I$9:I$11) | J12: =SUM(J$9:J$11) | ... M12: =SUM(M$9:M$11) | N12: =SUM($C12:$M12) | O12: =$C12+NPV(10%,$D12:$M12)
A14: III. COÛTS D'EXPLOITATION (OPEX)
A15: Coût moyen d'exploitation | B15: USD/oz | E15: 700 | F15: 700 | G15: 700 | H15: 700 | I15: 700 | J15: 700 | K15: 700 | L15: 700
A16: Total des coûts d'exploitation | B16: USD | C16: =C$4*C$15 | D16: =D$4*D$15 | E16: =E$4*E$15 | F16: =F$4*F$15 | G16: =G$4*G$15 | H16: =H$4*H$15 | I16: =I$4*I$15 | J16: =J$4*J$15 | ... M16: =M$4*M$15 | N16: =SUM($C16:$M16) | O16: =$C16+NPV(10%,$D16:$M16)
A18: IV. FLUX NETS DE TRESORERIE AVANT IMPÔTS
A19: Flux nets de trésorerie avant impôts | B19: USD | C19: =C$6-C$12-C$16 | D19: =D$6-D$12-D$16 | E19: =E$6-E$12-E$16 | F19: =F$6-F$12-F$16 | G19: =G$6-G$12-G$16 | H19: =H$6-H$12-H$16 | I19: =I$6-I$12-I$16 | J19: =J$6-J$12-J$16 | ... M19: =M$6-M$12-M$16 | N19: =SUM($C19:$M19) | O19: =$C19+NPV(10%,$D19:$M19)
A20: Taux de rendement interne avant impôts | B20: % | C20: =IF(ISNUMBER(IRR($C19:C19)),IF(IRR($C19:C19)>0,IRR($C19:C19),""),"") | D20: =IF(ISNUMBER(IRR($C19:D19)),IF(IRR($C19:D19)>0,IRR($C19:D19),""),"") | E20: =IF(ISNUMBER(IRR($C19:E19)),IF(IRR($C19:E19)>0,IRR($C19:E19),""),"") | F20: =IF(ISNUMBER(IRR($C19:F19)),IF(IRR($C19:F19)>0,IRR($C19:F19),""),"") | G20: =IF(ISNUMBER(IRR($C19:G19)),IF(IRR($C19:G19)>0,IRR($C19:G19),""),"") | H20: =IF(ISNUMBER(IRR($C19:H19)),IF(IRR($C19:H19)>0,IRR($C19:H19),""),"") | I20: =IF(ISNUMBER(IRR($C19:I19)),IF(IRR($C19:I19)>0,IRR($C19:I19),""),"") | J20: =IF(ISNUMBER(IRR($C19:J19)),IF(IRR($C19:J19)>0,IRR($C19:J19),""),"") | ... M20: =IF(ISNUMBER(IRR($C19:M19)),IF(IRR($C19:M19)>0,IRR($C19:M19),""),"")
A22: V. DROITS FIXES
A23: Droits fixes | B23: USD | C23: 100000 | N23: =SUM($C23:$M23) | O23: =$C23+NPV(10%,$D23:$M23)
A25: VI. REDEVANCE SUPERFICAIRE
A26: Superficie de la mine | B26: km² | C26: 100 | D26: 100 | E26: 100 | F26: 100 | G26: 100 | H26: 100 | I26: 100 | J26: 100 | K26: 100 | L26: 100 | M26: 100
A27: Montant de la redevance superfiaire | B27: USD/km² | C27: 100 | D27: 100 | E27: 100 | F27: 100 | G27: 100 | H27: 100 | I27: 100 | J27: 100 | K27: 100 | L27: 100 | M27: 100
A28: Redevance superficiaire | B28: USD | C28: =C$26*C$27 | D28: =D$26*D$27 | E28: =E$26*E$27 | F28: =F$26*F$27 | G28: =G$26*G$27 | H28: =H$26*H$27 | I28: =I$26*I$27 | J28: =J$26*J$27 | ... M28: =M$26*M$27 | N28: =SUM($C28:$M28) | O28: =$C28+NPV(10%,$D28:$M28)
A30: VII. REDEVANCE MINIERE
A31: Taux de la redevance minière | B31: % | C31: =IF(ISNUMBER(C5),IF(C$5<1300,3%,IF(C$5<1500,4%,5%)),"") | D31: =IF(ISNUMBER(D5),IF(D$5<1300,3%,IF(D$5<1500,4%,5%)),"") | E31: =IF(ISNUMBER(E5),IF(E$5<1300,3%,IF(E$5<1500,4%,5%)),"") | F31: =IF(ISNUMBER(F5),IF(F$5<1300,3%,IF(F$5<1500,4%,5%)),"") | G31: =IF(ISNUMBER(G5),IF(G$5<1300,3%,IF(G$5<1500,4%,5%)),"") | H31: =IF(ISNUMBER(H5),IF(H$5<1300,3%,IF(H$5<1500,4%,5%)),"") | I31: =IF(ISNUMBER(I5),IF(I$5<1300,3%,IF(I$5<1500,4%,5%)),"") | J31: =IF(ISNUMBER(J5),IF(J$5<1300,3%,IF(J$5<1500,4%,5%)),"") | ... M31: =IF(ISNUMBER(M5),IF(M$5<1300,3%,IF(M$5<1500,4%,5%)),"")
A32: Redevance minière | B32: USD | C32: =IF(ISNUMBER(C31),C$6*C$31,0) | D32: =IF(ISNUMBER(D31),D$6*D$31,0) | E32: =IF(ISNUMBER(E31),E$6*E$31,0) | F32: =IF(ISNUMBER(F31),F$6*F$31,0) | G32: =IF(ISNUMBER(G31),G$6*G$31,0) | H32: =IF(ISNUMBER(H31),H$6*H$31,0) | I32: =IF(ISNUMBER(I31),I$6*I$31,0) | J32: =IF(ISNUMBER(J31),J$6*J$31,0) | ... M32: =IF(ISNUMBER(M31),M$6*M$31,0) | N32: =SUM($C32:$M32) | O32: =$C32+NPV(10%,$D32:$M32)

Sheet 04_05_Charges_f_2
A1: Nom | B1: Unité | C1: Année 1 | D1: Année 2 | E1: Année 3 | F1: Année 4 | G1: Année 5 | H1: Année 6 | I1: Année 7 | J1: Année 8 | K1: Année 9 | L1: Année 10 | M1: Année 11
A3: Durée restante maximum | B3: Années | C3: 11 | D3: 10 | E3: 9 | F3: 8 | G3: 7 | H3: 6 | I3: 5 | J3: 4 | K3: 3 | L3: 2 | M3: 1
A5: I. AMORTISSEMENTS DES CONSTRUCTIONS INDUSTRIELLES
A6: Durée d'amortissement linéaire | B6: Années | C6: 10
A7: Coefficient d'amortissement dégressif | B7: Coefficient | C7: 1
A9: Immobilisations de l'année A1
A10: Durée restante | B10: Années | C10: =IF($C$6<C$3,$C$6,C$3) | D10: =IF(C10=0,0,IF(C10-1<D$3,C10-1,D$3)) | E10: =IF(D10=0,0,IF(D10-1<E$3,D10-1,E$3)) | F10: =IF(E10=0,0,IF(E10-1<F$3,E10-1,F$3)) | G10: =IF(F10=0,0,IF(F10-1<G$3,F10-1,G$3)) | H10: =IF(G10=0,0,IF(G10-1<H$3,G10-1,H$3)) | I10: =IF(H10=0,0,IF(H10-1<I$3,H10-1,I$3)) | J10: =IF(I10=0,0,IF(I10-1<J$3,I10-1,J$3)) | K10: =IF(J10=0,0,IF(J10-1<K$3,J10-1,K$3)) | ... M10: =IF(L10=0,0,IF(L10-1<M$3,L10-1,M$3))
A11: Base amortissable | B11: USD | C11: =Modèle!C$9 | D11: =C15 | E11: =D15 | F11: =E15 | G11: =F15 | H11: =G15 | I11: =H15 | J11: =I15 | K11: =J15 | ... M11: =L15
A12: Inverse de la durée restante | B12: % | C12: =IF(C10=0,0,1/C10) | D12: =IF(D10=0,0,1/D10) | E12: =IF(E10=0,0,1/E10) | F12: =IF(F10=0,0,1/F10) | G12: =IF(G10=0,0,1/G10) | H12: =IF(H10=0,0,1/H10) | I12: =IF(I10=0,0,1/I10) | J12: =IF(J10=0,0,1/J10) | ... M12: =IF(M10=0,0,1/M10)
A13: Taux dégressif | B13: % | C13: =IF(C10=0,0,IF($C$7*1/$C$6>C12,$C$7*1/$C$6,C12)) | D13: =IF(D10=0,0,IF($C$7*1/$C$6>D12,$C$7*1/$C$6,D12)) | E13: =IF(E10=0,0,IF($C$7*1/$C$6>E12,$C$7*1/$C$6,E12)) | F13: =IF(F10=0,0,IF($C$7*1/$C$6>F12,$C$7*1/$C$6,F12)) | G13: =IF(G10=0,0,IF($C$7*1/$C$6>G12,$C$7*1/$C$6,G12)) | H13: =IF(H10=0,0,IF($C$7*1/$C$6>H12,$C$7*1/$C$6,H12)) | I13: =IF(I10=0,0,IF($C$7*1/$C$6>I12,$C$7*1/$C$6,I12)) | J13: =IF(J10=0,0,IF($C$7*1/$C$6>J12,$C$7*1/$C$6,J12)) | ... M13: =IF(M10=0,0,IF($C$7*1/$C$6>M12,$C$7*1/$C$6,M12))
A14: Charge d'amortissement | B14: USD | C14: =C11*C13 | D14: =D11*D13 | E14: =E11*E13 | F14: =F11*F13 | G14: =G11*G13 | H14: =H11*H13 | I14: =I11*I13 | J14: =J11*J13 | ... M14: =M11*M13
A15: Amortissement restant | B15: USD | C15: =C11-C14 | D15: =D11-D14 | E15: =E11-E14 | F15: =F11-F14 | G15: =G11-G14 | H15: =H11-H14 | I15: =I11-I14 | J15: =J11-J14 | ... M15: =M11-M14
A17: Immobilisations de l'année A2
A18: Durée restante | B18: Années | D18: =IF($C$6<D$3,$C$6,D$3) | E18: =IF(D18=0,0,IF(D18-1<E$3,D18-1,E$3)) | F18: =IF(E18=0,0,IF(E18-1<F$3,E18-1,F$3)) | G18: =IF(F18=0,0,IF(F18-1<G$3,F18-1,G$3)) | H18: =IF(G18=0,0,IF(G18-1<H$3,G18-1,H$3)) | I18: =IF(H18=0,0,IF(H18-1<I$3,H18-1,I$3)) | J18: =IF(I18=0,0,IF(I18-1<J$3,I18-1,J$3)) | K18: =IF(J18=0,0,IF(J18-1<K$3,J18-1,K$3)) | L18: =IF(K18=0,0,IF(K18-1<L$3,K18-1,L$3)) | M18: =IF(L18=0,0,IF(L18-1<M$3,L18-1,M$3))
A19: Base amortissable | B19: USD | D19: =Modèle!D$9 | E19: =D23 | F19: =E23 | G19: =F23 | H19: =G23 | I19: =H23 | J19: =I23 | K19: =J23 | L19: =K23 | M19: =L23
A20: Inverse de la durée restante | B20: % | D20: =IF(D18=0,0,1/D18) | E20: =IF(E18=0,0,1/E18) | F20: =IF(F18=0,0,1/F18) | G20: =IF(G18=0,0,1/G18) | H20: =IF(H18=0,0,1/H18) | I20: =IF(I18=0,0,1/I18) | J20: =IF(J18=0,0,1/J18) | K20: =IF(K18=0,0,1/K18) | ... M20: =IF(M18=0,0,1/M18)
A21: Taux dégressif | B21: % | D21: =IF(D18=0,0,IF($C$7*1/$C$6>D20,$C$7*1/$C$6,D20)) | E21: =IF(E18=0,0,IF($C$7*1/$C$6>E20,$C$7*1/$C$6,E20)) | F21: =IF(F18=0,0,IF($C$7*1/$C$6>F20,$C$7*1/$C$6,F20)) | G21: =IF(G18=0,0,IF($C$7*1/$C$6>G20,$C$7*1/$C$6,G20)) | H21: =IF(H18=0,0,IF($C$7*1/$C$6>H20,$C$7*1/$C$6,H20)) | I21: =IF(I18=0,0,IF($C$7*1/$C$6>I20,$C$7*1/$C$6,I20)) | J21: =IF(J18=0,0,IF($C$7*1/$C$6>J20,$C$7*1/$C$6,J20)) | K21: =IF(K18=0,0,IF($C$7*1/$C$6>K20,$C$7*1/$C$6,K20)) | ... M21: =IF(M18=0,0,IF($C$7*1/$C$6>M20,$C$7*1/$C$6,M20))
A22: Charge d'amortissement | B22: USD | D22: =D19*D21 | E22: =E19*E21 | F22: =F19*F21 | G22: =G19*G21 | H22: =H19*H21 | I22: =I19*I21 | J22: =J19*J21 | K22: =K19*K21 | ... M22: =M19*M21
A23: Amortissement restant | B23: USD | D23: =D19-D22 | E23: =E19-E22 | F23: =F19-F22 | G23: =G19-G22 | H23: =H19-H22 | I23: =I19-I22 | J23: =J19-J22 | K23: =K19-K22 | ... M23: =M19-M22
A25: Amortissements des constructions industrielles | B25: USD | C25: =C$14+C$22 | D25: =D$14+D$22 | E25: =E$14+E$22 | F25: =F$14+F$22 | G25: =G$14+G$22 | H25: =H$14+H$22 | I25: =I$14+I$22 | J25: =J$14+J$22 | ... M25: =M$14+M$22
A27: II. AMORTISSEMENTS DES BIENS D'EQUIPEMENT
A28: Durée d'amortissement linéaire | B28: Années | C28: 5
A29: Coefficient d'amortissement dégressif | B29: Coefficient | C29: 2
A31: Immobilisations de l'année A1
A32: Durée restante | B32: Années | C32: =IF($C$28<C$3,$C$28,C$3) | D32: =IF(C32=0,0,IF(C32-1<D$3,C32-1,D$3)) | E32: =IF(D32=0,0,IF(D32-1<E$3,D32-1,E$3)) | F32: =IF(E32=0,0,IF(E32-1<F$3,E32-1,F$3)) | G32: =IF(F32=0,0,IF(F32-1<G$3,F32-1,G$3)) | H32: =IF(G32=0,0,IF(G32-1<H$3,G32-1,H$3)) | I32: =IF(H32=0,0,IF(H32-1<I$3,H32-1,I$3)) | J32: =IF(I32=0,0,IF(I32-1<J$3,I32-1,J$3)) | K32: =IF(J32=0,0,IF(J32-1<K$3,J32-1,K$3)) | ... M32: =IF(L32=0,0,IF(L32-1<M$3,L32-1,M$3))
A33: Base amortissable | B33: USD | C33: =Modèle!C$10 | D33: =C37 | E33: =D37 | F33: =E37 | G33: =F37 | H33: =G37 | I33: =H37 | J33: =I37 | K33: =J37 | ... M33: =L37
A34: Inverse de la durée restante | B34: % | C34: =IF(C32=0,0,1/C32) | D34: =IF(D32=0,0,1/D32) | E34: =IF(E32=0,0,1/E32) | F34: =IF(F32=0,0,1/F32) | G34: =IF(G32=0,0,1/G32) | H34: =IF(H32=0,0,1/H32) | I34: =IF(I32=0,0,1/I32) | J34: =IF(J32=0,0,1/J32) | ... M34: =IF(M32=0,0,1/M32)
A35: Taux dégressif | B35: % | C35: =IF(C32=0,0,IF($C$29*1/$C$28>C34,$C$29*1/$C$28,C34)) | D35: =IF(D32=0,0,IF($C$29*1/$C$28>D34,$C$29*1/$C$28,D34)) | E35: =IF(E32=0,0,IF($C$29*1/$C$28>E34,$C$29*1/$C$28,E34)) | F35: =IF(F32=0,0,IF($C$29*1/$C$28>F34,$C$29*1/$C$28,F34)) | G35: =IF(G32=0,0,IF($C$29*1/$C$28>G34,$C$29*1/$C$28,G34)) | H35: =IF(H32=0,0,IF($C$29*1/$C$28>H34,$C$29*1/$C$28,H34)) | I35: =IF(I32=0,0,IF($C$29*1/$C$28>I34,$C$29*1/$C$28,I34)) | J35: =IF(J32=0,0,IF($C$29*1/$C$28>J34,$C$29*1/$C$28,J34)) | ... M35: =IF(M32=0,0,IF($C$29*1/$C$28>M34,$C$29*1/$C$28,M34))
A36: Charge d'amortissement | B36: USD | C36: =C33*C35 | D36: =D33*D35 | E36: =E33*E35 | F36: =F33*F35 | G36: =G33*G35 | H36: =H33*H35 | I36: =I33*I35 | J36: =J33*J35 | ... M36: =M33*M35
A37: Amortissement restant | B37: USD | C37: =C33-C36 | D37: =D33-D36 | E37: =E33-E36 | F37: =F33-F36 | G37: =G33-G36 | H37: =H33-H36 | I37: =I33-I36 | J37: =J33-J36 | ... M37: =M33-M36
A39: Immobilisations de l'année A2
A40: Durée restante | B40: Années | D40: =IF($C$28<D$3,$C$28,D$3) | E40: =IF(D40=0,0,IF(D40-1<E$3,D40-1,E$3)) | F40: =IF(E40=0,0,IF(E40-1<F$3,E40-1,F$3)) | G40: =IF(F40=0,0,IF(F40-1<G$3,F40-1,G$3)) | H40: =IF(G40=0,0,IF(G40-1<H$3,G40-1,H$3)) | I40: =IF(H40=0,0,IF(H40-1<I$3,H40-1,I$3)) | J40: =IF(I40=0,0,IF(I40-1<J$3,I40-1,J$3)) | K40: =IF(J40=0,0,IF(J40-1<K$3,J40-1,K$3)) | L40: =IF(K40=0,0,IF(K40-1<L$3,K40-1,L$3)) | M40: =IF(L40=0,0,IF(L40-1<M$3,L40-1,M$3))
A41: Base amortissable | B41: USD | D41: =Modèle!D$10 | E41: =D45 | F41: =E45 | G41: =F45 | H41: =G45 | I41: =H45 | J41: =I45 | K41: =J45 | L41: =K45 | M41: =L45
A42: Inverse de la durée restante | B42: % | D42: =IF(D40=0,0,1/D40) | E42: =IF(E40=0,0,1/E40) | F42: =IF(F40=0,0,1/F40) | G42: =IF(G40=0,0,1/G40) | H42: =IF(H40=0,0,1/H40) | I42: =IF(I40=0,0,1/I40) | J42: =IF(J40=0,0,1/J40) | K42: =IF(K40=0,0,1/K40) | ... M42: =IF(M40=0,0,1/M40)
A43: Taux dégressif | B43: % | D43: =IF(D40=0,0,IF($C$29*1/$C$28>D42,$C$29*1/$C$28,D42)) | E43: =IF(E40=0,0,IF($C$29*1/$C$28>E42,$C$29*1/$C$28,E42)) | F43: =IF(F40=0,0,IF($C$29*1/$C$28>F42,$C$29*1/$C$28,F42)) | G43: =IF(G40=0,0,IF($C$29*1/$C$28>G42,$C$29*1/$C$28,G42)) | H43: =IF(H40=0,0,IF($C$29*1/$C$28>H42,$C$29*1/$C$28,H42)) | I43: =IF(I40=0,0,IF($C$29*1/$C$28>I42,$C$29*1/$C$28,I42)) | J43: =IF(J40=0,0,IF($C$29*1/$C$28>J42,$C$29*1/$C$28,J42)) | K43: =IF(K40=0,0,IF($C$29*1/$C$28>K42,$C$29*1/$C$28,K42)) | ... M43: =IF(M40=0,0,IF($C$29*1/$C$28>M42,$C$29*1/$C$28,M42))
A44: Charge d'amortissement | B44: USD | D44: =D41*D43 | E44: =E41*E43 | F44: =F41*F43 | G44: =G41*G43 | H44: =H41*H43 | I44: =I41*I43 | J44: =J41*J43 | K44: =K41*K43 | ... M44: =M41*M43
A45: Amortissement restant | B45: USD | D45: =D41-D44 | E45: =E41-E44 | F45: =F41-F44 | G45: =G41-G44 | H45: =H41-H44 | I45: =I41-I44 | J45: =J41-J44 | K45: =K41-K44 | ... M45: =M41-M44
A47: Immobilisations de l'année A3
A48: Durée restante | B48: Années | E48: =IF($C$28<E$3,$C$28,E$3) | F48: =IF(E48=0,0,IF(E48-1<F$3,E48-1,F$3)) | G48: =IF(F48=0,0,IF(F48-1<G$3,F48-1,G$3)) | H48: =IF(G48=0,0,IF(G48-1<H$3,G48-1,H$3)) | I48: =IF(H48=0,0,IF(H48-1<I$3,H48-1,I$3)) | J48: =IF(I48=0,0,IF(I48-1<J$3,I48-1,J$3)) | K48: =IF(J48=0,0,IF(J48-1<K$3,J48-1,K$3)) | L48: =IF(K48=0,0,IF(K48-1<L$3,K48-1,L$3)) | M48: =IF(L48=0,0,IF(L48-1<M$3,L48-1,M$3))
A49: Base amortissable | B49: USD | E49: =Modèle!E$10 | F49: =E53 | G49: =F53 | H49: =G53 | I49: =H53 | J49: =I53 | K49: =J53 | L49: =K53 | M49: =L53
...

Sheet 05_05_Charges_f_1
A1: Nom | B1: Unité | C1: Année 1 | D1: Année 2 | E1: Année 3 | F1: Année 4 | G1: Année 5 | H1: Année 6 | I1: Année 7 | J1: Année 8 | K1: Année 9 | L1: Année 10 | M1: Année 11 | N1: SOMME | O1: VAN
A3: I. PRODUCTION
A4: Production d'or | B4: oz | E4: 250000 | F4: 250000 | G4: 250000 | H4: 250000 | I4: 250000 | J4: 250000 | K4: 250000 | L4: 250000 | N4: =SUM($C4:$M4)
A5: Cours de l'or | B5: USD/oz | E5: 1300 | F5: 1300 | G5: 1300 | H5: 1300 | I5: 1300 | J5: 1300 | K5: 1300 | L5: 1300
A6: Chiffre d'affaires | B6: USD | C6: =C$4*C$5 | D6: =D$4*D$5 | E6: =E$4*E$5 | F6: =F$4*F$5 | G6: =G$4*G$5 | H6: =H$4*H$5 | I6: =I$4*I$5 | J6: =J$4*J$5 | ... M6: =M$4*M$5 | N6: =SUM($C6:$M6) | O6: =$C6+NPV(10%,$D6:$M6)
A8: II. DEPENSES D'INVESTISSEMENT (CAPEX)
A9: Coûts des construction industrielles | B9: USD | C9: 50000000 | D9: 100000000 | N9: =SUM($C9:$M9) | O9: =$C9+NPV(10%,$D9:$M9)
A10: Coûts des biens d'équipement | B10: USD | D10: 50000000 | E10: 5000000 | F10: 5000000 | G10: 5000000 | H10: 5000000 | I10: 5000000 | J10: 5000000 | K10: 5000000 | L10: 5000000 | N10: =SUM($C10:$M10) | O10: =$C10+NPV(10%,$D10:$M10)
A11: Coûts de réhabilitation du site | B11: USD | M11: 10000000 | N11: =SUM($C11:$M11) | O11: =$C11+NPV(10%,$D11:$M11)
A12: Total des dépenses d'investissement | B12: USD | C12: =SUM(C$9:C$11) | D12: =SUM(D$9:D$11) | E12: =SUM(E$9:E$11) | F12: =SUM(F$9:F$11) | G12: =SUM(G$9:G$11) | H12: =SUM(H$9:H$11) | I12: =SUM(I$9:I$11) | J12: =SUM(J$9:J$11) | ... M12: =SUM(M$9:M$11) | N12: =SUM($C12:$M12) | O12: =$C12+NPV(10%,$D12:$M12)
A14: III. COÛTS D'EXPLOITATION (OPEX)
A15: Coût moyen d'exploitation | B15: USD/oz | E15: 700 | F15: 700 | G15: 700 | H15: 700 | I15: 700 | J15: 700 | K15: 700 | L15: 700
A16: Total des coûts d'exploitation | B16: USD | C16: =C$4*C$15 | D16: =D$4*D$15 | E16: =E$4*E$15 | F16: =F$4*F$15 | G16: =G$4*G$15 | H16: =H$4*H$15 | I16: =I$4*I$15 | J16: =J$4*J$15 | ... M16: =M$4*M$15 | N16: =SUM($C16:$M16) | O16: =$C16+NPV(10%,$D16:$M16)
A18: IV. FLUX NETS DE TRESORERIE AVANT IMPÔTS
A19: Flux nets de trésorerie avant impôts | B19: USD | C19: =C$6-C$12-C$16 | D19: =D$6-D$12-D$16 | E19: =E$6-E$12-E$16 | F19: =F$6-F$12-F$16 | G19: =G$6-G$12-G$16 | H19: =H$6-H$12-H$16 | I19: =I$6-I$12-I$16 | J19: =J$6-J$12-J$16 | ... M19: =M$6-M$12-M$16 | N19: =SUM($C19:$M19) | O19: =$C19+NPV(10%,$D19:$M19)
A20: Taux de rendement interne avant impôts | B20: % | C20: =IF(ISNUMBER(IRR($C19:C19)),IF(IRR($C19:C19)>0,IRR($C19:C19),""),"") | D20: =IF(ISNUMBER(IRR($C19:D19)),IF(IRR($C19:D19)>0,IRR($C19:D19),""),"") | E20: =IF(ISNUMBER(IRR($C19:E19)),IF(IRR($C19:E19)>0,IRR($C19:E19),""),"") | F20: =IF(ISNUMBER(IRR($C19:F19)),IF(IRR($C19:F19)>0,IRR($C19:F19),""),"") | G20: =IF(ISNUMBER(IRR($C19:G19)),IF(IRR($C19:G19)>0,IRR($C19:G19),""),"") | H20: =IF(ISNUMBER(IRR($C19:H19)),IF(IRR($C19:H19)>0,IRR($C19:H19),""),"") | I20: =IF(ISNUMBER(IRR($C19:I19)),IF(IRR($C19:I19)>0,IRR($C19:I19),""),"") | J20: =IF(ISNUMBER(IRR($C19:J19)),IF(IRR($C19:J19)>0,IRR($C19:J19),""),"") | ... M20: =IF(ISNUMBER(IRR($C19:M19)),IF(IRR($C19:M19)>0,IRR($C19:M19),""),"")
A22: V. DROITS FIXES
A23: Droits fixes | B23: USD | C23: 100000 | N23: =SUM($C23:$M23) | O23: =$C23+NPV(10%,$D23:$M23)
A25: VI. REDEVANCE SUPERFICAIRE
A26: Superficie de la mine | B26: km² | C26: 100 | D26: 100 | E26: 100 | F26: 100 | G26: 100 | H26: 100 | I26: 100 | J26: 100 | K26: 100 | L26: 100 | M26: 100
A27: Montant de la redevance superfiaire | B27: USD/km² | C27: 100 | D27: 100 | E27: 100 | F27: 100 | G27: 100 | H27: 100 | I27: 100 | J27: 100 | K27: 100 | L27: 100 | M27: 100
A28: Redevance superficiaire | B28: USD | C28: =C$26*C$27 | D28: =D$26*D$27 | E28: =E$26*E$27 | F28: =F$26*F$27 | G28: =G$26*G$27 | H28: =H$26*H$27 | I28: =I$26*I$27 | J28: =J$26*J$27 | ... M28: =M$26*M$27 | N28: =SUM($C28:$M28) | O28: =$C28+NPV(10%,$D28:$M28)
A30: VII. REDEVANCE MINIERE
A31: Taux de la redevance minière | B31: % | C31: =IF(ISNUMBER(C5),IF(C$5<1300,3%,IF(C$5<1500,4%,5%)),"") | D31: =IF(ISNUMBER(D5),IF(D$5<1300,3%,IF(D$5<1500,4%,5%)),"") | E31: =IF(ISNUMBER(E5),IF(E$5<1300,3%,IF(E$5<1500,4%,5%)),"") | F31: =IF(ISNUMBER(F5),IF(F$5<1300,3%,IF(F$5<1500,4%,5%)),"") | G31: =IF(ISNUMBER(G5),IF(G$5<1300,3%,IF(G$5<1500,4%,5%)),"") | H31: =IF(ISNUMBER(H5),IF(H$5<1300,3%,IF(H$5<1500,4%,5%)),"") | I31: =IF(ISNUMBER(I5),IF(I$5<1300,3%,IF(I$5<1500,4%,5%)),"") | J31: =IF(ISNUMBER(J5),IF(J$5<1300,3%,IF(J$5<1500,4%,5%)),"") | ... M31: =IF(ISNUMBER(M5),IF(M$5<1300,3%,IF(M$5<1500,4%,5%)),"")
A32: Redevance minière | B32: USD | C32: =IF(ISNUMBER(C31),C$6*C$31,0) | D32: =IF(ISNUMBER(D31),D$6*D$31,0) | E32: =IF(ISNUMBER(E31),E$6*E$31,0) | F32: =IF(ISNUMBER(F31),F$6*F$31,0) | G32: =IF(ISNUMBER(G31),G$6*G$31,0) | H32: =IF(ISNUMBER(H31),H$6*H$31,0) | I32: =IF(ISNUMBER(I31),I$6*I$31,0) | J32: =IF(ISNUMBER(J31),J$6*J$31,0) | ... M32: =IF(ISNUMBER(M31),M$6*M$31,0) | N32: =SUM($C32:$M32) | O32: =$C32+NPV(10%,$D32:$M32)

Sheet 05_05_Charges_f_2
A1: Nom | B1: Unité | C1: Année 1 | D1: Année 2 | E1: Année 3 | F1: Année 4 | G1: Année 5 | H1: Année 6 | I1: Année 7 | J1: Année 8 | K1: Année 9 | L1: Année 10 | M1: Année 11
A3: Durée restante maximum | B3: Années | C3: 11 | D3: 10 | E3: 9 | F3: 8 | G3: 7 | H3: 6 | I3: 5 | J3: 4 | K3: 3 | L3: 2 | M3: 1
A5: I. AMORTISSEMENTS DES CONSTRUCTIONS INDUSTRIELLES
A6: Durée d'amortissement linéaire | B6: Années | C6: 10
A7: Coefficient d'amortissement dégressif | B7: Coefficient | C7: 1
A9: Immobilisations de l'année A1
A10: Durée restante | B10: Années | C10: =IF($C$6<C$3,$C$6,C$3) | D10: =IF(C10=0,0,IF(C10-1<D$3,C10-1,D$3)) | E10: =IF(D10=0,0,IF(D10-1<E$3,D10-1,E$3)) | F10: =IF(E10=0,0,IF(E10-1<F$3,E10-1,F$3)) | G10: =IF(F10=0,0,IF(F10-1<G$3,F10-1,G$3)) | H10: =IF(G10=0,0,IF(G10-1<H$3,G10-1,H$3)) | I10: =IF(H10=0,0,IF(H10-1<I$3,H10-1,I$3)) | J10: =IF(I10=0,0,IF(I10-1<J$3,I10-1,J$3)) | K10: =IF(J10=0,0,IF(J10-1<K$3,J10-1,K$3)) | ... M10: =IF(L10=0,0,IF(L10-1<M$3,L10-1,M$3))
A11: Base amortissable | B11: USD | C11: =Modèle!C$9 | D11: =C15 | E11: =D15 | F11: =E15 | G11: =F15 | H11: =G15 | I11: =H15 | J11: =I15 | K11: =J15 | ... M11: =L15
A12: Inverse de la durée restante | B12: % | C12: =IF(C10=0,0,1/C10) | D12: =IF(D10=0,0,1/D10) | E12: =IF(E10=0,0,1/E10) | F12: =IF(F10=0,0,1/F10) | G12: =IF(G10=0,0,1/G10) | H12: =IF(H10=0,0,1/H10) | I12: =IF(I10=0,0,1/I10) | J12: =IF(J10=0,0,1/J10) | ... M12: =IF(M10=0,0,1/M10)
A13: Taux dégressif | B13: % | C13: =IF(C10=0,0,IF($C$7*1/$C$6>C12,$C$7*1/$C$6,C12)) | D13: =IF(D10=0,0,IF($C$7*1/$C$6>D12,$C$7*1/$C$6,D12)) | E13: =IF(E10=0,0,IF($C$7*1/$C$6>E12,$C$7*1/$C$6,E12)) | F13: =IF(F10=0,0,IF($C$7*1/$C$6>F12,$C$7*1/$C$6,F12)) | G13: =IF(G10=0,0,IF($C$7*1/$C$6>G12,$C$7*1/$C$6,G12)) | H13: =IF(H10=0,0,IF($C$7*1/$C$6>H12,$C$7*1/$C$6,H12)) | I13: =IF(I10=0,0,IF($C$7*1/$C$6>I12,$C$7*1/$C$6,I12)) | J13: =IF(J10=0,0,IF($C$7*1/$C$6>J12,$C$7*1/$C$6,J12)) | ... M13: =IF(M10=0,0,IF($C$7*1/$C$6>M12,$C$7*1/$C$6,M12))
A14: Charge d'amortissement | B14: USD | C14: =C11*C13 | D14: =D11*D13 | E14: =E11*E13 | F14: =F11*F13 | G14: =G11*G13 | H14: =H11*H13 | I14: =I11*I13 | J14: =J11*J13 | ... M14: =M11*M13
A15: Amortissement restant | B15: USD | C15: =C11-C14 | D15: =D11-D14 | E15: =E11-E14 | F15: =F11-F14 | G15: =G11-G14 | H15: =H11-H14 | I15: =I11-I14 | J15: =J11-J14 | ... M15: =M11-M14
A17: Immobilisations de l'année A2
A18: Durée restante | B18: Années | D18: =IF($C$6<D$3,$C$6,D$3) | E18: =IF(D18=0,0,IF(D18-1<E$3,D18-1,E$3)) | F18: =IF(E18=0,0,IF(E18-1<F$3,E18-1,F$3)) | G18: =IF(F18=0,0,IF(F18-1<G$3,F18-1,G$3)) | H18: =IF(G18=0,0,IF(G18-1<H$3,G18-1,H$3)) | I18: =IF(H18=0,0,IF(H18-1<I$3,H18-1,I$3)) | J18: =IF(I18=0,0,IF(I18-1<J$3,I18-1,J$3)) | K18: =IF(J18=0,0,IF(J18-1<K$3,J18-1,K$3)) | L18: =IF(K18=0,0,IF(K18-1<L$3,K18-1,L$3)) | M18: =IF(L18=0,0,IF(L18-1<M$3,L18-1,M$3))
A19: Base amortissable | B19: USD | D19: =Modèle!D$9 | E19: =D23 | F19: =E23 | G19: =F23 | H19: =G23 | I19: =H23 | J19: =I23 | K19: =J23 | L19: =K23 | M19: =L23
A20: Inverse de la durée restante | B20: % | D20: =IF(D18=0,0,1/D18) | E20: =IF(E18=0,0,1/E18) | F20: =IF(F18=0,0,1/F18) | G20: =IF(G18=0,0,1/G18) | H20: =IF(H18=0,0,1/H18) | I20: =IF(I18=0,0,1/I18) | J20: =IF(J18=0,0,1/J18) | K20: =IF(K18=0,0,1/K18) | ... M20: =IF(M18=0,0,1/M18)
A21: Taux dégressif | B21: % | D21: =IF(D18=0,0,IF($C$7*1/$C$6>D20,$C$7*1/$C$6,D20)) | E21: =IF(E18=0,0,IF($C$7*1/$C$6>E20,$C$7*1/$C$6,E20)) | F21: =IF(F18=0,0,IF($C$7*1/$C$6>F20,$C$7*1/$C$6,F20)) | G21: =IF(G18=0,0,IF($C$7*1/$C$6>G20,$C$7*1/$C$6,G20)) | H21: =IF(H18=0,0,IF($C$7*1/$C$6>H20,$C$7*1/$C$6,H20)) | I21: =IF(I18=0,0,IF($C$7*1/$C$6>I20,$C$7*1/$C$6,I20)) | J21: =IF(J18=0,0,IF($C$7*1/$C$6>J20,$C$7*1/$C$6,J20)) | K21: =IF(K18=0,0,IF($C$7*1/$C$6>K20,$C$7*1/$C$6,K20)) | ... M21: =IF(M18=0,0,IF($C$7*1/$C$6>M20,$C$7*1/$C$6,M20))
A22: Charge d'amortissement | B22: USD | D22: =D19*D21 | E22: =E19*E21 | F22: =F19*F21 | G22: =G19*G21 | H22: =H19*H21 | I22: =I19*I21 | J22: =J19*J21 | K22: =K19*K21 | ... M22: =M19*M21
A23: Amortissement restant | B23: USD | D23: =D19-D22 | E23: =E19-E22 | F23: =F19-F22 | G23: =G19-G22 | H23: =H19-H22 | I23: =I19-I22 | J23: =J19-J22 | K23: =K19-K22 | ... M23: =M19-M22
A25: Amortissements des constructions industrielles | B25: USD | C25: =C$14+C$22 | D25: =D$14+D$22 | E25: =E$14+E$22 | F25: =F$14+F$22 | G25: =G$14+G$22 | H25: =H$14+H$22 | I25: =I$14+I$22 | J25: =J$14+J$22 | ... M25: =M$14+M$22
A27: II. AMORTISSEMENTS DES BIENS D'EQUIPEMENT
A28: Durée d'amortissement linéaire | B28: Années | C28: 5
A29: Coefficient d'amortissement dégressif | B29: Coefficient | C29: 2
A31: Immobilisations de l'année A1
A32: Durée restante | B32: Années | C32: =IF($C$28<C$3,$C$28,C$3) | D32: =IF(C32=0,0,IF(C32-1<D$3,C32-1,D$3)) | E32: =IF(D32=0,0,IF(D32-1<E$3,D32-1,E$3)) | F32: =IF(E32=0,0,IF(E32-1<F$3,E32-1,F$3)) | G32: =IF(F32=0,0,IF(F32-1<G$3,F32-1,G$3)) | H32: =IF(G32=0,0,IF(G32-1<H$3,G32-1,H$3)) | I32: =IF(H32=0,0,IF(H32-1<I$3,H32-1,I$3)) | J32: =IF(I32=0,0,IF(I32-1<J$3,I32-1,J$3)) | K32: =IF(J32=0,0,IF(J32-1<K$3,J32-1,K$3)) | ... M32: =IF(L32=0,0,IF(L32-1<M$3,L32-1,M$3))
A33: Base amortissable | B33: USD | C33: =Modèle!C$10 | D33: =C37 | E33: =D37 | F33: =E37 | G33: =F37 | H33: =G37 | I33: =H37 | J33: =I37 | K33: =J37 | ... M33: =L37
A34: Inverse de la durée restante | B34: % | C34: =IF(C32=0,0,1/C32) | D34: =IF(D32=0,0,1/D32) | E34: =IF(E32=0,0,1/E32) | F34: =IF(F32=0,0,1/F32) | G34: =IF(G32=0,0,1/G32) | H34: =IF(H32=0,0,1/H32) | I34: =IF(I32=0,0,1/I32) | J34: =IF(J32=0,0,1/J32) | ... M34: =IF(M32=0,0,1/M32)
A35: Taux dégressif | B35: % | C35: =IF(C32=0,0,IF($C$29*1/$C$28>C34,$C$29*1/$C$28,C34)) | D35: =IF(D32=0,0,IF($C$29*1/$C$28>D34,$C$29*1/$C$28,D34)) | E35: =IF(E32=0,0,IF($C$29*1/$C$28>E34,$C$29*1/$C$28,E34)) | F35: =IF(F32=0,0,IF($C$29*1/$C$28>F34,$C$29*1/$C$28,F34)) | G35: =IF(G32=0,0,IF($C$29*1/$C$28>G34,$C$29*1/$C$28,G34)) | H35: =IF(H32=0,0,IF($C$29*1/$C$28>H34,$C$29*1/$C$28,H34)) | I35: =IF(I32=0,0,IF($C$29*1/$C$28>I34,$C$29*1/$C$28,I34)) | J35: =IF(J32=0,0,IF($C$29*1/$C$28>J34,$C$29*1/$C$28,J34)) | ... M35: =IF(M32=0,0,IF($C$29*1/$C$28>M34,$C$29*1/$C$28,M34))
A36: Charge d'amortissement | B36: USD | C36: =C33*C35 | D36: =D33*D35 | E36: =E33*E35 | F36: =F33*F35 | G36: =G33*G35 | H36: =H33*H35 | I36: =I33*I35 | J36: =J33*J35 | ... M36: =M33*M35
A37: Amortissement restant | B37: USD | C37: =C33-C36 | D37: =D33-D36 | E37: =E33-E36 | F37: =F33-F36 | G37: =G33-G36 | H37: =H33-H36 | I37: =I33-I36 | J37: =J33-J36 | ... M37: =M33-M36
A39: Immobilisations de l'année A2
A40: Durée restante | B40: Années | D40: =IF($C$28<D$3,$C$28,D$3) | E40: =IF(D40=0,0,IF(D40-1<E$3,D40-1,E$3)) | F40: =IF(E40=0,0,IF(E40-1<F$3,E40-1,F$3)) | G40: =IF(F40=0,0,IF(F40-1<G$3,F40-1,G$3)) | H40: =IF(G40=0,0,IF(G40-1<H$3,G40-1,H$3)) | I40: =IF(H40=0,0,IF(H40-1<I$3,H40-1,I$3)) | J40: =IF(I40=0,0,IF(I40-1<J$3,I40-1,J$3)) | K40: =IF(J40=0,0,IF(J40-1<K$3,J40-1,K$3)) | L40: =IF(K40=0,0,IF(K40-1<L$3,K40-1,L$3)) | M40: =IF(L40=0,0,IF(L40-1<M$3,L40-1,M$3))
A41: Base amortissable | B41: USD | D41: =Modèle!D$10 | E41: =D45 | F41: =E45 | G41: =F45 | H41: =G45 | I41: =H45 | J41: =I45 | K41: =J45 | L41: =K45 | M41: =L45
A42: Inverse de la durée restante | B42: % | D42: =IF(D40=0,0,1/D40) | E42: =IF(E40=0,0,1/E40) | F42: =IF(F40=0,0,1/F40) | G42: =IF(G40=0,0,1/G40) | H42: =IF(H40=0,0,1/H40) | I42: =IF(I40=0,0,1/I40) | J42: =IF(J40=0,0,1/J40) | K42: =IF(K40=0,0,1/K40) | ... M42: =IF(M40=0,0,1/M40)
A43: Taux dégressif | B43: % | D43: =IF(D40=0,0,IF($C$29*1/$C$28>D42,$C$29*1/$C$28,D42)) | E43: =IF(E40=0,0,IF($C$29*1/$C$28>E42,$C$29*1/$C$28,E42)) | F43: =IF(F40=0,0,IF($C$29*1/$C$28>F42,$C$29*1/$C$28,F42)) | G43: =IF(G40=0,0,IF($C$29*1/$C$28>G42,$C$29*1/$C$28,G42)) | H43: =IF(H40=0,0,IF($C$29*1/$C$28>H42,$C$29*1/$C$28,H42)) | I43: =IF(I40=0,0,IF($C$29*1/$C$28>I42,$C$29*1/$C$28,I42)) | J43: =IF(J40=0,0,IF($C$29*1/$C$28>J42,$C$29*1/$C$28,J42)) | K43: =IF(K40=0,0,IF($C$29*1/$C$28>K42,$C$29*1/$C$28,K42)) | ... M43: =IF(M40=0,0,IF($C$29*1/$C$28>M42,$C$29*1/$C$28,M42))
A44: Charge d'amortissement | B44: USD | D44: =D41*D43 | E44: =E41*E43 | F44: =F41*F43 | G44: =G41*G43 | H44: =H41*H43 | I44: =I41*I43 | J44: =J41*J43 | K44: =K41*K43 | ... M44: =M41*M43
A45: Amortissement restant | B45: USD | D45: =D41-D44 | E45: =E41-E44 | F45: =F41-F44 | G45: =G41-G44 | H45: =H41-H44 | I45: =I41-I44 | J45: =J41-J44 | K45: =K41-K44 | ... M45: =M41-M44
A47: Immobilisations de l'année A3
A48: Durée restante | B48: Années | E48: =IF($C$28<E$3,$C$28,E$3) | F48: =IF(E48=0,0,IF(E48-1<F$3,E48-1,F$3)) | G48: =IF(F48=0,0,IF(F48-1<G$3,F48-1,G$3)) | H48: =IF(G48=0,0,IF(G48-1<H$3,G48-1,H$3)) | I48: =IF(H48=0,0,IF(H48-1<I$3,H48-1,I$3)) | J48: =IF(I48=0,0,IF(I48-1<J$3,I48-1,J$3)) | K48: =IF(J48=0,0,IF(J48-1<K$3,J48-1,K$3)) | L48: =IF(K48=0,0,IF(K48-1<L$3,K48-1,L$3)) | M48: =IF(L48=0,0,IF(L48-1<M$3,L48-1,M$3))
A49: Base amortissable | B49: USD | E49: =Modèle!E$10 | F49: =E53 | G49: =F53 | H49: =G53 | I49: =H53 | J49: =I53 | K49: =J53 | L49: =K53 | M49: =L53
...

Sheet 06_06_IS_IMF_1
A1: Nom | B1: Unité | C1: Année 1 | D1: Année 2 | E1: Année 3 | F1: Année 4 | G1: Année 5 | H1: Année 6 | I1: Année 7 | J1: Année 8 | K1: Année 9 | L1: Année 10 | M1: Année 11 | N1: SOMME | O1: VAN
A3: I. PRODUCTION
A4: Production d'or | B4: oz | E4: 250000 | F4: 250000 | G4: 250000 | H4: 250000 | I4: 250000 | J4: 250000 | K4: 250000 | L4: 250000 | N4: =SUM($C4:$M4)
A5: Cours de l'or | B5: USD/oz | E5: 1300 | F5: 1300 | G5: 1300 | H5: 1300 | I5: 1300 | J5: 1300 | K5: 1300 | L5: 1300
A6: Chiffre d'affaires | B6: USD | C6: =C$4*C$5 | D6: =D$4*D$5 | E6: =E$4*E$5 | F6: =F$4*F$5 | G6: =G$4*G$5 | H6: =H$4*H$5 | I6: =I$4*I$5 | J6: =J$4*J$5 | ... M6: =M$4*M$5 | N6: =SUM($C6:$M6) | O6: =$C6+NPV(10%,$D6:$M6)
A8: II. DEPENSES D'INVESTISSEMENT (CAPEX)
A9: Coûts des construction industrielles | B9: USD | C9: 50000000 | D9: 100000000 | N9: =SUM($C9:$M9) | O9: =$C9+NPV(10%,$D9:$M9)
A10: Coûts des biens d'équipement | B10: USD | D10: 50000000 | E10: 5000000 | F10: 5000000 | G10: 5000000 | H10: 5000000 | I10: 5000000 | J10: 5000000 | K10: 5000000 | L10: 5000000 | N10: =SUM($C10:$M10) | O10: =$C10+NPV(10%,$D10:$M10)
A11: Coûts de réhabilitation du site | B11: USD | M11: 10000000 | N11: =SUM($C11:$M11) | O11: =$C11+NPV(10%,$D11:$M11)
A12: Total des dépenses d'investissement | B12: USD | C12: =SUM(C$9:C$11) | D12: =SUM(D$9:D$11) | E12: =SUM(E$9:E$11) | F12: =SUM(F$9:F$11) | G12: =SUM(G$9:G$11) | H12: =SUM(H$9:H$11) | I12: =SUM(I$9:I$11) | J12: =SUM(J$9:J$11) | ... M12: =SUM(M$9:M$11) | N12: =SUM($C12:$M12) | O12: =$C12+NPV(10%,$D12:$M12)
A14: III. COÛTS D'EXPLOITATION (OPEX)
A15: Coût moyen d'exploitation | B15: USD/oz | E15: 700 | F15: 700 | G15: 700 | H15: 700 | I15: 700 | J15: 700 | K15: 700 | L15: 700
A16: Total des coûts d'exploitation | B16: USD | C16: =C$4*C$15 | D16: =D$4*D$15 | E16: =E$4*E$15 | F16: =F$4*F$15 | G16: =G$4*G$15 | H16: =H$4*H$15 | I16: =I$4*I$15 | J16: =J$4*J$15 | ... M16: =M$4*M$15 | N16: =SUM($C16:$M16) | O16: =$C16+NPV(10%,$D16:$M16)
A18: IV. FLUX NETS DE TRESORERIE AVANT IMPÔTS
A19: Flux nets de trésorerie avant impôts | B19: USD | C19: =C$6-C$12-C$16 | D19: =D$6-D$12-D$16 | E19: =E$6-E$12-E$16 | F19: =F$6-F$12-F$16 | G19: =G$6-G$12-G$16 | H19: =H$6-H$12-H$16 | I19: =I$6-I$12-I$16 | J19: =J$6-J$12-J$16 | ... M19: =M$6-M$12-M$16 | N19: =SUM($C19:$M19) | O19: =$C19+NPV(10%,$D19:$M19)
A20: Taux de rendement interne avant impôts | B20: % | C20: =IF(ISNUMBER(IRR($C19:C19)),IF(IRR($C19:C19)>0,IRR($C19:C19),""),"") | D20: =IF(ISNUMBER(IRR($C19:D19)),IF(IRR($C19:D19)>0,IRR($C19:D19),""),"") | E20: =IF(ISNUMBER(IRR($C19:E19)),IF(IRR($C19:E19)>0,IRR($C19:E19),""),"") | F20: =IF(ISNUMBER(IRR($C19:F19)),IF(IRR($C19:F19)>0,IRR($C19:F19),""),"") | G20: =IF(ISNUMBER(IRR($C19:G19)),IF(IRR($C19:G19)>0,IRR($C19:G19),""),"") | H20: =IF(ISNUMBER(IRR($C19:H19)),IF(IRR($C19:H19)>0,IRR($C19:H19),""),"") | I20: =IF(ISNUMBER(IRR($C19:I19)),IF(IRR($C19:I19)>0,IRR($C19:I19),""),"") | J20: =IF(ISNUMBER(IRR($C19:J19)),IF(IRR($C19:J19)>0,IRR($C19:J19),""),"") | ... M20: =IF(ISNUMBER(IRR($C19:M19)),IF(IRR($C19:M19)>0,IRR($C19:M19),""),"")
A22: V. DROITS FIXES
A23: Droits fixes | B23: USD | C23: 100000 | N23: =SUM($C23:$M23) | O23: =$C23+NPV(10%,$D23:$M23)
A25: VI. REDEVANCE SUPERFICAIRE
A26: Superficie de la mine | B26: km² | C26: 100 | D26: 100 | E26: 100 | F26: 100 | G26: 100 | H26: 100 | I26: 100 | J26: 100 | K26: 100 | L26: 100 | M26: 100
A27: Montant de la redevance superfiaire | B27: USD/km² | C27: 100 | D27: 100 | E27: 100 | F27: 100 | G27: 100 | H27: 100 | I27: 100 | J27: 100 | K27: 100 | L27: 100 | M27: 100
A28: Redevance superficiaire | B28: USD | C28: =C$26*C$27 | D28: =D$26*D$27 | E28: =E$26*E$27 | F28: =F$26*F$27 | G28: =G$26*G$27 | H28: =H$26*H$27 | I28: =I$26*I$27 | J28: =J$26*J$27 | ... M28: =M$26*M$27 | N28: =SUM($C28:$M28) | O28: =$C28+NPV(10%,$D28:$M28)
A30: VII. REDEVANCE MINIERE
A31: Taux de la redevance minière | B31: % | C31: =IF(ISNUMBER(C5),IF(C$5<1300,3%,IF(C$5<1500,4%,5%)),"") | D31: =IF(ISNUMBER(D5),IF(D$5<1300,3%,IF(D$5<1500,4%,5%)),"") | E31: =IF(ISNUMBER(E5),IF(E$5<1300,3%,IF(E$5<1500,4%,5%)),"") | F31: =IF(ISNUMBER(F5),IF(F$5<1300,3%,IF(F$5<1500,4%,5%)),"") | G31: =IF(ISNUMBER(G5),IF(G$5<1300,3%,IF(G$5<1500,4%,5%)),"") | H31: =IF(ISNUMBER(H5),IF(H$5<1300,3%,IF(H$5<1500,4%,5%)),"") | I31: =IF(ISNUMBER(I5),IF(I$5<1300,3%,IF(I$5<1500,4%,5%)),"") | J31: =IF(ISNUMBER(J5),IF(J$5<1300,3%,IF(J$5<1500,4%,5%)),"") | ... M31: =IF(ISNUMBER(M5),IF(M$5<1300,3%,IF(M$5<1500,4%,5%)),"")
A32: Redevance minière | B32: USD | C32: =IF(ISNUMBER(C31),C$6*C$31,0) | D32: =IF(ISNUMBER(D31),D$6*D$31,0) | E32: =IF(ISNUMBER(E31),E$6*E$31,0) | F32: =IF(ISNUMBER(F31),F$6*F$31,0) | G32: =IF(ISNUMBER(G31),G$6*G$31,0) | H32: =IF(ISNUMBER(H31),H$6*H$31,0) | I32: =IF(ISNUMBER(I31),I$6*I$31,0) | J32: =IF(ISNUMBER(J31),J$6*J$31,0) | ... M32: =IF(ISNUMBER(M31),M$6*M$31,0) | N32: =SUM($C32:$M32) | O32: =$C32+NPV(10%,$D32:$M32)
A34: VIII. IMPÔT SUR LES SOCIETES (IS)
A35: Bénéfice avant report des pertes | B35: USD | C35: =C$6-C$16-C$23-C$28-C$32-'Amortissements et Emprunt'!C$25-'Amortissements et Emprunt'!C$119-'Amortissements et Emprunt'!C133-'Amortissements et Emprunt'!C$157 | D35: =D$6-D$16-D$23-D$28-D$32-'Amortissements et Emprunt'!D$25-'Amortissements et Emprunt'!D$119-'Amortissements et Emprunt'!D133-'Amortissements et Emprunt'!D$157 | E35: =E$6-E$16-E$23-E$28-E$32-'Amortissements et Emprunt'!E$25-'Amortissements et Emprunt'!E$119-'Amortissements et Emprunt'!E133-'Amortissements et Emprunt'!E$157 | F35: =F$6-F$16-F$23-F$28-F$32-'Amortissements et Emprunt'!F$25-'Amortissements et Emprunt'!F$119-'Amortissements et Emprunt'!F133-'Amortissements et Emprunt'!F$157 | G35: =G$6-G$16-G$23-G$28-G$32-'Amortissements et Emprunt'!G$25-'Amortissements et Emprunt'!G$119-'Amortissements et Emprunt'!G133-'Amortissements et Emprunt'!G$157 | H35: =H$6-H$16-H$23-H$28-H$32-'Amortissements et Emprunt'!H$25-'Amortissements et Emprunt'!H$119-'Amortissements et Emprunt'!H133-'Amortissements et Emprunt'!H$157 | I35: =I$6-I$16-I$23-I$28-I$32-'Amortissements et Emprunt'!I$25-'Amortissements et Emprunt'!I$119-'Amortissements et Emprunt'!I133-'Amortissements et Emprunt'!I$157 | J35: =J$6-J$16-J$23-J$28-J$32-'Amortissements et Emprunt'!J$25-'Amortissements et Emprunt'!J$119-'Amortissements et Emprunt'!J133-'Amortissements et Emprunt'!J$157 | ... M35: =M$6-M$16-M$23-M$28-M$32-'Amortissements et Emprunt'!M$25-'Amortissements et Emprunt'!M$119-'Amortissements et Emprunt'!M133-'Amortissements et Emprunt'!M$157 | N35: =SUM($C35:$M35) | O35: =$C35+NPV(10%,$D35:$M35)
A36: Report des pertes | B36: USD | D36: =IF(C37<0,C37,0) | E36: =IF(D37<0,D37,0) | F36: =IF(E37<0,E37,0) | G36: =IF(F37<0,F37,0) | H36: =IF(G37<0,G37,0) | I36: =IF(H37<0,H37,0) | J36: =IF(I37<0,I37,0) | K36: =IF(J37<0,J37,0) | ... M36: =IF(L37<0,L37,0)
A37: Bénéfice fiscal | B37: USD | C37: =C$35+C$36 | D37: =D$35+D$36 | E37: =E$35+E$36 | F37: =F$35+F$36 | G37: =G$35+G$36 | H37: =H$35+H$36 | I37: =I$35+I$36 | J37: =J$35+J$36 | ... M37: =M$35+M$36 | N37: =SUM($C37:$M37) | O37: =$C37+NPV(10%,$D37:$M37)
A38: Taux de l'impôt sur les sociétés | B38: % | C38: 0.3 | D38: 0.3 | E38: 0.3 | F38: 0.3 | G38: 0.3 | H38: 0.3 | I38: 0.3 | J38: 0.3 | K38: 0.3 | L38: 0.3 | M38: 0.3
A39: Impôt sur les sociétés | B39: USD | C39: =IF(C$37>0,C$37*C$38,0) | D39: =IF(D$37>0,D$37*D$38,0) | E39: =IF(E$37>0,E$37*E$38,0) | F39: =IF(F$37>0,F$37*F$38,0) | G39: =IF(G$37>0,G$37*G$38,0) | H39: =IF(H$37>0,H$37*H$38,0) | I39: =IF(I$37>0,I$37*I$38,0) | J39: =IF(J$37>0,J$37*J$38,0) | ... M39: =IF(M$37>0,M$37*M$38,0) | N39: =SUM($C39:$M39) | O39: =$C39+NPV(10%,$D39:$M39)
A41: IX. IMPÔT MINIMUM FORFAITAIRE (IMF)
A42: Montant minimum | B42: USD | C42: 2000 | D42: 2000 | E42: 2000 | F42: 2000 | G42: 2000 | H42: 2000 | I42: 2000 | J42: 2000 | K42: 2000 | L42: 2000 | M42: 2000
A43: Taux de l'impôt minimum forfaitaire | B43: % | C43: 0.01 | D43: 0.01 | E43: 0.01 | F43: 0.01 | G43: 0.01 | H43: 0.01 | I43: 0.01 | J43: 0.01 | K43: 0.01 | L43: 0.01 | M43: 0.01
A44: Impôt minimum forfaitaire | B44: USD | C44: =IF(C$6*C$43>C$42,C$6*C$43,C$42) | D44: =IF(D$6*D$43>D$42,D$6*D$43,D$42) | E44: =IF(E$6*E$43>E$42,E$6*E$43,E$42) | F44: =IF(F$6*F$43>F$42,F$6*F$43,F$42) | G44: =IF(G$6*G$43>G$42,G$6*G$43,G$42) | H44: =IF(H$6*H$43>H$42,H$6*H$43,H$42) | I44: =IF(I$6*I$43>I$42,I$6*I$43,I$42) | J44: =IF(J$6*J$43>J$42,J$6*J$43,J$42) | ... M44: =IF(M$6*M$43>M$42,M$6*M$43,M$42) | N44: =SUM($C44:$M44) | O44: =$C44+NPV(10%,$D44:$M44)
A46: X. IMPÔT SUR LES SOCIETES (IS) / IMPÔT MINIMUM FORFAITAIRE (IMF)
