Workbook

Sheet Modèle_législation en vigueur
A1: Nom | B1: Unité | C1: Année 1 | D1: Année 2 | E1: Année 3 | F1: Année 4 | G1: Année 5 | H1: Année 6 | I1: Année 7 | J1: Année 8 | K1: Année 9 | L1: Année 10 | M1: Année 11 | N1: Année 12 | O1: Année 13 | P1: Année 14 | Q1: Année 15 | R1: SOMME | S1: VAN
A3: I. PRODUCTION
A4: Production d'or | B4: oz | E4: 300000 | F4: 300000 | G4: 300000 | H4: 300000 | I4: 300000 | J4: 300000 | K4: 300000 | L4: 300000 | M4: 300000 | N4: 300000 | O4: 300000 | P4: 300000 | R4: =SUM($C4:$Q4) -> 3600000
A5: Cours de l'or | B5: USD/oz | E5: 1600 | F5: 1300 | G5: 1300 | H5: 1300 | I5: 1300 | J5: 1300 | K5: 1300 | L5: 1300 | M5: 1300 | N5: 1300 | O5: 1300 | P5: 1300
A6: Chiffre d'affaires | B6: USD | C6: =C$4*C$5 -> 0 | D6: =D$4*D$5 -> 0 | E6: =E$4*E$5 -> 480000000 | F6: =F$4*F$5 -> 390000000 | G6: =G$4*G$5 -> 390000000 | H6: =H$4*H$5 -> 390000000 | I6: =I$4*I$5 -> 390000000 | J6: =J$4*J$5 -> 390000000 | ... Q6: =Q$4*Q$5 -> 0 | R6: =SUM($C6:$Q6) -> 4770000000 | S6: =$C6+NPV(10%,$D6:$Q6) -> 2.4901436e+09
A8: II. DEPENSES D'INVESTISSEMENT (CAPEX)
A9: Coûts des construction industrielles | B9: USD | C9: 50000000 | D9: 150000000 | R9: =SUM($C9:$Q9) -> 200000000 | S9: =$C9+NPV(10%,$D9:$Q9) -> 1.8636364e+08
A10: Coûts des biens d'équipement | B10: USD | D10: 80000000 | E10: 10000000 | F10: 10000000 | G10: 10000000 | H10: 10000000 | I10: 10000000 | J10: 10000000 | K10: 10000000 | L10: 10000000 | M10: 10000000 | N10: 10000000 | O10: 10000000 | P10: 10000000 | R10: =SUM($C10:$Q10) -> 200000000 | S10: =$C10+NPV(10%,$D10:$Q10) -> 1.3466993e+08
A11: Coûts de réhabilitation du site | B11: USD | Q11: 30000000 | R11: =SUM($C11:$Q11) -> 30000000 | S11: =$C11+NPV(10%,$D11:$Q11) -> 27272727
A12: Total des dépenses d'investissement | B12: USD | C12: =SUM(C$9:C$11) -> 50000000 | D12: =SUM(D$9:D$11) -> 230000000 | E12: =SUM(E$9:E$11) -> 10000000 | F12: =SUM(F$9:F$11) -> 10000000 | G12: =SUM(G$9:G$11) -> 10000000 | H12: =SUM(H$9:H$11) -> 10000000 | I12: =SUM(I$9:I$11) -> 10000000 | J12: =SUM(J$9:J$11) -> 10000000 | ... Q12: =SUM(Q$9:Q$11) -> 30000000 | R12: =SUM($C12:$Q12) -> 430000000 | S12: =$C12+NPV(10%,$D12:$Q12) -> 3.289335e+08
A14: III. COÛTS D'EXPLOITATION (OPEX)
A15: Coût moyen d'exploitation | B15: USD/oz | E15: 800 | F15: 800 | G15: 800 | H15: 800 | I15: 800 | J15: 800 | K15: 800 | L15: 800 | M15: 800 | N15: 800 | O15: 800 | P15: 800
A16: Total des coûts d'exploitation | B16: USD | C16: =C$4*C$15 -> 0 | D16: =D$4*D$15 -> 0 | E16: =E$4*E$15 -> 240000000 | F16: =F$4*F$15 -> 240000000 | G16: =G$4*G$15 -> 240000000 | H16: =H$4*H$15 -> 240000000 | I16: =I$4*I$15 -> 240000000 | J16: =J$4*J$15 -> 240000000 | ... Q16: =Q$4*Q$15 -> 0 | R16: =SUM($C16:$Q16) -> 2880000000 | S16: =$C16+NPV(10%,$D16:$Q16) -> 1.4866237e+09
A18: IV. FLUX NETS DE TRESORERIE AVANT IMPÔTS
A19: Flux nets de trésorerie avant impôts | B19: USD | C19: =C$6-C$12-C$16 -> -50000000 | D19: =D$6-D$12-D$16 -> -230000000 | E19: =E$6-E$12-E$16 -> 230000000 | F19: =F$6-F$12-F$16 -> 140000000 | G19: =G$6-G$12-G$16 -> 140000000 | H19: =H$6-H$12-H$16 -> 140000000 | I19: =I$6-I$12-I$16 -> 140000000 | J19: =J$6-J$12-J$16 -> 140000000 | ... Q19: =Q$6-Q$12-Q$16 -> -30000000 | R19: =SUM($C19:$Q19) -> 1460000000 | S19: =$C19+NPV(10%,$D19:$Q19) -> 6.7458646e+08
A20: Taux de rendement interne avant impôts | B20: % | C20: =IF(ISNUMBER(IRR($C19:C19)),IF(IRR($C19:C19)>0,IRR($C19:C19),""),"") | D20: =IF(ISNUMBER(IRR($C19:D19)),IF(IRR($C19:D19)>0,IRR($C19:D19),""),"") | E20: =IF(ISNUMBER(IRR($C19:E19)),IF(IRR($C19:E19)>0,IRR($C19:E19),""),"") | F20: =IF(ISNUMBER(IRR($C19:F19)),IF(IRR($C19:F19)>0,IRR($C19:F19),""),"") -> 0.19701925 | G20: =IF(ISNUMBER(IRR($C19:G19)),IF(IRR($C19:G19)>0,IRR($C19:G19),""),"") -> 0.36607214 | H20: =IF(ISNUMBER(IRR($C19:H19)),IF(IRR($C19:H19)>0,IRR($C19:H19),""),"") -> 0.45069468 | I20: =IF(ISNUMBER(IRR($C19:I19)),IF(IRR($C19:I19)>0,IRR($C19:I19),""),"") -> 0.49588878 | J20: =IF(ISNUMBER(IRR($C19:J19)),IF(IRR($C19:J19)>0,IRR($C19:J19),""),"") -> 0.52127836 | ... Q20: =IF(ISNUMBER(IRR($C19:Q19)),IF(IRR($C19:Q19)>0,IRR($C19:Q19),""),"") -> 0.55693685
A22: V. DROITS FIXES
A23: Droits fixes | B23: USD | C23: 50000 | R23: =SUM($C23:$Q23) -> 50000 | S23: =$C23+NPV(10%,$D23:$Q23) -> 50000
A25: VI. REDEVANCE SUPERFICAIRE
A26: Superficie de la mine | B26: km² | C26: 150 | D26: 150 | E26: 150 | F26: 150 | G26: 150 | H26: 150 | I26: 150 | J26: 150 | K26: 150 | L26: 150 | M26: 150 | N26: 150 | O26: 150 | P26: 150 | Q26: 150
A27: Montant de la redevance superfiaire | B27: USD/km² | C27: 100 | D27: 100 | E27: 100 | F27: 100 | G27: 100 | H27: 500 | I27: 500 | J27: 500 | K27: 500 | L27: 500 | M27: 500 | N27: 500 | O27: 500 | P27: 500 | Q27: 500
A28: Redevance superficiaire | B28: USD | C28: =C$26*C$27 -> 15000 | D28: =D$26*D$27 -> 15000 | E28: =E$26*E$27 -> 15000 | F28: =F$26*F$27 -> 15000 | G28: =G$26*G$27 -> 15000 | H28: =H$26*H$27 -> 75000 | I28: =I$26*I$27 -> 75000 | J28: =J$26*J$27 -> 75000 | ... Q28: =Q$26*Q$27 -> 75000 | R28: =SUM($C28:$Q28) -> 825000 | S28: =$C28+NPV(10%,$D28:$Q28) -> 377309.63 | U28: =S28/$S$71 -> 0.00089160537
A30: VII. REDEVANCE MINIERE
A31: Taux de la redevance minière | B31: % | C31: 0.03 | D31: 0.03 | E31: 0.03 | F31: 0.03 | G31: 0.03 | H31: 0.03 | I31: 0.03 | J31: 0.03 | K31: 0.03 | L31: 0.03 | M31: 0.03 | N31: 0.03 | O31: 0.03 | P31: 0.03 | Q31: 0.03
A32: Redevance minière | B32: USD | C32: =IF(ISNUMBER(C31),C$6*C$31,0) -> 0 | D32: =IF(ISNUMBER(D31),D$6*D$31,0) -> 0 | E32: =IF(ISNUMBER(E31),E$6*E$31,0) -> 14400000 | F32: =IF(ISNUMBER(F31),F$6*F$31,0) -> 11700000 | G32: =IF(ISNUMBER(G31),G$6*G$31,0) -> 11700000 | H32: =IF(ISNUMBER(H31),H$6*H$31,0) -> 11700000 | I32: =IF(ISNUMBER(I31),I$6*I$31,0) -> 11700000 | J32: =IF(ISNUMBER(J31),J$6*J$31,0) -> 11700000 | ... Q32: =IF(ISNUMBER(Q31),Q$6*Q$31,0) -> 0 | R32: =SUM($C32:$Q32) -> 143100000 | S32: =$C32+NPV(10%,$D32:$Q32) -> 74704309 | U32: =S32/$S$71 -> 0.17653078
A34: +. LA TAXE SUR LA RENTE
A35: Taux de revalorisation des pertes | B35: % | C35: 0.02 | D35: 0.02 | E35: 0.02 | F35: 0.02 | G35: 0.02 | H35: 0.02 | I35: 0.02 | J35: 0.02 | K35: 0.02 | L35: 0.02 | M35: 0.02 | N35: 0.02 | O35: 0.02 | P35: 0.02 | Q35: 0.02
A36: Flux nets de trésorerie revalorisés | B36: USD | C36: =IF(C19<0,C19*(1+C35),C19) -> -51000000 | D36: =IF(D19<0,D19*(1+D35),D19) -> -234600000 | E36: =IF(E19<0,E19*(1+E35),E19) -> 230000000 | F36: =IF(F19<0,F19*(1+F35),F19) -> 140000000 | G36: =IF(G19<0,G19*(1+G35),G19) -> 140000000 | H36: =IF(H19<0,H19*(1+H35),H19) -> 140000000 | I36: =IF(I19<0,I19*(1+I35),I19) -> 140000000 | J36: =IF(J19<0,J19*(1+J35),J19) -> 140000000 | ... Q36: =IF(Q19<0,Q19*(1+Q35),Q19) -> -30600000 | R36: =SUM($C36:$Q36) -> 1453800000 | S36: =$C36+NPV(10%,$D36:$Q36) -> 6.6924664e+08
A37: Taux de rendement interne | B37: % | C37: =IF(ISNUMBER(IRR($C36:C36)),IF(IRR($C36:C36)>0,IRR($C36:C36),""),"") | D37: =IF(ISNUMBER(IRR($C36:D36)),IF(IRR($C36:D36)>0,IRR($C36:D36),""),"") | E37: =IF(ISNUMBER(IRR($C36:E36)),IF(IRR($C36:E36)>0,IRR($C36:E36),""),"") | F37: =IF(ISNUMBER(IRR($C36:F36)),IF(IRR($C36:F36)>0,IRR($C36:F36),""),"") -> 0.18176457 | G37: =IF(ISNUMBER(IRR($C36:G36)),IF(IRR($C36:G36)>0,IRR($C36:G36),""),"") -> 0.35153498 | H37: =IF(ISNUMBER(IRR($C36:H36)),IF(IRR($C36:H36)>0,IRR($C36:H36),""),"") -> 0.43695198 | I37: =IF(ISNUMBER(IRR($C36:I36)),IF(IRR($C36:I36)>0,IRR($C36:I36),""),"") -> 0.48279067 | J37: =IF(ISNUMBER(IRR($C36:J36)),IF(IRR($C36:J36)>0,IRR($C36:J36),""),"") -> 0.50866839 | ... Q37: =IF(ISNUMBER(IRR($C36:Q36)),IF(IRR($C36:Q36)>0,IRR($C36:Q36),""),"") -> 0.54544451
A38: Seuil de déclenchement de la taxe sur la rente | B38: % | C38: 0.15 | D38: 0.15 | E38: 0.15 | F38: 0.15 | G38: 0.15 | H38: 0.15 | I38: 0.15 | J38: 0.15 | K38: 0.15 | L38: 0.15 | M38: 0.15 | N38: 0.15 | O38: 0.15 | P38: 0.15 | Q38: 0.15
A39: Report des pertes revalorisées | D39: =IF(C40<0,C40,0) -> -51000000 | E39: =IF(D40<0,D40,0) -> -285600000 | F39: =IF(E40<0,E40,0) -> -55600000 | G39: =IF(F40<0,F40,0) -> 0 | H39: =IF(G40<0,G40,0) -> 0 | I39: =IF(H40<0,H40,0) -> 0 | J39: =IF(I40<0,I40,0) -> 0 | K39: =IF(J40<0,J40,0) -> 0 | ... Q39: =IF(P40<0,P40,0) -> 0
A40: Flux nets de trésorerie après report des pertes revalorisées | B40: USD | C40: =C36+C39 -> -51000000 | D40: =D36+D39 -> -285600000 | E40: =E36+E39 -> -55600000 | F40: =F36+F39 -> 84400000 | G40: =G36+G39 -> 140000000 | H40: =H36+H39 -> 140000000 | I40: =I36+I39 -> 140000000 | J40: =J36+J39 -> 140000000 | ... Q40: =Q36+Q39 -> -30600000 | R40: =SUM($C40:$Q40) -> 1061600000 | S40: =$C40+NPV(10%,$D40:$Q40) -> 3.4507685e+08
A41: Taux de la taxe sur la rente | B41: % | C41: 0.2 | D41: 0.2 | E41: 0.2 | F41: 0.2 | G41: 0.2 | H41: 0.2 | I41: 0.2 | J41: 0.2 | K41: 0.2 | L41: 0.2 | M41: 0.2 | N41: 0.2 | O41: 0.2 | P41: 0.2 | Q41: 0.2
A42: Taxe sur la rente | B42: USD | C42: =IF(C37<C38,0,IF(C40<0,0,C40*C41)) -> 0 | D42: =IF(D37<D38,0,IF(D40<0,0,D40*D41)) -> 0 | E42: =IF(E37<E38,0,IF(E40<0,0,E40*E41)) -> 0 | F42: =IF(F37<F38,0,IF(F40<0,0,F40*F41)) -> 16880000 | G42: =IF(G37<G38,0,IF(G40<0,0,G40*G41)) -> 28000000 | H42: =IF(H37<H38,0,IF(H40<0,0,H40*H41)) -> 28000000 | I42: =IF(I37<I38,0,IF(I40<0,0,I40*I41)) -> 28000000 | J42: =IF(J37<J38,0,IF(J40<0,0,J40*J41)) -> 28000000 | ... Q42: =IF(Q37<Q38,0,IF(Q40<0,0,Q40*Q41)) -> 0 | R42: =SUM($C42:$Q42) -> 296880000 | S42: =$C42+NPV(10%,$D42:$Q42) -> 1.4194431e+08 | U42: =S42/$S$71 -> 0.33542295
A44: VIII. IMPÔT SUR LES SOCIETES (IS)
A45: Bénéfice avant report des pertes | B45: USD | C45: =C$6-C$16-C$23-C$28-C$32-C$42+'Amortissements et Emprunt'!C191 -> -7565000 | D45: =D$6-D$16-D$23-D$28-D$32-D$42+'Amortissements et Emprunt'!D191 -> -41765000 | E45: =E$6-E$16-E$23-E$28-E$32-E$42+'Amortissements et Emprunt'!E191 -> 184235000 | F45: =F$6-F$16-F$23-F$28-F$32-F$42+'Amortissements et Emprunt'!F191 -> 80455000 | G45: =G$6-G$16-G$23-G$28-G$32-G$42+'Amortissements et Emprunt'!G191 -> 69735000 | H45: =H$6-H$16-H$23-H$28-H$32-H$42+'Amortissements et Emprunt'!H191 -> 70075000 | I45: =I$6-I$16-I$23-I$28-I$32-I$42+'Amortissements et Emprunt'!I191 -> 70363889 | J45: =J$6-J$16-J$23-J$28-J$32-J$42+'Amortissements et Emprunt'!J191 -> 70513889 | ... Q45: =Q$6-Q$16-Q$23-Q$28-Q$32-Q$42+'Amortissements et Emprunt'!Q191 -> -49364683 | R45: =SUM($C45:$Q45) -> 942145000 | S45: =$C45+NPV(10%,$D45:$Q45) -> 5.023728e+08
A46: Report des pertes | B46: USD | D46: =IF(C47<0,C47,0) -> -7565000 | E46: =IF(D47<0,D47,0) -> -49330000 | F46: =IF(E47<0,E47,0) -> 0 | G46: =IF(F47<0,F47,0) -> 0 | H46: =IF(G47<0,G47,0) -> 0 | I46: =IF(H47<0,H47,0) -> 0 | J46: =IF(I47<0,I47,0) -> 0 | K46: =IF(J47<0,J47,0) -> 0 | ... Q46: =IF(P47<0,P47,0) -> 0
A47: Bénéfice fiscal | B47: USD | C47: =C$45+C$46 -> -7565000 | D47: =D$45+D$46 -> -49330000 | E47: =E$45+E$46 -> 134905000 | F47: =F$45+F$46 -> 80455000 | G47: =G$45+G$46 -> 69735000 | H47: =H$45+H$46 -> 70075000 | I47: =I$45+I$46 -> 70363889 | J47: =J$45+J$46 -> 70513889 | ... Q47: =Q$45+Q$46 -> -49364683 | R47: =SUM($C47:$Q47) -> 885250000 | S47: =$C47+NPV(10%,$D47:$Q47) -> 4.5472693e+08
A48: Taux de l'impôt sur les sociétés | B48: % | C48: 0.3 | D48: 0.3 | E48: 0.3 | F48: 0.3 | G48: 0.3 | H48: 0.3 | I48: 0.3 | J48: 0.3 | K48: 0.3 | L48: 0.3 | M48: 0.3 | N48: 0.3 | O48: 0.3 | P48: 0.3 | Q48: 0.3
A49: Impôt sur les sociétés | B49: USD | C49: =IF(C$47>0,C$47*C$48,0) -> 0 | D49: =IF(D$47>0,D$47*D$48,0) -> 0 | E49: =IF(E$47>0,E$47*E$48,0) -> 40471500 | F49: =IF(F$47>0,F$47*F$48,0) -> 24136500 | G49: =IF(G$47>0,G$47*G$48,0) -> 20920500 | H49: =IF(H$47>0,H$47*H$48,0) -> 21022500 | I49: =IF(I$47>0,I$47*I$48,0) -> 21109167 | J49: =IF(J$47>0,J$47*J$48,0) -> 21154167 | ... Q49: =IF(Q$47>0,Q$47*Q$48,0) -> 0 | R49: =SUM($C49:$Q49) -> 2.974529e+08 | S49: =$C49+NPV(10%,$D49:$Q49) -> 1.56041e+08
...

Sheet Modèle_projet de loi
A1: Nom | B1: Unité | C1: Année 1 | D1: Année 2 | E1: Année 3 | F1: Année 4 | G1: Année 5 | H1: Année 6 | I1: Année 7 | J1: Année 8 | K1: Année 9 | L1: Année 10 | M1: Année 11 | N1: Année 12 | O1: Année 13 | P1: Année 14 | Q1: Année 15 | R1: SOMME | S1: VAN
A3: I. PRODUCTION
A4: Production d'or | B4: oz | E4: 300000 | F4: 300000 | G4: 300000 | H4: 300000 | I4: 300000 | J4: 300000 | K4: 300000 | L4: 300000 | M4: 300000 | N4: 300000 | O4: 300000 | P4: 300000 | R4: =SUM($C4:$Q4) -> 3600000
A5: Cours de l'or | B5: USD/oz | E5: 1600 | F5: 1600 | G5: 1600 | H5: 1600 | I5: 1600 | J5: 1600 | K5: 1600 | L5: 1600 | M5: 1600 | N5: 1600 | O5: 1600 | P5: 1600
A6: Chiffre d'affaires | B6: USD | C6: =C$4*C$5 -> 0 | D6: =D$4*D$5 -> 0 | E6: =E$4*E$5 -> 480000000 | F6: =F$4*F$5 -> 480000000 | G6: =G$4*G$5 -> 480000000 | H6: =H$4*H$5 -> 480000000 | I6: =I$4*I$5 -> 480000000 | J6: =J$4*J$5 -> 480000000 | ... Q6: =Q$4*Q$5 -> 0 | R6: =SUM($C6:$Q6) -> 5760000000 | S6: =$C6+NPV(10%,$D6:$Q6) -> 2.9732473e+09
A8: II. DEPENSES D'INVESTISSEMENT (CAPEX)
A9: Coûts des construction industrielles | B9: USD | C9: 50000000 | D9: 150000000 | R9: =SUM($C9:$Q9) -> 200000000 | S9: =$C9+NPV(10%,$D9:$Q9) -> 1.8636364e+08
A10: Coûts des biens d'équipement | B10: USD | D10: 80000000 | E10: 10000000 | F10: 10000000 | G10: 10000000 | H10: 10000000 | I10: 10000000 | J10: 10000000 | K10: 10000000 | L10: 10000000 | M10: 10000000 | N10: 10000000 | O10: 10000000 | P10: 10000000 | R10: =SUM($C10:$Q10) -> 200000000 | S10: =$C10+NPV(10%,$D10:$Q10) -> 1.3466993e+08
A11: Coûts de réhabilitation du site | B11: USD | Q11: 30000000 | R11: =SUM($C11:$Q11) -> 30000000 | S11: =$C11+NPV(10%,$D11:$Q11) -> 27272727
A12: Total des dépenses d'investissement | B12: USD | C12: =SUM(C$9:C$11) -> 50000000 | D12: =SUM(D$9:D$11) -> 230000000 | E12: =SUM(E$9:E$11) -> 10000000 | F12: =SUM(F$9:F$11) -> 10000000 | G12: =SUM(G$9:G$11) -> 10000000 | H12: =SUM(H$9:H$11) -> 10000000 | I12: =SUM(I$9:I$11) -> 10000000 | J12: =SUM(J$9:J$11) -> 10000000 | ... Q12: =SUM(Q$9:Q$11) -> 30000000 | R12: =SUM($C12:$Q12) -> 430000000 | S12: =$C12+NPV(10%,$D12:$Q12) -> 3.289335e+08
A14: III. COÛTS D'EXPLOITATION (OPEX)
A15: Coût moyen d'exploitation | B15: USD/oz | E15: 800 | F15: 800 | G15: 800 | H15: 800 | I15: 800 | J15: 800 | K15: 800 | L15: 800 | M15: 800 | N15: 800 | O15: 800 | P15: 800
A16: Total des coûts d'exploitation | B16: USD | C16: =C$4*C$15 -> 0 | D16: =D$4*D$15 -> 0 | E16: =E$4*E$15 -> 240000000 | F16: =F$4*F$15 -> 240000000 | G16: =G$4*G$15 -> 240000000 | H16: =H$4*H$15 -> 240000000 | I16: =I$4*I$15 -> 240000000 | J16: =J$4*J$15 -> 240000000 | ... Q16: =Q$4*Q$15 -> 0 | R16: =SUM($C16:$Q16) -> 2880000000 | S16: =$C16+NPV(10%,$D16:$Q16) -> 1.4866237e+09
A18: IV. FLUX NETS DE TRESORERIE AVANT IMPÔTS
A19: Flux nets de trésorerie avant impôts | B19: USD | C19: =C$6-C$12-C$16 -> -50000000 | D19: =D$6-D$12-D$16 -> -230000000 | E19: =E$6-E$12-E$16 -> 230000000 | F19: =F$6-F$12-F$16 -> 230000000 | G19: =G$6-G$12-G$16 -> 230000000 | H19: =H$6-H$12-H$16 -> 230000000 | I19: =I$6-I$12-I$16 -> 230000000 | J19: =J$6-J$12-J$16 -> 230000000 | ... Q19: =Q$6-Q$12-Q$16 -> -30000000 | R19: =SUM($C19:$Q19) -> 2450000000 | S19: =$C19+NPV(10%,$D19:$Q19) -> 1.1576902e+09
A20: Taux de rendement interne avant impôts | B20: % | C20: =IF(ISNUMBER(IRR($C19:C19)),IF(IRR($C19:C19)>0,IRR($C19:C19),""),"") | D20: =IF(ISNUMBER(IRR($C19:D19)),IF(IRR($C19:D19)>0,IRR($C19:D19),""),"") | E20: =IF(ISNUMBER(IRR($C19:E19)),IF(IRR($C19:E19)>0,IRR($C19:E19),""),"") | F20: =IF(ISNUMBER(IRR($C19:F19)),IF(IRR($C19:F19)>0,IRR($C19:F19),""),"") -> 0.34744637 | G20: =IF(ISNUMBER(IRR($C19:G19)),IF(IRR($C19:G19)>0,IRR($C19:G19),""),"") -> 0.54585935 | H20: =IF(ISNUMBER(IRR($C19:H19)),IF(IRR($C19:H19)>0,IRR($C19:H19),""),"") -> 0.63444649 | I20: =IF(ISNUMBER(IRR($C19:I19)),IF(IRR($C19:I19)>0,IRR($C19:I19),""),"") -> 0.67761811 | J20: =IF(ISNUMBER(IRR($C19:J19)),IF(IRR($C19:J19)>0,IRR($C19:J19),""),"") -> 0.69990923 | ... Q20: =IF(ISNUMBER(IRR($C19:Q19)),IF(IRR($C19:Q19)>0,IRR($C19:Q19),""),"") -> 0.72605458
A22: V. DROITS FIXES
A23: Droits fixes | B23: USD | C23: 5000000 | R23: =SUM($C23:$Q23) -> 5000000 | S23: =$C23+NPV(10%,$D23:$Q23) -> 5000000
A25: VI. REDEVANCE SUPERFICAIRE
A26: Superficie de la mine | B26: km² | C26: 150 | D26: 150 | E26: 150 | F26: 150 | G26: 150 | H26: 150 | I26: 150 | J26: 150 | K26: 150 | L26: 150 | M26: 150 | N26: 150 | O26: 150 | P26: 150 | Q26: 150
A27: Montant de la redevance superfiaire | B27: USD/km² | C27: 100 | D27: 100 | E27: 100 | F27: 100 | G27: 100 | H27: 500 | I27: 500 | J27: 500 | K27: 500 | L27: 500 | M27: 500 | N27: 500 | O27: 500 | P27: 500 | Q27: 500
A28: Redevance superficiaire | B28: USD | C28: =C$26*C$27 -> 15000 | D28: =D$26*D$27 -> 15000 | E28: =E$26*E$27 -> 15000 | F28: =F$26*F$27 -> 15000 | G28: =G$26*G$27 -> 15000 | H28: =H$26*H$27 -> 75000 | I28: =I$26*I$27 -> 75000 | J28: =J$26*J$27 -> 75000 | ... Q28: =Q$26*Q$27 -> 75000 | R28: =SUM($C28:$Q28) -> 825000 | S28: =$C28+NPV(10%,$D28:$Q28) -> 377309.63 | U28: =S28/$S$71 -> 0.00050563352
A30: VII. REDEVANCE MINIERE
A31: Taux de la redevance minière | B31: % | C31: 0.06 | D31: 0.06 | E31: 0.06 | F31: 0.06 | G31: 0.06 | H31: 0.06 | I31: 0.06 | J31: 0.06 | K31: 0.06 | L31: 0.06 | M31: 0.06 | N31: 0.06 | O31: 0.06 | P31: 0.06 | Q31: 0.06
A32: Redevance minière | B32: USD | C32: =IF(ISNUMBER(C31),C$6*C$31,0) -> 0 | D32: =IF(ISNUMBER(D31),D$6*D$31,0) -> 0 | E32: =IF(ISNUMBER(E31),E$6*E$31,0) -> 28800000 | F32: =IF(ISNUMBER(F31),F$6*F$31,0) -> 28800000 | G32: =IF(ISNUMBER(G31),G$6*G$31,0) -> 28800000 | H32: =IF(ISNUMBER(H31),H$6*H$31,0) -> 28800000 | I32: =IF(ISNUMBER(I31),I$6*I$31,0) -> 28800000 | J32: =IF(ISNUMBER(J31),J$6*J$31,0) -> 28800000 | ... Q32: =IF(ISNUMBER(Q31),Q$6*Q$31,0) -> 0 | R32: =SUM($C32:$Q32) -> 345600000 | S32: =$C32+NPV(10%,$D32:$Q32) -> 1.7839484e+08 | U32: =S32/$S$71 -> 0.23906734
A34: +. LA TAXE SUR LA RENTE
A35: Taux de revalorisation des pertes | B35: % | C35: 0.02 | D35: 0.02 | E35: 0.02 | F35: 0.02 | G35: 0.02 | H35: 0.02 | I35: 0.02 | J35: 0.02 | K35: 0.02 | L35: 0.02 | M35: 0.02 | N35: 0.02 | O35: 0.02 | P35: 0.02 | Q35: 0.02
A36: Flux nets de trésorerie revalorisés | B36: USD | C36: =IF(C19<0,C19*(1+C35),C19) -> -51000000 | D36: =IF(D19<0,D19*(1+D35),D19) -> -234600000 | E36: =IF(E19<0,E19*(1+E35),E19) -> 230000000 | F36: =IF(F19<0,F19*(1+F35),F19) -> 230000000 | G36: =IF(G19<0,G19*(1+G35),G19) -> 230000000 | H36: =IF(H19<0,H19*(1+H35),H19) -> 230000000 | I36: =IF(I19<0,I19*(1+I35),I19) -> 230000000 | J36: =IF(J19<0,J19*(1+J35),J19) -> 230000000 | ... Q36: =IF(Q19<0,Q19*(1+Q35),Q19) -> -30600000 | R36: =SUM($C36:$Q36) -> 2443800000 | S36: =$C36+NPV(10%,$D36:$Q36) -> 1.1523504e+09
A37: Taux de rendement interne | B37: % | C37: =IF(ISNUMBER(IRR($C36:C36)),IF(IRR($C36:C36)>0,IRR($C36:C36),""),"") | D37: =IF(ISNUMBER(IRR($C36:D36)),IF(IRR($C36:D36)>0,IRR($C36:D36),""),"") | E37: =IF(ISNUMBER(IRR($C36:E36)),IF(IRR($C36:E36)>0,IRR($C36:E36),""),"") | F37: =IF(ISNUMBER(IRR($C36:F36)),IF(IRR($C36:F36)>0,IRR($C36:F36),""),"") -> 0.33140025 | G37: =IF(ISNUMBER(IRR($C36:G36)),IF(IRR($C36:G36)>0,IRR($C36:G36),""),"") -> 0.53041424 | H37: =IF(ISNUMBER(IRR($C36:H36)),IF(IRR($C36:H36)>0,IRR($C36:H36),""),"") -> 0.61973587 | I37: =IF(ISNUMBER(IRR($C36:I36)),IF(IRR($C36:I36)>0,IRR($C36:I36),""),"") -> 0.66348955 | J37: =IF(ISNUMBER(IRR($C36:J36)),IF(IRR($C36:J36)>0,IRR($C36:J36),""),"") -> 0.68620185 | ... Q37: =IF(ISNUMBER(IRR($C36:Q36)),IF(IRR($C36:Q36)>0,IRR($C36:Q36),""),"") -> 0.71316911
A38: Seuil de déclenchement de la taxe sur la rente | B38: % | C38: 0.15 | D38: 0.15 | E38: 0.15 | F38: 0.15 | G38: 0.15 | H38: 0.15 | I38: 0.15 | J38: 0.15 | K38: 0.15 | L38: 0.15 | M38: 0.15 | N38: 0.15 | O38: 0.15 | P38: 0.15 | Q38: 0.15
A39: Report des pertes revalorisées | D39: =IF(C40<0,C40,0) -> -51000000 | E39: =IF(D40<0,D40,0) -> -285600000 | F39: =IF(E40<0,E40,0) -> -55600000 | G39: =IF(F40<0,F40,0) -> 0 | H39: =IF(G40<0,G40,0) -> 0 | I39: =IF(H40<0,H40,0) -> 0 | J39: =IF(I40<0,I40,0) -> 0 | K39: =IF(J40<0,J40,0) -> 0 | ... Q39: =IF(P40<0,P40,0) -> 0
A40: Flux nets de trésorerie après report des pertes revalorisées | B40: USD | C40: =C36+C39 -> -51000000 | D40: =D36+D39 -> -285600000 | E40: =E36+E39 -> -55600000 | F40: =F36+F39 -> 174400000 | G40: =G36+G39 -> 230000000 | H40: =H36+H39 -> 230000000 | I40: =I36+I39 -> 230000000 | J40: =J36+J39 -> 230000000 | ... Q40: =Q36+Q39 -> -30600000 | R40: =SUM($C40:$Q40) -> 2051600000 | S40: =$C40+NPV(10%,$D40:$Q40) -> 8.2818056e+08
A41: Taux de la taxe sur la rente | B41: % | C41: 0.2 | D41: 0.2 | E41: 0.2 | F41: 0.2 | G41: 0.2 | H41: 0.2 | I41: 0.2 | J41: 0.2 | K41: 0.2 | L41: 0.2 | M41: 0.2 | N41: 0.2 | O41: 0.2 | P41: 0.2 | Q41: 0.2
A42: Taxe sur la rente | B42: USD | C42: =IF(C37<C38,0,IF(C40<0,0,C40*C41)) -> 0 | D42: =IF(D37<D38,0,IF(D40<0,0,D40*D41)) -> 0 | E42: =IF(E37<E38,0,IF(E40<0,0,E40*E41)) -> 0 | F42: =IF(F37<F38,0,IF(F40<0,0,F40*F41)) -> 34880000 | G42: =IF(G37<G38,0,IF(G40<0,0,G40*G41)) -> 46000000 | H42: =IF(H37<H38,0,IF(H40<0,0,H40*H41)) -> 46000000 | I42: =IF(I37<I38,0,IF(I40<0,0,I40*I41)) -> 46000000 | J42: =IF(J37<J38,0,IF(J40<0,0,J40*J41)) -> 46000000 | ... Q42: =IF(Q37<Q38,0,IF(Q40<0,0,Q40*Q41)) -> 0 | R42: =SUM($C42:$Q42) -> 494880000 | S42: =$C42+NPV(10%,$D42:$Q42) -> 2.3856505e+08 | U42: =S42/$S$71 -> 0.31970159
A44: VIII. IMPÔT SUR LES SOCIETES (IS)
A45: Bénéfice avant report des pertes | B45: USD | C45: =C$6-C$16-C$23-C$28-C$32-C$42+'Amortissements et Emprunt'!C191 -> -12515000 | D45: =D$6-D$16-D$23-D$28-D$32-D$42+'Amortissements et Emprunt'!D191 -> -41765000 | E45: =E$6-E$16-E$23-E$28-E$32-E$42+'Amortissements et Emprunt'!E191 -> 169835000 | F45: =F$6-F$16-F$23-F$28-F$32-F$42+'Amortissements et Emprunt'!F191 -> 135355000 | G45: =G$6-G$16-G$23-G$28-G$32-G$42+'Amortissements et Emprunt'!G191 -> 124635000 | H45: =H$6-H$16-H$23-H$28-H$32-H$42+'Amortissements et Emprunt'!H191 -> 124975000 | I45: =I$6-I$16-I$23-I$28-I$32-I$42+'Amortissements et Emprunt'!I191 -> 1.2526389e+08 | J45: =J$6-J$16-J$23-J$28-J$32-J$42+'Amortissements et Emprunt'!J191 -> 1.2541389e+08 | ... Q45: =Q$6-Q$16-Q$23-Q$28-Q$32-Q$42+'Amortissements et Emprunt'!Q191 -> -49364683 | R45: =SUM($C45:$Q45) -> 1.526695e+09 | S45: =$C45+NPV(10%,$D45:$Q45) -> 7.8021524e+08
A46: Report des pertes | B46: USD | D46: =IF(C47<0,C47,0) -> -12515000 | E46: =IF(D47<0,D47,0) -> -54280000 | F46: =IF(E47<0,E47,0) -> 0 | G46: =IF(F47<0,F47,0) -> 0 | H46: =IF(G47<0,G47,0) -> 0 | I46: =IF(H47<0,H47,0) -> 0 | J46: =IF(I47<0,I47,0) -> 0 | K46: =IF(J47<0,J47,0) -> 0 | ... Q46: =IF(P47<0,P47,0) -> 0
A47: Bénéfice fiscal | B47: USD | C47: =C$45+C$46 -> -12515000 | D47: =D$45+D$46 -> -54280000 | E47: =E$45+E$46 -> 115555000 | F47: =F$45+F$46 -> 135355000 | G47: =G$45+G$46 -> 124635000 | H47: =H$45+H$46 -> 124975000 | I47: =I$45+I$46 -> 1.2526389e+08 | J47: =J$45+J$46 -> 1.2541389e+08 | ... Q47: =Q$45+Q$46 -> -49364683 | R47: =SUM($C47:$Q47) -> 1.4599e+09 | S47: =$C47+NPV(10%,$D47:$Q47) -> 7.2397846e+08
A48: Taux de l'impôt sur les sociétés | B48: % | C48: 0 | D48: 0 | E48: 0 | F48: 0.35 | G48: 0.35 | H48: 0.35 | I48: 0.35 | J48: 0.35 | K48: 0.35 | L48: 0.35 | M48: 0.35 | N48: 0.35 | O48: 0.35 | P48: 0.35 | Q48: 0.35
A49: Impôt sur les sociétés | B49: USD | C49: =IF(C$47>0,C$47*C$48,0) -> 0 | D49: =IF(D$47>0,D$47*D$48,0) -> 0 | E49: =IF(E$47>0,E$47*E$48,0) -> 0 | F49: =IF(F$47>0,F$47*F$48,0) -> 47374250 | G49: =IF(G$47>0,G$47*G$48,0) -> 43622250 | H49: =IF(H$47>0,H$47*H$48,0) -> 43741250 | I49: =IF(I$47>0,I$47*I$48,0) -> 43842361 | J49: =IF(J$47>0,J$47*J$48,0) -> 43894861 | ... Q49: =IF(Q$47>0,Q$47*Q$48,0) -> 0 | R49: =SUM($C49:$Q49) -> 5.1117664e+08 | S49: =$C49+NPV(10%,$D49:$Q49) -> 2.4616836e+08
...

Sheet Amortissements et Emprunt
A1: Nom | B1: Unité | C1: Année 1 | D1: Année 2 | E1: Année 3 | F1: Année 4 | G1: Année 5 | H1: Année 6 | I1: Année 7 | J1: Année 8 | K1: Année 9 | L1: Année 10 | M1: Année 11 | N1: Année 12 | O1: Année 13 | P1: Année 14 | Q1: Année 15
A3: Durée restante maximum | B3: Années | C3: 15 | D3: 14 | E3: 13 | F3: 12 | G3: 11 | H3: 10 | I3: 9 | J3: 8 | K3: 7 | L3: 6 | M3: 5 | N3: 4 | O3: 3 | P3: 2 | Q3: 1
A5: I. AMORTISSEMENTS DES CONSTRUCTIONS INDUSTRIELLES
A6: Durée d'amortissement linéaire | B6: Années | C6: 10
A7: Coefficient d'amortissement dégressif | B7: Coefficient | C7: 1
A9: Immobilisations de l'année A1
A10: Durée restante | B10: Années | C10: =IF($C$6<C$3,$C$6,C$3) -> 10 | D10: =IF(C10=0,0,IF(C10-1<D$3,C10-1,D$3)) -> 9 | E10: =IF(D10=0,0,IF(D10-1<E$3,D10-1,E$3)) -> 8 | F10: =IF(E10=0,0,IF(E10-1<F$3,E10-1,F$3)) -> 7 | G10: =IF(F10=0,0,IF(F10-1<G$3,F10-1,G$3)) -> 6 | H10: =IF(G10=0,0,IF(G10-1<H$3,G10-1,H$3)) -> 5 | I10: =IF(H10=0,0,IF(H10-1<I$3,H10-1,I$3)) -> 4 | J10: =IF(I10=0,0,IF(I10-1<J$3,I10-1,J$3)) -> 3 | K10: =IF(J10=0,0,IF(J10-1<K$3,J10-1,K$3)) -> 2 | ... Q10: =IF(P10=0,0,IF(P10-1<Q$3,P10-1,Q$3)) -> 0
A11: Base amortissable | B11: USD | C11: ='Modèle_législation en vigueur'!C9 -> 50000000 | D11: =C15 -> 45000000 | E11: =D15 -> 40000000 | F11: =E15 -> 35000000 | G11: =F15 -> 30000000 | H11: =G15 -> 25000000 | I11: =H15 -> 20000000 | J11: =I15 -> 15000000 | K11: =J15 -> 10000000 | ... Q11: =P15 -> 0
A12: Inverse de la durée restante | B12: % | C12: =IF(C10=0,0,1/C10) -> 0.1 | D12: =IF(D10=0,0,1/D10) -> 0.11111111 | E12: =IF(E10=0,0,1/E10) -> 0.125 | F12: =IF(F10=0,0,1/F10) -> 0.14285714 | G12: =IF(G10=0,0,1/G10) -> 0.16666667 | H12: =IF(H10=0,0,1/H10) -> 0.2 | I12: =IF(I10=0,0,1/I10) -> 0.25 | J12: =IF(J10=0,0,1/J10) -> 0.33333333 | ... Q12: =IF(Q10=0,0,1/Q10) -> 0
A13: Taux dégressif | B13: % | C13: =IF(C10=0,0,IF($C$7*1/$C$6>C12,$C$7*1/$C$6,C12)) -> 0.1 | D13: =IF(D10=0,0,IF($C$7*1/$C$6>D12,$C$7*1/$C$6,D12)) -> 0.11111111 | E13: =IF(E10=0,0,IF($C$7*1/$C$6>E12,$C$7*1/$C$6,E12)) -> 0.125 | F13: =IF(F10=0,0,IF($C$7*1/$C$6>F12,$C$7*1/$C$6,F12)) -> 0.14285714 | G13: =IF(G10=0,0,IF($C$7*1/$C$6>G12,$C$7*1/$C$6,G12)) -> 0.16666667 | H13: =IF(H10=0,0,IF($C$7*1/$C$6>H12,$C$7*1/$C$6,H12)) -> 0.2 | I13: =IF(I10=0,0,IF($C$7*1/$C$6>I12,$C$7*1/$C$6,I12)) -> 0.25 | J13: =IF(J10=0,0,IF($C$7*1/$C$6>J12,$C$7*1/$C$6,J12)) -> 0.33333333 | ... Q13: =IF(Q10=0,0,IF($C$7*1/$C$6>Q12,$C$7*1/$C$6,Q12)) -> 0
A14: Charge d'amortissement | B14: USD | C14: =C11*C13 -> 5000000 | D14: =D11*D13 -> 5000000 | E14: =E11*E13 -> 5000000 | F14: =F11*F13 -> 5000000 | G14: =G11*G13 -> 5000000 | H14: =H11*H13 -> 5000000 | I14: =I11*I13 -> 5000000 | J14: =J11*J13 -> 5000000 | ... Q14: =Q11*Q13 -> 0
A15: Amortissement restant | B15: USD | C15: =C11-C14 -> 45000000 | D15: =D11-D14 -> 40000000 | E15: =E11-E14 -> 35000000 | F15: =F11-F14 -> 30000000 | G15: =G11-G14 -> 25000000 | H15: =H11-H14 -> 20000000 | I15: =I11-I14 -> 15000000 | J15: =J11-J14 -> 10000000 | ... Q15: =Q11-Q14 -> 0
A17: Immobilisations de l'année A2
A18: Durée restante | B18: Années | D18: =IF($C$6<D$3,$C$6,D$3) -> 10 | E18: =IF(D18=0,0,IF(D18-1<E$3,D18-1,E$3)) -> 9 | F18: =IF(E18=0,0,IF(E18-1<F$3,E18-1,F$3)) -> 8 | G18: =IF(F18=0,0,IF(F18-1<G$3,F18-1,G$3)) -> 7 | H18: =IF(G18=0,0,IF(G18-1<H$3,G18-1,H$3)) -> 6 | I18: =IF(H18=0,0,IF(H18-1<I$3,H18-1,I$3)) -> 5 | J18: =IF(I18=0,0,IF(I18-1<J$3,I18-1,J$3)) -> 4 | K18: =IF(J18=0,0,IF(J18-1<K$3,J18-1,K$3)) -> 3 | L18: =IF(K18=0,0,IF(K18-1<L$3,K18-1,L$3)) -> 2 | ... Q18: =IF(P18=0,0,IF(P18-1<Q$3,P18-1,Q$3)) -> 0
A19: Base amortissable | B19: USD | D19: ='Modèle_législation en vigueur'!D9 -> 150000000 | E19: =D23 -> 135000000 | F19: =E23 -> 120000000 | G19: =F23 -> 105000000 | H19: =G23 -> 90000000 | I19: =H23 -> 75000000 | J19: =I23 -> 60000000 | K19: =J23 -> 45000000 | L19: =K23 -> 30000000 | ... Q19: =P23 -> 0
A20: Inverse de la durée restante | B20: % | D20: =IF(D18=0,0,1/D18) -> 0.1 | E20: =IF(E18=0,0,1/E18) -> 0.11111111 | F20: =IF(F18=0,0,1/F18) -> 0.125 | G20: =IF(G18=0,0,1/G18) -> 0.14285714 | H20: =IF(H18=0,0,1/H18) -> 0.16666667 | I20: =IF(I18=0,0,1/I18) -> 0.2 | J20: =IF(J18=0,0,1/J18) -> 0.25 | K20: =IF(K18=0,0,1/K18) -> 0.33333333 | ... Q20: =IF(Q18=0,0,1/Q18) -> 0
A21: Taux dégressif | B21: % | D21: =IF(D18=0,0,IF($C$7*1/$C$6>D20,$C$7*1/$C$6,D20)) -> 0.1 | E21: =IF(E18=0,0,IF($C$7*1/$C$6>E20,$C$7*1/$C$6,E20)) -> 0.11111111 | F21: =IF(F18=0,0,IF($C$7*1/$C$6>F20,$C$7*1/$C$6,F20)) -> 0.125 | G21: =IF(G18=0,0,IF($C$7*1/$C$6>G20,$C$7*1/$C$6,G20)) -> 0.14285714 | H21: =IF(H18=0,0,IF($C$7*1/$C$6>H20,$C$7*1/$C$6,H20)) -> 0.16666667 | I21: =IF(I18=0,0,IF($C$7*1/$C$6>I20,$C$7*1/$C$6,I20)) -> 0.2 | J21: =IF(J18=0,0,IF($C$7*1/$C$6>J20,$C$7*1/$C$6,J20)) -> 0.25 | K21: =IF(K18=0,0,IF($C$7*1/$C$6>K20,$C$7*1/$C$6,K20)) -> 0.33333333 | ... Q21: =IF(Q18=0,0,IF($C$7*1/$C$6>Q20,$C$7*1/$C$6,Q20)) -> 0
A22: Charge d'amortissement | B22: USD | D22: =D19*D21 -> 15000000 | E22: =E19*E21 -> 15000000 | F22: =F19*F21 -> 15000000 | G22: =G19*G21 -> 15000000 | H22: =H19*H21 -> 15000000 | I22: =I19*I21 -> 15000000 | J22: =J19*J21 -> 15000000 | K22: =K19*K21 -> 15000000 | ... Q22: =Q19*Q21 -> 0
A23: Amortissement restant | B23: USD | D23: =D19-D22 -> 135000000 | E23: =E19-E22 -> 120000000 | F23: =F19-F22 -> 105000000 | G23: =G19-G22 -> 90000000 | H23: =H19-H22 -> 75000000 | I23: =I19-I22 -> 60000000 | J23: =J19-J22 -> 45000000 | K23: =K19-K22 -> 30000000 | ... Q23: =Q19-Q22 -> 0
A25: Amortissements des constructions industrielles | B25: USD | C25: =C$14+C$22 -> 5000000 | D25: =D$14+D$22 -> 20000000 | E25: =E$14+E$22 -> 20000000 | F25: =F$14+F$22 -> 20000000 | G25: =G$14+G$22 -> 20000000 | H25: =H$14+H$22 -> 20000000 | I25: =I$14+I$22 -> 20000000 | J25: =J$14+J$22 -> 20000000 | ... Q25: =Q$14+Q$22 -> 0
A27: II. AMORTISSEMENTS DES BIENS D'EQUIPEMENT
A28: Durée d'amortissement linéaire | B28: Années | C28: 15
A29: Coefficient d'amortissement dégressif | B29: Coefficient | C29: 1.5
A31: Immobilisations de l'année A1
A32: Durée restante | B32: Années | C32: =IF($C$6<C$3,$C$6,C$3) -> 10 | D32: =IF(C32=0,0,IF(C32-1<D$3,C32-1,D$3)) -> 9 | E32: =IF(D32=0,0,IF(D32-1<E$3,D32-1,E$3)) -> 8 | F32: =IF(E32=0,0,IF(E32-1<F$3,E32-1,F$3)) -> 7 | G32: =IF(F32=0,0,IF(F32-1<G$3,F32-1,G$3)) -> 6 | H32: =IF(G32=0,0,IF(G32-1<H$3,G32-1,H$3)) -> 5 | I32: =IF(H32=0,0,IF(H32-1<I$3,H32-1,I$3)) -> 4 | J32: =IF(I32=0,0,IF(I32-1<J$3,I32-1,J$3)) -> 3 | K32: =IF(J32=0,0,IF(J32-1<K$3,J32-1,K$3)) -> 2 | ... Q32: =IF(P32=0,0,IF(P32-1<Q$3,P32-1,Q$3)) -> 0
A33: Base amortissable | B33: USD | C33: ='Modèle_législation en vigueur'!C10 -> 0 | D33: =C37 -> 0 | E33: =D37 -> 0 | F33: =E37 -> 0 | G33: =F37 -> 0 | H33: =G37 -> 0 | I33: =H37 -> 0 | J33: =I37 -> 0 | K33: =J37 -> 0 | ... Q33: =P37 -> 0
A34: Inverse de la durée restante | B34: % | C34: =IF(C32=0,0,1/C32) -> 0.1 | D34: =IF(D32=0,0,1/D32) -> 0.11111111 | E34: =IF(E32=0,0,1/E32) -> 0.125 | F34: =IF(F32=0,0,1/F32) -> 0.14285714 | G34: =IF(G32=0,0,1/G32) -> 0.16666667 | H34: =IF(H32=0,0,1/H32) -> 0.2 | I34: =IF(I32=0,0,1/I32) -> 0.25 | J34: =IF(J32=0,0,1/J32) -> 0.33333333 | ... Q34: =IF(Q32=0,0,1/Q32) -> 0
A35: Taux dégressif | B35: % | C35: =IF(C32=0,0,IF($C$29*1/$C$28>C34,$C$29*1/$C$28,C34)) -> 0.1 | D35: =IF(D32=0,0,IF($C$29*1/$C$28>D34,$C$29*1/$C$28,D34)) -> 0.11111111 | E35: =IF(E32=0,0,IF($C$29*1/$C$28>E34,$C$29*1/$C$28,E34)) -> 0.125 | F35: =IF(F32=0,0,IF($C$29*1/$C$28>F34,$C$29*1/$C$28,F34)) -> 0.14285714 | G35: =IF(G32=0,0,IF($C$29*1/$C$28>G34,$C$29*1/$C$28,G34)) -> 0.16666667 | H35: =IF(H32=0,0,IF($C$29*1/$C$28>H34,$C$29*1/$C$28,H34)) -> 0.2 | I35: =IF(I32=0,0,IF($C$29*1/$C$28>I34,$C$29*1/$C$28,I34)) -> 0.25 | J35: =IF(J32=0,0,IF($C$29*1/$C$28>J34,$C$29*1/$C$28,J34)) -> 0.33333333 | ... Q35: =IF(Q32=0,0,IF($C$29*1/$C$28>Q34,$C$29*1/$C$28,Q34)) -> 0
A36: Charge d'amortissement | B36: USD | C36: =C33*C35 -> 0 | D36: =D33*D35 -> 0 | E36: =E33*E35 -> 0 | F36: =F33*F35 -> 0 | G36: =G33*G35 -> 0 | H36: =H33*H35 -> 0 | I36: =I33*I35 -> 0 | J36: =J33*J35 -> 0 | ... Q36: =Q33*Q35 -> 0
A37: Amortissement restant | B37: USD | C37: =C33-C36 -> 0 | D37: =D33-D36 -> 0 | E37: =E33-E36 -> 0 | F37: =F33-F36 -> 0 | G37: =G33-G36 -> 0 | H37: =H33-H36 -> 0 | I37: =I33-I36 -> 0 | J37: =J33-J36 -> 0 | ... Q37: =Q33-Q36 -> 0
A39: Immobilisations de l'année A2
A40: Durée restante | B40: Années | D40: =IF($C$6<D$3,$C$6,D$3) -> 10 | E40: =IF(D40=0,0,IF(D40-1<E$3,D40-1,E$3)) -> 9 | F40: =IF(E40=0,0,IF(E40-1<F$3,E40-1,F$3)) -> 8 | G40: =IF(F40=0,0,IF(F40-1<G$3,F40-1,G$3)) -> 7 | H40: =IF(G40=0,0,IF(G40-1<H$3,G40-1,H$3)) -> 6 | I40: =IF(H40=0,0,IF(H40-1<I$3,H40-1,I$3)) -> 5 | J40: =IF(I40=0,0,IF(I40-1<J$3,I40-1,J$3)) -> 4 | K40: =IF(J40=0,0,IF(J40-1<K$3,J40-1,K$3)) -> 3 | L40: =IF(K40=0,0,IF(K40-1<L$3,K40-1,L$3)) -> 2 | ... Q40: =IF(P40=0,0,IF(P40-1<Q$3,P40-1,Q$3)) -> 0
A41: Base amortissable | B41: USD | D41: ='Modèle_législation en vigueur'!D10 -> 80000000 | E41: =D45 -> 72000000 | F41: =E45 -> 64000000 | G41: =F45 -> 56000000 | H41: =G45 -> 48000000 | I41: =H45 -> 40000000 | J41: =I45 -> 32000000 | K41: =J45 -> 24000000 | L41: =K45 -> 16000000 | ... Q41: =P45 -> 0
A42: Inverse de la durée restante | B42: % | D42: =IF(D40=0,0,1/D40) -> 0.1 | E42: =IF(E40=0,0,1/E40) -> 0.11111111 | F42: =IF(F40=0,0,1/F40) -> 0.125 | G42: =IF(G40=0,0,1/G40) -> 0.14285714 | H42: =IF(H40=0,0,1/H40) -> 0.16666667 | I42: =IF(I40=0,0,1/I40) -> 0.2 | J42: =IF(J40=0,0,1/J40) -> 0.25 | K42: =IF(K40=0,0,1/K40) -> 0.33333333 | ... Q42: =IF(Q40=0,0,1/Q40) -> 0
A43: Taux dégressif | B43: % | D43: =IF(D40=0,0,IF($C$29*1/$C$28>D42,$C$29*1/$C$28,D42)) -> 0.1 | E43: =IF(E40=0,0,IF($C$29*1/$C$28>E42,$C$29*1/$C$28,E42)) -> 0.11111111 | F43: =IF(F40=0,0,IF($C$29*1/$C$28>F42,$C$29*1/$C$28,F42)) -> 0.125 | G43: =IF(G40=0,0,IF($C$29*1/$C$28>G42,$C$29*1/$C$28,G42)) -> 0.14285714 | H43: =IF(H40=0,0,IF($C$29*1/$C$28>H42,$C$29*1/$C$28,H42)) -> 0.16666667 | I43: =IF(I40=0,0,IF($C$29*1/$C$28>I42,$C$29*1/$C$28,I42)) -> 0.2 | J43: =IF(J40=0,0,IF($C$29*1/$C$28>J42,$C$29*1/$C$28,J42)) -> 0.25 | K43: =IF(K40=0,0,IF($C$29*1/$C$28>K42,$C$29*1/$C$28,K42)) -> 0.33333333 | ... Q43: =IF(Q40=0,0,IF($C$29*1/$C$28>Q42,$C$29*1/$C$28,Q42)) -> 0
A44: Charge d'amortissement | B44: USD | D44: =D41*D43 -> 8000000 | E44: =E41*E43 -> 8000000 | F44: =F41*F43 -> 8000000 | G44: =G41*G43 -> 8000000 | H44: =H41*H43 -> 8000000 | I44: =I41*I43 -> 8000000 | J44: =J41*J43 -> 8000000 | K44: =K41*K43 -> 8000000 | ... Q44: =Q41*Q43 -> 0
A45: Amortissement restant | B45: USD | D45: =D41-D44 -> 72000000 | E45: =E41-E44 -> 64000000 | F45: =F41-F44 -> 56000000 | G45: =G41-G44 -> 48000000 | H45: =H41-H44 -> 40000000 | I45: =I41-I44 -> 32000000 | J45: =J41-J44 -> 24000000 | K45: =K41-K44 -> 16000000 | ... Q45: =Q41-Q44 -> 0
A47: Immobilisations de l'année A3
A48: Durée restante | B48: Années | E48: =IF($C$6<E$3,$C$6,E$3) -> 10 | F48: =IF(E48=0,0,IF(E48-1<F$3,E48-1,F$3)) -> 9 | G48: =IF(F48=0,0,IF(F48-1<G$3,F48-1,G$3)) -> 8 | H48: =IF(G48=0,0,IF(G48-1<H$3,G48-1,H$3)) -> 7 | I48: =IF(H48=0,0,IF(H48-1<I$3,H48-1,I$3)) -> 6 | J48: =IF(I48=0,0,IF(I48-1<J$3,I48-1,J$3)) -> 5 | K48: =IF(J48=0,0,IF(J48-1<K$3,J48-1,K$3)) -> 4 | L48: =IF(K48=0,0,IF(K48-1<L$3,K48-1,L$3)) -> 3 | M48: =IF(L48=0,0,IF(L48-1<M$3,L48-1,M$3)) -> 2 | ... Q48: =IF(P48=0,0,IF(P48-1<Q$3,P48-1,Q$3)) -> 0
A49: Base amortissable | B49: USD | E49: ='Modèle_législation en vigueur'!E10 -> 10000000 | F49: =E53 -> 9000000 | G49: =F53 -> 8000000 | H49: =G53 -> 7000000 | I49: =H53 -> 6000000 | J49: =I53 -> 5000000 | K49: =J53 -> 4000000 | L49: =K53 -> 3000000 | M49: =L53 -> 2000000 | ... Q49: =P53 -> 0
...

Sheet Feuil1
D2: 1300 | E2: 1600
B3: Ligne | C3: Variable | D3: Valeur
B4: 1 | C4: Chiffre d'affaire (CA) | D4: ='Modèle_législation en vigueur'!S6 -> 2.4901436e+09 | E4: ='Modèle_projet de loi'!S6 -> 2.9732473e+09
B5: 2 | C5: Dépenses d'investissement (CAPEX) | D5: ='Modèle_législation en vigueur'!S12 -> 3.289335e+08 | E5: ='Modèle_projet de loi'!S12 -> 3.289335e+08
B6: 3 | C6: Dépenses d'exploitations (OPEX) | D6: ='Modèle_législation en vigueur'!S16 -> 1.4866237e+09 | E6: ='Modèle_projet de loi'!S16 -> 1.4866237e+09
B7: 4 | C7: Rente minière | D7: =D4-D5-D6 -> 6.7458646e+08 | E7: =E4-E5-E6 -> 1.1576902e+09
C8: Taux de rendement interne (TRI) | D8: ='Modèle_législation en vigueur'!Q20 -> 0.55693685 | E8: ='Modèle_projet de loi'!Q20 -> 0.72605458
