Workbook

Sheet Page de garde
A1: Page de garde
B5: REPUBLIQUE | I5: REPUBLIQUE DU SENEGAL
B7: MINISTERE | I7: FINANCES
B9: DIRECTION | I9: IMPOTS
B17: CENTRE DE DEPÔT: IMPOTS & DOMAINES
A23: ETATS FINANCIERS NORMALISES DU SYSTEME
A24: COMPTABLE OUEST AFRICAIN (SYSCOHADA)
B27: EXERCICE CLOS LE : | M27: 45657
A30: DESIGNATION DE L'ENTREPRISE
C35: DENOMINATION SOCIALE : | L35: SOCIETE NOUVELLE DES SALINS DU SINE SALOUM
C36: (ou nom et prénoms de l'exploitant)
C41: SIGLE USUEL : | H41: SNSSS
C46: ADRESSE COMPLETE : | J46: DIORHANE BP 200
C51: N° D'IDENTIFICATION FISCALE : | N51: 000018699
C55: SYSTEME NORMAL
C59: Documents déposés | V59: Réservé à la Direction Générale des Impôts
C62: Fiche d'identification et renseignements divers | S62: X | V62: Date de dépôt
C64: Bilan | S64: X
C66: Compte de résultat | S66: X | V66: Nom de l'agent de DGI ayant réceptionné le dépôt
C68: Tableau financier des ressources et emplois | S68: X
C70: Etat supplémentaire | S70: X | V70: Signature de l'agent et cachet du service
C72: Nombre de pages déposées par exemplaire | R72: 0
C73: Nombre d'exemplaires déposés | R73: 0

Sheet Fiche de renseignement R1
A1: Fiche R1
J3: SOCIETE NOUVELLE DES SALINS DU SINE SALOUM
B4: Désignation de l'entreprise | J4: =+'Page de garde'!L35 -> SOCIETE NOUVELLE DES SALINS DU SINE SALOUM
J6: DIORHANE BP 200 | AD6: SNSSS
C7: Adresse de l'entreprise | J7: ='Page de garde'!J46 -> DIORHANE BP 200 | AA7: Sigle usuel | AD7: =+'Page de garde'!H41 -> SNSSS
J9: 000018699
D10: N° d'identification | J10: =+'Page de garde'!N51 -> 000018699 | R10: Exercice clos le | V10: =+'Page de garde'!M27 -> 45657 | AC10: Durée (en mois) | AH10: 12
B13: ZA | E13: EXERCICE COMPTABLE | W13: DU | Y13: 45292 | AF13: AU | AH13: 45657
B16: ZB | E16: DATE D'ARRETE EFFECTIF DES COMPTES | U16: 45657
B20: ZC | E20: EXERCICE PRECEDENT CLOS LE | Q20: 45291 | Z20: DUREE EXERCICE PRECEDENT EN MOIS : | AL20: 12
B24: ZD | F24: 8520 | I24: SN-KLK-1965-B-10668 | W24: 0
F25: Greffe | I25: N° registre du Commerce | W25: N° répertoire des entreprises
B28: ZE | G28: 1413865720 | AE28: 030001
G29: N° de sécurité sociale | S29: N° Code employeur | AE29: Code activité principale
B32: ZF | D32: SOCIETE NOUVELLE DES SALINS DU SINE SALOUM | AE32: SNSSS
D33: Désignation de l'entreprise | AE33: Sigle
B36: ZG | G36: 33 941 19 04 | AA36: 200 | AE36: KAOLACK
G37: N° de téléphone | Q37: Télécopie | Y37: Code | AA37: Boîte postale | AE37: Ville
B40: ZH | D40: DIORHANE BP 200,KAOLACK
D41: Adresse géographique complète (Immeuble, rue, quartier, ville, pays)
B44: ZI | D44: INDUSTRIES ALIMENTAIRES
D45: Désignation précise de l'activité principale exercée par l'entreprise | AE45: % capacité production utilisée
D48: Rolande AKA EKPONON
D49: Nom, adresse et qualité de personne à contacter en cas de demande d'informations complémentaires
D52: MAMADOU DIEYE EXPETRT FISCAL TEL 77 523 64 00
D53: Nom du professionnel salarié de l'entreprise ou Nom, adresse et téléphone du cabinet comptable ou du professionnel INSCRIT A L'ORDRE NATIONAL DES EXPERTS COMPTABLES ET DES COMPTABLES AGREES ayant établi les états financiers.
D56: GAYE & ASSOCIES SARL VILLA 10564 DAKAR SACRE COEUR 3 VDN
D57: Noms et adresses du ou des commissaires au comptes
E64: Non assujettie | K64: Non (refus) | O64: Oui avec réserves | S64: X | T64: Oui sans réserves | Z64: Non assujettie | AG64: Non | AK64: X | AL64: Oui
C66: Etats financiers certifiés (cocher la case) | X66: Etats financiers approuvés par l'Assemblée Générale (cocher la case)
D69: ALAIN BOSSUYT | T69: Domiciliations bancaires
D70: Nom du signataire des états financiers | T70: Banque | AD70: Numéro de compte
T71: ECOBANK | AD71: SN094 01001 100000230001 54
D72: DIRECTEUR GENERAL | T72: BANQUE ATLANTIQUE | AD72: SN137 01001 080135650005 49
D73: Qualité du signataire des états financiers | T73: B.I.C.I.S | AD73: SN010 01520 000102000082 56
T74: CREDIT DU SENEGAL | AD74: SN 060 01030 165055062000 29
D75: 45712 | T75: B.O.A.S. | AD75: SN100 01003 001017420007 82
D76: Date de signature | T76: S.G.B.S. | AD76: SN011 02030 005000000089 43
T77: CBAO | AD77: SN012 02214 021436025526 11
T78: UBA PLATEAU | AD78: SN153 01303 303090005143 93
...

Sheet Activités de l'entreprise R2
A1: Fiche R2
B4: Désignation de l'entreprise : | C4: =+'Page de garde'!L35 -> SOCIETE NOUVELLE DES SALINS DU SINE SALOUM
B5: Adresse de l'entreprise :
B6: ='Fiche de renseignement R1'!J7 -> DIORHANE BP 200 | L6: Sigle usuel : | M6: =+'Page de garde'!H41 -> SNSSS
B7: N° d'identification : | L7: Exercice clos le :
B8: =+'Fiche de renseignement R1'!$J$10 -> 000018699 | L8: ='Fiche de renseignement R1'!V10 -> 45657 | M8: Durée (en mois) | N8: ='Fiche de renseignement R1'!AH10 -> 12
A10: FICHE D'IDENTIFICATION ET RENSEIGNEMENTS DIVERS 2
L12: Contrôle de l'entreprise (cocher la case)
A14: ZK | B14: Forme juridique (1) | F14: 0 | G14: 1 | K14: ZQ | L14: Entreprise sous contrôle public
A16: ZL | B16: Régime fiscal (1) | F16: 1 | K16: ZR | L16: Entreprise sous contrôle privé national | Q16: X
A18: ZM | B18: Pays du siège social (1) | F18: 0 | G18: 7 | K18: ZS | L18: Entreprise sous contrôle privé étranger
A20: ZN | B20: Nbre d'établissements dans le pays | F20: 1 | G20: 1
A22: ZO | B22: Nbre d'établissements hors du pays | F22: 0 | G22: 0
B23: pour lesquels une comptabilité distincte est tenue
A25: ZP | B25: 1ère année exercice dans le pays | E25: 0 | F25: 0 | G25: 0 | H25: 0
A28: ACTIVITE DE L'ENTREPRISE
B30: DESIGNATION DE L'ACTIVITE (2) | C30: Code nomenclature d'activité (1) | K30: Valeur Ajoutée (VA) HT | M30: % activité dans le CA HT ou la VA
B33: INDUSTRIES ALIMENTAIRES | D33: 0 | E33: 3 | F33: 0 | G33: 0 | H33: 0 | I33: 1 | L33: 15118888788 | M33: =+L33/$L$59 -> 1
M36: =+L36/$L$59 -> 0
M39: =+L39/$L$59 -> 0
M42: =+L42/$L$59 -> 0
M45: =+L45/$L$59 -> 0
M48: =+L48/$L$59 -> 0
M51: =+L51/$L$59 -> 0
M54: =+L54/$L$59 -> 0
B57: Divers
C59: TOTAL | L59: =SUM(L32:L56) -> 15118888788 | M59: =SUM(M32:M57) -> 1
B62: (1) Se réréfer aux tables des codes
B63: (2) Lister de manière précise les activités dans l'ordre décroissant du CAHT, ou de la valeur ajoutée (V.A.)
B64: (3) Rayer la mention inutile (utiliser de préférence la V.A.)

Sheet Dirigeants R3
A1: Fiche R3
A3: Désignation de l'entreprise | B3: ='Fiche de renseignement R1'!$J$4 -> SOCIETE NOUVELLE DES SALINS DU SINE SALOUM
A4: Adresse de l'entreprise | B4: ='Fiche de renseignement R1'!J7 -> DIORHANE BP 200 | D4: Sigle usuel | E4: ='Fiche de renseignement R1'!AD7 -> SNSSS
A5: N° d'identification fiscale | B5: =+'Fiche de renseignement R1'!$J$10 -> 000018699 | C5: Exercice clos le | D5: ='Fiche de renseignement R1'!V10 -> 45657 | E5: Durée (en mois) | F5: ='Fiche de renseignement R1'!AH10 -> 12
A7: FICHE D'IDENTIFICATION ET RENSEIGNEMENTS DIVERS 3
A9: DIRIGEANTS (1)
A11: Nom | B11: Prénoms | C11: Qualité | D11: N° d'identification fiscale | E11: Adressse (BP, ville, pays)
A12: BOSSUYT | B12: ALAIN | C12: DIRECTEUR GÉNÉRAL | E12: DIORHANE BP 200 KAOLACK
A27: (1) Dirigeants = Président Directeur Général, Directeur Général, Adminsitrateur Général, Gérant, Autres.
A29: MEMBRES DU CONSEIL D'ADMINISTRATION
A31: Nom | B31: Prénoms | C31: Qualité | E31: Adressse (BP, ville, pays)
A32: TIDIANE | B32: SYLLA | C32: Président | E32: Dakar
A33: FINACHEF | C33: Administrateur | E33: France
A34: COMPAGNIE COMERCIALE DES SELS MARINS | C34: Administrateur | E34: France
A35: ALPHA | B35: DIENG | C35: Administrateur | E35: Dakar
A36: COMPAGNIE DES SELS DU MIDI ET DES SALINES DE L'EST | C36: Administrateur | E36: France
A37: SALINS DU MIDI PARTICIPATIONS | C37: Administrateur | E37: France

Sheet Tableau des Notes R4
A1: FICHE R4
A2: Désignation entité : | D2: Excercice clos le : | E2: ='Fiche de renseignement R1'!V10 -> 45657
A3: ='Fiche de renseignement R1'!$J$4 -> SOCIETE NOUVELLE DES SALINS DU SINE SALOUM | D3: Durée en mois : | E3: ='Fiche de renseignement R1'!AH10 -> 12
A4: Numéro d'identification : | B4: =+'Fiche de renseignement R1'!$J$10 -> 000018699
A6: FICHE RECAPITULATIVE DES NOTES ANNEXES PRESENTEES
A8: NOTES | B8: INTITULES | C8: A | D8: N/A
A9: NOTE 1 | B9: DETTES GARANTIES PAR DES SURETES REELLES | D9: X
A10: NOTE 2 | B10: INFORMATIONS OBLIGATOIRES | C10: X
A11: NOTE 3A | B11: IMMOBILISATION BRUTE | C11: X
A12: NOTE 3B | B12: BIENS PRIS EN LOCATION ACQUISITION | D12: X
A13: NOTE 3C | B13: IMMOBILISATIONS : AMORTISSEMENTS | C13: X
A14: NOTE 3D | B14: IMMOBILISATIONS : PLUS -VALUES ET MOINS VALUE DE CESSION | C14: X
A15: NOTE 3E | B15: INFORMATION SUR LES REEVALUATIONS EFFECTUEES PAR L'ENTITE | D15: X
A16: NOTE 4 | B16: IMMOBILISATIONS FINANCIERES | C16: X
A17: NOTE 5 | B17: ACTIF CIRCULANT ET DETTES CIRCULANTES HAO | D17: X
A18: NOTE 6 | B18: STOCKS ET ENCOURS | C18: X
A19: NOTE 7 | B19: CLIENTS PRODUITS A RECEVOIR | C19: X
A20: NOTE 8 | B20: AUTRES CREANCES | C20: X
A21: NOTE 8A | B21: TABLEAU D’ETALEMENT DES CHARGES IMMOBILISEES | D21: X
A22: NOTE 9 | B22: TITRES DE PLACEMENT | D22: X
A23: NOTE 10 | B23: VALEURS A ENCAISSER | C23: X
A24: NOTE 11 | B24: DISPONIBILITES | C24: X
A25: NOTE 12 | B25: ECARTS DE CONVERSION ET TRANSFERTS DE CHARGES | D25: X
A26: NOTE 13 | B26: CAPITAL: VALEUR NOMINALE DES ACTIONS OU PARTS | C26: X
A27: NOTE 14 | B27: PRIMES ET RESERVES | C27: X
A28: NOTE 15A | B28: SUBVENTIONS ET PROVISIONS REGLEMENTEES | D28: X
A29: NOTE 15B | B29: AUTRES FONDS PROPRES | D29: X
A30: NOTE 16A | B30: DETTES FINANCIERES ET RESSOURCES ASSIMILEES | C30: X
A31: NOTE 16B | B31: ENGAGEMENTS DE RETRAITE ET AVANTAGES ASSIMILES ( METHODE ACTUARIELLE ) | D31: X
A32: NOTE 16B bis | B32: ENGAGEMENTS DE RETRAITE ET AVANTAGES ASSIMILES ( METHODE ACTUARIELLE ) | D32: X
A33: NOTE 16C | B33: ACTIFS ET PASSIFS EVENTUELS | D33: X
A34: NOTE 17 | B34: FOURNISSEURS D'EXPLOITATION | C34: X
A35: NOTE 18 | B35: DETTES FISCALES ET SOCIALES | C35: X
A36: NOTE 19 | B36: AUTRES DETTES ET PROVISIONS POUR RISQUES A COURT TERME | C36: X
A37: NOTE 20 | B37: BANQUES , CREDITS D'ESCOMPTE ET DE TRESORERIE | D37: X
A38: NOTE 21 | B38: CHIFFRES D'AFFAIRES ET AUTRES PRODUITS | C38: X
A39: NOTE 22 | B39: ACHATS | C39: X
A40: NOTE 23 | B40: TRANSPORTS | C40: X
A41: NOTE 24 | B41: SERVICES EXTERIEURS | C41: X
A42: NOTE 25 | B42: IMPOTS ET TAXES | C42: X
...

Sheet BILAN PAYSAGE
A1: BILAN PAYSAGE
A3: Désignation entité : | E3: =+'Fiche de renseignement R1'!$V$10 -> 45657 | I3: Excercice clos le : | J3: 0
A4: ='Fiche de renseignement R1'!$J$4 -> SOCIETE NOUVELLE DES SALINS DU SINE SALOUM | I4: Durée en mois : | J4: =+'Fiche de renseignement R1'!$AH$10 -> 12
A5: Numéro d'identification : | D5: =+'Fiche de renseignement R1'!$J$10 -> 000018699
A7: REF | B7: ACTIF | C7: Note | E7: Exercice au 31/12/N | G7: Exercice au 31/12/N-1 | H7: REF | I7: PASSIF | J7: Note | K7: Exercice au 31/12/N | L7: Exercice au 31/12/N-1
D8: Brut | E8: Amorts et Dépréc. | F8: Net | G8: Net | K8: Net | L8: Net
A9: AD | B9: IMMOBILISATIONS INCORPORELLES | C9: 3 | D9: 83951848 | E9: 22265627 | F9: 61686221 | G9: 61351638 | H9: CA | I9: CAPITAL | J9: 13 | K9: 554420000 | L9: 554420000
A10: AE | B10: Frais de développement et de prospection | D10: 26937701 | E10: 0 | F10: 26937701 | G10: 26937701 | H10: CB | I10: Apporteurs capital non appelé | J10: 13 | K10: 0 | L10: 0
A11: AF | B11: Brevets, licences, logiciels et droits similaires | D11: 23214147 | E11: 22265627 | F11: 948520 | G11: 613937 | H11: CD | I11: Primes liées au capital social | J11: 14 | K11: 0 | L11: 0
A12: AG | B12: Fonds commercial et droit au bail | D12: 0 | E12: 0 | F12: 0 | G12: 0 | H12: CE | I12: Ecarts de réévaluation | J12: 3e | K12: 0 | L12: 0
A13: AH | B13: Autres immobilisations incorporelles | D13: 33800000 | E13: 0 | F13: 33800000 | G13: 33800000 | H13: CF | I13: Réserves indisponibles | J13: 14 | K13: 112600000 | L13: 112600000
A14: AI | B14: IMMOBILISATIONS CORPORELLES | C14: 3 | D14: 10773653852 | E14: 7890614507 | F14: 2883039345 | G14: 2837221684 | H14: CG | I14: Réserves libres | J14: 14 | K14: 4665384806 | L14: 3899990322
A15: AJ | B15: Terrains (1) (1) dont placement en net ………../………… | D15: 1150375194 | E15: 888883591 | F15: 261491603 | G15: 358944554 | H15: CH | I15: Report à nouveau | J15: 14 | K15: 0 | L15: 0
A16: AK | B16: Bâtiments (1) dont placement en net ………../………… | D16: 1202980009 | E16: 390975978 | F16: 812004031 | G16: 701901602 | H16: CJ | I16: Résutat net de l'exercice (bénéfice + ou perte -) | K16: 3693778426 | L16: 4369124484
A17: AL | B17: Aménagements, agencements et installations | D17: 1411661925 | E17: 699436255 | F17: 712225670 | G17: 759335572 | H17: CL | I17: Subventions d'investissement | J17: 15 | K17: 0 | L17: 0
A18: AM | B18: Matériel, mobilier et actifs biologiques | D18: 6698804860 | E18: 5722626288 | F18: 976178572 | G18: 980520500 | H18: CM | I18: Provisions réglementées et fonds assimilés | J18: 15 | K18: 0 | L18: 0
A19: AN | B19: Matériel de transport | D19: 292836864 | E19: 180697395 | F19: 112139469 | G19: 30219456 | H19: CP | I19: TOTAL CAPITAUX PROPRES ET RESSOURCES ASSIMILEES | K19: 9026183232 | L19: 8936134806
A20: AP | B20: Avances & acomptes versés sur immobilisations | C20: 3 | D20: 16995000 | E20: 7995000 | F20: 9000000 | G20: 6300000 | H20: DA | I20: Emprunts et dettes financières diverses | J20: 16 | K20: 0 | L20: 0
A21: AQ | B21: IMMOBILISATIONS FINANCIERES | C21: 4 | D21: 185805618 | E21: 50237009 | F21: 135568609 | G21: 135568609 | H21: DB | I21: Dettes de location acquisition | J21: 16 | K21: 0 | L21: 0
A22: AR | B22: Titres de participation | D22: 115827689 | E22: 50227689 | F22: 65600000 | G22: 65595340 | H22: DC | I22: Provisions pour risques et charges | J22: 16 | K22: 1678869395 | L22: 1677152885
A23: AS | B23: Autres immobilisations financières | D23: 69977929 | E23: 9320 | F23: 69968609 | G23: 69973269 | H23: DD | I23: TOTAL DETTES FINANCIERES ET RESSOURCES ASSIMILEES | K23: 1678869395 | L23: 1677152885
A24: AZ | B24: TOTAL ACTIF IMMOBILISE | D24: 11043411318 | E24: 7963117143 | F24: 3080294175 | G24: 3034158551 | H24: DF | I24: TOTAL RESSOURCES STABLES | K24: 10705052627 | L24: 10613287691
A25: BA | B25: ACTIF CIRCULANT H.A.O. | C25: 5 | D25: 0 | E25: 0 | F25: 0 | G25: 0 | H25: DH | I25: Dettes circulantes HAO | J25: 5 | K25: 0 | L25: 0
A26: BB | B26: STOCKS ET ENCOURS | C26: 6 | D26: 5661958301 | E26: 193239513 | F26: 5468718788 | G26: 5434145929 | H26: DI | I26: Clients, avances reçues | J26: 7 | K26: 100649106 | L26: 130101598
A27: BG | B27: CREANCES ET EMPLOIS ASSIMILES | D27: 589493628 | E27: 0 | F27: 589493628 | G27: 502573136 | H27: DJ | I27: Fournisseurs d'exploitation | J27: 17 | K27: 658207070 | L27: 895063997
A28: BH | B28: Fournisseurs, avances versées | C28: 17 | D28: 72960138 | E28: 0 | F28: 72960138 | G28: 40979446 | H28: DK | I28: Dettes fiscales et sociales | J28: 18 | K28: 1039280617 | L28: 1105229702
A29: BI | B29: Clients | C29: 7 | D29: 401035558 | E29: 0 | F29: 401035558 | G29: 368525336 | H29: DM | I29: Autres dettes | J29: 19 | K29: 55426179 | L29: 10027048
A30: BJ | B30: Autres créances | C30: 8 | D30: 115497932 | E30: 0 | F30: 115497932 | G30: 93068354 | H30: DN | I30: Provisions pour risques à court terme | J30: 19 | K30: 0 | L30: 0
A31: BK | B31: TOTAL ACTIF CIRCULANT | D31: 6251451929 | E31: 193239513 | F31: 6058212416 | G31: 5936719065 | H31: DP | I31: TOTAL PASSIF CIRCULANT | K31: 1853562972 | L31: 2140422345
A32: BQ | B32: Titres de placement | C32: 9 | D32: 0 | E32: 0 | F32: 0 | G32: 0 | K32: 0 | L32: 0
A33: BR | B33: Valeurs à encaisser | C33: 10 | D33: 647200000 | E33: 0 | F33: 647200000 | G33: 1127750000 | H33: DQ | I33: Banques, crédit d'escompte | J33: 20 | K33: 0 | L33: 0
A34: BS | B34: Banques, chèques postaux, caisse et assimilés | C34: 11 | D34: 2780738330 | E34: 7829322 | F34: 2772909008 | G34: 2655082420 | H34: DR | I34: Banques, établissements financiers et crédits de trésorerie | J34: 20
A35: BT | B35: TOTAL TRESORERIE - ACTIF | D35: 3427938330 | E35: 7829322 | F35: 3420109008 | G35: 3782832420 | H35: DT | I35: TOTAL TRESORERIE - PASSIF | K35: 0 | L35: 0
A36: BU | B36: Ecarts de conversion - Actif | C36: 12 | D36: 0 | E36: 0 | F36: 0 | G36: 0 | H36: DV | I36: Ecarts de conversion - Passif | J36: 12 | K36: 0 | L36: 0
A37: BZ | B37: TOTAL GENERAL | D37: 20722801577 | E37: 8164185978 | F37: 12558615599 | G37: 12753710036 | H37: DZ | I37: TOTAL GENERAL | K37: 12558615599 | L37: 12753710036

Sheet COMPTE DE RESULTAT
A1: COMPTE DE RESULTAT
A3: Désignation entité : | D3: Excercice clos le : | E3: =+'Fiche de renseignement R1'!$V$10 -> 45657
A4: ='Fiche de renseignement R1'!$J$4 -> SOCIETE NOUVELLE DES SALINS DU SINE SALOUM | D4: Durée en mois : | E4: =+'Fiche de renseignement R1'!$AH$10 -> 12
A5: Numéro d'identification : | B5: =+'Fiche de renseignement R1'!$J$10 -> 000018699
A7: REF | B7: LIBELLES | D7: NOTE | E7: 31/12/N | F7: 31/12/N-1
A8: TA | B8: Ventes de marchandises | C8: + | D8: 21 | E8: 0 | F8: 0
A9: RA | B9: Achats de marchandises | C9: - | D9: 22 | E9: 0 | F9: 0
A10: RB | B10: Variation de stocks | C10: -/+ | D10: 6 | E10: 0 | F10: 0
A11: XA | B11: MARGE BRUTE SUR MARCHANDISES (somme TA à RB) | E11: 0 | F11: 0
A12: TB | B12: Ventes de produits fabriqués | C12: + | D12: 21 | E12: 15098202108 | F12: 17748425468
A13: TC | B13: Travaux, services vendus | C13: + | D13: 21 | E13: 0 | F13: 0
A14: TD | B14: Produits accessoires | C14: + | D14: 21 | E14: 20686680 | F14: 12712
A15: XB | B15: CHIFFRE D'AFFAIRES (A + B + C + D) | E15: 15118888788 | F15: 17748438180
A16: TE | B16: Production stockée (ou destockage) | C16: -/+ | D16: 6 | E16: 237085553 | F16: 100359957
A17: TF | B17: Production immobilisée | D17: 21 | E17: 63508535 | F17: 31315159
A18: TG | B18: Subventions d'exploitation | D18: 21 | E18: 0 | F18: 0
A19: TH | B19: Autres produits | C19: + | D19: 21 | E19: 1000949 | F19: 531038
A20: TI | B20: Transferts de charges | C20: + | D20: 12 | E20: 0 | F20: 53520000
A21: RC | B21: Achats de matières premières et fournitures liées | C21: - | D21: 22 | E21: 0 | F21: 0
A22: RD | B22: Variation de stocks de stocks de matières premières et fournitures liées | C22: -/+ | D22: 6 | E22: 0 | F22: 0
A23: RE | B23: Autres achats | C23: - | D23: 22 | E23: -3585894455 | F23: -4237015280
A24: RF | B24: Variation de stocks d'autres approvisionnements | C24: -/+ | D24: 6 | E24: 119698651 | F24: 330742202
A25: RG | B25: Transports | C25: - | D25: 23 | E25: -3453328573 | F25: -4753977481
A26: RH | B26: Services extérieurs | C26: - | D26: 24 | E26: -831356141 | F26: -818209910
A27: RI | B27: Impôts et taxes | C27: - | D27: 25 | E27: -12622427 | F27: -126423698
A28: RJ | B28: Autres charges | C28: - | D28: 26 | E28: -206216425 | F28: -107531581
A29: XC | B29: VALEUR AJOUTEE (XB + RA + RB) + (somme TE à RJ) | E29: 7450764455 | F29: 8221748586
A30: RK | B30: Charges de personnel | C30: - | D30: 27 | E30: -2313753672 | F30: -2215358068
A31: XD | B31: EXCEDENT BRUT D'EXPLOITATION (XC + RK) | E31: 5137010783 | F31: 6006390518
A32: TJ | B32: Reprises d'amortissements | C32: + | D32: 28 | E32: 82283490 | F32: 582203207
A33: RL | B33: Dotations aux amortissements, aux provisions et dépréciations | C33: - | D33: 3C & 28 | E33: -861586282 | F33: -874274421
A34: XE | B34: RESULTAT D'EXPLOITATION (XD + TJ + RL) | E34: 4357707991 | F34: 5714319304
A35: TK | B35: Revenus financiers et assimilés | C35: + | D35: 29 | E35: 23880790 | F35: 12452925
A36: TL | B36: Reprises de provisions et dépréciations financières | C36: + | D36: 28 | E36: 0 | F36: 0
A37: TM | B37: Tranfert de charges financières | C37: + | D37: 12 | E37: 0 | F37: 0
A38: RM | B38: Frais financiers et charges assimilées | C38: - | D38: 29 | E38: 0 | F38: -8096
A39: RN | B39: Dotations aux provisions et aux dépréciations financières | C39: - | D39: 3C & 28 | E39: 0 | F39: 0
A40: XF | B40: RESULTAT FINANCIER (somme TK à RN) | E40: 23880790 | F40: 12444829
A41: XG | B41: RESULTAT DES ACTIVITES ORDINAIRES (XE + XF) | E41: 4381588781 | F41: 5726764133
A42: TN | B42: Produits des cessions d'immobilisations | C42: + | D42: 3D | E42: 2118644 | F42: 0
...

Sheet FLUX DE TRESORERIE
A1: FLUX DE TRESORERIE
A3: Désignation entité : | D3: Excercice clos le : | E3: =+'Fiche de renseignement R1'!$V$10 -> 45657
A4: ='Fiche de renseignement R1'!$J$4 -> SOCIETE NOUVELLE DES SALINS DU SINE SALOUM | D4: Durée en mois : | E4: =+'Fiche de renseignement R1'!$AH$10 -> 12
A5: Numéro d'identification : | B5: =+'Fiche de renseignement R1'!$J$10 -> 000018699
A7: REF | B7: LIBELLES | D7: NOTE | E7: 31/12/N | F7: 31/12/N-1
A8: ZA | B8: Trésorerie nette au 1er janvier (Trésorerie actif N-1 - Trésorerie passif N-1) | C8: A | E8: 3782657420 | F8: 4084398932
B9: Flux de trésorerie provenant des activités opérationnelles
A10: FA | B10: Capacité d'Autofinancement Globale (CAFG) | E10: 4471566873 | F10: 4665810119
A11: FB | B11: - Variation de l'actif circulant HAO (1) | E11: 0 | F11: 0
A12: FC | B12: - Variation des stocks | E12: -34572859 | F12: -409104732
A13: FD | B13: - Variation des créances | E13: -86920492 | F13: 90268291
A14: FE | B14: + Variation du passif circulant (1) | E14: -286859373 | F14: -491347949
B15: Variation du BF lié aux activités opérationnelles (FB + FC + FD + FE) : …………………………………………….. | E15: -408352724 | F15: -810184390
A16: ZB | B16: Flux de trésorerie provenant des activités opérationnelles (somme FA à FE) | C16: B | E16: 4063214149 | F16: 3855625729
B17: Flux de trésorerie provenant des activités d'investissement
A18: FF | B18: - Décaissements liés aux acquisitions d'immobilisations incorporelles | E18: -760532 | F18: -329980
A19: FG | B19: - Décaissements liés aux acquisitions d'immobilisations corporelles | E19: -823390673 | F19: -553307261
A20: FH | B20: - Décaissements liés aux acquisitions d'immobilisations financières | E20: 0 | F20: 0
A21: FI | B21: + Encaissements liés aux cessions d'immobilisations incorporelles et corporelles | E21: 2118644 | F21: 0
A22: FJ | B22: + Encaissements liés aux cessions d'immobilisations financières | E22: 0
A23: ZC | B23: Flux de trésorerie provenant des activités d'investissement (somme FF à FJ) | C23: C | E23: -822032561 | F23: -553637241
B24: Flux de trésorerie provenant du financement par les capitaux propres
A25: FK | B25: + Augmentations de capital par apports nouveaux | E25: 0
A26: FL | B26: + Subventions d'investissements reçues | E26: 0
A27: FM | B27: - Prélèvements sur le capital | E27: 0
A28: FN | B28: - Dividendes versés | E28: -3603730000 | F28: -3603730000
A29: ZD | B29: Flux de trésorerie provenant du financement par les capitaux propres (somme FK à FN) | C29: D | E29: -3603730000 | F29: -3603730000
B30: Flux de trésorerie provenant du financement par les capitaux étrangers | E30: 0
A31: FO | B31: + Emprunts | E31: 0
A32: FP | B32: + Autres dettes financières | E32: 0
A33: FQ | B33: - Remboursements des emprunts et autres dettes financières | E33: 0
A34: ZE | B34: Flux de trésorerie provenant du financement par les capitaux étrangers (somme FO à FQ) | C34: E | E34: 0
A35: ZF | B35: Flux de trésorerie provenant des capitaux étrangers (D + E) | C35: F | E35: -3603730000 | F35: -3603730000
A36: ZG | B36: VARIATION DE LA TRESORERIE NETTE DE LA PERIODE (B + C + F) | C36: G | E36: -362548412 | F36: -301741512
A37: ZH | B37: Trésorerie nette au 31 décembre (G + A) Contrôle : Trésorerie actif N - Trésorerie passif N | C37: H | E37: 3420109008 | F37: 3782657420
B38: Contrôle

Sheet Note 1
A1: NOTE 1 : DETTES GARANTIES PAR DES SURETES REELLES
A3: Désignation entité : | D3: Excercice clos le : | E3: =+'Fiche de renseignement R1'!$V$10 -> 45657
A4: ='Fiche de renseignement R1'!$J$4 -> SOCIETE NOUVELLE DES SALINS DU SINE SALOUM | D4: Durée en mois : | E4: =+'Fiche de renseignement R1'!$AH$10 -> 12
A5: Numéro d'identification : | B5: =+'Fiche de renseignement R1'!$J$10 -> 000018699
A7: LIBELLES | B7: Note | C7: Montant brut | D7: SURETES REELLES
D8: Hypothèques | E8: Nantissements | F8: Gages/Autres
A10: Dettes financières et ressources assimilées :
A11: Emprunts obligataires convertibles | C11: 0 | D11: 0 | E11: 0 | F11: 0
A12: Autres emprunts obligataires | C12: 0 | D12: 0 | E12: 0 | F12: 0
A13: Emprunts et dette des établissements de crédit | C13: 0 | D13: 0 | E13: 0 | F13: 0
A14: Autres dettes financières | C14: 0 | D14: 0 | E14: 0 | F14: 0
A15: SOUS TOTAL (1) | C15: 0 | D15: 0 | E15: 0 | F15: 0
A17: Dettes de location-acquisition :
A18: Dettes de crédit-bail immobilier | C18: 0 | D18: 0 | E18: 0 | F18: 0
A19: Dettes de crédit-bail mobilier | C19: 0 | D19: 0 | E19: 0 | F19: 0
A20: Dettes sur contrats de location-vente | C20: 0 | D20: 0 | E20: 0 | F20: 0
A21: Dettes sur contrats de location-acquisition | C21: 0 | D21: 0 | E21: 0 | F21: 0
A22: SOUS TOTAL (2) | C22: 0 | D22: 0 | E22: 0 | F22: 0
A24: Dettes du passif circulant :
A25: Fournisseurs et comptes rattachés | C25: 0 | D25: 0 | E25: 0 | F25: 0
A26: Clients | C26: 0 | D26: 0 | E26: 0 | F26: 0
A27: Personnel | C27: 0 | D27: 0 | E27: 0 | F27: 0
A28: Sécurité sociale et organismes sociaux | C28: 0 | D28: 0 | E28: 0 | F28: 0
A29: Etat | C29: 0 | D29: 0 | E29: 0 | F29: 0
A30: Organismes internationaux | C30: 0 | D30: 0 | E30: 0 | F30: 0
A31: Associés et groupe | C31: 0 | D31: 0 | E31: 0 | F31: 0
A32: Créditeurs divers | C32: 0 | D32: 0 | E32: 0 | F32: 0
A33: SOUS TOTAL (3) | C33: 0 | D33: 0 | E33: 0 | F33: 0
A34: TOTAL (1) + (2) + (3) | C34: 0 | D34: 0 | E34: 0 | F34: 0
A35: ENGAGEMENTS FINANCIERS | E35: Engagements donnés | F35: Engagements reçus
A36: Engagements consentis à des entités liées | D36: 0 | E36: 0 | F36: 0
A37: Primes de remboursement non échus | D37: 0 | E37: 0 | F37: 0
A38: Avals, cautions, garanties | D38: 0 | E38: 0 | F38: 0
A39: Hypothèques, nantissements, gages, autres | D39: 0 | E39: 0 | F39: 0
A40: Effets escomptés non échus | D40: 0 | E40: 0 | F40: 0
A41: Créances commerciales et professionnelles cédées | D41: 0 | E41: 0 | F41: 0
A42: Abandon de créances conditionnelles | D42: 0 | E42: 0 | F42: 0
A43: TOTAL | E43: =SUM(E36:E42) -> 0 | F43: =SUM(F36:F42) -> 0
A44: Commentaire :
A45: NEANT

Sheet Note 2
A1: NOTE 2 : INFORMATIONS OBLIGATOIRES
A3: Désignation entité : | C3: Excercice clos le : | D3: =+'Fiche de renseignement R1'!$V$10 -> 45657
A4: ='Fiche de renseignement R1'!$J$4 -> SOCIETE NOUVELLE DES SALINS DU SINE SALOUM | C4: Durée en mois : | D4: =+'Fiche de renseignement R1'!$AH$10 -> 12
A5: Numéro d'identification : | B5: =+'Fiche de renseignement R1'!$J$10 -> 000018699
A7: A - DECLARATION DE CONFORMITE AU SYSCOHADA
A8: Les états financiers sont établis en conformité avec le Système comptable OHADA et l'acte uniforme relatif au droit comptable et à l'information financière
A9: B - REGLES ET METHODES COMPTABLES
A10: Les états financiers ont été confectionnés dans le respect desconventions, des postulats et des régles d'évaluation édictés par le SYSOHADA et l'acte uniforme
A11: C - DEROGATION AUX POSTULATS ET CONVENTIONS COMPTABLES
A12: Respect de tous les postulats et conventions comptables sans aucune dérogation
A13: D - INFORMATIONS COMPLEMENTAIRES RELATIVES AU BILAN, AU COMPTE DE RESULTAT ET AU TABLEAU DES FLUX DE TRESORERIE
A14: Pas d'informations complémentaires relatives aux autres états financiers

Sheet Note 3A
A1: NOTE 3A : IMMOBILISATION BRUTE
A3: Désignation entité : | E3: Excercice clos le : | F3: =+'Fiche de renseignement R1'!$V$10 -> 45657
A4: ='Fiche de renseignement R1'!$J$4 -> SOCIETE NOUVELLE DES SALINS DU SINE SALOUM | E4: Durée en mois : | F4: =+'Fiche de renseignement R1'!$AH$10 -> 12
A5: Numéro d'identification : | B5: =+'Fiche de renseignement R1'!$J$10 -> 000018699
A7: SITUATIONS ET MOUVEMENTS | B7: Montant brut à l'ouverture de l'exercice | C7: Acquisitions Apports Créations | D7: Virements de poste à poste | E7: Suite à une réévaluation pratiquée au cours de l'exercice | F7: Cessions Scissions Hors service | G7: Virements de poste à poste | H7: Montant brut à la clôture de l'exercice
A10: IMMOBILISATIONS INCORPORELLES | B10: 87818015 | C10: 760532 | D10: 0 | E10: 0 | F10: 4626699 | G10: 0 | H10: 83951848
A11: Frais de développement et de prospection | B11: 26937701 | C11: 0 | F11: 0 | H11: 26937701
A12: Brevets, licences, logiciels et droits similaires | B12: 27080314 | C12: 760532 | F12: 4626699 | H12: 23214147
A13: Fonds commercial et droit au bail | B13: 0 | C13: 0 | H13: 0
A14: Autres immobilisations incorporelles | B14: 33800000 | C14: 0 | H14: 33800000
A15: IMMOBILISATIONS CORPORELLES | B15: 10304845104 | C15: 823390673 | D15: 120864821 | E15: 0 | F15: 354756925 | G15: 120689821 | H15: 10773653852
A16: Terrains hors immeuble de placement | B16: 1163994254 | C16: 27940078 | F16: 0 | G16: 41559138 | H16: 1150375194
A17: Terrains immeuble de placement | B17: 0 | C17: 0 | F17: 0 | H17: 0
A18: Bâtiments hors immeuble de placement | B18: 1040275840 | C18: 175762729 | F18: 0 | G18: 13058560 | H18: 1202980009
A19: Bâtiments immeuble de placement | B19: 0 | C19: 0 | F19: 0 | H19: 0
A20: Aménagements, agencements et installations | B20: 1359502455 | C20: 115625148 | F20: 0 | G20: 63465678 | H20: 1411661925
A21: Matériel, mobilier et actifs biologiques | B21: 6508955691 | C21: 390956273 | D21: 120864821 | F21: 321971925 | H21: 6698804860
A22: Matériel de transport | B22: 217821864 | C22: 107800000 | F22: 32785000 | H22: 292836864
A23: AVANCES ET ACOMPTES VERSES SUR IMMOBILISATIONS | B23: 14295000 | C23: 5306445 | D23: 0 | E23: 0 | F23: 0 | G23: 2606445 | H23: 16995000
A24: IMMOBILISATIONS FINANCIERES | B24: 185805618 | C24: 0 | D24: 9320 | E24: 0 | F24: 0 | G24: 9320 | H24: 185805618
A25: Titres de participation | B25: 115837009 | C25: 0 | G25: 9320 | H25: 115827689
A26: Autres immobilisations financières | B26: 69968609 | C26: 0 | D26: 9320 | F26: 0 | H26: 69977929
A27: TOTAL GENERAL | B27: 10578468737 | C27: 824151205 | D27: 120874141 | E27: 0 | F27: 359383624 | G27: 120699141 | H27: 11043411318
A28: Commentaire :
A29: Les investissements ont porté :- sur la suite des travaux Kousmar phase 2 : digues, surverses, bois de planchéiage( 91,3 M ); -L'installation d'une Centrale photovoltaïque pour alimentation pompes station I1 ,2 x 22KW ,(87,1M) ; - l'acquistion de Pièces de rechange Liebherr pour roue pelle (25,8 M); -l'acquisition de Pompe VI350 – 1500m3/H – 22KW pour doublement capacité Station I1 (24,4M); 2 jeux de chaînes de traction pour 2 pelles flottantes EIK (25,5M); 1 train de roulement pour pelle Caterpillar 320D1 (27,0M); 4 chaînes nues pour les récolteurs 744LL1 et 744LL2 (21,6M); Pièces de rechanges pour récolteurs 744LL1 et 744LL2 (38,9M); Acquisition d'outillage d’atelier mécanique, Gaussmètre (17,9M); l'installation d'un portail coulissant ( 10,2 M) . En matière de Matériel de transport , nous avons effectué l'aquisition de 3 véhicules Toyota (107, 8 M) .

Sheet Note 3B
A1: NOTE 3B : BIENS PRIS EN LOCATION ACQUISITION
A3: Désignation entité : | G3: Excercice clos le : | H3: =+'Fiche de renseignement R1'!$V$10 -> 45657
A4: ='Fiche de renseignement R1'!$J$4 -> SOCIETE NOUVELLE DES SALINS DU SINE SALOUM | G4: Durée en mois : | H4: =+'Fiche de renseignement R1'!$AH$10 -> 12
A5: Numéro d'identification : | B5: =+'Fiche de renseignement R1'!$J$10 -> 000018699
A7: SITUATIONS ET MOUVEMENTS | B7: NATURE DU CONTRAT (I; M; A) | C7: A | D7: AUGMENTATIONS B | G7: DIMINUTIONS C | I7: D = A +B - C
C8: Montant brut à l'ouverture de l'exercice | D8: Acquisitions Apports Créations | E8: Virements de poste à poste | F8: Suite à une réévaluation pratiquée au cours de l'exercice | G8: Cessions Scissions Hors service | H8: Virements de poste à poste | I8: Montant brut à l'ouverture de l'exercice
B9: [1]
A10: Brevets, licences, logiciels et droits similaires | B10: 0 | C10: 0 | D10: 0 | E10: 0 | F10: 0 | G10: 0 | H10: 0 | I10: 0
A11: Fonds commercial et droit au bail | B11: 0 | C11: 0 | D11: 0 | E11: 0 | F11: 0 | G11: 0 | H11: 0 | I11: 0
A12: Autres immobilisations incorporelles | B12: 0 | C12: 0 | D12: 0 | E12: 0 | F12: 0 | G12: 0 | H12: 0 | I12: 0
A13: SOUS TOTAL : IMMOBILISATIONS INCORPORELLES | B13: 0 | C13: 0 | D13: 0 | E13: 0 | F13: 0 | G13: 0 | H13: 0 | I13: 0
A14: Terrains | B14: 0 | C14: 0 | D14: 0 | E14: 0 | F14: 0 | G14: 0 | H14: 0 | I14: 0
A15: Bâtiments | B15: 0 | C15: 0 | D15: 0 | E15: 0 | F15: 0 | G15: 0 | H15: 0 | I15: 0
A16: Aménagements, agencements et installations | B16: 0 | C16: 0 | D16: 0 | E16: 0 | F16: 0 | G16: 0 | H16: 0 | I16: 0
A17: Matériel, mobilier et actifs biologiques | B17: 0 | C17: 0 | D17: 0 | E17: 0 | F17: 0 | G17: 0 | H17: 0 | I17: 0
A18: Matériel de transport | B18: 0 | C18: 0 | D18: 0 | E18: 0 | F18: 0 | G18: 0 | H18: 0 | I18: 0
A19: SOUS TOTAL : IMMOBILISATIONS CORPORELLES | B19: 0 | C19: 0 | D19: 0 | E19: 0 | F19: 0 | G19: 0 | H19: 0 | I19: 0
A21: TOTAL GENERAL | B21: 0 | C21: 0 | D21: 0 | E21: 0 | F21: 0 | G21: 0 | H21: 0 | I21: 0
A22: [1] I : crédit-bail immobilier; M : crédit-bail mobilier; A : autres contrats (dédoubler le poste si montants significatifs)
A23: Commentaire :
A24: NEANT

Sheet Note 3C
A1: NOTE 3C : IMMOBILISATIONS (AMORTISSEMENTS)
A3: Désignation entité : | D3: Excercice clos le : | E3: =+'Fiche de renseignement R1'!$V$10 -> 45657
A4: ='Fiche de renseignement R1'!$J$4 -> SOCIETE NOUVELLE DES SALINS DU SINE SALOUM | D4: Durée en mois :
A5: Numéro d'identification : | B5: =+'Fiche de renseignement R1'!$J$10 -> 000018699
A7: SITUATIONS ET MOUVEMENTS | B7: A | C7: B | D7: C | E7: D = A +B - C
B8: Amortissements cumulés à l'ouverture de l'exercice | C8: Augmentations : Dotations de l'exercice | D8: Diminutions : Amortissements relatifs aux éléments sortis de l'actif | E8: Cumul des amortissements à la clôture de l'exercice
A10: Frais de développement et de prospection | B10: 0 | C10: 0 | D10: 0 | E10: 0
A11: Brevets, licences, logiciels et droits similaires | B11: 26449757 | C11: 422671 | D11: 4606801 | E11: 22265627
A12: Fonds commercial et droit au bail | B12: 0 | C12: 0 | D12: 0 | E12: 0
A13: Autres immobilisations incorporelles | B13: 0 | C13: 0 | D13: 0 | E13: 0
A14: SOUS TOTAL : IMMOBILISATIONS INCORPORELLES | B14: 26449757 | C14: 422671 | D14: 4606801 | E14: 22265627
A15: Terrains hors immeuble de placement | B15: 805049700 | C15: 83833891 | D15: 0 | E15: 888883591
A16: Terrains immeuble de placement | B16: 0 | C16: 0 | D16: 0 | E16: 0
A17: Bâtiments hors immeuble de placement | B17: 338374238 | C17: 52601740 | D17: 0 | E17: 390975978
A18: Bâtiments immeuble de placement | B18: 0 | C18: 0 | D18: 0 | E18: 0
A19: Aménagements, agencements et installations | B19: 600166883 | C19: 99269372 | D19: 0 | E19: 699436255
A20: Matériel, mobilier et actifs biologiques | B20: 5528435191 | C20: 515578621 | D20: 321387524 | E20: 5722626288
A21: Matériel de transport | B21: 187602408 | C21: 25879987 | D21: 32785000 | E21: 180697395
... A24: TOTAL GENERAL | B24: 7486078177 | C24: 777586282 | D24: 358779325 | E24: 7904885134
A25: Commentaire :
A26: La méthode de l'amortissement linéaire est la seule utilisée.

Sheet Note 3D
A1: NOTE 3D : IMMOBILISATIONS (PLUS-VALUES ET MOINS VALUES DE CESSION)
A3: Désignation entité : | D3: Excercice clos le : | E3: =+'Fiche de renseignement R1'!$V$10 -> 45657
A4: ='Fiche de renseignement R1'!$J$4 -> SOCIETE NOUVELLE DES SALINS DU SINE SALOUM | D4: Durée en mois : | E4: =+'Fiche de renseignement R1'!$AH$10 -> 12
A5: Numéro d'identification : | B5: =+'Fiche de renseignement R1'!$J$10 -> 000018699
B7: MONTANT BRUT | C7: AMORTISSEMENTS | D7: VALEUR COMPTABLE NETTE | E7: PRIX DE CESSION | F7: PLUS VALUE OU MOINS VALUE
C8: PRATIQUES
B9: A | C9: B | D9: C = A - B | E9: D | F9: E = D - C
A10: Frais de développement et de prospection | B10: 0 | C10: 0 | D10: 0 | E10: 0 | F10: 0
A11: Brevets, licences, logiciels et droits similaires | B11: 4626699 | C11: 4606801 | D11: 19898 | F11: -19898
A12: Fonds commercial et droit au bail | B12: 0 | C12: 0 | D12: 0 | E12: 0 | F12: 0
A13: Autres immobilisations incorporelles | B13: 0 | C13: 0 | D13: 0 | E13: 0 | F13: 0
A14: SOUS TOTAL : IMMOBILISATIONS INCORPORELLES | B14: 4626699 | C14: 4606801 | D14: 19898 | E14: 0 | F14: -19898
A15: Terrains | B15: 0 | C15: 0 | D15: 0 | E15: 0 | F15: 0
A16: Bâtiments | B16: 0 | C16: 0 | D16: 0 | E16: 0 | F16: 0
A17: Aménagements, agencements et installations | B17: 0 | C17: 0 | D17: 0 | E17: 0 | F17: 0
A18: Matériel, mobilier et actifs biologiques | B18: 321971925 | C18: 321387524 | D18: 584401 | E18: 0 | F18: -584401
A19: Matériel de transport | B19: 32785000 | C19: 32785000 | D19: 0 | E19: 0 | F19: 0
A20: SOUS TOTAL : IMMOBILISATIONS CORPORELLES | B20: 354756925 | C20: 354172524 | D20: 584401 | E20: 0 | F20: -584401
A21: Titres de participation | B21: 0 | C21: 0 | D21: 0 | E21: 0 | F21: 0
A22: Autres immobilisations financières | B22: 0 | C22: 0 | D22: 0 | E22: 0 | F22: 0
A23: SOUS TOTAL : IMMOBILISATIONS FINANCIERES | B23: 0 | C23: 0 | D23: 0 | E23: 0 | F23: 0
A25: TOTAL GENERAL | B25: 359383624 | C25: 358779325 | D25: 604299 | E25: 0 | F25: -604299
A26: Commentaire :
A27: Toutes les sorties correspondent à des mises au rebut. Le résultat sur cession correpond à une valeur nette comptable.

Sheet Note 3E
A1: NOTE 3E : INFORMATIONS SUR LES REEVALUATIONS EFFECTUEES PAR L'ENTITE
A3: Désignation entité : | C3: Excercice clos le : | D3: =+'Fiche de renseignement R1'!$V$10 -> 45657
A4: ='Fiche de renseignement R1'!$J$4 -> SOCIETE NOUVELLE DES SALINS DU SINE SALOUM | C4: Durée en mois : | D4: =+'Fiche de renseignement R1'!$AH$10 -> 12
A5: Numéro d'identification : | B5: =+'Fiche de renseignement R1'!$J$10 -> 000018699
A7: Nature et date des réévaluations :
A13: Eléments réévalués par postes du bilan | B13: Montants coûts historiques | C13: Amortissements supplémentaires
A22: Méthode de réévaluation utilisée :
A24: Traitement fiscal de l'écart de réévaluation
A25: et des amortissements supplémentaires :
A27: Montant de l'écart incorporé au capital :

Sheet Note 4
A1: NOTE 4 : IMMOBILISATIONS FINANCIERES
A3: Désignation entité : | E3: Excercice clos le : | F3: =+'Fiche de renseignement R1'!$V$10 -> 45657
A4: ='Fiche de renseignement R1'!$J$4 -> SOCIETE NOUVELLE DES SALINS DU SINE SALOUM | E4: Durée en mois : | F4: =+'Fiche de renseignement R1'!$AH$10 -> 12
A5: Numéro d'identification : | B5: =+'Fiche de renseignement R1'!$J$10 -> 000018699
A7: SITUATIONS ET MOUVEMENTS | B7: ANNEE N | C7: ANNEE N-1 | D7: Variation en % | E7: Créances à un an au plus | F7: Créances à plus d'un an et à deux ans au plus | G7: Créances à plus de deux ans
A9: Titres de participation | B9: 115827689 | C9: 115827689 | D9: 0 | G9: 115827689
A10: Prêts et créances
A11: Prêt au personnel
A12: Créances sur l'Etat
A13: Titres immobilisés
A14: Dépôts et cautionnements | B14: 69977929 | C14: 69973269 | D14: 6.659686e-05 | G14: 69973269
A15: Intérêts courus | B15: 0 | C15: 0 | E15: 0 | F15: 0 | G15: 0
A16: TOTAL BRUT | B16: 185805618 | C16: 185800958 | D16: 2.5080603e-05 | G16: 185805618
A17: Dépréciations titres de participation | B17: 50227689 | C17: 50227689 | D17: 0 | G17: 50227689
A18: Dépréciations autres immobilisations | B18: 9320 | C18: 9320 | D18: 0 | G18: 9320
A19: TOTAL NET DE DEPRECIATION | B19: 135568609 | C19: 135563949 | D19: 3.4374921e-05 | G19: 135568609
A21: Liste des filiales et participations :
A23: Dénomination sociale | B23: Localisation (ville/pays) | C23: Valeur d'acquisition | E23: % détenu | F23: Montant des capitaux propres filiale | G23: Résultat dernier exercice filiale
A25: Salins du Sénégal SA (1) | B25: Kaolack, Sénégal | C25: 65600000 | E25: 0.2 | F25: 328000000 | G25: néant
A26: Chérifienne des sels (2) | B26: Maroc | C26: 0 | E26: 0.35 | F26: 0 | G26: 0
C27: 0 | E27: 0 | F27: 0 | G27: 0
C28: 0 | E28: 0 | F28: 0 | G28: 0
C29: 0 | E29: 0 | F29: 0 | G29: 0
C30: 0 | E30: 0 | F30: 0 | G30: 0
C31: 0 | E31: 0 | F31: 0 | G31: 0
A32: Commentaire :
A33: (2) Absence d'informations sur cette société dont les actions sont totalement provisionnées.

Sheet Note 5
A1: NOTE 5 : ACTIF CIRCULANT HAO
A3: Désignation entité : | E3: Excercice clos le : | F3: =+'Fiche de renseignement R1'!$V$10 -> 45657
A4: ='Fiche de renseignement R1'!$J$4 -> SOCIETE NOUVELLE DES SALINS DU SINE SALOUM | E4: Durée en mois : | F4: =+'Fiche de renseignement R1'!$AH$10 -> 12
A5: Numéro d'identification : | B5: =+'Fiche de renseignement R1'!$J$10 -> 000018699
A8: LIBELLES | B8: ANNEE N | C8: ANNEE N-1 | D8: Variation en %
A10: Créances sur cessions d'immobilisations | B10: 0 | C10: 0
A11: Autres créances hors activités ordinaires | B11: 0 | C11: 0
A12: TOTAL BRUT | B12: 0 | C12: 0
A13: Dépréciations des créances HAO | B13: 0 | C13: 0
A14: TOTAL NET DE DEPRECIATION | B14: 0 | C14: 0
A15: Commentaire :
A20: DETTES CIRCULANTES HAO
A22: LIBELLES | B22: ANNEE N | D22: ANNEE N-1 | F22: VARIATION EN %
A24: Fournisseurs d'investissements | B24: 0 | D24: 0
A25: Fournisseurs d'investissements effets à payer | B25: 0 | D25: 0
A26: Versements restant à effectuer sur titres de participation et titres immobilisés non libérés | B26: 0 | D26: 0
A27: Autres dettes hors activités ordinaires | B27: 0 | D27: 0
A28: TOTAL | B28: 0 | D28: 0
A29: Commentaire :

Sheet Note 6
A1: NOTE 6 : STOCKS ET ENCOURS(1)
A3: Désignation entité : | C3: Excercice clos le : | D3: =+'Fiche de renseignement R1'!$V$10 -> 45657
A4: ='Fiche de renseignement R1'!$J$4 -> SOCIETE NOUVELLE DES SALINS DU SINE SALOUM | C4: Durée en mois : | D4: =+'Fiche de renseignement R1'!$AH$10 -> 12
A5: Numéro d'identification : | B5: =+'Fiche de renseignement R1'!$J$10 -> 000018699
A7: LIBELLES | B7: ANNEE N | C7: ANNEE N-1 | D7: VARIATION EN %
A9: Marchandises | B9: 0 | C9: 0
A10: Matières premmières et fournitures liées | B10: 0 | C10: 0
A11: Autres approvisionnements | B11: 3238992246 | C11: 3201175281 | D11: 0.011813463
A12: Produits en cours | B12: 683129800 | C12: 689421375 | D12: -0.0091258775
A13: Services en cours | B13: 0 | C13: 0
A14: Produits finis | B14: 1633464012 | C14: 1390086884 | D14: 0.17508052
A15: Produits intermédiaires | B15: 0 | C15: 0
A16: Stocks en cours de cours, en consignation ou en dépôt | B16: 0 | C16: 253311589 | D16: -1
A17: TOTAL BRUT STOCKS ET EN COURS | B17: 5555586058 | C17: 5533995129 | D17: 0.0039015085
A18: Dépréciations des stocks | B18: 193239513 | C18: 99849200 | D18: 0.93531358
A20: Total net de dépréciation | B20: 5362346545 | C20: 5434145929 | D20: -0.013212635
A21: (1) : Les stocks HAO seront inscrits dans l'actif circulant HAO que lorsque leur montant total est significatif
A22: (supérieur à 5% du total de l'actif circulant)
A23: Commentaire :
A24: Pas d'évolution signification sur les stocks

Sheet Note 7
A1: NOTE 7 : CLIENTS
A3: Désignation entité : | E3: Excercice clos le : | F3: =+'Fiche de renseignement R1'!$V$10 -> 45657
A4: ='Fiche de renseignement R1'!$J$4 -> SOCIETE NOUVELLE DES SALINS DU SINE SALOUM | E4: Durée en mois : | F4: =+'Fiche de renseignement R1'!$AH$10 -> 12
A5: Numéro d'identification : | B5: =+'Fiche de renseignement R1'!$J$10 -> 000018699
A7: LIBELLES | B7: ANNEE N | C7: ANNEE N-1 | D7: Variation en % | E7: Créances à un an au plus | F7: Créances à plus d'un an et à deux ans au plus | G7: Créances à plus de deux ans
A9: Clients (hors réserves de propriété Groupe) | B9: 401035558 | C9: 368525336 | D9: 0.088217061 | E9: 401035558 | F9: 0 | G9: 0
A10: Clients effets à recevoir (hors réserves de propriété Groupe) | B10: 0 | C10: 0 | E10: 0 | F10: 0 | G10: 0
A11: Clients effets à recevoir avec réserves de propriété | B11: 0 | C11: 0 | E11: 0 | F11: 0 | G11: 0
A12: Clients effets à recevoir Groupe | B12: 0 | C12: 0 | E12: 0 | F12: 0 | G12: 0
A13: Créances sur cession d'immobilisations | B13: 0 | C13: 0 | E13: 0 | F13: 0 | G13: 0
A14: Clients effets escomptés et non échus | B14: 0 | C14: 0 | E14: 0 | F14: 0 | G14: 0
A15: Créances litigieuses ou douteuses | B15: 0 | C15: 0 | E15: 0 | F15: 0 | G15: 0
A16: Clients produits à recevoir | B16: 0 | C16: 0 | E16: 0 | F16: 0 | G16: 0
A17: TOTAL BRUT CLIENTS | B17: 401035558 | C17: 368525336 | D17: 0.088217061 | E17: 401035558 | F17: 0 | G17: 0
A18: Dépréciations des comptes clients | B18: 0 | C18: 0 | E18: 0 | F18: 0 | G18: 0
A19: TOTAL NET DE DEPRECIATION | B19: 401035558 | C19: 368525336 | D19: 0.088217061 | E19: 401035558 | F19: 0 | G19: 0
A20: Clients, avances reçues hors groupe | B20: 100649106 | C20: 130101598 | D20: -0.22638071 | E20: 100649106 | F20: 0 | G20: 0
A21: Clients, avances reçues groupe | B21: 0 | C21: 0 | E21: 0 | F21: 0 | G21: 0
A22: Autres clients créditeurs | B22: 0 | C22: 0 | E22: 0 | F22: 0 | G22: 0
A23: TOTAL CLIENTS CREDITEURS | B23: 100649106 | C23: 130101598 | D23: -0.22638071 | E23: 100649106 | F23: 0 | G23: 0
A24: Commentaire :
A25: cette hausse de créances clients de 9% s'explique principalement par des retards de paiement de moins de 60 jours, qui ont été soldé à 60% sur le 1ier trimestre 2025

Sheet Note 8
A1: NOTE 8 : AUTRES CREANCES
A3: Désignation entité : | E3: Excercice clos le : | F3: =+'Fiche de renseignement R1'!$V$10 -> 45657
A4: ='Fiche de renseignement R1'!$J$4 -> SOCIETE NOUVELLE DES SALINS DU SINE SALOUM | E4: Durée en mois : | F4: =+'Fiche de renseignement R1'!$AH$10 -> 12
A5: Numéro d'identification : | B5: =+'Fiche de renseignement R1'!$J$10 -> 000018699
A7: LIBELLES | B7: ANNEE N | C7: ANNEE N-1 | D7: Variation en % | E7: Créances à un an au plus | F7: Créances à plus d'un an et à deux ans au plus | G7: Créances à plus de deux ans
A9: Personnel | B9: 31363230 | C9: 39425083 | D9: -0.20448538 | E9: 31363230 | F9: 0 | G9: 0
A10: Organismes sociaux | B10: 10820270 | C10: 5064464 | D10: 1.1365084 | E10: 10820270 | F10: 0 | G10: 0
A11: État et Collectivités publiques | B11: 8696565 | C11: 8696565 | D11: 0 | E11: 0 | F11: 0 | G11: 8696565
A12: Organismes internationaux | B12: 0 | C12: 0 | E12: 0 | F12: 0 | G12: 0
A13: Apporteurs, associés et groupe | F13: 0 | G13: 0
A14: Compte transitoire ajustement spécial lié à la révision du SYSCOHADA | B14: 0 | C14: 0 | E14: 0 | F14: 0 | G14: 0
A15: Autres débiteurs divers | B15: 64617867 | C15: 39882242 | D15: 0.62021651 | E15: 64617867 | F15: 0 | G15: 0
A16: Comptes permanents non bloqués des établissements et des succursales | B16: 0 | C16: 0 | E16: 0 | F16: 0 | G16: 0
A17: Comptes de liaison charges et produits | B17: 0 | C17: 0 | E17: 0 | F17: 0 | G17: 0
A18: Comptes de liaison des sociétés en participation | B18: 0 | C18: 0 | E18: 0 | F18: 0 | G18: 0
A19: TOTAL BRUT AUTRES CREANCES | B19: 115497932 | C19: 93068354 | D19: 0.24100112 | E19: 106801367 | F19: 0 | G19: 8696565
A20: Dépréciations des autres créances | B20: 0 | C20: 0
A21: TOTAL NET DE DEPRECIATION | B21: 115497932 | C21: 93068354 | D21: 0.24100112 | E21: 106801367 | F21: 0 | G21: 8696565
A22: Commentaire :
A23: Le poste autre débiteur enrégistre une importante augmentation due essentiellement aux charges constatées d'avance.

Sheet Note 8A
A1: NOTE 8A : TABLEAU D'ETALEMENT DES CHARGES IMMOBILISEES
A3: Désignation entité : | E3: Excercice clos le : | F3: =+'Fiche de renseignement R1'!$V$10 -> 45657
A4: ='Fiche de renseignement R1'!$J$4 -> SOCIETE NOUVELLE DES SALINS DU SINE SALOUM | E4: Durée en mois : | F4: =+'Fiche de renseignement R1'!$AH$10 -> 12
A5: Numéro d'identification : | B5: =+'Fiche de renseignement R1'!$J$10 -> 000018699
A7: LIBELLES | B7: Frais d'établissement | D7: Charges à répartir sur plusiers exercices | F7: Primes de remboursement des obligations
A9: Montant global à étaler au 1er janvier 2018
A10: Durée d'étalement
A12: Exercice 2018
A17: Total exercice 2018
A18: Total exercice 2019
A19: Total exercice 2020
A20: Total exercice 2021
A21: Total exercice 2022
A22: TOTAL GENERAL
A26: NEANT

Sheet Note 9
A1: NOTE 9 : TITRES DE PLACEMENT
A3: Désignation entité : | C3: Excercice clos le : | D3: =+'Fiche de renseignement R1'!$V$10 -> 45657
A4: ='Fiche de renseignement R1'!$J$4 -> SOCIETE NOUVELLE DES SALINS DU SINE SALOUM | C4: Durée en mois : | D4: =+'Fiche de renseignement R1'!$AH$10 -> 12
A5: Numéro d'identification : | B5: =+'Fiche de renseignement R1'!$J$10 -> 000018699
A7: LIBELLES | B7: ANNEE N | C7: ANNEE N-1 | D7: VARIATION EN %
A9: Titres de trésor et bons de caisse à court terme | B9: 0 | C9: 0
A10: Actions | B10: 0 | C10: 0
A11: Obligations | B11: 0 | C11: 0
A12: Bons de souscription | B12: 0 | C12: 0
A13: Titres négociables hors régions | B13: 0 | C13: 0
A14: Intérêts courus | B14: 0 | C14: 0
A15: Autres valeurs assimilées | B15: 0 | C15: 0
A16: TOTAL BRUT STOCKS ET EN COURS | B16: 0 | C16: 0
A17: Dépréciations des titres | B17: 0 | C17: 0
A19: TOTAL | B19: 0 | C19: 0
A20: Commentaire :

Sheet Note 10
A1: NOTE 10 : VALEURS A ENCAISSER
A3: Désignation entité : | C3: Excercice clos le : | D3: =+'Fiche de renseignement R1'!$V$10 -> 45657
A4: ='Fiche de renseignement R1'!$J$4 -> SOCIETE NOUVELLE DES SALINS DU SINE SALOUM | C4: Durée en mois : | D4: =+'Fiche de renseignement R1'!$AH$10 -> 12
A5: Numéro d'identification : | B5: =+'Fiche de renseignement R1'!$J$10 -> 000018699
A7: LIBELLES | B7: ANNEE N | C7: ANNEE N-1 | D7: VARIATION EN %
A9: Effets à encaisser | B9: 647200000 | C9: 1127750000 | D9: -0.42611394
A10: Effets à l'encaissement | B10: 0 | C10: 0
A11: Chèques à encaisser | B11: 0 | C11: 0
A12: Chèques à l'encaissement | B12: 0 | C12: 0
A13: Cartes de crédit à encaisser | B13: 0 | C13: 0
A14: Autres valeurs à encaisser | B14: 0 | C14: 0
A15: TOTAL BRUT VALEURS A ENCAISSER | B15: 647200000 | C15: 1127750000 | D15: -0.42611394
A16: Dépréciations des valeurs à encaisser | B16: 0 | C16: 0
A18: TOTAL NET DE DEPRECIATIONS | B18: 647200000 | C18: 1127750000 | D18: -0.42611394
A19: Commentaire :
A20: Diminution des effets à encaisser due à la baisse de volume de vente (Notons que sur Décembre il n'y a pas eu de vente vers la Côte d'Ivoire, le Bénin.

Sheet Note 11
A1: NOTE 11 : DISPONIBILITES
A3: Désignation entité : | C3: Excercice clos le : | D3: =+'Fiche de renseignement R1'!$V$10 -> 45657
A4: ='Fiche de renseignement R1'!$J$4 -> SOCIETE NOUVELLE DES SALINS DU SINE SALOUM | C4: Durée en mois : | D4: =+'Fiche de renseignement R1'!$AH$10 -> 12
A5: Numéro d'identification : | B5: =+'Fiche de renseignement R1'!$J$10 -> 000018699
A7: LIBELLES | B7: ANNEE N | C7: ANNEE N-1 | D7: VARIATION EN %
A9: Banques locales | B9: 2767672277 | C9: 2652354879 | D9: 0.043477364
A10: Banques autres états région
A11: Banques, dépôt à terme | B11: 0 | C11: 0
A12: Autres banques | B12: 7829322 | C12: 7829322 | D12: 0 %
A13: Banques, intérêts courus
A14: Chèques postaux | B14: 1613420 | C14: 1613420 | D14: 0
A15: Autres établissements financiers
A16: Etablissements financiers intérêts courus
A17: Intruments de trésorerie
A18: Caisse | B18: 3623311 | C18: 1114121 | D18: 2.2521701
A19: Caisse électronique mobile
A20: Régies d'avances et virements accréditifs | B20: 0 | C20: 0
A21: TOTAL BRUT DISPONIBILITES | B21: 2780738330 | C21: 2662911742 | D21: 0.044247275
A22: Dépréciations | B22: 7829322 | C22: 7829322
A24: TOTAL NET DE DEPRECIATIONS | B24: 2772909008 | C24: 2655082420 | D24: 0.044247275
A25: Commentaire :
A32: NB : Banques et intérêts courus et Etablissement financiers intérêts courus figurent dans cette rubrique
A33: en négatif si le compte principal est débiteur

Sheet Note 12
A1: NOTE 12 : ECARTS DE CONVERSION
A3: Désignation entité : | E3: Excercice clos le : | F3: =+'Fiche de renseignement R1'!$V$10 -> 45657
A4: ='Fiche de renseignement R1'!$J$4 -> SOCIETE NOUVELLE DES SALINS DU SINE SALOUM | E4: Durée en mois : | F4: =+'Fiche de renseignement R1'!$AH$10 -> 12
A5: Numéro d'identification : | B5: =+'Fiche de renseignement R1'!$J$10 -> 000018699
A7: LIBELLES | B7: Devises | C7: Montant en devises | E7: Cours UML année acquisition | F7: Cours UML 31/12 | G7: Variation en valeur absolue
A9: Ecarts de conversion actif : Détailler les créances et dettes concernées | B9: 0 | C9: 0 | E9: 0 | F9: 0 | G9: 0
B10: 0 | C10: 0 | E10: 0 | F10: 0 | G10: 0
B11: 0 | C11: 0 | E11: 0 | F11: 0 | G11: 0
A12: Ecarts de conversion passif : Détailler les créances et dettes concernées | B12: 0 | C12: 0 | E12: 0 | F12: 0 | G12: 0
B13: 0 | C13: 0 | E13: 0 | F13: 0 | G13: 0
B14: 0 | C14: 0 | E14: 0 | F14: 0 | G14: 0
B15: 0 | C15: 0 | E15: 0 | F15: 0 | G15: 0
B16: 0 | C16: 0 | E16: 0 | F16: 0 | G16: 0
A17: Commentaire :
A22: TRANSFERTS DE CHARGES
A24: LIBELLES | B24: ANNEE N | D24: ANNEE N-1 | F24: VARIATION EN %
A26: Transferts de charges d'exploitation : Détailler la nature des charges transférées | B26: 0 | D26: 0
B27: 0 | D27: 0
B28: 0 | D28: 0
A29: Transferts de charges financières : Détailler la nature des charges transférées | B29: 0 | D29: 0
B30: 0 | D30: 0
B31: 0 | D31: 0
B32: 0 | D32: 0
B33: 0 | D33: 0
A34: Commentaire :
A35: NEANT

Sheet Note 13
A1: NOTE 13 : CAPITAL
A3: Désignation entité : | E3: Excercice clos le : | F3: =+'Fiche de renseignement R1'!$V$10 -> 45657
A4: ='Fiche de renseignement R1'!$J$4 -> SOCIETE NOUVELLE DES SALINS DU SINE SALOUM | E4: Durée en mois : | F4: =+'Fiche de renseignement R1'!$AH$10 -> 12
A5: Numéro d'identification : | B5: =+'Fiche de renseignement R1'!$J$10 -> 000018699
E7: Valeur nominale des actions ou parts : | G7: 10000
A8: NOMS ET PRENOMS | B8: Nationalité | C8: Nature des actions ou parts (ordinaires ou préférences) | E8: Nombre | F8: Montant total | G8: Cessions ou remboursements en cours d'exercice
A10: SALINS DU MIDI PARTICIPATION | B10: FRANCAISE | C10: ORDINAIRES | E10: 40060 | F10: 400600000 | G10: 0
A11: Héritiers feu Idrissa Gueye | B11: Sénégalaise | C11: ORDINAIRES | E11: 10718 | F11: 107180000 | G11: 0
A12: M. Moustapha Seck | B12: Sénégalaise | C12: ORDINAIRES | E12: 1710 | F12: 17100000 | G12: 0
A13: Mme Yaye Bani DIALLO-Veuve DIOP | B13: Sénégalaise | C13: ORDINAIRES | E13: 1446 | F13: 14460000 | G13: 0
A14: Héritiers Feu Abdoulaye Fofana | B14: Sénégalaise | C14: ORDINAIRES | E14: 800 | F14: 8000000 | G14: 0
A15: Héritiers feu Amadou Ly | B15: Sénégalaise | C15: ORDINAIRES | E15: 687 | F15: 6870000 | G15: 0
A16: Compagnie Commerciale des Sel Marins | B16: Française | C16: ORDINAIRES | E16: 9 | F16: 90000 | G16: 0
A17: TIDIANE SYLLA / ALPHA DIENG | B17: SENEGALAISE | C17: ORDINAIRES | E17: 6 | F17: 60000 | G17: 0
A18: GUY DESCHAMPS /OMAR GUEYE | B18: SENEGALAISE | C18: ORDINAIRES | E18: 6 | F18: 60000 | G18: 0
C19: TOTAL | E19: 55442 | F19: 554420000 | G19: 0
A21: Le capital social n'a pas connu d'évolution.

Sheet Note 14
A1: NOTE 14 : PRIMES ET RESERVES
A3: Désignation entité : | E3: Excercice clos le : | F3: =+'Fiche de renseignement R1'!$V$10 -> 45657
A4: ='Fiche de renseignement R1'!$J$4 -> SOCIETE NOUVELLE DES SALINS DU SINE SALOUM | E4: Durée en mois : | F4: =+'Fiche de renseignement R1'!$AH$10 -> 12
A5: Numéro d'identification : | B5: =+'Fiche de renseignement R1'!$J$10 -> 000018699
A7: LIBELLES | B7: ANNEE N | D7: ANNEE N-1 | F7: VARIATION EN VALEUR ABSOLUE
A9: Primes d'apport | B9: 0 | D9: 0 | F9: 0
A10: Primes d'émission | B10: 0 | D10: 0 | F10: 0
A11: Primes de fusion | B11: 0 | D11: 0 | F11: 0
A12: Primes de conversion | B12: 0 | D12: 0 | F12: 0
A13: Autres primes | B13: 0 | D13: 0 | F13: 0
A14: TOTAL PRIMES | B14: 0 | D14: 0 | F14: 0
A16: Réserves légales | B16: 112600000 | D16: 112600000 | F16: 0
A17: Réserves statutaires | B17: 0 | D17: 0 | F17: 0
A18: Réserves de plus-values nettes à long terme | B18: 0 | D18: 0 | F18: 0
A19: Réserves d'attribution gratuite d'actions au personnel salarié et aux dirigeants | B19: 0 | D19: 0 | F19: 0
A20: Autres réserves réglementées | B20: 0 | D20: 0 | F20: 0
A21: TOTAL RESERVES INDISPONIBLES | B21: 112600000 | D21: 112600000 | F21: 0
... A25: Report à nouveau | B25: 0 | D25: 0 | F25: 0
A27: Commentaire :
A28: L'Assemblée Générale Ordinaire (AGO) du 14-05-2024 avait décidé d'augmenter les réserves libres de 765 394 484 XOF

Sheet Note 15A
A1: NOTE 15A : SUBVENTIONS ET PROVISIONS REGLEMENTEES
A3: Désignation entité : | E3: Excercice clos le : | F3: =+'Fiche de renseignement R1'!$V$10 -> 45657
A4: ='Fiche de renseignement R1'!$J$4 -> SOCIETE NOUVELLE DES SALINS DU SINE SALOUM | E4: Durée en mois : | F4: =+'Fiche de renseignement R1'!$AH$10 -> 12
A5: Numéro d'identification : | B5: =+'Fiche de renseignement R1'!$J$10 -> 000018699
A7: LIBELLES | B7: NOTE | C7: Année N | D7: ANNEE N-1 | E7: Variation en valeur absolue | F7: Variation en % | G7: Régime fiscal | H7: Échéances
A9: Etat | C9: 0 | D9: 0 | E9: 0 | G9: 0
A10: Régions | C10: 0 | D10: 0 | E10: 0 | G10: 0
A11: Départements | C11: 0 | D11: 0 | E11: 0 | G11: 0
A12: Communes et collectivités publiques décentralisées | C12: 0 | D12: 0 | E12: 0 | G12: 0
A13: Entités publiques ou mixtes | C13: 0 | D13: 0 | E13: 0 | G13: 0
A14: Entités et organismes privés | C14: 0 | D14: 0 | E14: 0 | G14: 0
A15: Organismes internationaux | C15: 0 | D15: 0 | E15: 0 | G15: 0
A16: Autres | C16: 0 | D16: 0 | E16: 0 | G16: 0
A17: TOTAL SUBVENTIONS | C17: 0 | D17: 0 | E17: 0 | G17: 0
C18: 0 | D18: 0 | E18: 0 | G18: 0
A19: Amortissements dérogatoires | C19: 0 | D19: 0 | E19: 0 | G19: 0
A20: Plus-values de cession à réinvestir | C20: 0 | D20: 0 | E20: 0 | G20: 0
A21: Provision spéciale de réévaluation | C21: 0 | D21: 0 | E21: 0 | G21: 0
A22: Provisions réglementées relatives aux immobilisations | C22: 0 | D22: 0 | E22: 0 | G22: 0
A23: Provisions réglementées relatives aux stocks | C23: 0 | D23: 0 | E23: 0 | G23: 0
A24: Provisions pour investissement | C24: 0 | D24: 0 | E24: 0 | G24: 0
A25: Autres provisions et fonds réglementés | C25: 0 | D25: 0 | E25: 0 | G25: 0
A26: TOTAL PROVISIONS REGLEMENTEES | C26: 0 | D26: 0 | E26: 0 | G26: 0
A28: TOTAL SUBVENTIONS ET PROVISIONS REGLEMENTEES | C28: 0 | D28: 0 | E28: 0 | G28: 0
A30: Commentaire :
A31: NEANT

Sheet Note 15B
A1: NOTE 15B : AUTRES FONDS PROPRES(1)
A3: Désignation entité : | E3: Excercice clos le : | F3: =+'Fiche de renseignement R1'!$V$10 -> 45657
A4: ='Fiche de renseignement R1'!$J$4 -> SOCIETE NOUVELLE DES SALINS DU SINE SALOUM | E4: Durée en mois : | F4: =+'Fiche de renseignement R1'!$AH$10 -> 12
A5: Numéro d'identification : | B5: =+'Fiche de renseignement R1'!$J$10 -> 000018699
A7: LIBELLES | B7: NOTE | C7: Année N | D7: ANNEE N-1 | E7: Variation en valeur absolue | F7: Variation en % | G7: Échéances
A9: Titres participatifs | C9: 0 | D9: 0 | E9: 0
A10: Avances conditionnées | C10: 0 | D10: 0 | E10: 0
A11: Titres subordonnés à durée indéterminée (TSDI) | C11: 0 | D11: 0 | E11: 0
A12: Obligations remboursables en actions (ORA) | C12: 0 | D12: 0 | E12: 0
A13: Autres | C13: 0 | D13: 0 | E13: 0
A14: TOTAL AUTRES FONDS PROPRES | C14: 0 | D14: 0 | E14: 0
A16: (1) : Le cas échéant, une rubrique "Autres fonds propre" (montant des émissions de titres participatifs,
A17: avances conditionnées,…) sur une ligne séparée est intercalée entre les rubriques
A18: "TOTAL CAPTAUX PROPRES ET RESSOURCES ASSIMILEES" et "EMPRUNTS ET DETTES FINANCIERES" si le
A19: montant des autres fonds propres est significatif.
A21: Commentaire :
A22: NEANT

Sheet Note 16A
A1: NOTE 16A : DETTES FINANCIERES ET RESSOURCES ASSIMILEES
A3: Désignation entité : | D3: Excercice clos le : | F3: =+'Fiche de renseignement R1'!$V$10 -> 45657
A4: ='Fiche de renseignement R1'!$J$4 -> SOCIETE NOUVELLE DES SALINS DU SINE SALOUM | D4: Durée en mois : | F4: =+'Fiche de renseignement R1'!$AH$10 -> 12
A5: Numéro d'identification : | B5: =+'Fiche de renseignement R1'!$J$10 -> 000018699
A7: LIBELLES | B7: Année N | C7: ANNEE N-1 | D7: Variation en valeur absolue | E7: Variation en % | F7: Dettes à un an au plus | G7: Dettes à plus d'un an et à deux ans au plus | H7: Dettes à plus de deux ans
A9: Emprunts obligataires | B9: 0 | C9: 0 | D9: 0 | F9: 0 | G9: 0 | H9: 0
A10: Emprunts et dettes auprès des établissements de crédit | B10: 0 | C10: 0 | D10: 0 | F10: 0 | G10: 0 | H10: 0
A11: Avances reçues de l'Etat | B11: 0 | C11: 0 | D11: 0 | F11: 0 | G11: 0 | H11: 0
A12: Avances reçues et comptes courants bloqués | B12: 0 | C12: 0 | D12: 0 | F12: 0 | G12: 0 | H12: 0
A13: Dépôts et cautionnement reçus | B13: 0 | C13: 0 | D13: 0 | F13: 0 | G13: 0 | H13: 0
A14: Intérêts courus | B14: 0 | C14: 0 | D14: 0 | F14: 0 | G14: 0 | H14: 0
A15: Avances assorties de conditions particulières | B15: 0 | C15: 0 | D15: 0 | F15: 0 | G15: 0 | H15: 0
A16: Autres emprunts et dettes | B16: 0 | C16: 0 | D16: 0 | F16: 0 | G16: 0 | H16: 0
