Workbook
Name _xlfn_IFERROR: none
Name _xlfn_STDEV_S: none
Name conv_ton_to_lb: [1]ControlPanel!$C$10
Name Excel_BuiltIn__FilterDatabase: #REF!
Name Excel_BuiltIn__FilterDatabase: Résultats!$F$183:$G$194

Sheet Présentation
I5: Modèle financier: mine d'or
B10: Objectif
B23: Table des matières
B44: Relation au modele FARI du FMI
B60: DISCLAIMER
J72: Ce travail est sous la licence Creative Commons Attribution 4.0 International.
J73: Pour une copie de cette licence, merci de vous rendre sur le site : https://creativecommons.org/licenses/by/4.0/deed.fr

Sheet Résultats
B1: Resultats
B4: Hypothèses - synthèse | C4: unités
B5: Réserves récupérables | C5: tonnes | D5: =SUM(Modèle!G8:BD8) -> 4284000
B6: Première production | C6: année | D6: =Modèle!$C$31 -> 1
B7: Couts d'exploration | C7: $m | D7: =Paramètres!C118 -> 0
B8: Couts de développement (CAPEX) | C8: $m | D8: =Paramètres!C120 -> 407
B9: Production / CAPEX | C9: tonnes/$m | D9: =D5/D8 -> 10525.799
B10: Prix du minerai | C10: $/tonne | D10: =Paramètres!$G$108 -> 1600
B11: Prix du minerai | C11: $/lb
B12: Cout opérationnel par tonne | C12: $/tonne | D12: =Paramètres!J122 -> 507.5
B13: Cout opérationnel par tonne | C13: $/lb
B14: Charge de traitement / raffinage | C14: $/lb | D14: =Paramètres!F104 -> 0
B15: Total C1 cash costs | C15: $/lb | D15: =D12+Paramètres!F101+Paramètres!F103+(Modèle!C376*1000000/Modèle!C8) -> 587.5
B16: Taux d'actualisation (investisseurs) | C16: % | D16: =Paramètres!F93 -> 0.1
B17: Taux d'actualisation (Etat) | C17: % | D17: =Paramètres!F94 -> 0.125
B18: Inflation | C18: % | D18: =Paramètres!F95 -> 0.02
B19: Taux d’intérêt réel | C19: % | D19: =Paramètres!F92 -> 0.125
B20: Endettement (capitaux propres/actifs) | C20: % | D20: =Paramètres!F90 -> 0.5
B22: Résultats - synthèse | C22: unités
B23: Flux de trésorerie nets avant impôts du projet (actualisés) | C23: $m | D23: =Modèle!C25 -> 2122.6808
B24: TRI avant impôt du projet | C24: % | D24: =Modèle!C24 -> 0
B25: TRI après impôt du projet | C25: % | D25: =Modèle!C351 -> 0
B26: Taux de rendement minimum - investisseurs | C26: % | D26: =D17 -> 0.125
B27: TRI supérieur au rendement minimum? | D27: =D25>D26 -> FALSE
B28: Période de retour sur investissement (cash-flow non actualisés) | C28: années | D28: =Modèle!C283 -> 0
B29: Période de retour sur investissement (cash-flow actualisés) | C29: années | D29: =Modèle!C288 -> 0
B32: Utiliser « sélection des données » dans chaque graphique pour ajuster la longueur des axes et les cellules de données, par exemple, après avoir changé le régime fiscal ou le profil du projet.
J145: Projet selectionné:
J146: =Paramètres!$F$7 -> Sénégal (SGO - Convention Sabodala)
B180: Tableaux utilises pour certains graphiques
B182: Graphique 1. TEMI
C183: TEMI
B184: {=TRANSPOSE(Modèle!G426:Q426)} -> RDC - 2002 | C184: {=TRANSPOSE(Modèle!G430:Q430)} -> 0.44477093
B185: RDC - amendement | C185: 0.57598027
B186: Chili | C186: 0.53409525
B187: Perou | C187: 0.37911521
B188: Australie Occidentale | C188: 0.54683945
B189: Tanzanie | C189: 0.40238031
B190: Ghana | C190: 0.50177467
B191: Zambie - 2016 | C191: 0.42882023
...

Sheet Paramètres
A1: INPUTS
D3: Hypotheses du regime fiscal - principaux impots et taxes
L5: --- Selection de regimes fiscaux a comparer ---
D6: Choisir le numero du regime fiscal | F6: 11 | H6: 1 | I6: 2 | J6: 3 | K6: 4 | L6: 5 | M6: 6 | N6: 7 | O6: 8 | P6: 9 | Q6: 10 | R6: 11
D7: Nom du regime fiscal | F7: =INDEX(H7:R7,$F$6) -> Sénégal (SGO - Convention Sabodala) | H7: RDC - 2002 | I7: RDC - amendement | J7: Chili | K7: Perou | L7: Australie Occidentale | M7: Tanzanie | N7: Ghana | O7: Zambie - 2016 | P7: RDC - redevance a taux variable | Q7: RDC - taxe sur la rente | R7: Sénégal (SGO - Convention Sabodala)
D9: Bonus de signature | E9: $mm | F9: =INDEX(H9:R9,$F$138) -> 0 | H9: 0 | I9: 0 | J9: 0 | K9: 0 | L9: 0 | M9: 0 | N9: 0 | O9: 0 | P9: 0 | Q9: 0 | R9: 0
D10: Redevance
D11: Taux de redevance | E11: % | F11: =INDEX(H11:R11,$F$138) -> 0.05 | H11: 0.025 | I11: 0.035 | J11: 0 | K11: 0 | L11: 0.025 | M11: 0.04 | N11: 0.05 | O11: 0.05 | P11: 0.025 | Q11: 0.025 | R11: 0.05
D12: Assiette de la redevance (nette / brute) | E12: switch | F12: =INDEX(H12:R12,$F$138) -> gross | H12: net | I12: gross | J12: gross | K12: gross | L12: gross | M12: gross | N12: gross | O12: gross | P12: gross | Q12: gross | R12: gross
D13: Impôt sur les bénéfices
D14: Taux de l’impôt sur les bénéfices | E14: % | F14: =INDEX(H14:R14,$F$138) -> 0.25 | H14: 0.3 | I14: 0.35 | J14: 0.224 | K14: 0.28 | L14: 0.3 | M14: 0.3 | N14: 0.35 | O14: 0.3 | P14: 0.3 | Q14: 0.3 | R14: 0.25
D15: Deductibilite des couts d'exploration | E15: switch | F15: =INDEX(H15:R15,$F$138) -> deferred | H15: deferred | I15: deferred | J15: deferred | K15: deferred | L15: deferred | M15: deferred | N15: deferred | O15: deferred | P15: deferred | Q15: deferred | R15: deferred
D16: Deductibilite des couts d'investissement - immobilisation incorporelles | E16: switch | F16: =INDEX(H16:R16,$F$138) -> deferred | H16: deferred | I16: deferred | J16: deferred | K16: deferred | L16: deferred | M16: deferred | N16: deferred | O16: deferred | P16: deferred | Q16: deferred | R16: deferred
D17: Amortissement des couts d'investissement - immobilisations corporelles | E17: switch | F17: =INDEX(H17:R17,$F$138) -> deferred | H17: deferred | I17: deferred | J17: deferred | K17: deferred | L17: deferred | M17: deferred | N17: deferred | O17: deferred | P17: deferred | Q17: deferred | R17: deferred
D18: Report des pertes | E18: years | F18: =INDEX(H18:R18,$F$138) -> 5 | H18: 5 | I18: 5 | J18: 100 | K18: 4 | L18: 100 | M18: 100 | N18: 5 | O18: 10 | P18: 5 | Q18: 5 | R18: 5
D19: Report des pertes (limite) | E19: % | F19: =INDEX(H19:R19,$F$138) -> 1 | H19: 1 | I19: 1 | J19: 1 | K19: 1 | L19: 1 | M19: 1 | N19: 1 | O19: 0.5 | P19: 1 | Q19: 1 | R19: 1
D20: Regime d'amortissement (sur le capital physique et de remplacement) | E20: years | F20: =INDEX(H20:R20,$F$138) -> 5 | H20: 2 | I20: 5 | J20: 10 | K20: 10 | L20: 20 | M20: 1 | N20: 5 | O20: 4 | P20: 5 | Q20: 5 | R20: 5
D21: Amortissement accelere | F21: =INDEX(H21:R21,$F$138) -> 0 | H21: 1
D22: Option pour les redevances a taux variables (variables dans les tableaux ci-dessous)
D23: Redevance a taux variable - basee sur les prix (choisir entre les systemes 1 et 2) | E23: switch | F23: =INDEX(H23:R23,$F$138) -> 1 | H23: 1 | I23: 1 | J23: 1 | K23: 1 | L23: 1 | M23: 1 | N23: 1 | O23: 1 | P23: 4 | Q23: 1 | R23: 1
D24: Redevance a taux variable - basee sur les prix, pas sur le revenu marginal (choisir entre les systemes 1 et 2) | F24: =INDEX(H24:R24,$F$138) -> 1 | H24: 1 | I24: 1 | J24: 1 | K24: 1 | L24: 1 | M24: 1 | N24: 1 | O24: 1 | P24: 1 | Q24: 1 | R24: 1
D25: Taux de la taxe sur la rente | E25: % | F25: =INDEX(H25:R25,$F$138) -> 0 | Q25: 0.075
D26: Seuil de la taxe sur la rente | E26: % | F26: =INDEX(H26:R26,$F$138) -> 0 | Q26: 0.25
D27: Deductibilite de l'Impot sur les benefices (oui/non) | E27: switch | F27: =INDEX(H27:R27,$F$138) -> 0
D28: Taxe sur la marge opérationnelle (Choisir 1, 2, 3, 4 dans la section des taux variables) | E28: switch | F28: =INDEX(H28:R28,$F$138) -> 1 | H28: 1 | I28: 1 | J28: 3 | K28: 2 | L28: 1 | M28: 1 | N28: 1 | O28: 1 | P28: 1 | Q28: 1 | R28: 1
D29: Impôt variable sur les bénéfices (1 = off, 2 = on) | E29: switch | F29: =INDEX(H29:R29,$F$138) -> 1 | H29: 1 | I29: 1 | J29: 1 | K29: 1 | L29: 1 | M29: 1 | N29: 1 | O29: 1 | P29: 1 | Q29: 1 | R29: 1
D30: Taux de l'mpot sur les profits excedentaires (RDC amendement) | E30: % | F30: =INDEX(H30:R30,$F$138) -> 0 | H30: 0 | I30: 0.5 | J30: 0 | K30: 0 | L30: 0 | M30: 0 | N30: 0 | O30: 0 | P30: 0 | Q30: 0 | R30: 0
D31: Seuil de l'impot sur les profits excedentaires (RDC amendement) | E31: % | F31: =INDEX(H31:R31,$F$138) -> 0 | H31: 0 | I31: 0.25 | J31: 0 | K31: 0 | L31: 0 | M31: 0 | N31: 0 | O31: 0 | P31: 0 | Q31: 0 | R31: 0
D32: Taux du surcout sur les flux de tresorerie | E32: % | F32: =INDEX(H32:R32,$F$138) -> 0 | H32: 0 | I32: 0 | J32: 0 | K32: 0 | L32: 0 | M32: 0 | N32: 0 | O32: 0 | P32: 0 | Q32: 0 | R32: 0
D33: Deductibilite de l'Impot sur les benefices (oui/non) | E33: switch | F33: =INDEX(H33:R33,$F$138) -> 0
D34: Autres taxes et dispositions pertinentes
D35: Impôt sur le revenu des valeurs mobilières | E35: % | F35: =INDEX(H35:R35,$F$138) -> 0.1 | H35: 0.1 | I35: 0.1 | J35: 0.35 | K35: 0.068 | L35: 0.3 | M35: 0.1 | N35: 0.08 | O35: 0.1 | P35: 0.1 | Q35: 0.1 | R35: 0.1
D36: Participation gratuite de l’Etat (sans contribution) | E36: % | F36: =INDEX(H36:R36,$F$138) -> 0.1 | H36: 0.05 | I36: 0.1 | J36: 0 | K36: 0 | L36: 0 | M36: 0 | N36: 0.1 | O36: 0 | P36: 0.05 | Q36: 0.05 | R36: 0.1
D37: Tax provincial (redevance unitaire) | E37: $/ton | F37: =INDEX(H37:R37,$F$138) -> 0
D38: Drotis de douane | E38: % | F38: =INDEX(H38:R38,$F$138) -> 0 | H38: 0.05 | I38: 0.05 | J38: 0 | K38: 0 | L38: 0 | M38: 0 | N38: 0 | O38: 0 | P38: 0.05 | Q38: 0.05 | R38: 0
D39: Clause de rehabilitation (oui/non) | E39: switch | F39: =INDEX(H39:R39,$F$138) -> 0
D40: Clause sur le declenchement de la rehabilitation | E40: % depletion | F40: =INDEX(H40:R40,$F$138) -> 0
D42: Amortissement accelere
D44: Amortissement annee 1 | H44: 0.6
D45: Amortissement annee 2 | H45: 0.2
...

Sheet Modèle
A2: Verification: | C2: =AND(A:A) -> TRUE | E2: annee | G2: 1 | H2: =G2+1 -> 2 | I2: =H2+1 -> 3 | J2: =I2+1 -> 4 | K2: =J2+1 -> 5 | L2: =K2+1 -> 6 | M2: =L2+1 -> 7 | N2: =M2+1 -> 8 | O2: =N2+1 -> 9 | ... BD2: =BC2+1 -> 50
A4: Flux de tresorerie du projet
D7: Flux de tresorerie du projet avant impots: reel | E7: annee | G7: =G$2 -> 1 | H7: =H$2 -> 2 | I7: =I$2 -> 3 | J7: =J$2 -> 4 | K7: =K$2 -> 5 | L7: =L$2 -> 6 | M7: =M$2 -> 7 | N7: =N$2 -> 8 | ... BD7: =BD$2 -> 50
C8: =SUM(G8:BD8) -> 4284000 | D8: Production | E8: tonnes | G8: =Paramètres!G115 -> 245000 | H8: =Paramètres!H115 -> 359000 | I8: =Paramètres!I115 -> 360000 | J8: =Paramètres!J115 -> 400000 | K8: =Paramètres!K115 -> 400000 | L8: =Paramètres!L115 -> 400000 | M8: =Paramètres!M115 -> 400000 | N8: =Paramètres!N115 -> 320000 | ... BD8: =Paramètres!BD115 -> 0
C9: =SUM(G9:BD9) -> 6854.4 | D9: Chiffre d'affaires brut | E9: $mm reel | G9: =G8*Paramètres!G108/1000000 -> 392 | H9: =H8*Paramètres!H108/1000000 -> 574.4 | I9: =I8*Paramètres!I108/1000000 -> 576 | J9: =J8*Paramètres!J108/1000000 -> 640 | K9: =K8*Paramètres!K108/1000000 -> 640 | L9: =L8*Paramètres!L108/1000000 -> 640 | M9: =M8*Paramètres!M108/1000000 -> 640 | N9: =N8*Paramètres!N108/1000000 -> 512 | ... BD9: =BD8*Paramètres!BD108/1000000 -> 0
C10: =SUM(G10:BD10) -> 0 | D10: Transport et traitement apres imposition | E10: $mm reel | G10: =Paramètres!G116+Paramètres!G117 -> 0 | H10: =Paramètres!H116+Paramètres!H117 -> 0 | I10: =Paramètres!I116+Paramètres!I117 -> 0 | J10: =Paramètres!J116+Paramètres!J117 -> 0 | K10: =Paramètres!K116+Paramètres!K117 -> 0 | L10: =Paramètres!L116+Paramètres!L117 -> 0 | M10: =Paramètres!M116+Paramètres!M117 -> 0 | N10: =Paramètres!N116+Paramètres!N117 -> 0 | ... BD10: =Paramètres!BD116+Paramètres!BD117 -> 0
A11: =ROUND(C11-(C9-C10),5)=0 -> TRUE | C11: =SUM(G11:BD11) -> 6854.4 | D11: Chiffre d'affaires net | E11: $mm reel | G11: =G9-G10 -> 392 | H11: =H9-H10 -> 574.4 | I11: =I9-I10 -> 576 | J11: =J9-J10 -> 640 | K11: =K9-K10 -> 640 | L11: =L9-L10 -> 640 | M11: =M9-M10 -> 640 | N11: =N9-N10 -> 512 | ... BD11: =BD9-BD10 -> 0
C12: =SUM(G12:BD12) -> 0 | D12: Couts d’exploration | E12: $mm reel | G12: =Paramètres!G118 -> 0 | H12: =Paramètres!H118 -> 0 | I12: =Paramètres!I118 -> 0 | J12: =Paramètres!J118 -> 0 | K12: =Paramètres!K118 -> 0 | L12: =Paramètres!L118 -> 0 | M12: =Paramètres!M118 -> 0 | N12: =Paramètres!N118 -> 0 | ... BD12: =Paramètres!BD118 -> 0
C13: =SUM(G13:BD13) -> 0 | D13: Couts d’investissement en capital - incorporel | E13: $mm reel | G13: =Paramètres!G119 -> 0 | H13: =Paramètres!H119 -> 0 | I13: =Paramètres!I119 -> 0 | J13: =Paramètres!J119 -> 0 | K13: =Paramètres!K119 -> 0 | L13: =Paramètres!L119 -> 0 | M13: =Paramètres!M119 -> 0 | N13: =Paramètres!N119 -> 0 | ... BD13: =Paramètres!BD119 -> 0
C14: =SUM(G14:BD14) -> 407 | D14: Couts d’investissement en capital - corporel | E14: $mm reel | G14: =Paramètres!G120 -> 37 | H14: =Paramètres!H120 -> 109 | I14: =Paramètres!I120 -> 160 | J14: =Paramètres!J120 -> 0 | K14: =Paramètres!K120 -> 0 | L14: =Paramètres!L120 -> 0 | M14: =Paramètres!M120 -> 0 | N14: =Paramètres!N120 -> 24 | ... BD14: =Paramètres!BD120 -> 0
C15: =SUM(G15:BD15) -> 253 | D15: Capital de réinvestissement | E15: $mm reel | G15: =Paramètres!G121 -> 41 | H15: =Paramètres!H121 -> 37 | I15: =Paramètres!I121 -> 45 | J15: =Paramètres!J121 -> 25 | K15: =Paramètres!K121 -> 27 | L15: =Paramètres!L121 -> 12 | M15: =Paramètres!M121 -> 11 | N15: =Paramètres!N121 -> 8 | ... BD15: =Paramètres!BD121 -> 0
D16: Couts opérationnels - extraction | E16: $mm reel | G16: =Paramètres!G122*G$8/1000000 -> 171.01 | H16: =Paramètres!H122*H$8/1000000 -> 169.0172 | I16: =Paramètres!I122*I$8/1000000 -> 177.984 | J16: =Paramètres!J122*J$8/1000000 -> 203 | K16: =Paramètres!K122*K$8/1000000 -> 217 | L16: =Paramètres!L122*L$8/1000000 -> 203 | M16: =Paramètres!M122*M$8/1000000 -> 180 | N16: =Paramètres!N122*N$8/1000000 -> 176 | ... BD16: =Paramètres!BD122*BD$8/1000000 -> 0
C17: =SUM(G17:BD17) -> 2594.0134 | D17: Couts opérationnels - total | E17: $mm reel | G17: =SUM(G16:G16) -> 171.01 | H17: =SUM(H16:H16) -> 169.0172 | I17: =SUM(I16:I16) -> 177.984 | J17: =SUM(J16:J16) -> 203 | K17: =SUM(K16:K16) -> 217 | L17: =SUM(L16:L16) -> 203 | M17: =SUM(M16:M16) -> 180 | N17: =SUM(N16:N16) -> 176 | ... BD17: =SUM(BD16:BD16) -> 0
C18: =SUM(G18:BD18) -> 0 | D18: Parafiscalité | E18: $mm reel | G18: =Paramètres!G127 -> 0 | H18: =Paramètres!H127 -> 0 | I18: =Paramètres!I127 -> 0 | J18: =Paramètres!J127 -> 0 | K18: =Paramètres!K127 -> 0 | L18: =Paramètres!L127 -> 0 | M18: =Paramètres!M127 -> 0 | N18: =Paramètres!N127 -> 0 | ... BD18: =Paramètres!BD127 -> 0
C19: =SUM(G19:BD19) -> 5 | D19: Couts de fermeture et de rehabilitation | E19: $mm reel | G19: =Paramètres!G128 -> 0 | H19: =Paramètres!H128 -> 0 | I19: =Paramètres!I128 -> 0 | J19: =Paramètres!J128 -> 0 | K19: =Paramètres!K128 -> 0 | L19: =Paramètres!L128 -> 0 | M19: =Paramètres!M128 -> 0 | N19: =Paramètres!N128 -> 0 | ... BD19: =Paramètres!BD128 -> 0
C20: =SUM(G20:BD20) -> 3259.0134 | D20: Couts totaux | E20: $mm reel | G20: =SUM(G12:G15)+G17+G18+G19 -> 249.01 | H20: =SUM(H12:H15)+H17+H18+H19 -> 315.0172 | I20: =SUM(I12:I15)+I17+I18+I19 -> 382.984 | J20: =SUM(J12:J15)+J17+J18+J19 -> 228 | K20: =SUM(K12:K15)+K17+K18+K19 -> 244 | L20: =SUM(L12:L15)+L17+L18+L19 -> 215 | M20: =SUM(M12:M15)+M17+M18+M19 -> 191 | N20: =SUM(N12:N15)+N17+N18+N19 -> 208 | ... BD20: =SUM(BD12:BD15)+BD17+BD18+BD19 -> 0
A21: =ROUND(C21-(C11-SUM(C12:C19)),5)=0 -> TRUE | C21: =SUM(G21:BD21) -> 3595.3866 | D21: Flux de tresorerie du projet avant redevances, droits de douanes et impots | E21: $mm reel | G21: =G11-G20 -> 142.99 | H21: =H11-H20 -> 259.3828 | I21: =I11-I20 -> 193.016 | J21: =J11-J20 -> 412 | K21: =K11-K20 -> 396 | L21: =L11-L20 -> 425 | M21: =M11-M20 -> 449 | N21: =N11-N20 -> 304 | ... BD21: =BD11-BD20 -> 0
C23: =AVERAGE(G23:BD23) -> 0.50058345 | D23: Marge operationnelle (EBITDA/CA brut) | E23: % | G23: =IFERROR(G21/G11,"") -> 0.36477041 | H23: =IFERROR(H21/H11,"") -> 0.45157173 | I23: =IFERROR(I21/I11,"") -> 0.33509722 | J23: =IFERROR(J21/J11,"") -> 0.64375 | K23: =IFERROR(K21/K11,"") -> 0.61875 | L23: =IFERROR(L21/L11,"") -> 0.6640625 | M23: =IFERROR(M21/M11,"") -> 0.7015625 | N23: =IFERROR(N21/N11,"") -> 0.59375 | ... BD23: =IFERROR(BD21/BD11,"")
C24: =IFERROR(IRR($G21:BD21),0) -> 0 | D24: Taux de rendement interne (reel) | E24: % | G24: =IFERROR(IRR($G21:G21),"--") -> -- | H24: =IFERROR(IRR($G21:H21),"--") -> -- | I24: =IFERROR(IRR($G21:I21),"--") -> -- | J24: =IFERROR(IRR($G21:J21),"--") -> -- | K24: =IFERROR(IRR($G21:K21),"--") -> -- | L24: =IFERROR(IRR($G21:L21),"--") -> -- | M24: =IFERROR(IRR($G21:M21),"--") -> -- | N24: =IFERROR(IRR($G21:N21),"--") -> -- | ... BD24: =IFERROR(IRR($G21:BD21),"--") -> --
C25: =NPV(Paramètres!$F$93,$H$21:$BD$21)+$G$21 -> 2122.6808 | D25: Flux de tresorerie du projet avant impots, VAN10 | E25: $mm reel
D27: Reperes
C28: =MAX(G28:BD28) -> 50 | D28: Annees du projet | E28: annee | G28: =(SUM($G$8:G20)>0)*1+F28 -> 1 | H28: =(SUM($G$8:H20)>0)*1+G28 -> 2 | I28: =(SUM($G$8:I20)>0)*1+H28 -> 3 | J28: =(SUM($G$8:J20)>0)*1+I28 -> 4 | K28: =(SUM($G$8:K20)>0)*1+J28 -> 5 | L28: =(SUM($G$8:L20)>0)*1+K28 -> 6 | M28: =(SUM($G$8:M20)>0)*1+L28 -> 7 | N28: =(SUM($G$8:N20)>0)*1+M28 -> 8 | ... BD28: =(SUM($G$8:BD20)>0)*1+BC28 -> 50
C29: =MAX(G29:BD29) -> 17 | D29: Annees de production | E29: annee | G29: =((G8>0)*1+F29)*(G8>0) -> 1 | H29: =((H8>0)*1+G29)*(H8>0) -> 2 | I29: =((I8>0)*1+H29)*(I8>0) -> 3 | J29: =((J8>0)*1+I29)*(J8>0) -> 4 | K29: =((K8>0)*1+J29)*(K8>0) -> 5 | L29: =((L8>0)*1+K29)*(L8>0) -> 6 | M29: =((M8>0)*1+L29)*(M8>0) -> 7 | N29: =((N8>0)*1+M29)*(N8>0) -> 8 | ... BD29: =((BD8>0)*1+BC29)*(BD8>0) -> 0
C30: =MAX(G30:BD30) -> 17 | D30: Annees de production restantes | E30: annee | G30: =($C$29-G29+1)*(G8>0) -> 17 | H30: =($C$29-H29+1)*(H8>0) -> 16 | I30: =($C$29-I29+1)*(I8>0) -> 15 | J30: =($C$29-J29+1)*(J8>0) -> 14 | K30: =($C$29-K29+1)*(K8>0) -> 13 | L30: =($C$29-L29+1)*(L8>0) -> 12 | M30: =($C$29-M29+1)*(M8>0) -> 11 | N30: =($C$29-N29+1)*(N8>0) -> 10 | ... BD30: =($C$29-BD29+1)*(BD8>0) -> 0
C31: =SUM(G31:BD31) -> 1 | D31: Annee de premiere production | E31: annee | G31: =IF(G29=1,G28,0) -> 1 | H31: =IF(H29=1,H28,0) -> 0 | I31: =IF(I29=1,I28,0) -> 0 | J31: =IF(J29=1,J28,0) -> 0 | K31: =IF(K29=1,K28,0) -> 0 | L31: =IF(L29=1,L28,0) -> 0 | M31: =IF(M29=1,M28,0) -> 0 | N31: =IF(N29=1,N28,0) -> 0 | ... BD31: =IF(BD29=1,BD28,0) -> 0
D34: Periode de retour sur investissement
C35: =MAX(G35:BD35) -> 449 | D35: Flux de tresorerie du projet avant impot | E35: $mm reel | G35: =G21 -> 142.99 | H35: =H21 -> 259.3828 | I35: =I21 -> 193.016 | J35: =J21 -> 412 | K35: =K21 -> 396 | L35: =L21 -> 425 | M35: =M21 -> 449 | N35: =N21 -> 304 | ... BD35: =BD21 -> 0
C36: =MAX(G36:BD36) -> 3595.3866 | D36: Flux cumulatifs de tresorerie du projet avant impot | E36: $mm reel | G36: =G35+F36 -> 142.99 | H36: =H35+G36 -> 402.3728 | I36: =I35+H36 -> 595.3888 | J36: =J35+I36 -> 1007.3888 | K36: =K35+J36 -> 1403.3888 | L36: =L35+K36 -> 1828.3888 | M36: =M35+L36 -> 2277.3888 | N36: =N35+M36 -> 2581.3888 | ... BD36: =BD35+BC36 -> 3595.3866
C37: =MAX(G37:BD37) -> 0 | D37: Periode de retour sur investissement | E37: annee | G37: =IF(AND(G36<=0,H36>0),G28+(-G36/H35),0) -> 0 | H37: =IF(AND(H36<=0,I36>0),H28+(-H36/I35),0) -> 0 | I37: =IF(AND(I36<=0,J36>0),I28+(-I36/J35),0) -> 0 | J37: =IF(AND(J36<=0,K36>0),J28+(-J36/K35),0) -> 0 | K37: =IF(AND(K36<=0,L36>0),K28+(-K36/L35),0) -> 0 | L37: =IF(AND(L36<=0,M36>0),L28+(-L36/M35),0) -> 0 | M37: =IF(AND(M36<=0,N36>0),M28+(-M36/N35),0) -> 0 | N37: =IF(AND(N36<=0,O36>0),N28+(-N36/O35),0) -> 0 | ... BD37: =IF(AND(BD36<=0,BE36>0),BD28+(-BD36/BE35),0) -> 0
D39: Inflation
D40: Indice d'inflation | E40: indice | G40: =IF(Paramètres!G$113=1,1,(1+Paramètres!$F$95)^(Paramètres!G$113-1)) -> 1 | H40: =IF(Paramètres!H$113=1,1,(1+Paramètres!$F$95)^(Paramètres!H$113-1)) -> 1.02 | I40: =IF(Paramètres!I$113=1,1,(1+Paramètres!$F$95)^(Paramètres!I$113-1)) -> 1.0404 | J40: =IF(Paramètres!J$113=1,1,(1+Paramètres!$F$95)^(Paramètres!J$113-1)) -> 1.061208 | K40: =IF(Paramètres!K$113=1,1,(1+Paramètres!$F$95)^(Paramètres!K$113-1)) -> 1.0824322 | L40: =IF(Paramètres!L$113=1,1,(1+Paramètres!$F$95)^(Paramètres!L$113-1)) -> 1.1040808 | M40: =IF(Paramètres!M$113=1,1,(1+Paramètres!$F$95)^(Paramètres!M$113-1)) -> 1.1261624 | N40: =IF(Paramètres!N$113=1,1,(1+Paramètres!$F$95)^(Paramètres!N$113-1)) -> 1.1486857 | ... BD40: =IF(Paramètres!BD$113=1,1,(1+Paramètres!$F$95)^(Paramètres!BD$113-1)) -> 2.6388118
D42: Flux de tresorerie du projet avant impot: Nominal | E42: year | G42: =G$2 -> 1 | H42: =H$2 -> 2 | I42: =I$2 -> 3 | J42: =J$2 -> 4 | K42: =K$2 -> 5 | L42: =L$2 -> 6 | M42: =M$2 -> 7 | N42: =N$2 -> 8 | ... BD42: =BD$2 -> 50
C43: =SUM(G43:BD43) -> 7785.0252 | D43: Chiffre d'affaires brut | E43: $mm reel | G43: =G9*G$40 -> 392 | H43: =H9*H$40 -> 585.888 | I43: =I9*I$40 -> 599.2704 | J43: =J9*J$40 -> 679.17312 | K43: =K9*K$40 -> 692.75658 | L43: =L9*L$40 -> 706.61171 | M43: =M9*M$40 -> 720.74395 | N43: =N9*N$40 -> 588.12706 | ... BD43: =BD9*BD$40 -> 0
C44: =SUM(G44:BD44) -> 0 | D44: Transport et traitement apres imposition | E44: $mm reel | G44: =G10*G$40 -> 0 | H44: =H10*H$40 -> 0 | I44: =I10*I$40 -> 0 | J44: =J10*J$40 -> 0 | K44: =K10*K$40 -> 0 | L44: =L10*L$40 -> 0 | M44: =M10*M$40 -> 0 | N44: =N10*N$40 -> 0 | ... BD44: =BD10*BD$40 -> 0
A45: =ROUND(C45-(C43-C44),5)=0 -> TRUE | C45: =SUM(G45:BD45) -> 7785.0252 | D45: Chiffre d'affaires net | E45: $mm reel | G45: =G11*G$40 -> 392 | H45: =H11*H$40 -> 585.888 | I45: =I11*I$40 -> 599.2704 | J45: =J11*J$40 -> 679.17312 | K45: =K11*K$40 -> 692.75658 | L45: =L11*L$40 -> 706.61171 | M45: =M11*M$40 -> 720.74395 | N45: =N11*N$40 -> 588.12706 | ... BD45: =BD11*BD$40 -> 0
C46: =SUM(G46:BD46) -> 0 | D46: Couts d’exploration | E46: $mm reel | G46: =G12*G$40 -> 0 | H46: =H12*H$40 -> 0 | I46: =I12*I$40 -> 0 | J46: =J12*J$40 -> 0 | K46: =K12*K$40 -> 0 | L46: =L12*L$40 -> 0 | M46: =M12*M$40 -> 0 | N46: =N12*N$40 -> 0 | ... BD46: =BD12*BD$40 -> 0
C47: =SUM(G47:BD47) -> 0 | D47: Couts d’investissement en capital - incorporel | E47: $mm reel | G47: =G13*G$40 -> 0 | H47: =H13*H$40 -> 0 | I47: =I13*I$40 -> 0 | J47: =J13*J$40 -> 0 | K47: =K13*K$40 -> 0 | L47: =L13*L$40 -> 0 | M47: =M13*M$40 -> 0 | N47: =N13*N$40 -> 0 | ... BD47: =BD13*BD$40 -> 0
C48: =SUM(G48:BD48) -> 438.24796 | D48: Couts d’investissement en capital - corporel | E48: $mm reel | G48: =G14*G$40 -> 37 | H48: =H14*H$40 -> 111.18 | I48: =I14*I$40 -> 166.464 | J48: =J14*J$40 -> 0 | K48: =K14*K$40 -> 0 | L48: =L14*L$40 -> 0 | M48: =M14*M$40 -> 0 | N48: =N14*N$40 -> 27.568456 | ... BD48: =BD14*BD$40 -> 0
C49: =SUM(G49:BD49) -> 274.3098 | D49: Capital de réinvestissement | E49: $mm reel | G49: =G15*G$40 -> 41 | H49: =H15*H$40 -> 37.74 | I49: =I15*I$40 -> 46.818 | J49: =J15*J$40 -> 26.5302 | K49: =K15*K$40 -> 29.225668 | L49: =L15*L$40 -> 13.24897 | M49: =M15*M$40 -> 12.387787 | N49: =N15*N$40 -> 9.1894853 | ... BD49: =BD15*BD$40 -> 0
C50: =SUM(G50:BD50) -> 2979.6184 | D50: Couts opérationnels - extraction | E50: $mm reel | G50: =G17*G$40 -> 171.01 | H50: =H17*H$40 -> 172.39754 | I50: =I17*I$40 -> 185.17455 | J50: =J17*J$40 -> 215.42522 | K50: =K17*K$40 -> 234.88778 | L50: =L17*L$40 -> 224.1284 | M50: =M17*M$40 -> 202.70924 | N50: =N17*N$40 -> 202.16868 | ... BD50: =BD17*BD$40 -> 0
...
