Workbook
Name Agency_type: Table15[Type d''Agence]
Name Commodities_list: Table5_Commodities_list[Description de produit HS av. volume]
Name Commodity_names: Table5_Commodities_list[Description de produit HS]
Name Companies_list: Companies[Nom complet de l’entreprise]
Name Currency_code_list: Table1_Country_codes_and_currencies[Code de devise (ISO 4217)]
Name GFS_list: Table6_GFS_codes_classification[Combiné]
Name Government_entities_list: Government_agencies[Nom complet de l’entité]
Name Project_phases_list: Table12[Étapes du projet]
Name Projectname: Companies15[Nom complet du projet]
Name Reporting_options_list: Table3_Reporting_options[Liste]
Name Revenue_stream_list: Government_revenues_table[Nom du flux de revenus]
Name Sector_list: Table7_sectors[Secteur (s)]
Name Simple_options_list: Table2_Simple_options[Liste]
Name Total_reconciled: Table10[Valeur de revenus]
Name Total_revenues: Government_revenues_table[Valeur des revenus]

Sheet Introduction
E4: Rempli le : | F4: 45293
C10: Modèle de données résumées pour les divulgations ITIE
C11: Version 2.0 appliquée le 1er Juillet 2019
C13: En remplissant ce modèle de données résumées avec des données de votre Rapport ITIE, vous rendrez ces dernières accessibles sous un format lisible par machine (Exigence 7.2.d).
C14: « Rendre le Rapport ITIE disponible en format données ouvertes (xlsx ou csv) en ligne et faire connaître sa disponibilité » - Exigence ITIE 7.1.c
C16: Comment fonctionne la publication de données ITIE :
C17: 1. N’utiliser qu’un classeur Excel par exercice fiscal couvert. Si la déclaration porte à la fois sur les hydrocarbures et l’exploitation minière, ces deux secteurs peuvent être inclus dans un seul classeur.
C18: 2. Remplir le classeur entier - parties 1 à 5
C19: 3. Prière de soumettre cette fiche de données en même temps que le Rapport ITIE. L’envoyer au Secrétariat international à : data@eiti.org.
C20: 4. Les données serviront à alimenter le référentiel mondial de données ITIE, disponible sur le site Internet international de l’ITIE à https://eiti.org/fr/donnees. Le fichier vous sera renvoyé, afin de pouvoir être publié sur les canaux de votre choix.
C22: Le présent formulaire modèle devra être rempli intégralement et soumis au Secrétariat international de l’ITIE pour chaque exercice fiscal couvert par le rapportage ITIE.
C25: Ce classeur comporte cinq parties. Insérer vos données en commençant par la partie 1 et continuer jusqu’à la partie 5
C27: Partie 1 (Présentation) : Insérer les caractéristiques relatives au pays et aux données.
... C31: Partie 5 (Données d’entreprise) : Inscrire des données d’entreprise - et celle de niveau projet - par flux de revenus.
C33: Le Secrétariat international peut prodiguer conseils et soutien sur demande. Veuillez le contacter à | E33: data@eiti.org
C35: Les cellules en orange doivent être complétées avant la soumission | E35: Les cellules en bleu ne servent qu’à indiquer les sources et/ou à inscrire des commentaires | G35: Les cellules en blanc n’exigent aucune action
C37: Vous recevrez des retours immédiats sur un certain nombre des données que vous aurez inscrites, et certaines cellules se rempliront automatiquement.
C40: Terminologie : Divulgation | E40: Terminologie : Options simples
C41: Oui, divulgation systématique : Si les données sont divulguées régulièrement et systématiquement par des entités de l’État et ou des entreprises, et si ces données sont fiables, sélectionner Oui, divulgation systématique | E41: Oui : Tous les aspects de la question ont reçu une réponse/ont été couverts.
C42: Oui, à travers le rapportage ITIE : Si le Rapport ITIE ou son site couvre certaines lacunes de divulgation relatives aux données du gouvernement ou des entreprises, sélectionner « Oui, dans le Rapport ITIE ». | E42: Partiellement : Des aspects de la question ont reçu une réponse/ont été couverts.
C43: Non disponible : Les données sont applicables au pays, mais il n’y a pas de données ou d’informations disponibles. | E43: Non : Aucune information n’est couverte.
C44: Sans objet : Si une exigence n’est pas pertinente, sélectionner « Sans objet ». Faire référence à toute information à ce sujet, telle que contenue dans le Rapport ITIE ou dans le procès-verbal d’une réunion du Groupe multipartite. | E44: Sans objet : La question n’est pas pertinente pour la rubrique en question. Si une explication est requise, faire référence à toute information démontrant la non-applicabilité.
C46: Pour plus d’information sur l’ITIE, visitez notre site Internet https://eiti.org/fr
C47: Vous voulez en savoir plus sur votre pays ? Vérifiez si votre pays met en œuvre la Norme ITIE en visitant https://eiti.org/fr/pays
C48: Pour la version la plus récente des modèles de données résumées, consultez https://eiti.org/fr/document/modele-donnees-resumees-itie
C49: Faites-nous connaître vos réactions ou signalez tout conflit au niveau des données ! Écrivez-nous à data@eiti.org
C51: Site Internet www.eiti.org Courriel secretariat@eiti.org Téléphone +47 22 20 08 00 Télécopieur +47 22 83 08 02
C52: Adresse EITI International Secretariat, Rådhusgata 26, 0151 Oslo, Norvège
B53: Pays ou région
B55: Exercice fiscal couvert par ce fichier de données
B56: Exercice fiscal couvert par ce fichier de données
B58: Source de données
B59: Source de données
B60: Source de données
B61: Source de données
B62: Source de données
B63: Source de données
B64: Source de données
B65: Source de données
B66: Source de données
...

Sheet Partie 1 - Présentation
G3: Modèle de données résumées
G4: =Introduction!G4 -> 0
C8: Partie 1 - (Présentation) Elle couvre les caractéristiques du pays et des données
C9: Comment remplir cette feuille :
C10: 1. Commençant par en haut, sélectionner votre réponse dans la colonne grise. Des indications s’affichent dans les cadres jaunes dès que la cellule a été sélectionnée.
C11: 2. Lorsqu’il aura été répondu à certaines questions, de nouvelles indications et questions peuvent s’afficher. Merci de répondre à chacune d’elles jusqu’à ce que la section ait été remplie.
C12: 3. Inclure au besoin toute information supplémentaire ou tout commentaire dans la colonne Source/Commentaires.
C13: Si vous avez des questions, veuillez contacter data@eiti.org
C15: Les cellules en orange doivent être complétées avant la soumission | E15: Les cellules en bleu pâle ne servent qu’à indiquer les sources et/ou à inscrire des commentaires | G15: Les cellules en blanc n’exigent aucune action
C17: Partie 1 - Présentation
C18: Description | E18: Inscrire les données dans cette colonne | G18: Source/Commentaires
C19: Pays ou région
B20: Pays ou région | C20: Nom du pays ou de la région | E20: Sénégal
B21: Pays ou région | C21: Code ISO de la devise | E21: =IFERROR(VLOOKUP($E$20,Table1_Country_codes_and_currencies[],3,FALSE),"") -> SEN
B22: Pays ou région | C22: Nom de la monnaie nationale | E22: =IFERROR(VLOOKUP($E$20,Table1_Country_codes_and_currencies[],7,FALSE),"") -> Franc CFA d’Afrique de l’Ouest
B23: Pays ou région | C23: Monnaie nationale selon ISO-4217 | E23: =IFERROR(VLOOKUP($E$20,Table1_Country_codes_and_currencies[],5,FALSE),"") -> XOF
C24: Exercice fiscal couvert par ce fichier de données
B25: Exercice fiscal couvert par ce fichier de données | C25: Date de début | E25: 44562
B26: Exercice fiscal couvert par ce fichier de données | C26: Date de fin | E26: 44926
C27: Source de données
B28: Source de données | C28: Un Rapport ITIE a-t-il été préparé par un Administrateur indépendant ? | E28: Oui
B29: Source de données | C29: Quel est le nom de l’entreprise ? | E29: Enerteam
B30: Source de données | C30: Date à laquelle le Rapport ITIE a été rendu public | E30: 45282
B31: Source de données | C31: URL, Rapport ITIE | E31: https://itie.sn/rapport-itie-2022/
B32: Source de données | C32: Les données ITIE sont-elles systématiquement divulguées par le gouvernement à une adresse unique? | E32: Oui | G32: A travers la plateforme "Fusion"
B33: Source de données | C33: Date de publication des données ITIE | G33: Annuellement avec la publication du rapport ITIE
B34: Source de données | C34: Lien vers le site Internet (URL) de données ITIE | E34: https://donnees.itie.sn/dashboard/
B35: Source de données | C35: Existe-t-il d’autres fichiers de caractère pertinent ? | E35: Oui | G35: Les annexes au rapport ITIE 2022
B36: Source de données | C36: Date à laquelle l’autre fichier a été rendu public | E36: 45282
B37: Source de données | C37: URL | E37: https://itie.sn/rapport-itie-2022/ | G37: Les annexes au rapport ITIE 2022
C38: Accessibilités des données et données ouvertes (Exigence 7.2)
C39: Le gouvernement applique-t-il une politique de données ouvertes ? | E39: Oui, à travers le rapportage ITIE
B40: Couverture/périmètre des données | C40: Portail/fichiers de données ouvertes | E40: https://donnees.itie.sn/dashboard/
B41: Couverture/périmètre des données | C41: Couverture/périmètre des données
B42: Couverture/périmètre des données | C42: Couverture sectorielle
B43: Couverture/périmètre des données | C43: Pétrole | E43: Oui
B44: Couverture/périmètre des données | C44: Gaz | E44: Oui
B45: Couverture/périmètre des données | C45: Mines (y compris carrières) | E45: Oui
B46: Couverture/périmètre des données | C46: Autres secteurs (autres que les secteur en amont) | E46: Sans objet
B47: Couverture/périmètre des données | C47: Si oui, préciser le nom (insérer de nouvelles lignes si multiples) | E47: Sans objet
...

Sheet Partie 2 - Liste de pointage
H3: Modèle de données résumées
H4: =Introduction!G4 -> 0
B8: Partie 2 (liste de vérification) Elle couvre l’information contextuelle et financière agrégée prévue par les Exigences ITIE 2,3,4,5 et 6.
B9: Comment remplir cette feuille :
B10: Pour chaque ligne, veuillez procéder comme suit
B11: 1. Commençant par le haut, répondez aux questions de la première colonne (Inclusion). Des indications vous sont données dans les cadres jaunes une fois que la cellule est mise en évidence. Cliquez sur les cellules relatives à chaque Exigence ITIE pour faire apparaître le libellé de la Norme ITIE.
B12: 2. D’autres orientations apparaissent lorsque vous remplissez les cellules. Remplissez-les comme indiqué, complétant chaque colonne de chaque ligne avant de remplir la ligne suivante.
B13: Par exemple, en sélectionnant « Oui, dans le Rapport ITIE », le texte « Veuillez inclure la section du Rapport ITIE » dans la case Source/unités apparaît.
B14: 3. Insérez au besoin toute information supplémentaire ou tout commentaire dans la colonne Commentaires/Notes.
B15: Si vous avez des questions, veuillez contacter data@eiti.org
B17: Les cellules en orange doivent être complétées avant la soumission | D17: Les cellules en bleu pâle ne servent qu’à indiquer les sources et/ou inscrire des commentaires | F17: Ignorez les cellules en blanc, car elles n’exigent aucune action
B19: Partie 2 - Liste de pointage
B20: Veuillez répondre à toutes les questions posées ci-dessous.
B22: Exigence | D22: Inclusion | F22: Source/unités | H22: Commentaires/Notes
B23: Exigence ITIE 2.1 : Cadre légal et régime fiscal
B24: Le gouvernement publie-t-il des informations concernant
B25: Les lois et réglementations ? | D25: Oui, à travers le rapportage ITIE | F25: Section 4.1.3.1 et 4.2.2.1 du rapport ITIE 2022
B26: Vue d’ensemble des rôles des agences gouvernementales ? | D26: Oui, à travers le rapportage ITIE | F26: Section 4.1.3.2 et 4.2.2.2 du rapport ITIE 2022
B27: Régime des droits pétroliers et miniers? | D27: Oui, à travers le rapportage ITIE | F27: Section 4.1.4.2 et 4.2.3.2 du rapport ITIE 2022
B28: Régime fiscal ? | D28: Oui, à travers le rapportage ITIE | F28: Section 4.1.3.3 et 4.2.2.3 du rapport ITIE 2022
B30: Exigence ITIE 2.2: Octroi des contrats et licences
B31: Le gouvernement publie-t-il des informations concernant
B32: le processus d’octroi des licences ? | D32: Oui, à travers le rapportage ITIE | F32: Section 4.1.5.1 du Rapport ITIE 2022 (Mines) Section 4.2.4.1 du Rapport ITIE 2022 (Hydrocarbures)
B33: et les critères techniques et financiers utilisés ? | D33: Oui, à travers le rapportage ITIE | F33: Section 4.1.5.1 du Rapport ITIE 2022 (Mines) Section 4.2.4.1 du Rapport ITIE 2022 (Hydrocarbures) Section 4.2.4.5 du Rapport ITIE 2022 (Hydrocarbures)
B34: le(s) processus de transfert de licences ? | D34: Oui, à travers le rapportage ITIE | F34: Section 4.1.5.2 du Rapport ITIE 2022 (Mines) Section 4.2.4.2 du Rapport ITIE 2022 (Hydrocarbures)
B35: et les critères techniques et financiers utilisés ? | D35: Oui, à travers le rapportage ITIE | F35: Section 4.1.5.2 du Rapport ITIE 2022 (Mines) Section 4.2.4.2 du Rapport ITIE 2022 (Hydrocarbures) Section 4.2.4.5 du Rapport ITIE 2022 (Hydrocarbures)
B36: processus d’appel d’offres : | D36: Oui, à travers le rapportage ITIE | F36: Section 4.1.5.6 du Rapport ITIE 2022 (Mines) Section 4.2.4.6 du Rapport ITIE 2022 (Hydrocarbures)
B37: Nombre d’octrois et de transferts pour l’exercice couvert | D37: Oui, à travers le rapportage ITIE | F37: Section 4.1.5.5 du Rapport ITIE 2022 (Mines) Section 4.2.4.6 du Rapport ITIE 2022 (Hydrocarbures) | H37: Secteur minier : 17 octrois, Les renouvellements opérés en 2022 ne peuvent pas être consultés dans le registre des titres miniers communiqué par la DGM Dix (10) transferts ont été opéré en 2022 Secteur des hydrocarbures : Aucun nouvel octroi réalisé en 2022 1 seul renouvellement en 2022 Pas de transfert en 2022
B39: Exigence ITIE 2.3: Registre des licences
B40: Registres des licences pour le secteur minier | D40: Oui, divulgation systématique | F40: https://cadastreminiersenegal.sn/FR/
B41: Registre des licences pour le secteur pétrolier | D41: Oui, divulgation systématique | F41: https ://cadastrepetrolier.sec.gouv.sn/
B42: Registre des licences pour tout autre secteur - ajouter des lignes au besoin | D42: Sans objet.
B44: Exigence ITIE 2.4: Divulgation des contrats
B45: Politique sur la divulgation des contrats | D45: Oui, à travers le rapportage ITIE | F45: Section 4.7 du Rapport ITIE 2022
B46: Les contrats sont-ils divulgués ? | D46: Oui, divulgation systématique | F46: http://itie.sn/contrats-miniers/ http://itie.sn/hydrocarbure/contrats-petroliers/
B47: Registre des contrats pour le secteur minier | D47: Oui, divulgation systématique
B48: Registre des contrats pour le secteur pétrolier | D48: Oui, divulgation systématique
B49: Registre des contrats pour tout autre secteur - ajouter des ligne s’il y en a plusieurs | D49: Sans objet.
B51: Exigence ITIE 2.5: Propriété réelle
B52: Politique du gouvernement concernant la propriété réelle | D52: Oui, à travers le rapportage ITIE | F52: Section 4.6 du Rapport ITIE 2022
...

Sheet Partie 3 - Entités déclarantes
E3: Modèle de données résumées
E4: =Introduction!G4 -> 0
B8: Partie 3 (Entités déclarantes) Elle énumère les entités déclarantes (entités de l’État, entreprises et projets) et fournit des informations y afférentes.
B9: Comment remplir cette feuille :
B10: 1. Veuillez commencer par la première case (liste des entités déclarantes de l’État), en indiquant le nom de chacune d’elles
B11: 2. Remplissez la ligne des identifiants d’entreprise Des orientations vous seront données dans les cases jaunes lorsque la cellule est mise en évidence
B12: 3. Remplissez la liste des entreprises déclarantes, commençant par la première colonne, « Nom complet de l’entreprise » Remplissez en suivant les instructions, complétant chaque colonne sur chaque ligne avant de commencer la ligne suivante.
B13: 4. Remplissez la liste des Projets à déclarer, commençant par la première colonne, « Nom complet du projet »
B14: Si vous avez des questions, veuillez contacter data@eiti.org
B16: Partie 3 - Entités déclarantes
B17: Veuillez fournir une liste de toutes les entités déclarantes, accompagnée de l’information y afférente
B19: Liste des entités de l’État déclarantes
B20: Nom complet de l’entité | C20: Type d'Agence | D20: N° d’identifiant (le cas échéant) | E20: Total déclaré
B21: Direction Générale des Impôts et des Domaines | C21: Administration centrale | E21: 1.4444216e+11
B22: Direction Générale des Douanes | C22: Administration centrale | E22: 4.4632321e+10
B23: Direction Générale des Mines | C23: Administration centrale | E23: 43205899976
B24: Direction Générale de la Comptabilité Publique et du Trésor | C24: Administration centrale | E24: 20167182595
B25: Institution de Prévoyance Retraite du Sénégal | C25: Administration centrale | E25: 4872733599
B26: Société des Pétroles du Sénégal | C26: Société publique financière et Entreprise d'Etat | E26: 1.4660184e+09
B27: Caisse de Sécurité Sociale | C27: Administration centrale | E27: 8.7298828e+08
B28: Direction des Eaux, Forêts, Chasses et Conservation des Sols | C28: Administration centrale | E28: 5.3841661e+08
B29: Direction de l'Environnement et des Etablissements Classés | C29: Administration centrale | E29: 215142411
E30: =SUBTOTAL(109,Government_agencies[Total déclaré]) -> 2.6041286e+11
B32: Liste des entreprises déclarantes
B33: Identifiants d’entreprise
B34: Exemple : N° identification de contribuable | C34: The Brønnøysund Register Centre | D34: Si possible, indiquer le lien vers le registre ou l’entité
B36: Nom complet de l’entreprise | C36: Type d'entreprise | D36: Identifiant de l’entreprise | E36: Secteur | F36: Matières premières (séparation par virgule) | G36: Cotation boursière ou site Internet d’entreprise | H36: Rapport financier audité (si indisponible, bilan comptable ou flux de trésorerie…) | I36: Rapport de paiements à l’État | J36: Colonne1
B37: Sabodala Gold Operations (SGO) | C37: Privée | D37: 2850023 2G3 | E37: Minier | F37: Or | G37: https://www.endeavourmining.com/investors/institutional-ownership%20https://www.londonstockexchange.com/stock/EDV/endeavour-mining-plc/analysis | H37: Oui | I37: =SUMIF(Table10[Entreprise],Companies[[#This Row],[Nom complet de l’entreprise]],Table10[Valeur de revenus]) -> 79362301472
B38: Société de Commercialisation du Ciment (SOCOCIM) | C38: Privée | D38: 16627 | E38: Minier | F38: Calcaire/Marne | G38: http://www.sococim.com/SOCOCIM-INDUSTRIES | H38: Oui | I38: =SUMIF(Table10[Entreprise],Companies[[#This Row],[Nom complet de l’entreprise]],Table10[Valeur de revenus]) -> 49422883618
B39: Ciments du Sahel (CDS) | C39: Privée | D39: 0325995 2G3 | E39: Minier | F39: Calcaire/Argile/Latérite | H39: Oui | I39: =SUMIF(Table10[Entreprise],Companies[[#This Row],[Nom complet de l’entreprise]],Table10[Valeur de revenus]) -> 31680942223
B40: Grande Côte Opérations (GCO) | C40: Privée | D40: 2849258 2G3 | E40: Minier | F40: Minéraux lourds | G40: https://gco.eramet.com/ | H40: Oui | I40: =SUMIF(Table10[Entreprise],Companies[[#This Row],[Nom complet de l’entreprise]],Table10[Valeur de revenus]) -> 19192313250
B41: Petowal Mining Company (PMC) SA | C41: Privée | D41: 005844700 | E41: Minier | F41: Or/Argent | G41: https://www.rml.com.au/ | H41: Oui | I41: =SUMIF(Table10[Entreprise],Companies[[#This Row],[Nom complet de l’entreprise]],Table10[Valeur de revenus]) -> 18111307290
B42: Dangote Industries Sénégal SA (DANGOTE) | C42: Privée | D42: 2707208 2G3 | E42: Minier | F42: Argile, Calcaire, Latérite | G42: https://www.dangotecement.com/operations/senegal/ | H42: Oui | I42: =SUMIF(Table10[Entreprise],Companies[[#This Row],[Nom complet de l’entreprise]],Table10[Valeur de revenus]) -> 15636352228
B43: Woodside Energy Senegal | C43: Privée | D43: 005014204 2G0 | E43: Pétrole & Gaz | F43: Gaz | G43: https://www.woodside.com.au/fr/what-we-do/international-exploration-developments-and-marketing/s%c3%a9n%c3%a9gal | H43: Oui | I43: =SUMIF(Table10[Entreprise],Companies[[#This Row],[Nom complet de l’entreprise]],Table10[Valeur de revenus]) -> 1.3300041e+10
B44: BP Sénégal Investments Limited | C44: Privée | D44: 006420509 | E44: Pétrole & Gaz | F44: Gaz | G44: https://www.bp.com/ | H44: Oui | I44: =SUMIF(Table10[Entreprise],Companies[[#This Row],[Nom complet de l’entreprise]],Table10[Valeur de revenus]) -> 8882740419
B45: Industries Chimiques du Sénégal (ICS) | C45: Privée | D45: 0022955 2G3 | E45: Minier | F45: Phosphates | G45: http://www.ics.sn/ | H45: Oui | I45: =SUMIF(Table10[Entreprise],Companies[[#This Row],[Nom complet de l’entreprise]],Table10[Valeur de revenus]) -> 6382723361
B46: Compagnie Générale d'Exploitation de Carrière (COGECA) | C46: Privée | D46: 0196784 | E46: Minier | F46: Basalte/calcaire | H46: Oui | I46: =SUMIF(Table10[Entreprise],Companies[[#This Row],[Nom complet de l’entreprise]],Table10[Valeur de revenus]) -> 3845633020
B47: Gécamines (GECAMINES) | C47: Privée | D47: 2292168 2G3 | E47: Minier | F47: Basalte | G47: https://www.gecamines.cd/ | H47: Oui | I47: =SUMIF(Table10[Entreprise],Companies[[#This Row],[Nom complet de l’entreprise]],Table10[Valeur de revenus]) -> 3544861329
B48: Société Minière de la Vallée du fleuve Sénégal (SOMIVA) | C48: Privée | D48: 4475142 2G3 | E48: Minier | F48: Phosphates | H48: Non | I48: =SUMIF(Table10[Entreprise],Companies[[#This Row],[Nom complet de l’entreprise]],Table10[Valeur de revenus]) -> 1872119684
B49: Société des Pétroles du Sénégal (PETROSEN) | C49: Société publique financière et Entreprise d'Etat | D49: 0224498 2G3 | E49: Pétrole & Gaz | F49: Gaz | G49: http://www.petrosen.sn/ | H49: Oui | I49: =SUMIF(Table10[Entreprise],Companies[[#This Row],[Nom complet de l’entreprise]],Table10[Valeur de revenus]) -> 942684751
...

Sheet Partie 4 - Recettes de l’État
N3: Modèle de données résumées
N4: =Introduction!G4 -> 0
F8: Partie 4 (Recettes de l’État) Elle contient des données exhaustives sur les revenus de l’État par flux de revenu, en utilisant la classification SFP.
F9: Comment remplir cette feuille :
F10: 1. Inscrivez le nom de tous les flux de revenus de l’État pour le secteur extractif, y compris les flux inférieurs aux seuils de matérialité convenus (utiliser une ligne pour chaque flux de revenus et pour chaque entité de l’État)
F11: 2. Inscrivez le nom de l’entité de l’État percevant les revenus (sélectionnez celle-ci sur la liste déroulante) Elle y figurera parce que vous aurez déjà inscrit l’entité de l’État à la Partie 3).
F12: 3. Choisissez le Secteur et la Classification SFP auxquels ce flux de revenus s’applique. Consultez les orientations fournies dans le Cadre SFP pour le rapportage ITIE. Si un flux de revenus ne peut être désagrégé par secteur, sélectionnez « Autre ».
F13: 4. Dans la colonne Valeur des revenus inscrivez le chiffre total de chaque flux de revenus tel que divulgué par le gouvernement, qui inclut également les revenus qui n’ont pas été rapprochés.
F14: Nota : Les paiements versés par les entreprises aux gouvernements au nom de leurs employés doivent être exclus (par exemple, l’impôt sur le revenu des particuliers / impôts retenus à la source, cotisations des employés pour la sécurité sociale) car ils ne sont pas considérés comme étant des paiements par des entreprises au gouvernement.
F15: 5. Si des paiements sont recensés dans le Rapport ITIE mais ne correspondent pas aux catégories SFP, veuillez les lister dans la case ci-dessous dénommée « Informations supplémentaires ».
F16: Si vous avez des questions, veuillez contacter data@eiti.org
F18: Total des recettes de l’État provenant du secteur extractif (utilisant la classification SFP) | M18: Cadre SFP pour le rapportage ITIE
M19: Exigence ITIE 5.1.b: Classification des revenus
F20: Exigence ITIE 4.1.d: Divulgation exhaustive de la part du gouvernement
B21: GFS Niveau 1 | C21: GFS Niveau 2 | D21: GFS Niveau 3 | E21: GFS Niveau 4 | F21: Classification SFP | G21: Secteur | H21: Nom du flux de revenus | I21: Entité de l’État | J21: Valeur des revenus | K21: Devise | M21: En quoi consiste le SFP ?
B22: =IFERROR(VLOOKUP(Government_revenues_table[[#This Row],[Classification SFP]],Table6_GFS_codes_classification[],COLUMNS($F:F)+3,FALSE),"Do not enter data") -> Autre revenu (14E) | C22: =IFERROR(VLOOKUP(Government_revenues_table[[#This Row],[Classification SFP]],Table6_GFS_codes_classification[],COLUMNS($F:G)+3,FALSE),"Do not enter data") -> Revenu dégagé de la propriété (141E) | D22: =IFERROR(VLOOKUP(Government_revenues_table[[#This Row],[Classification SFP]],Table6_GFS_codes_classification[],COLUMNS($F:H)+3,FALSE),"Do not enter data") -> Loyers (1415E) | E22: =IFERROR(VLOOKUP(Government_revenues_table[[#This Row],[Classification SFP]],Table6_GFS_codes_classification[],COLUMNS($F:I)+3,FALSE),"Do not enter data") -> Redevances (1415E1) | F22: Redevances (1415E1) | G22: Minier | H22: Redevance minière | I22: Direction Générale des Mines | J22: 42108704590 | K22: XOF | M22: SFP, sigle pour «Statistiques de Finances Publiques », est un cadre international pour la classification des flux de revenus afin de les rendre comparables d’un pays et d’une période à l’autre. Voir l’exemple de cadre complet ci-dessous. Le cadre utilisé ci-dessous a été élaboré par le FMI et le Secrétariat international de l’ITIE. Les chiffres à droite ont été spécifiquement conçus pour les entreprises du secteur extractif La lettre E dans la colonne des codes SFP signifie que ce sont les codes utilisés pour les revenus issus des entreprises extractives. Les chiffres situés à gauche de la lettre E sont les codes SFP réguliers.
B23: =IFERROR(VLOOKUP(Government_revenues_table[[#This Row],[Classification SFP]],Table6_GFS_codes_classification[],COLUMNS($F:F)+3,FALSE),"Do not enter data") -> Impôts (11E) | C23: =IFERROR(VLOOKUP(Government_revenues_table[[#This Row],[Classification SFP]],Table6_GFS_codes_classification[],COLUMNS($F:G)+3,FALSE),"Do not enter data") -> Impôts sur les biens et services (114E) | D23: =IFERROR(VLOOKUP(Government_revenues_table[[#This Row],[Classification SFP]],Table6_GFS_codes_classification[],COLUMNS($F:H)+3,FALSE),"Do not enter data") -> Impôts généraux sur les biens et services (TVA, taxes sur les ventes, taxes sur le chiffre d’affaires (1141E) | E23: =IFERROR(VLOOKUP(Government_revenues_table[[#This Row],[Classification SFP]],Table6_GFS_codes_classification[],COLUMNS($F:I)+3,FALSE),"Do not enter data") -> Impôts généraux sur les biens et services (TVA, taxes sur les ventes, taxes sur le chiffre d’affaires (1141E) | F23: Impôts généraux sur les biens et services (TVA, taxes sur les ventes, taxes sur le chiffre d’affaires)(1141E) | G23: Minier | H23: Taxe sur la valeur ajoutée reversée | I23: Direction Générale des Impôts et des Domaines | J23: 32526122862 | K23: XOF
B24: =IFERROR(VLOOKUP(Government_revenues_table[[#This Row],[Classification SFP]],Table6_GFS_codes_classification[],COLUMNS($F:F)+3,FALSE),"Do not enter data") -> Impôts (11E) | C24: =IFERROR(VLOOKUP(Government_revenues_table[[#This Row],[Classification SFP]],Table6_GFS_codes_classification[],COLUMNS($F:G)+3,FALSE),"Do not enter data") -> Impôts sur la masse salariale et la force de travail (112E) | D24: =IFERROR(VLOOKUP(Government_revenues_table[[#This Row],[Classification SFP]],Table6_GFS_codes_classification[],COLUMNS($F:H)+3,FALSE),"Do not enter data") -> Impôts sur la masse salariale et la force de travail (112E) | E24: =IFERROR(VLOOKUP(Government_revenues_table[[#This Row],[Classification SFP]],Table6_GFS_codes_classification[],COLUMNS($F:I)+3,FALSE),"Do not enter data") -> Impôts sur la masse salariale et la force de travail (112E) | F24: Impôts sur la masse salariale et la force de travail (112E) | G24: Minier | H24: Retenues à la source sur salaires (IR, TRIMF et CFCE) | I24: Direction Générale des Impôts et des Domaines | J24: 25990968213 | K24: XOF
B25: =IFERROR(VLOOKUP(Government_revenues_table[[#This Row],[Classification SFP]],Table6_GFS_codes_classification[],COLUMNS($F:F)+3,FALSE),"Do not enter data") -> Impôts (11E) | C25: =IFERROR(VLOOKUP(Government_revenues_table[[#This Row],[Classification SFP]],Table6_GFS_codes_classification[],COLUMNS($F:G)+3,FALSE),"Do not enter data") -> Taxes sur le commerce et les transactions au niveau international (115E) | D25: =IFERROR(VLOOKUP(Government_revenues_table[[#This Row],[Classification SFP]],Table6_GFS_codes_classification[],COLUMNS($F:H)+3,FALSE),"Do not enter data") -> Droits de douane et autres droits d’importation (1151E) | E25: =IFERROR(VLOOKUP(Government_revenues_table[[#This Row],[Classification SFP]],Table6_GFS_codes_classification[],COLUMNS($F:I)+3,FALSE),"Do not enter data") -> Droits de douane et autres droits d’importation (1151E) | F25: Droits de douane et autres droits d’importation (1151E) | G25: Minier | H25: Taxe sur la valeur ajoutée | I25: Direction Générale des Douanes | J25: 23377806013 | K25: XOF
B26: =IFERROR(VLOOKUP(Government_revenues_table[[#This Row],[Classification SFP]],Table6_GFS_codes_classification[],COLUMNS($F:F)+3,FALSE),"Do not enter data") -> Impôts (11E) | C26: =IFERROR(VLOOKUP(Government_revenues_table[[#This Row],[Classification SFP]],Table6_GFS_codes_classification[],COLUMNS($F:G)+3,FALSE),"Do not enter data") -> Impôts sur le revenu, le bénéfice et les plus-values | D26: =IFERROR(VLOOKUP(Government_revenues_table[[#This Row],[Classification SFP]],Table6_GFS_codes_classification[],COLUMNS($F:H)+3,FALSE),"Do not enter data") -> Impôts ordinaires sur le revenu, le bénéfice et les plus-values (1112E1) | E26: =IFERROR(VLOOKUP(Government_revenues_table[[#This Row],[Classification SFP]],Table6_GFS_codes_classification[],COLUMNS($F:I)+3,FALSE),"Do not enter data") -> Impôts ordinaires sur le revenu, le bénéfice et les plus-values (1112E1) | F26: Impôts ordinaires sur le revenu, le bénéfice et les plus-values (1112E1) | G26: Minier | H26: Impôt sur le revenu des valeurs mobilières | I26: Direction Générale des Impôts et des Domaines | J26: 22522304771 | K26: XOF
B27: =IFERROR(VLOOKUP(Government_revenues_table[[#This Row],[Classification SFP]],Table6_GFS_codes_classification[],COLUMNS($F:F)+3,FALSE),"Do not enter data") -> Autre revenu (14E) | C27: =IFERROR(VLOOKUP(Government_revenues_table[[#This Row],[Classification SFP]],Table6_GFS_codes_classification[],COLUMNS($F:G)+3,FALSE),"Do not enter data") -> Revenu dégagé de la propriété (141E) | D27: =IFERROR(VLOOKUP(Government_revenues_table[[#This Row],[Classification SFP]],Table6_GFS_codes_classification[],COLUMNS($F:H)+3,FALSE),"Do not enter data") -> Dividendes (1412E) | E27: =IFERROR(VLOOKUP(Government_revenues_table[[#This Row],[Classification SFP]],Table6_GFS_codes_classification[],COLUMNS($F:I)+3,FALSE),"Do not enter data") -> Provenant de la participation de l’État (1412E2) | F27: Provenant de la participation de l’État (1412E2) | G27: Minier | H27: Dividendes versés à l'Etat | I27: Direction Générale de la Comptabilité Publique et du Trésor | J27: 16599906089 | K27: XOF | M27: Pour plus d’orientations, visitez la page https://eiti.org/fr/document/modele-donnees-resumees-itie
B28: =IFERROR(VLOOKUP(Government_revenues_table[[#This Row],[Classification SFP]],Table6_GFS_codes_classification[],COLUMNS($F:F)+3,FALSE),"Do not enter data") -> Impôts (11E) | C28: =IFERROR(VLOOKUP(Government_revenues_table[[#This Row],[Classification SFP]],Table6_GFS_codes_classification[],COLUMNS($F:G)+3,FALSE),"Do not enter data") -> Impôts sur les biens et services (114E) | D28: =IFERROR(VLOOKUP(Government_revenues_table[[#This Row],[Classification SFP]],Table6_GFS_codes_classification[],COLUMNS($F:H)+3,FALSE),"Do not enter data") -> Impôts généraux sur les biens et services (TVA, taxes sur les ventes, taxes sur le chiffre d’affaires (1141E) | E28: =IFERROR(VLOOKUP(Government_revenues_table[[#This Row],[Classification SFP]],Table6_GFS_codes_classification[],COLUMNS($F:I)+3,FALSE),"Do not enter data") -> Impôts généraux sur les biens et services (TVA, taxes sur les ventes, taxes sur le chiffre d’affaires (1141E) | F28: Impôts généraux sur les biens et services (TVA, taxes sur les ventes, taxes sur le chiffre d’affaires)(1141E) | G28: Minier | H28: Taxe spéciale sur le ciment | I28: Direction Générale des Impôts et des Domaines | J28: 15433880734 | K28: XOF | M28: ou https://www.imf.org/external/pubs/ft/gfs/manual/pdf/2014companion/FrenchGFSM.pdf
B29: =IFERROR(VLOOKUP(Government_revenues_table[[#This Row],[Classification SFP]],Table6_GFS_codes_classification[],COLUMNS($F:F)+3,FALSE),"Do not enter data") -> Impôts (11E) | C29: =IFERROR(VLOOKUP(Government_revenues_table[[#This Row],[Classification SFP]],Table6_GFS_codes_classification[],COLUMNS($F:G)+3,FALSE),"Do not enter data") -> Impôts sur le revenu, le bénéfice et les plus-values | D29: =IFERROR(VLOOKUP(Government_revenues_table[[#This Row],[Classification SFP]],Table6_GFS_codes_classification[],COLUMNS($F:H)+3,FALSE),"Do not enter data") -> Impôts ordinaires sur le revenu, le bénéfice et les plus-values (1112E1) | E29: =IFERROR(VLOOKUP(Government_revenues_table[[#This Row],[Classification SFP]],Table6_GFS_codes_classification[],COLUMNS($F:I)+3,FALSE),"Do not enter data") -> Impôts ordinaires sur le revenu, le bénéfice et les plus-values (1112E1) | F29: Impôts ordinaires sur le revenu, le bénéfice et les plus-values (1112E1) | G29: Minier | H29: Impôt sur les sociétés | I29: Direction Générale des Impôts et des Domaines | J29: 13447825420 | K29: XOF
B30: =IFERROR(VLOOKUP(Government_revenues_table[[#This Row],[Classification SFP]],Table6_GFS_codes_classification[],COLUMNS($F:F)+3,FALSE),"Do not enter data") -> Impôts (11E) | C30: =IFERROR(VLOOKUP(Government_revenues_table[[#This Row],[Classification SFP]],Table6_GFS_codes_classification[],COLUMNS($F:G)+3,FALSE),"Do not enter data") -> Impôts sur les biens et services (114E) | D30: =IFERROR(VLOOKUP(Government_revenues_table[[#This Row],[Classification SFP]],Table6_GFS_codes_classification[],COLUMNS($F:H)+3,FALSE),"Do not enter data") -> Impôts généraux sur les biens et services (TVA, taxes sur les ventes, taxes sur le chiffre d’affaires (1141E) | E30: =IFERROR(VLOOKUP(Government_revenues_table[[#This Row],[Classification SFP]],Table6_GFS_codes_classification[],COLUMNS($F:I)+3,FALSE),"Do not enter data") -> Impôts généraux sur les biens et services (TVA, taxes sur les ventes, taxes sur le chiffre d’affaires (1141E) | F30: Impôts généraux sur les biens et services (TVA, taxes sur les ventes, taxes sur le chiffre d’affaires)(1141E) | G30: Minier | H30: Taxe sur le ciment | I30: Direction Générale des Impôts et des Domaines | J30: 10289539042 | K30: XOF
B31: =IFERROR(VLOOKUP(Government_revenues_table[[#This Row],[Classification SFP]],Table6_GFS_codes_classification[],COLUMNS($F:F)+3,FALSE),"Do not enter data") -> Impôts (11E) | C31: =IFERROR(VLOOKUP(Government_revenues_table[[#This Row],[Classification SFP]],Table6_GFS_codes_classification[],COLUMNS($F:G)+3,FALSE),"Do not enter data") -> Taxes sur le commerce et les transactions au niveau international (115E) | D31: =IFERROR(VLOOKUP(Government_revenues_table[[#This Row],[Classification SFP]],Table6_GFS_codes_classification[],COLUMNS($F:H)+3,FALSE),"Do not enter data") -> Droits de douane et autres droits d’importation (1151E) | E31: =IFERROR(VLOOKUP(Government_revenues_table[[#This Row],[Classification SFP]],Table6_GFS_codes_classification[],COLUMNS($F:I)+3,FALSE),"Do not enter data") -> Droits de douane et autres droits d’importation (1151E) | F31: Droits de douane et autres droits d’importation (1151E) | G31: Minier | H31: Droits de douane | I31: Direction Générale des Douanes | J31: 9617818617 | K31: XOF
B32: =IFERROR(VLOOKUP(Government_revenues_table[[#This Row],[Classification SFP]],Table6_GFS_codes_classification[],COLUMNS($F:F)+3,FALSE),"Do not enter data") -> Impôts (11E) | C32: =IFERROR(VLOOKUP(Government_revenues_table[[#This Row],[Classification SFP]],Table6_GFS_codes_classification[],COLUMNS($F:G)+3,FALSE),"Do not enter data") -> Impôts sur la masse salariale et la force de travail (112E) | D32: =IFERROR(VLOOKUP(Government_revenues_table[[#This Row],[Classification SFP]],Table6_GFS_codes_classification[],COLUMNS($F:H)+3,FALSE),"Do not enter data") -> Impôts sur la masse salariale et la force de travail (112E) | E32: =IFERROR(VLOOKUP(Government_revenues_table[[#This Row],[Classification SFP]],Table6_GFS_codes_classification[],COLUMNS($F:I)+3,FALSE),"Do not enter data") -> Impôts sur la masse salariale et la force de travail (112E) | F32: Impôts sur la masse salariale et la force de travail (112E) | G32: Pétrole & Gaz | H32: Retenues à la source sur salaires (IR, TRIMF et CFCE) | I32: Direction Générale des Impôts et des Domaines | J32: 6582588951 | K32: XOF
B33: =IFERROR(VLOOKUP(Government_revenues_table[[#This Row],[Classification SFP]],Table6_GFS_codes_classification[],COLUMNS($F:F)+3,FALSE),"Do not enter data") -> Impôts (11E) | C33: =IFERROR(VLOOKUP(Government_revenues_table[[#This Row],[Classification SFP]],Table6_GFS_codes_classification[],COLUMNS($F:G)+3,FALSE),"Do not enter data") -> Impôts sur le revenu, le bénéfice et les plus-values | D33: =IFERROR(VLOOKUP(Government_revenues_table[[#This Row],[Classification SFP]],Table6_GFS_codes_classification[],COLUMNS($F:H)+3,FALSE),"Do not enter data") -> Impôts ordinaires sur le revenu, le bénéfice et les plus-values (1112E1) | E33: =IFERROR(VLOOKUP(Government_revenues_table[[#This Row],[Classification SFP]],Table6_GFS_codes_classification[],COLUMNS($F:I)+3,FALSE),"Do not enter data") -> Impôts ordinaires sur le revenu, le bénéfice et les plus-values (1112E1) | F33: Impôts ordinaires sur le revenu, le bénéfice et les plus-values (1112E1) | G33: Pétrole & Gaz | H33: Retenues à la source sur bénéfice non commercial | I33: Direction Générale des Impôts et des Domaines | J33: 5520710688 | K33: XOF
B34: =IFERROR(VLOOKUP(Government_revenues_table[[#This Row],[Classification SFP]],Table6_GFS_codes_classification[],COLUMNS($F:F)+3,FALSE),"Do not enter data") -> Impôts (11E) | C34: =IFERROR(VLOOKUP(Government_revenues_table[[#This Row],[Classification SFP]],Table6_GFS_codes_classification[],COLUMNS($F:G)+3,FALSE),"Do not enter data") -> Impôts sur le revenu, le bénéfice et les plus-values | D34: =IFERROR(VLOOKUP(Government_revenues_table[[#This Row],[Classification SFP]],Table6_GFS_codes_classification[],COLUMNS($F:H)+3,FALSE),"Do not enter data") -> Impôts ordinaires sur le revenu, le bénéfice et les plus-values (1112E1) | E34: =IFERROR(VLOOKUP(Government_revenues_table[[#This Row],[Classification SFP]],Table6_GFS_codes_classification[],COLUMNS($F:I)+3,FALSE),"Do not enter data") -> Impôts ordinaires sur le revenu, le bénéfice et les plus-values (1112E1) | F34: Impôts ordinaires sur le revenu, le bénéfice et les plus-values (1112E1) | G34: Pétrole & Gaz | H34: Retenue à la source sur sommes versées à des tiers | I34: Direction Générale des Impôts et des Domaines | J34: 5030892002 | K34: XOF
B35: =IFERROR(VLOOKUP(Government_revenues_table[[#This Row],[Classification SFP]],Table6_GFS_codes_classification[],COLUMNS($F:F)+3,FALSE),"Do not enter data") -> Cotisations sociales (12E) | C35: =IFERROR(VLOOKUP(Government_revenues_table[[#This Row],[Classification SFP]],Table6_GFS_codes_classification[],COLUMNS($F:G)+3,FALSE),"Do not enter data") -> Cotisations patronales à la sécurité sociale (1212E) | D35: =IFERROR(VLOOKUP(Government_revenues_table[[#This Row],[Classification SFP]],Table6_GFS_codes_classification[],COLUMNS($F:H)+3,FALSE),"Do not enter data") -> Cotisations patronales à la sécurité sociale (1212E) | E35: =IFERROR(VLOOKUP(Government_revenues_table[[#This Row],[Classification SFP]],Table6_GFS_codes_classification[],COLUMNS($F:I)+3,FALSE),"Do not enter data") -> Cotisations patronales à la sécurité sociale (1212E) | F35: Cotisations patronales à la sécurité sociale (1212E) | G35: Minier | H35: Cotisations sociales (y compris les pénalités)(IPRES) | I35: Institution de Prévoyance Retraite du Sénégal | J35: 4607220095 | K35: XOF
B36: =IFERROR(VLOOKUP(Government_revenues_table[[#This Row],[Classification SFP]],Table6_GFS_codes_classification[],COLUMNS($F:F)+3,FALSE),"Do not enter data") -> Impôts (11E) | C36: =IFERROR(VLOOKUP(Government_revenues_table[[#This Row],[Classification SFP]],Table6_GFS_codes_classification[],COLUMNS($F:G)+3,FALSE),"Do not enter data") -> Impôts sur le revenu, le bénéfice et les plus-values | D36: =IFERROR(VLOOKUP(Government_revenues_table[[#This Row],[Classification SFP]],Table6_GFS_codes_classification[],COLUMNS($F:H)+3,FALSE),"Do not enter data") -> Impôts ordinaires sur le revenu, le bénéfice et les plus-values (1112E1) | E36: =IFERROR(VLOOKUP(Government_revenues_table[[#This Row],[Classification SFP]],Table6_GFS_codes_classification[],COLUMNS($F:I)+3,FALSE),"Do not enter data") -> Impôts ordinaires sur le revenu, le bénéfice et les plus-values (1112E1) | F36: Impôts ordinaires sur le revenu, le bénéfice et les plus-values (1112E1) | G36: Minier | H36: Retenues à la source sur bénéfice non commercial | I36: Direction Générale des Impôts et des Domaines | J36: 3563953859 | K36: XOF
B37: =IFERROR(VLOOKUP(Government_revenues_table[[#This Row],[Classification SFP]],Table6_GFS_codes_classification[],COLUMNS($F:F)+3,FALSE),"Do not enter data") -> Impôts (11E) | C37: =IFERROR(VLOOKUP(Government_revenues_table[[#This Row],[Classification SFP]],Table6_GFS_codes_classification[],COLUMNS($F:G)+3,FALSE),"Do not enter data") -> Taxes sur le commerce et les transactions au niveau international (115E) | D37: =IFERROR(VLOOKUP(Government_revenues_table[[#This Row],[Classification SFP]],Table6_GFS_codes_classification[],COLUMNS($F:H)+3,FALSE),"Do not enter data") -> Droits de douane et autres droits d’importation (1151E) | E37: =IFERROR(VLOOKUP(Government_revenues_table[[#This Row],[Classification SFP]],Table6_GFS_codes_classification[],COLUMNS($F:I)+3,FALSE),"Do not enter data") -> Droits de douane et autres droits d’importation (1151E) | F37: Droits de douane et autres droits d’importation (1151E) | G37: Pétrole & Gaz | H37: Redevance statistique UEMOA | I37: Direction Générale des Douanes | J37: 2224611231 | K37: XOF
B38: =IFERROR(VLOOKUP(Government_revenues_table[[#This Row],[Classification SFP]],Table6_GFS_codes_classification[],COLUMNS($F:F)+3,FALSE),"Do not enter data") -> Impôts (11E) | C38: =IFERROR(VLOOKUP(Government_revenues_table[[#This Row],[Classification SFP]],Table6_GFS_codes_classification[],COLUMNS($F:G)+3,FALSE),"Do not enter data") -> Taxes sur le commerce et les transactions au niveau international (115E) | D38: =IFERROR(VLOOKUP(Government_revenues_table[[#This Row],[Classification SFP]],Table6_GFS_codes_classification[],COLUMNS($F:H)+3,FALSE),"Do not enter data") -> Droits de douane et autres droits d’importation (1151E) | E38: =IFERROR(VLOOKUP(Government_revenues_table[[#This Row],[Classification SFP]],Table6_GFS_codes_classification[],COLUMNS($F:I)+3,FALSE),"Do not enter data") -> Droits de douane et autres droits d’importation (1151E) | F38: Droits de douane et autres droits d’importation (1151E) | G38: Minier | H38: Redevance statistique UEMOA | I38: Direction Générale des Douanes | J38: 1786007941 | K38: XOF
B39: =IFERROR(VLOOKUP(Government_revenues_table[[#This Row],[Classification SFP]],Table6_GFS_codes_classification[],COLUMNS($F:F)+3,FALSE),"Do not enter data") -> Impôts (11E) | C39: =IFERROR(VLOOKUP(Government_revenues_table[[#This Row],[Classification SFP]],Table6_GFS_codes_classification[],COLUMNS($F:G)+3,FALSE),"Do not enter data") -> Taxes sur le commerce et les transactions au niveau international (115E) | D39: =IFERROR(VLOOKUP(Government_revenues_table[[#This Row],[Classification SFP]],Table6_GFS_codes_classification[],COLUMNS($F:H)+3,FALSE),"Do not enter data") -> Droits de douane et autres droits d’importation (1151E) | E39: =IFERROR(VLOOKUP(Government_revenues_table[[#This Row],[Classification SFP]],Table6_GFS_codes_classification[],COLUMNS($F:I)+3,FALSE),"Do not enter data") -> Droits de douane et autres droits d’importation (1151E) | F39: Droits de douane et autres droits d’importation (1151E) | G39: Pétrole & Gaz | H39: Prélèvement communautaire solidaire UEMOA | I39: Direction Générale des Douanes | J39: 1779688959 | K39: XOF
B40: =IFERROR(VLOOKUP(Government_revenues_table[[#This Row],[Classification SFP]],Table6_GFS_codes_classification[],COLUMNS($F:F)+3,FALSE),"Do not enter data") -> Impôts (11E) | C40: =IFERROR(VLOOKUP(Government_revenues_table[[#This Row],[Classification SFP]],Table6_GFS_codes_classification[],COLUMNS($F:G)+3,FALSE),"Do not enter data") -> Impôts sur le revenu, le bénéfice et les plus-values | D40: =IFERROR(VLOOKUP(Government_revenues_table[[#This Row],[Classification SFP]],Table6_GFS_codes_classification[],COLUMNS($F:H)+3,FALSE),"Do not enter data") -> Impôts ordinaires sur le revenu, le bénéfice et les plus-values (1112E1) | E40: =IFERROR(VLOOKUP(Government_revenues_table[[#This Row],[Classification SFP]],Table6_GFS_codes_classification[],COLUMNS($F:I)+3,FALSE),"Do not enter data") -> Impôts ordinaires sur le revenu, le bénéfice et les plus-values (1112E1) | F40: Impôts ordinaires sur le revenu, le bénéfice et les plus-values (1112E1) | G40: Minier | H40: Contribution économique locale (CEL VA et CEL VL) | I40: Direction Générale de la Comptabilité Publique et du Trésor | J40: 1770577202 | K40: XOF
... B46: =IFERROR(VLOOKUP(Government_revenues_table[[#This Row],[Classification SFP]],Table6_GFS_codes_classification[],COLUMNS($F:F)+3,FALSE),"Do not enter data") -> Cotisations sociales (12E) | C46: =IFERROR(VLOOKUP(Government_revenues_table[[#This Row],[Classification SFP]],Table6_GFS_codes_classification[],COLUMNS($F:G)+3,FALSE),"Do not enter data") -> Cotisations patronales à la sécurité sociale (1212E) | D46: =IFERROR(VLOOKUP(Government_revenues_table[[#This Row],[Classification SFP]],Table6_GFS_codes_classification[],COLUMNS($F:H)+3,FALSE),"Do not enter data") -> Cotisations patronales à la sécurité sociale (1212E) | E46: =IFERROR(VLOOKUP(Government_revenues_table[[#This Row],[Classification SFP]],Table6_GFS_codes_classification[],COLUMNS($F:I)+3,FALSE),"Do not enter data") -> Cotisations patronales à la sécurité sociale (1212E) | F46: Cotisations patronales à la sécurité sociale (1212E) | G46: Minier | H46: Cotisations sociales (y compris les pénalités) | I46: Caisse de Sécurité Sociale | J46: 856016492 | K46: XOF
F47: Autres paiements de loyer (1415E5) | G47: Pétrole & Gaz | H47: Loyer superficiaire | I47: Société des Pétroles du Sénégal | J47: 8.4118323e+08 | K47: XOF
F48: Impôts ordinaires sur le revenu, le bénéfice et les plus-values (1112E1) | G48: Minier | H48: Patente | I48: Direction Générale de la Comptabilité Publique et du Trésor | J48: 700210162 | K48: XOF
F49: Autres impôts payés par les entreprises exploitant des ressources naturelles (116E) | G49: Minier | H49: Appui institutionnel | I49: Direction Générale des Mines | J49: 597564136 | K49: XOF
F50: Impôts généraux sur les biens et services (TVA, taxes sur les ventes, taxes sur le chiffre d’affaires)(1141E) | G50: Pétrole & Gaz | H50: Taxe sur la valeur ajoutée reversée | I50: Direction Générale des Impôts et des Domaines | J50: 495067538 | K50: XOF
F51: Autres impôts payés par les entreprises exploitant des ressources naturelles (116E) | G51: Minier | H51: Appui Institutionnel (Fonds d'appui au Mini. De l'Env) | I51: Direction des Eaux, Forêts, Chasses et Conservation des Sols | J51: 488520113 | K51: XOF
...

Sheet Partie 5 - Données d’entreprise
C2: Partie 5 (Données d’entreprise) Elle contient des données venant des entreprises - et du niveau projet - par flux de revenus. Les entreprises et projets sont indiqués sur le menu déroulant car ils ont été saisis sur la feuille 3.
C3: Comment remplir cette feuille :
C4: 1. Sélectionnez le nom de l’entreprise sur le menu déroulant
C5: 2. Sélectionnez l’entité collectrice de l’État et le nom du paiement sur le menu déroulant
C6: 3. Indiquez si le flux de paiements est (i) perçu par projet et (ii) déclaré par projet
C7: 4. Inscrivez l’information de projet : nom du projet et devise de déclaration
C8: 5. Inscrivez la valeur des revenus telle que divulguée par le gouvernement et ajoutez tout commentaire pertinent.
C9: Si vous avez des questions, veuillez contacter data@eiti.org
C11: Recettes de l’État par entreprise et projet
C13: Exigence ITIE 4.1.c: Paiements des entreprises ; Exigence ITIE 4.7: Déclaration par projet
B14: Secteur | C14: Entreprise | D14: Entité de l’État | E14: Nom du paiement | F14: Perçu par projet (O/N) | G14: Déclaré par projet (O/N) | H14: Nom du projet | I14: Devise de déclaration | J14: Valeur de revenus | K14: Paiement effectué en nature? | L14: Volume en nature (si applicable) | M14: Unité (si applicable) | N14: Commentaires
B15: =VLOOKUP(C15,Companies[],3,FALSE) -> 4507995 2G3 | C15: African Investment Group SA (AIG) | D15: Direction Générale des Mines | E15: Redevance minière | F15: Oui | G15: Oui | H15: NC | I15: XOF | J15: 64914144
B16: =VLOOKUP(C16,Companies[],3,FALSE) -> 4507995 2G3 | C16: African Investment Group SA (AIG) | D16: Direction Générale des Mines | E16: Redevance superficiaire | F16: Oui | G16: Oui | H16: NC | I16: XOF | J16: 5654400
B17: =VLOOKUP(C17,Companies[],3,FALSE) -> 4507995 2G3 | C17: African Investment Group SA (AIG) | D17: Institution de Prévoyance Retraite du Sénégal | E17: Cotisations sociales (y compris les pénalités)(IPRES) | F17: Non | G17: Non | H17: NC | I17: XOF | J17: 500000
B18: =VLOOKUP(C18,Companies[],3,FALSE) -> 4151750 2Y2 | C18: Agem Sénégal Exploration SUARL (AGEM) | D18: Direction Générale des Impôts et des Domaines | E18: Retenues à la source sur salaires (IR, TRIMF et CFCE) | F18: Non | G18: Non | H18: NOUMOUFOUKHA | I18: XOF | J18: 379247187
B19: =VLOOKUP(C19,Companies[],3,FALSE) -> 4151750 2Y2 | C19: Agem Sénégal Exploration SUARL (AGEM) | D19: Institution de Prévoyance Retraite du Sénégal | E19: Cotisations sociales (y compris les pénalités)(IPRES) | F19: Non | G19: Non | H19: NOUMOUFOUKHA | I19: XOF | J19: 35032337
B20: =VLOOKUP(C20,Companies[],3,FALSE) -> 4151750 2Y2 | C20: Agem Sénégal Exploration SUARL (AGEM) | D20: Direction Générale des Mines | E20: Appui institutionnel | F20: Oui | G20: Oui | H20: DAORALA | I20: XOF | J20: 17500157
B21: =VLOOKUP(C21,Companies[],3,FALSE) -> 4151750 2Y2 | C21: Agem Sénégal Exploration SUARL (AGEM) | D21: Direction Générale des Mines | E21: Appui institutionnel | F21: Oui | G21: Oui | H21: NOUMOUFOUKHA | I21: XOF | J21: 17500157
B22: =VLOOKUP(C22,Companies[],3,FALSE) -> 4151750 2Y2 | C22: Agem Sénégal Exploration SUARL (AGEM) | D22: Direction Générale des Mines | E22: Appui institutionnel | F22: Oui | G22: Oui | H22: SENALA | I22: XOF | J22: 17500157
B23: =VLOOKUP(C23,Companies[],3,FALSE) -> 4151750 2Y2 | C23: Agem Sénégal Exploration SUARL (AGEM) | D23: Caisse de Sécurité Sociale | E23: Cotisations sociales (y compris les pénalités) | F23: Non | G23: Non | H23: NOUMOUFOUKHA | I23: XOF | J23: 7499995
B24: =VLOOKUP(C24,Companies[],3,FALSE) -> 4151750 2Y2 | C24: Agem Sénégal Exploration SUARL (AGEM) | D24: Direction Générale des Mines | E24: Redevance superficiaire | F24: Oui | G24: Oui | H24: NOUMOUFOUKHA | I24: XOF | J24: 3675000
B25: =VLOOKUP(C25,Companies[],3,FALSE) -> 4151750 2Y2 | C25: Agem Sénégal Exploration SUARL (AGEM) | D25: Direction Générale des Mines | E25: Droits d'entrée fixes | F25: Oui | G25: Oui | H25: NOUMOUFOUKHA | I25: XOF | J25: 2500000
C26: Agem Sénégal Exploration SUARL (AGEM) | D26: Direction Générale des Mines | E26: Redevance superficiaire | F26: Oui | G26: Oui | H26: SENALA | I26: XOF | J26: 2362500
C27: Agem Sénégal Exploration SUARL (AGEM) | D27: Direction Générale des Impôts et des Domaines | E27: Retenues à la source sur bénéfice non commercial | F27: Oui | G27: Oui | H27: NOUMOUFOUKHA | I27: XOF | J27: 1775459
C28: Agem Sénégal Exploration SUARL (AGEM) | D28: Direction Générale des Impôts et des Domaines | E28: Retenue à la source sur sommes versées à des tiers | F28: Non | G28: Non | H28: NOUMOUFOUKHA | I28: XOF | J28: 1744422
C29: Agem Sénégal Exploration SUARL (AGEM) | D29: Direction Générale des Impôts et des Domaines | E29: Impôt sur le revenu des valeurs mobilières | F29: Non | G29: Non | H29: NOUMOUFOUKHA | I29: XOF | J29: 1061897
C30: Agem Sénégal Exploration SUARL (AGEM) | D30: Direction Générale des Mines | E30: Redevance superficiaire | F30: Oui | G30: Oui | H30: DAORALA | I30: XOF | J30: 415000
C31: Baobab Mining and Chemical Corp SA | D31: Direction Générale des Impôts et des Domaines | E31: Impôt sur les sociétés | F31: Oui | G31: Oui | H31: NC | I31: XOF | J31: 550233854
C32: Baobab Mining and Chemical Corp SA | D32: Direction Générale des Mines | E32: Redevance minière | F32: Oui | G32: Oui | H32: NC | I32: XOF | J32: 80168375
C33: Baobab Mining and Chemical Corp SA | D33: Direction Générale des Impôts et des Domaines | E33: Retenues à la source sur salaires (IR, TRIMF et CFCE) | F33: Non | G33: Non | H33: NC | I33: XOF | J33: 70301928
C34: Baobab Mining and Chemical Corp SA | D34: Direction Générale des Mines | E34: Redevance superficiaire | F34: Oui | G34: Oui | H34: NC | I34: XOF | J34: 18632000
C35: Baobab Mining and Chemical Corp SA | D35: Institution de Prévoyance Retraite du Sénégal | E35: Cotisations sociales (y compris les pénalités)(IPRES) | F35: Non | G35: Non | H35: NC | I35: XOF | J35: 10200637
C36: Baobab Mining and Chemical Corp SA | D36: Direction Générale des Douanes | E36: Redevance statistique UEMOA | F36: Oui | G36: Oui | H36: NC | I36: XOF | J36: 5792675
C37: Baobab Mining and Chemical Corp SA | D37: Direction Générale des Impôts et des Domaines | E37: Impôt sur le revenu des valeurs mobilières | F37: Non | G37: Non | H37: NC | I37: XOF | J37: 4952376
... C182: Grande Côte Opérations (GCO) | D182: Direction Générale des Impôts et des Domaines | E182: Taxe sur la valeur ajoutée reversée | F182: Non | G182: Non | H182: DIOGO | I182: XOF | J182: 8874240
B183: =VLOOKUP(C183,Companies[],3,FALSE) -> 2849258 2G3 | C183: Grande Côte Opérations (GCO) | D183: Direction Générale des Impôts et des Domaines | E183: Retenue à la source sur sommes versées à des tiers | F183: Non | G183: Non | H183: DIOGO | I183: XOF | J183: 8195632
B184: =VLOOKUP(C184,Companies[],3,FALSE) -> 2849258 2G3 | C184: Grande Côte Opérations (GCO) | D184: Direction Générale des Douanes | E184: Taxe d'enregistrement des véhicules | F184: Oui | G184: Oui | H184: DIOGO | I184: XOF | J184: 1156317
B185: =VLOOKUP(C185,Companies[],3,FALSE) -> 2849258 2G3 | C185: Grande Côte Opérations (GCO) | D185: Direction Générale des Douanes | E185: Autres flux de paiements significatifs (> 25 millions de FCFA) (reconciliables) | F185: Non | G185: Non | H185: DIOGO | I185: XOF | J185: 1103470
C186: Iamgold BOTO | D186: Direction Générale des Impôts et des Domaines | E186: Retenues à la source sur salaires (IR, TRIMF et CFCE) | F186: Non | G186: Non | H186: Boto | I186: XOF | J186: 312064500
C187: Iamgold BOTO | D187: Direction Générale des Impôts et des Domaines | E187: Retenues à la source sur bénéfice non commercial | F187: Oui | G187: Oui | H187: Boto | I187: XOF | J187: 99024067
...

Sheet Listes
A1: Tableau 1 - Codes de pays | I1: Tableau 2 - Options simples | K1: Tableau 3 - Options de déclaration | N1: Tableau 5 - Liste de matières premières | S1: Tableau 6 - Codes/Classification GFS | AA1: Tableau 7 - Secteurs | AC1: Tableau 8 - Phases de projet | AE1: Tableau 9 - Types d'agences gouvernementales
A2: Nom de pays ou région | B2: Code ISO de pays (alpha 2) | C2: Code ISO de devise (alpha 3) | D2: Code numérique ISO (UN M49) | E2: Code de devise (ISO 4217) | F2: Code numérique de devise (ISO 4217) | G2: Devise | I2: Liste | K2: Liste | N2: Code de produit HS | O2: Description de produit HS | P2: Description de produit HS av. volume | S2: Combiné | T2: Codes GFS des flux de revenus issus des entreprises extractives | U2: Code GFS | V2: GFS Niveau 1 | W2: GFS Niveau 2 | X2: GFS Niveau 3 | Y2: GFS Niveau 4 | AA2: Secteur (s) | AC2: Étapes du projet | AE2: Type d'Agence
A3: Afghanistan | B3: AF | C3: AFG | D3: 4 | E3: AFN | F3: 971 | G3: Afghani afghan | I3: <Sélectionner l’option> | K3: <Rapportage ITIE ou divulgation systématique?> | N3: 2606 | O3: Aluminium (2606) | P3: Aluminium (2606), volume | S3: Impôts ordinaires sur le revenu, le bénéfice et les plus-values (1112E1) | T3: Impôts ordinaires sur le revenu, le bénéfice et les plus-values | U3: 1112E1 | V3: Impôts (11E) | W3: Impôts sur le revenu, le bénéfice et les plus-values | X3: Impôts ordinaires sur le revenu, le bénéfice et les plus-values (1112E1) | Y3: Impôts ordinaires sur le revenu, le bénéfice et les plus-values (1112E1) | AA3: <Sélectionner le secteur> | AC3: <Sélectionner l’étape> | AE3: Administration centrale
A4: Afrique du Sud | B4: ZA | C4: ZAF | D4: 710 | E4: ZAR | F4: 710 | G4: Rand sud-africain | I4: Oui | K4: Oui, divulgation systématique | N4: 2524 | O4: Amiante (2524) | P4: Amiante (2524), volume | S4: Impôts extraordinaires sur le revenu, le bénéfice et les plus-values (1112E2) | T4: Impôts extraordinaires sur le revenu, le bénéfice et les plus-values | U4: 1112E2 | V4: Impôts (11E) | W4: Impôts sur le revenu, le bénéfice et les plus-values (111E) | X4: Impôts extraordinaires sur le revenu, le bénéfice et les plus-values (1112E2) | Y4: Impôts extraordinaires sur le revenu, le bénéfice et les plus-values (1112E2) | AA4: Pétrole | AC4: Prospection | AE4: Administration d'Etat fédéré
A5: Albanie | B5: AL | C5: ALB | D5: 8 | E5: ALL | F5: 8 | G5: Lek albanais | I5: Partiellement | K5: Oui, à travers le rapportage ITIE | N5: 2514 | O5: Ardoise (2514) | P5: Ardoise (2514), volume | S5: Impôts sur la masse salariale et la force de travail (112E) | T5: Impôts sur la masse salariale et la force de travail | U5: 112E | V5: Impôts (11E) | W5: Impôts sur la masse salariale et la force de travail (112E) | X5: Impôts sur la masse salariale et la force de travail (112E) | Y5: Impôts sur la masse salariale et la force de travail (112E) | AA5: Gaz | AC5: Production | AE5: Administration locale
A6: Algérie | B6: DZ | C6: DZA | D6: 12 | E6: DZD | F6: 12 | G6: Dinar algérien | I6: Non | K6: Sans objet. | N6: 7106 | O6: Argent (7106) | P6: Argent (7106), volume | S6: Impôts sur la propriété (113E) | T6: Impôts sur la propriété | U6: 113E | V6: Impôts (11E) | W6: Impôts sur la propriété (113E) | X6: Impôts sur la propriété (113E) | Y6: Impôts sur la propriété (113E) | AA6: Minier | AC6: Développement | AE6: Société publique financière et Entreprise d'Etat
A7: Allemagne | B7: DE | C7: DEU | D7: 276 | E7: EUR | F7: 978 | G7: Euro | I7: Sans objet | K7: Non disponible | N7: 7202 | O7: Ferro-alliages (7202) | P7: Ferro-alliages (7202), volume | S7: Impôts généraux sur les biens et services (TVA, taxes sur les ventes, taxes sur le chiffre d’affaires)(1141E) | T7: Impôts généraux sur les biens et services (TVA, taxes sur les ventes, taxes sur le chiffre d’affaires) | U7: 1141E | V7: Impôts (11E) | W7: Impôts sur les biens et services (114E) | X7: Impôts généraux sur les biens et services (TVA, taxes sur les ventes, taxes sur le chiffre d’affaires (1141E) | Y7: Impôts généraux sur les biens et services (TVA, taxes sur les ventes, taxes sur le chiffre d’affaires (1141E) | AA7: Sans objet | AC7: Autres | AE7: Autre
A8: Andorre | B8: AD | C8: AND | D8: 20 | E8: EUR | F8: 978 | G8: Euro | N8: 2509 | O8: Argile (2509) | P8: Argile (2509), volume | S8: Droits d’accise (1142E) | T8: Droits d’accise | U8: 1142E | V8: Impôts (11E) | W8: Impôts sur les biens et services (114E) | X8: Droits d’accise (1142E) | Y8: Droits d’accise (1142E) | AA8: Pétrole & Gaz | AC8: Sans objet
A9: Angola | B9: AO | C9: AGO | D9: 24 | E9: AOA | F9: 973 | G9: Kwanza angolais | I9: Tableau 4 - Liste des codes de devise | N9: 2617 | O9: Autres (2617) | P9: Autres (2617), volume | S9: Droits de licence (114521E) | T9: Droits de licence | U9: 114521E | V9: Impôts (11E) | W9: Impôts sur les biens et services (114E) | X9: Impôts sur l’usage de biens/permission d’utiliser des biens ou d’exécuter des activités (1145E) | Y9: Droits de licence (114521E) | AA9: Autres
