Workbook

Sheet Index
A1: Feuille | B1: Fichier source | C1: Feuille d'origine
A2: 01_00_Donn_es | B2: 00. Données.xlsx | C2: 0) Données
A3: 02_01_Donn_es_3 | B3: 01. Données (3).xlsx | C3: 1) Données
A4: 03_01_Donn_es | B4: 01. Données.xlsx | C4: 1) Données
A5: 04_01_Situation | B5: 01. Situation initiale.xlsx | C5: 1) Situation initiale
A6: 05_01_Vente_loc | B6: 01. Vente locale.xlsx | C6: 1) Vente locale
A7: 06_02_Exportati_1 | B7: 02. Exportations mensuelles.xlsx | C7: 1) Données
A8: 06_02_Exportati_2 | B8: 02. Exportations mensuelles.xlsx | C8: 2) Exportations mensuelles
A9: 07_02_R_gime_fi_1 | B9: 02. Régime fiscal.xlsx | C9: 1) Données
A10: 07_02_R_gime_fi_2 | B10: 02. Régime fiscal.xlsx | C10: 2) Régime fiscal
A11: 08_03_Exportati_1 | B11: 03. Exportations semestrielles.xlsx | C11: 1) Données
A12: 08_03_Exportati_2 | B12: 03. Exportations semestrielles.xlsx | C12: 2) Exportations mensuelles
... A32: 13_05_Manipulat_5 | B32: 05. Manipulation de la teneur.xlsx | C32: 5) Manipulation de la teneur

Sheet 01_00_Donn_es
A1: RECAPITULATIF | E1: COMPTES DE RESULTAT | J1: TVA | K1: Taux | L1: Montant
A2: Taux d'imposition | C2: Taux
A3: TVA | C3: 0.2 | E3: Entreprise extractive
A4: IS | C4: 0.3 | E4: Charges | G4: Produits
E5: Achats locaux | F5: =H13+H21+H29 | G5: Ventes | H5: 1000 | J5: TVA collectée | K5: X | L5: X
A6: Achats importés | B6: Valeur | C6: TVA | E6: Achats importés | F6: 130 | J6: TVA déductible Achats locaux | K6: X | L6: X
A7: Entreprise extractive | B7: X | C7: X | E7: Salaires | F7: 300 | J7: TVA déductible Achats importés | K7: X | L7: X
A8: Sous-traitant 1 | B8: X | C8: X | E8: Bénéfice | F8: =H9-SUM(F5:F7) | J8: TVA à reverser | L8: X
A9: Sous-traitant 2 | B9: X | C9: X | E9: Somme | F9: =SUM(F5:F8) | G9: Somme | H9: =SUM(H5:H8)
A10: Sous-traitant 3 | B10: X | C10: X
A11: Fournisseurs locaux | B11: X | C11: X | E11: Sous-traitant 1 : Chimie
A12: Total | B12: =SUM(B7:B11) | C12: =SUM(C7:C11) | E12: Charges | G12: Produits
E13: Achats locaux | F13: 30 | G13: Ventes | H13: 100 | J13: TVA collectée | K13: X | L13: X
A14: Achats locaux | B14: Valeur | C14: TVA | E14: Achats importés | F14: 20 | J14: TVA déductible Achats locaux | K14: X | L14: X
A15: Entreprise extractive | B15: X | C15: X | E15: Salaires | F15: 20 | J15: TVA déductible Achats importés | K15: X | L15: X
A16: Sous-traitant 1 | B16: X | C16: X | E16: Bénéfice | F16: =H17-SUM(F13:F15) | J16: TVA à reverser | L16: X
A17: Sous-traitant 2 | B17: X | C17: X | E17: Somme | F17: =SUM(F13:F16) | G17: Somme | H17: =SUM(H13:H16)
A18: Sous-traitant 3 | B18: X | C18: X
A19: Fournisseurs locaux | B19: X | C19: X | E19: Sous-traitant 2 : Machines et services après vente
A20: Total | B20: =SUM(B15:B19) | C20: =SUM(C15:C19) | E20: Charges | G20: Produits
E21: Achats locaux | F21: 50 | G21: Ventes | H21: 250 | J21: TVA collectée | K21: X | L21: X
A22: Recettes de TVA | C22: TVA | E22: Achats importés | F22: 100 | J22: TVA déductible Achats locaux | K22: X | L22: X
A23: Douanes | C23: X | E23: Salaires | F23: 20 | J23: TVA déductible Achats importés | K23: X | L23: X
A24: Entreprise extractive | C24: X | E24: Bénéfice | F24: =H25-SUM(F21:F23) | J24: TVA à reverser | L24: X
A25: Sous-traitant 1 | C25: X | E25: Somme | F25: =SUM(F21:F24) | G25: Somme | H25: =SUM(H21:H24)
A26: Sous-traitant 2 | C26: X
A27: Sous-traitant 3 | C27: X | E27: Sous-traitant 3 : Société de gardiennage
A28: Fournisseurs locaux | C28: X | E28: Charges | G28: Produits
A29: Total | C29: =SUM(C23:C28) | E29: Achats locaux | F29: 10 | G29: Ventes | H29: 120 | J29: TVA collectée | K29: X | L29: X
E30: Achats importés | F30: 0 | J30: TVA déductible Achats locaux | K30: X | L30: X
A31: Recettes d'IS | B31: Bénéfice | C31: IS | E31: Salaires | F31: 80 | J31: TVA déductible Achats importés | K31: X | L31: X
A32: Entreprise extractive | B32: X | C32: X | E32: Bénéfice | F32: =H33-SUM(F29:F31) | J32: TVA à reverser | L32: X
A33: Sous-traitant 1 | B33: X | C33: X | E33: Somme | F33: =SUM(F29:F32) | G33: Somme | H33: =SUM(H29:H32)
A34: Sous-traitant 2 | B34: X | C34: X
A35: Sous-traitant 3 | B35: X | C35: X | E35: Fournisseurs locaux des sous-traitants
A36: Fournisseurs locaux | B36: X | C36: X | E36: Charges | G36: Produits
A37: Total | C37: =SUM(C32:C36) | E37: Achats locaux | F37: 0 | G37: Ventes | H37: =F13+F21+F29 | J37: TVA collectée | K37: X | L37: X
E38: Achats importés | F38: 0 | J38: TVA déductible Achats locaux | K38: X | L38: X
A39: Recettes totales | C39: Recettes | E39: Salaires | F39: 50 | J39: TVA déductible Achats importés | K39: X | L39: X
A40: TVA | C40: X | E40: Bénéfice | F40: =H41-SUM(F37:F39) | J40: TVA à reverser | L40: X
...

Sheet 02_01_Donn_es_3
C1: Janvier | D1: Février | E1: Mars | F1: Avril | G1: Mai | H1: Juin | I1: Juillet | J1: Août | K1: Septembre | L1: Octobre | M1: Novembre | N1: Décembre | O1: Total | P1: Moyenne
A2: Cours | B2: USD/oz | C2: 1000 | D2: 1100 | E2: 1400 | F2: 1050 | G2: 900 | H2: 800 | I2: 850 | J2: 1300 | K2: 1600 | L2: 1700 | M2: 1800 | N2: 2000 | P2: =AVERAGE(C2:N2)
A3: Minerai extrait | B3: t | C3: 10000 | D3: 12000 | E3: 12000 | F3: 15000 | G3: 15000 | H3: 9000 | I3: 9000 | J3: 12000 | K3: 12000 | L3: 14000 | M3: 12000 | N3: 10000 | O3: =SUM(C3:N3) | P3: =AVERAGE(C3:N3)
A4: Teneur | B4: oz/t | C4: 0.223 | D4: 0.225 | E4: 0.198 | F4: 0.185 | G4: 0.185 | H4: 0.223 | I4: 0.321 | J4: 0.311 | K4: 0.255 | L4: 0.286 | M4: 0.296 | N4: 0.223 | P4: =AVERAGE(C4:N4)
A5: Production réalisée | B5: oz | C5: =C3*C4 | D5: =D3*D4 | E5: =E3*E4 | F5: =F3*F4 | G5: =G3*G4 | H5: =H3*H4 | I5: =I3*I4 | J5: =J3*J4 | ... N5: =N3*N4 | O5: =SUM(C5:N5) | P5: =P3*P4

Sheet 03_01_Donn_es
A1: 1) Comprendre les données de l’exercice
A3: BILAN
A4: Actif | D4: Passif
A5: Immobilisations | C5: =SUM(C6:C7) | D5: Capitaux propres | F5: 3000
A6: – Terrain | C6: 3000
A7: – Équipements | C7: 7000
A8: Stock | C8: 1000 | D8: Dettes | F8: 8000
A9: Total Actif | C9: =C5+C8 | D9: Total Passif | F9: =F5+F8
A11: COMPTE DE RESULTAT
A12: Charges | D12: Produits
A13: Coûts de production | C13: =C14+C17 | D13: Chiffre d'affaires | F13: =100*50
A14: – Charges d'exploitation | C14: =SUM(C15:C16)
A15: –– Intrants | C15: 2000
A16: –– Amortisements | B16: 0.05 | C16: =B16*C7
A17: – Charges finnacières | B17: 0.05 | C17: =F8*B17
A18: Profit | C18: =F13-C13
A19: Total Charges | C19: =C13+C18 | D19: Total Produits | F19: =F13

Sheet 04_01_Situation
A1: 1) Situation initiale
A3: BILAN
A4: Actif | D4: Passif
A5: Immobilisations | C5: =SUM(C6:C7) | D5: Capitaux propres | F5: 3000
A6: – Terrain | C6: 3000
A7: – Équipements | C7: 7000
A8: Stock | C8: 1000 | D8: Dettes | F8: 8000
A9: Total Actif | C9: =C5+C8 | D9: Total Passif | F9: =F5+F8
A11: COMPTE DE RESULTAT
A12: Charges | D12: Produits
A13: Coûts de production | C13: =C14+C21 | D13: Chiffre d'affaires | F13: =100*50
A14: – Charges d'exploitation | C14: =SUM(C15:C17)
A15: –– Intrants | C15: 2000
A16: –– Amortisements | B16: 0.05 | C16: =B16*C7
A17: –– Taxes | C17: =SUM(C18:C20)
A18: ––– Redevances superficiaires | B18: 0.01 | C18: =C6*B18
A19: ––– Redevances minières | B19: 0.05 | C19: =F13*B19
A20: ––– Droits de douane | B20: 0.075 | C20: =C15*B20
A21: – Charges finnacières | B21: 0.05 | C21: =F8*B21
A22: Profit | C22: =F13-C13
A23: – Impôt sur les sociétés | B23: 0.3 | C23: =C22*B23
A24: – Profit après impôt | C24: =C22-C23
A25: – Dividendes | B25: 0.5 | C25: =C24*B25
A26: – Réserves | B26: 0.5 | C26: =C24*B26
A27: Total Charges | C27: =C13+C22 | D27: Total Produits | F27: =F13

Sheet 05_01_Vente_loc
A1: RECAPITULATIF | E1: COMPTES DE RESULTAT | J1: TVA | K1: Taux | L1: Montant
A2: Taux d'imposition | C2: Taux
A3: TVA | C3: 0.2 | E3: Entreprise extractive
A4: IS | C4: 0.3 | E4: Charges | G4: Produits
E5: Achats locaux | F5: =H13+H21+H29 | G5: Ventes | H5: 1000 | J5: TVA collectée | K5: =$C$3 | L5: =H5*K5
A6: Achats importés | B6: Valeur | C6: TVA | E6: Achats importés | F6: 130 | J6: TVA déductible Achats locaux | K6: =$C$3 | L6: =F5*K6
A7: Entreprise extractive | B7: =F6 | C7: =L7 | E7: Salaires | F7: 300 | J7: TVA déductible Achats importés | K7: =$C$3 | L7: =F6*K7
A8: Sous-traitant 1 | B8: =F14 | C8: =L15 | E8: Bénéfice | F8: =H9-SUM(F5:F7) | J8: TVA à reverser | L8: =L5-SUM(L6:L7)
A9: Sous-traitant 2 | B9: =F22 | C9: =L23 | E9: Somme | F9: =SUM(F5:F8) | G9: Somme | H9: =SUM(H5:H8)
A10: Sous-traitant 3 | B10: =F30 | C10: =L31
A11: Fournisseurs locaux | B11: =F38 | C11: =L39 | E11: Sous-traitant 1 : Chimie
A12: Total | B12: =SUM(B7:B11) | C12: =SUM(C7:C11) | E12: Charges | G12: Produits
E13: Achats locaux | F13: 30 | G13: Ventes | H13: 100 | J13: TVA collectée | K13: =$C$3 | L13: =H13*K13
A14: Achats locaux | B14: Valeur | C14: TVA | E14: Achats importés | F14: 20 | J14: TVA déductible Achats locaux | K14: =$C$3 | L14: =F13*K14
A15: Entreprise extractive | B15: =F5 | C15: =L6 | E15: Salaires | F15: 20 | J15: TVA déductible Achats importés | K15: =$C$3 | L15: =F14*K15
A16: Sous-traitant 1 | B16: =F13 | C16: =L14 | E16: Bénéfice | F16: =H17-SUM(F13:F15) | J16: TVA à reverser | L16: =L13-SUM(L14:L15)
A17: Sous-traitant 2 | B17: =F21 | C17: =L22 | E17: Somme | F17: =SUM(F13:F16) | G17: Somme | H17: =SUM(H13:H16)
A18: Sous-traitant 3 | B18: =F29 | C18: =L30
A19: Fournisseurs locaux | B19: =F37 | C19: =L38 | E19: Sous-traitant 2 : Machines et services après vente
A20: Total | B20: =SUM(B15:B19) | C20: =SUM(C15:C19) | E20: Charges | G20: Produits
E21: Achats locaux | F21: 50 | G21: Ventes | H21: 250 | J21: TVA collectée | K21: =$C$3 | L21: =H21*K21
A22: Recettes de TVA | C22: TVA | E22: Achats importés | F22: 100 | J22: TVA déductible Achats locaux | K22: =$C$3 | L22: =F21*K22
A23: Douanes | C23: =L7+L15+L23+L31+L39 | E23: Salaires | F23: 20 | J23: TVA déductible Achats importés | K23: =$C$3 | L23: =F22*K23
A24: Entreprise extractive | C24: =L8 | E24: Bénéfice | F24: =H25-SUM(F21:F23) | J24: TVA à reverser | L24: =L21-SUM(L22:L23)
A25: Sous-traitant 1 | C25: =L16 | E25: Somme | F25: =SUM(F21:F24) | G25: Somme | H25: =SUM(H21:H24)
A26: Sous-traitant 2 | C26: =L24
A27: Sous-traitant 3 | C27: =L32 | E27: Sous-traitant 3 : Société de gardiennage
A28: Fournisseurs locaux | C28: =L40 | E28: Charges | G28: Produits
A29: Total | C29: =SUM(C23:C28) | E29: Achats locaux | F29: 10 | G29: Ventes | H29: 120 | J29: TVA collectée | K29: =$C$3 | L29: =H29*K29
E30: Achats importés | F30: 0 | J30: TVA déductible Achats locaux | K30: =$C$3 | L30: =F29*K30
A31: Recettes d'IS | B31: Bénéfice | C31: IS | E31: Salaires | F31: 80 | J31: TVA déductible Achats importés | K31: =$C$3 | L31: =F30*K31
A32: Entreprise extractive | B32: =F8 | C32: =IF(B32>0,B32*$C$4,0) | E32: Bénéfice | F32: =H33-SUM(F29:F31) | J32: TVA à reverser | L32: =L29-SUM(L30:L31)
A33: Sous-traitant 1 | B33: =F16 | C33: =IF(B33>0,B33*$C$4,0) | E33: Somme | F33: =SUM(F29:F32) | G33: Somme | H33: =SUM(H29:H32)
A34: Sous-traitant 2 | B34: =F24 | C34: =IF(B34>0,B34*$C$4,0)
A35: Sous-traitant 3 | B35: =F32 | C35: =IF(B35>0,B35*$C$4,0) | E35: Fournisseurs locaux des sous-traitants
A36: Fournisseurs locaux | B36: =F40 | C36: =IF(B36>0,B36*$C$4,0) | E36: Charges | G36: Produits
A37: Total | C37: =SUM(C32:C36) | E37: Achats locaux | F37: 0 | G37: Ventes | H37: =F13+F21+F29 | J37: TVA collectée | K37: =$C$3 | L37: =H37*K37
E38: Achats importés | F38: 0 | J38: TVA déductible Achats locaux | K38: =$C$3 | L38: =F37*K38
A39: Recettes totales | C39: Recettes | E39: Salaires | F39: 50 | J39: TVA déductible Achats importés | K39: =$C$3 | L39: =F38*K39
A40: TVA | C40: =C29 | E40: Bénéfice | F40: =H41-SUM(F37:F39) | J40: TVA à reverser | L40: =L37-SUM(L38:L39)
...

Sheet 06_02_Exportati_1
C1: Janvier | D1: Février | E1: Mars | F1: Avril | G1: Mai | H1: Juin | I1: Juillet | J1: Août | K1: Septembre | L1: Octobre | M1: Novembre | N1: Décembre | O1: Total | P1: Moyenne
A2: Cours | B2: USD/oz | C2: 1000 | D2: 1100 | E2: 1400 | F2: 1050 | G2: 900 | H2: 800 | I2: 850 | J2: 1300 | K2: 1600 | L2: 1700 | M2: 1800 | N2: 2000 | P2: =AVERAGE(C2:N2)
A3: Minerai extrait | B3: t | C3: 10000 | D3: 12000 | E3: 12000 | F3: 15000 | G3: 15000 | H3: 9000 | I3: 9000 | J3: 12000 | K3: 12000 | L3: 14000 | M3: 12000 | N3: 10000 | O3: =SUM(C3:N3) | P3: =AVERAGE(C3:N3)
A4: Teneur | B4: oz/t | C4: 0.223 | D4: 0.225 | E4: 0.198 | F4: 0.185 | G4: 0.185 | H4: 0.223 | I4: 0.321 | J4: 0.311 | K4: 0.255 | L4: 0.286 | M4: 0.296 | N4: 0.223 | P4: =AVERAGE(C4:N4)
A5: Production réalisée | B5: oz | C5: =C3*C4 | D5: =D3*D4 | E5: =E3*E4 | F5: =F3*F4 | G5: =G3*G4 | H5: =H3*H4 | I5: =I3*I4 | J5: =J3*J4 | ... N5: =N3*N4 | O5: =SUM(C5:N5) | P5: =P3*P4

Sheet 06_02_Exportati_2
C1: Janvier | D1: Février | E1: Mars | F1: Avril | G1: Mai | H1: Juin | I1: Juillet | J1: Août | K1: Septembre | L1: Octobre | M1: Novembre | N1: Décembre | O1: Total | P1: Moyenne
A2: Cours | B2: USD/oz | C2: 1000 | D2: 1100 | E2: 1400 | F2: 1050 | G2: 900 | H2: 800 | I2: 850 | J2: 1300 | K2: 1600 | L2: 1700 | M2: 1800 | N2: 2000 | P2: =AVERAGE(C2:N2)
A3: Minerai extrait | B3: t | C3: 10000 | D3: 12000 | E3: 12000 | F3: 15000 | G3: 15000 | H3: 9000 | I3: 9000 | J3: 12000 | K3: 12000 | L3: 14000 | M3: 12000 | N3: 10000 | O3: =SUM(C3:N3) | P3: =AVERAGE(C3:N3)
A4: Teneur | B4: oz/t | C4: 0.223 | D4: 0.225 | E4: 0.198 | F4: 0.185 | G4: 0.185 | H4: 0.223 | I4: 0.321 | J4: 0.311 | K4: 0.255 | L4: 0.286 | M4: 0.296 | N4: 0.223 | P4: =AVERAGE(C4:N4)
A5: Production réalisée | B5: oz | C5: =C3*C4 | D5: =D3*D4 | E5: =E3*E4 | F5: =F3*F4 | G5: =G3*G4 | H5: =H3*H4 | I5: =I3*I4 | J5: =J3*J4 | ... N5: =N3*N4 | O5: =SUM(C5:N5) | P5: =P3*P4
A6: Chiffre d'affaires réalisé | B6: USD | C6: =C5*C2 | D6: =D5*D2 | E6: =E5*E2 | F6: =F5*F2 | G6: =G5*G2 | H6: =H5*H2 | I6: =I5*I2 | J6: =J5*J2 | ... N6: =N5*N2 | O6: =SUM(C6:N6) | P6: =P2*P5
A7: Redevance minière (5%) | B7: USD | C7: =C6*5% | D7: =D6*5% | E7: =E6*5% | F7: =F6*5% | G7: =G6*5% | H7: =H6*5% | I7: =I6*5% | J7: =J6*5% | ... N7: =N6*5% | O7: =SUM(C7:N7) | P7: =AVERAGE(C7:N7)

Sheet 07_02_R_gime_fi_1
A1: 1) Comprendre les données de l’exercice
A3: BILAN
A4: Actif | D4: Passif
A5: Immobilisations | C5: =SUM(C6:C7) | D5: Capitaux propres | F5: 3000
A6: – Terrain | C6: 3000
A7: – Équipements | C7: 7000
A8: Stock | C8: 1000 | D8: Dettes | F8: 8000
A9: Total Actif | C9: =C5+C8 | D9: Total Passif | F9: =F5+F8
A11: COMPTE DE RESULTAT
A12: Charges | D12: Produits
A13: Coûts de production | C13: =C14+C17 | D13: Chiffre d'affaires | F13: =100*50
A14: – Charges d'exploitation | C14: =SUM(C15:C16)
A15: –– Intrants | C15: 2000
A16: –– Amortisements | B16: 0.05 | C16: =B16*C7
A17: – Charges finnacières | B17: 0.05 | C17: =F8*B17
A18: Profit | C18: =F13-C13
A19: Total Charges | C19: =C13+C18 | D19: Total Produits | F19: =F13

Sheet 07_02_R_gime_fi_2
A1: 2) Appliquer un régime fiscal
A3: BILAN
A4: Actif | D4: Passif
A5: Immobilisations | C5: =SUM(C6:C7) | D5: Capitaux propres | F5: 3000
A6: – Terrain | C6: 3000
A7: – Équipements | C7: 7000
A8: Stock | C8: 1000 | D8: Dettes | F8: 8000
A9: Total Actif | C9: =C5+C8 | D9: Total Passif | F9: =F5+F8
A11: COMPTE DE RESULTAT
A12: Charges | D12: Produits
A13: Coûts de production | C13: =C14+C21 | D13: Chiffre d'affaires | F13: =100*50
A14: – Charges d'exploitation | C14: =SUM(C15:C17)
A15: –– Intrants | C15: 2000
A16: –– Amortisements | B16: 0.05 | C16: =B16*C7
A17: –– Taxes | C17: =SUM(C18:C20)
A18: ––– Redevances superficiaires | B18: 0.01 | C18: =C6*B18
A19: ––– Redevances minières | B19: 0.05 | C19: =F13*B19
A20: ––– Droits de douane | B20: 0.075 | C20: =C15*B20
A21: – Charges finnacières | B21: 0.05 | C21: =F8*B21
A22: Profit | C22: =F13-C13
A23: – Impôt sur les sociétés | B23: 0.3 | C23: =C22*B23
A24: – Profit après impôt | C24: =C22-C23
A25: – Dividendes | B25: 0.5 | C25: =C24*B25
A26: – Réserves | B26: 0.5 | C26: =C24*B26
A27: Total Charges | C27: =C13+C22 | D27: Total Produits | F27: =F13

Sheet 08_03_Exportati_1
C1: Janvier | D1: Février | E1: Mars | F1: Avril | G1: Mai | H1: Juin | I1: Juillet | J1: Août | K1: Septembre | L1: Octobre | M1: Novembre | N1: Décembre | O1: Total | P1: Moyenne
A2: Cours | B2: USD/oz | C2: 1000 | D2: 1100 | E2: 1400 | F2: 1050 | G2: 900 | H2: 800 | I2: 850 | J2: 1300 | K2: 1600 | L2: 1700 | M2: 1800 | N2: 2000 | P2: =AVERAGE(C2:N2)
A3: Minerai extrait | B3: t | C3: 10000 | D3: 12000 | E3: 12000 | F3: 15000 | G3: 15000 | H3: 9000 | I3: 9000 | J3: 12000 | K3: 12000 | L3: 14000 | M3: 12000 | N3: 10000 | O3: =SUM(C3:N3) | P3: =AVERAGE(C3:N3)
A4: Teneur | B4: oz/t | C4: 0.223 | D4: 0.225 | E4: 0.198 | F4: 0.185 | G4: 0.185 | H4: 0.223 | I4: 0.321 | J4: 0.311 | K4: 0.255 | L4: 0.286 | M4: 0.296 | N4: 0.223 | P4: =AVERAGE(C4:N4)
A5: Production réalisée | B5: oz | C5: =C3*C4 | D5: =D3*D4 | E5: =E3*E4 | F5: =F3*F4 | G5: =G3*G4 | H5: =H3*H4 | I5: =I3*I4 | J5: =J3*J4 | ... N5: =N3*N4 | O5: =SUM(C5:N5) | P5: =P3*P4

Sheet 08_03_Exportati_2
C1: Janvier | D1: Février | E1: Mars | F1: Avril | G1: Mai | H1: Juin | I1: Juillet | J1: Août | K1: Septembre | L1: Octobre | M1: Novembre | N1: Décembre | O1: Total | P1: Moyenne
A2: Cours | B2: USD/oz | C2: 1000 | D2: 1100 | E2: 1400 | F2: 1050 | G2: 900 | H2: 800 | I2: 850 | J2: 1300 | K2: 1600 | L2: 1700 | M2: 1800 | N2: 2000 | P2: =AVERAGE(C2:N2)
A3: Minerai extrait | B3: t | C3: 10000 | D3: 12000 | E3: 12000 | F3: 15000 | G3: 15000 | H3: 9000 | I3: 9000 | J3: 12000 | K3: 12000 | L3: 14000 | M3: 12000 | N3: 10000 | O3: =SUM(C3:N3) | P3: =AVERAGE(C3:N3)
A4: Teneur | B4: oz/t | C4: 0.223 | D4: 0.225 | E4: 0.198 | F4: 0.185 | G4: 0.185 | H4: 0.223 | I4: 0.321 | J4: 0.311 | K4: 0.255 | L4: 0.286 | M4: 0.296 | N4: 0.223 | P4: =AVERAGE(C4:N4)
A5: Production réalisée | B5: oz | C5: =C3*C4 | D5: =D3*D4 | E5: =E3*E4 | F5: =F3*F4 | G5: =G3*G4 | H5: =H3*H4 | I5: =I3*I4 | J5: =J3*J4 | ... N5: =N3*N4 | O5: =SUM(C5:N5) | P5: =P3*P4
A6: Chiffre d'affaires réalisé | B6: USD | C6: =C5*C2 | D6: =D5*D2 | E6: =E5*E2 | F6: =F5*F2 | G6: =G5*G2 | H6: =H5*H2 | I6: =I5*I2 | J6: =J5*J2 | ... N6: =N5*N2 | O6: =SUM(C6:N6) | P6: =P2*P5
A7: Redevance minière (5%) | B7: USD | C7: =C6*5% | D7: =D6*5% | E7: =E6*5% | F7: =F6*5% | G7: =G6*5% | H7: =H6*5% | I7: =I6*5% | J7: =J6*5% | ... N7: =N6*5% | O7: =SUM(C7:N7) | P7: =AVERAGE(C7:N7)

Sheet 08_03_Exportati_3
C1: Janvier | D1: Février | E1: Mars | F1: Avril | G1: Mai | H1: Juin | I1: Juillet | J1: Août | K1: Septembre | L1: Octobre | M1: Novembre | N1: Décembre | O1: Total | P1: Moyenne
A2: Cours | B2: USD/oz | C2: 1000 | D2: 1100 | E2: 1400 | F2: 1050 | G2: 900 | H2: 800 | I2: 850 | J2: 1300 | K2: 1600 | L2: 1700 | M2: 1800 | N2: 2000 | P2: =AVERAGE(C2:N2)
A3: Minerai extrait | B3: t | C3: 10000 | D3: 12000 | E3: 12000 | F3: 15000 | G3: 15000 | H3: 9000 | I3: 9000 | J3: 12000 | K3: 12000 | L3: 14000 | M3: 12000 | N3: 10000 | O3: =SUM(C3:N3) | P3: =AVERAGE(C3:N3)
A4: Teneur | B4: oz/t | C4: 0.223 | D4: 0.225 | E4: 0.198 | F4: 0.185 | G4: 0.185 | H4: 0.223 | I4: 0.321 | J4: 0.311 | K4: 0.255 | L4: 0.286 | M4: 0.296 | N4: 0.223 | P4: =AVERAGE(C4:N4)
A5: Production réalisée | B5: oz | C5: =C3*C4 | D5: =D3*D4 | E5: =E3*E4 | F5: =F3*F4 | G5: =G3*G4 | H5: =H3*H4 | I5: =I3*I4 | J5: =J3*J4 | ... N5: =N3*N4 | O5: =SUM(C5:N5) | P5: =P3*P4
A6: Chiffre d'affaires réalisé | B6: USD | H6: =SUM(C5:H5)*H2 | N6: =SUM(I5:N5)*N2 | O6: =SUM(C6:N6) | P6: =O6/12
A7: Redevance minière (5%) | B7: USD | H7: =H6*5% | N7: =N6*5% | O7: =SUM(C7:N7) | P7: =O7/12
O8: =O7-'2) Exportations mensuelles'!O7
O9: =O8/'2) Exportations mensuelles'!O7

Sheet 09_03_Manipulat_1
A1: 1) Situation initiale
A3: BILAN
A4: Actif | D4: Passif
A5: Immobilisations | C5: =SUM(C6:C7) | D5: Capitaux propres | F5: 3000
A6: – Terrain | C6: 3000
A7: – Équipements | C7: 7000
A8: Stock | C8: 1000 | D8: Dettes | F8: 8000
A9: Total Actif | C9: =C5+C8 | D9: Total Passif | F9: =F5+F8
A11: COMPTE DE RESULTAT
A12: Charges | D12: Produits
A13: Coûts de production | C13: =C14+C21 | D13: Chiffre d'affaires | F13: =100*50
A14: – Charges d'exploitation | C14: =SUM(C15:C17)
A15: –– Intrants | C15: 2000
A16: –– Amortisements | B16: 0.05 | C16: =B16*C7
A17: –– Taxes | C17: =SUM(C18:C20)
A18: ––– Redevances superficiaires | B18: 0.01 | C18: =C6*B18
A19: ––– Redevances minières | B19: 0.05 | C19: =F13*B19
A20: ––– Droits de douane | B20: 0.075 | C20: =C15*B20
A21: – Charges finnacières | B21: 0.05 | C21: =F8*B21
A22: Profit | C22: =F13-C13
A23: – Impôt sur les sociétés | B23: 0.3 | C23: =C22*B23
A24: – Profit après impôt | C24: =C22-C23
A25: – Dividendes | B25: 0.5 | C25: =C24*B25
A26: – Réserves | B26: 0.5 | C26: =C24*B26
A27: Total Charges | C27: =C13+C22 | D27: Total Produits | F27: =F13

Sheet 09_03_Manipulat_2
A1: 2) Sous-capitalisation
A3: BILAN
A4: Actif | D4: Passif
A5: Immobilisations | C5: =SUM(C6:C7) | D5: Capitaux propres | F5: 1000
A6: – Terrain | C6: 3000
A7: – Équipements | C7: 7000
A8: Stock | C8: 1000 | D8: Dettes | F8: 10000
A9: Total Actif | C9: =C5+C8 | D9: Total Passif | F9: =F5+F8
A11: COMPTE DE RESULTAT
A12: Charges | D12: Produits
A13: Coûts de production | C13: =C14+C21 | D13: Chiffre d'affaires | F13: =100*50
A14: – Charges d'exploitation | C14: =SUM(C15:C17)
A15: –– Intrants | C15: 2000
A16: –– Amortisements | B16: 0.05 | C16: =B16*C7
A17: –– Taxes | C17: =SUM(C18:C20)
A18: ––– Redevances superficiaires | B18: 0.01 | C18: =C6*B18
A19: ––– Redevances minières | B19: 0.05 | C19: =F13*B19
A20: ––– Droits de douane | B20: 0.075 | C20: =C15*B20
A21: – Charges finnacières | B21: 0.05 | C21: =F8*B21
A22: Profit | C22: =F13-C13
A23: – Impôt sur les sociétés | B23: 0.3 | C23: =C22*B23
A24: – Profit après impôt | C24: =C22-C23
A25: – Dividendes | B25: 0.5 | C25: =C24*B25
A26: – Réserves | B26: 0.5 | C26: =C24*B26
A27: Total Charges | C27: =C13+C22 | D27: Total Produits | F27: =F13

Sheet 09_03_Manipulat_3
A1: 3) Manipulation des coûts
A3: BILAN
A4: Actif | D4: Passif
A5: Immobilisations | C5: =SUM(C6:C7) | D5: Capitaux propres | F5: 1000
A6: – Terrain | C6: 3000
A7: – Équipements | C7: 12000
A8: Stock | C8: 1000 | D8: Dettes | F8: 15000
A9: Total Actif | C9: =C5+C8 | D9: Total Passif | F9: =F5+F8
A11: COMPTE DE RESULTAT
A12: Charges | D12: Produits
A13: Coûts de production | C13: =C14+C21 | D13: Chiffre d'affaires | F13: =100*50
A14: – Charges d'exploitation | C14: =SUM(C15:C17)
A15: –– Intrants | C15: 2800
A16: –– Amortisements | B16: 0.05 | C16: =B16*C7
A17: –– Taxes | C17: =SUM(C18:C20)
A18: ––– Redevances superficiaires | B18: 0.01 | C18: =C6*B18
A19: ––– Redevances minières | B19: 0.05 | C19: =F13*B19
A20: ––– Droits de douane | B20: 0.075 | C20: =C15*B20
A21: – Charges finnacières | B21: 0.05 | C21: =F8*B21
A22: Profit | C22: =F13-C13
A23: – Impôt sur les sociétés | B23: 0.3 | C23: =C22*B23
A24: – Profit après impôt | C24: =C22-C23
A25: – Dividendes | B25: 0.5 | C25: =C24*B25
A26: – Réserves | B26: 0.5 | C26: =C24*B26
A27: Total Charges | C27: =C13+C22 | D27: Total Produits | F27: =F13

Sheet 10_03_Variation_1
A1: 1) Comprendre les données de l’exercice
A3: BILAN
A4: Actif | D4: Passif
A5: Immobilisations | C5: =SUM(C6:C7) | D5: Capitaux propres | F5: 3000
A6: – Terrain | C6: 3000
A7: – Équipements | C7: 7000
A8: Stock | C8: 1000 | D8: Dettes | F8: 8000
A9: Total Actif | C9: =C5+C8 | D9: Total Passif | F9: =F5+F8
A11: COMPTE DE RESULTAT
A12: Charges | D12: Produits
A13: Coûts de production | C13: =C14+C17 | D13: Chiffre d'affaires | F13: =100*50
A14: – Charges d'exploitation | C14: =SUM(C15:C16)
A15: –– Intrants | C15: 2000
A16: –– Amortisements | B16: 0.05 | C16: =B16*C7
A17: – Charges finnacières | B17: 0.05 | C17: =F8*B17
A18: Profit | C18: =F13-C13
A19: Total Charges | C19: =C13+C18 | D19: Total Produits | F19: =F13

Sheet 10_03_Variation_2
A1: 2) Appliquer un régime fiscal
A3: BILAN
A4: Actif | D4: Passif
A5: Immobilisations | C5: =SUM(C6:C7) | D5: Capitaux propres | F5: 3000
A6: – Terrain | C6: 3000
A7: – Équipements | C7: 7000
A8: Stock | C8: 1000 | D8: Dettes | F8: 8000
A9: Total Actif | C9: =C5+C8 | D9: Total Passif | F9: =F5+F8
A11: COMPTE DE RESULTAT
A12: Charges | D12: Produits
A13: Coûts de production | C13: =C14+C21 | D13: Chiffre d'affaires | F13: =100*50
A14: – Charges d'exploitation | C14: =SUM(C15:C17)
A15: –– Intrants | C15: 2000
A16: –– Amortisements | B16: 0.05 | C16: =B16*C7
A17: –– Taxes | C17: =SUM(C18:C20)
A18: ––– Redevances superficiaires | B18: 0.01 | C18: =C6*B18
A19: ––– Redevances minières | B19: 0.05 | C19: =F13*B19
A20: ––– Droits de douane | B20: 0.075 | C20: =C15*B20
A21: – Charges finnacières | B21: 0.05 | C21: =F8*B21
A22: Profit | C22: =F13-C13
A23: – Impôt sur les sociétés | B23: 0.3 | C23: =C22*B23
A24: – Profit après impôt | C24: =C22-C23
A25: – Dividendes | B25: 0.5 | C25: =C24*B25
A26: – Réserves | B26: 0.5 | C26: =C24*B26
A27: Total Charges | C27: =C13+C22 | D27: Total Produits | F27: =F13

Sheet 10_03_Variation_3
A1: 3) Simuler une variation des cours
A3: BILAN
A4: Actif | D4: Passif
A5: Immobilisations | C5: =SUM(C6:C7) | D5: Capitaux propres | F5: 3000
A6: – Terrain | C6: 3000
A7: – Équipements | C7: 7000
A8: Stock | C8: 1000 | D8: Dettes | F8: 8000
A9: Total Actif | C9: =C5+C8 | D9: Total Passif | F9: =F5+F8
A11: COMPTE DE RESULTAT
A12: Charges | D12: Produits
A13: Coûts de production | C13: =C14+C21 | D13: Chiffre d'affaires | F13: =100*60
A14: – Charges d'exploitation | C14: =SUM(C15:C17)
A15: –– Intrants | C15: 2000
A16: –– Amortisements | B16: 0.05 | C16: =B16*C7
A17: –– Taxes | C17: =SUM(C18:C20)
A18: ––– Redevances superficiaires | B18: 0.01 | C18: =C6*B18
A19: ––– Redevances minières | B19: 0.05 | C19: =F13*B19
A20: ––– Droits de douane | B20: 0.075 | C20: =C15*B20
A21: – Charges finnacières | B21: 0.05 | C21: =F8*B21
A22: Profit | C22: =F13-C13
A23: – Impôt sur les sociétés | B23: 0.3 | C23: =C22*B23
A24: – Profit après impôt | C24: =C22-C23
A25: – Dividendes | B25: 0.5 | C25: =C24*B25
A26: – Réserves | B26: 0.5 | C26: =C24*B26
A27: Total Charges | C27: =C13+C22 | D27: Total Produits | F27: =F13

Sheet 11_04_Contrat_d_1
C1: Janvier | D1: Février | E1: Mars | F1: Avril | G1: Mai | H1: Juin | I1: Juillet | J1: Août | K1: Septembre | L1: Octobre | M1: Novembre | N1: Décembre | O1: Total | P1: Moyenne
A2: Cours | B2: USD/oz | C2: 1000 | D2: 1100 | E2: 1400 | F2: 1050 | G2: 900 | H2: 800 | I2: 850 | J2: 1300 | K2: 1600 | L2: 1700 | M2: 1800 | N2: 2000 | P2: =AVERAGE(C2:N2)
A3: Minerai extrait | B3: t | C3: 10000 | D3: 12000 | E3: 12000 | F3: 15000 | G3: 15000 | H3: 9000 | I3: 9000 | J3: 12000 | K3: 12000 | L3: 14000 | M3: 12000 | N3: 10000 | O3: =SUM(C3:N3) | P3: =AVERAGE(C3:N3)
A4: Teneur | B4: oz/t | C4: 0.223 | D4: 0.225 | E4: 0.198 | F4: 0.185 | G4: 0.185 | H4: 0.223 | I4: 0.321 | J4: 0.311 | K4: 0.255 | L4: 0.286 | M4: 0.296 | N4: 0.223 | P4: =AVERAGE(C4:N4)
A5: Production réalisée | B5: oz | C5: =C3*C4 | D5: =D3*D4 | E5: =E3*E4 | F5: =F3*F4 | G5: =G3*G4 | H5: =H3*H4 | I5: =I3*I4 | J5: =J3*J4 | ... N5: =N3*N4 | O5: =SUM(C5:N5) | P5: =P3*P4

Sheet 11_04_Contrat_d_2
C1: Janvier | D1: Février | E1: Mars | F1: Avril | G1: Mai | H1: Juin | I1: Juillet | J1: Août | K1: Septembre | L1: Octobre | M1: Novembre | N1: Décembre | O1: Total | P1: Moyenne
A2: Cours | B2: USD/oz | C2: 1000 | D2: 1100 | E2: 1400 | F2: 1050 | G2: 900 | H2: 800 | I2: 850 | J2: 1300 | K2: 1600 | L2: 1700 | M2: 1800 | N2: 2000 | P2: =AVERAGE(C2:N2)
A3: Minerai extrait | B3: t | C3: 10000 | D3: 12000 | E3: 12000 | F3: 15000 | G3: 15000 | H3: 9000 | I3: 9000 | J3: 12000 | K3: 12000 | L3: 14000 | M3: 12000 | N3: 10000 | O3: =SUM(C3:N3) | P3: =AVERAGE(C3:N3)
A4: Teneur | B4: oz/t | C4: 0.223 | D4: 0.225 | E4: 0.198 | F4: 0.185 | G4: 0.185 | H4: 0.223 | I4: 0.321 | J4: 0.311 | K4: 0.255 | L4: 0.286 | M4: 0.296 | N4: 0.223 | P4: =AVERAGE(C4:N4)
A5: Production réalisée | B5: oz | C5: =C3*C4 | D5: =D3*D4 | E5: =E3*E4 | F5: =F3*F4 | G5: =G3*G4 | H5: =H3*H4 | I5: =I3*I4 | J5: =J3*J4 | ... N5: =N3*N4 | O5: =SUM(C5:N5) | P5: =P3*P4
A6: Chiffre d'affaires réalisé | B6: USD | C6: =C5*C2 | D6: =D5*D2 | E6: =E5*E2 | F6: =F5*F2 | G6: =G5*G2 | H6: =H5*H2 | I6: =I5*I2 | J6: =J5*J2 | ... N6: =N5*N2 | O6: =SUM(C6:N6) | P6: =P2*P5
A7: Redevance minière (5%) | B7: USD | C7: =C6*5% | D7: =D6*5% | E7: =E6*5% | F7: =F6*5% | G7: =G6*5% | H7: =H6*5% | I7: =I6*5% | J7: =J6*5% | ... N7: =N6*5% | O7: =SUM(C7:N7) | P7: =AVERAGE(C7:N7)

Sheet 11_04_Contrat_d_3
C1: Janvier | D1: Février | E1: Mars | F1: Avril | G1: Mai | H1: Juin | I1: Juillet | J1: Août | K1: Septembre | L1: Octobre | M1: Novembre | N1: Décembre | O1: Total | P1: Moyenne
A2: Cours | B2: USD/oz | C2: 1000 | D2: 1100 | E2: 1400 | F2: 1050 | G2: 900 | H2: 800 | I2: 850 | J2: 1300 | K2: 1600 | L2: 1700 | M2: 1800 | N2: 2000 | P2: =AVERAGE(C2:N2)
A3: Minerai extrait | B3: t | C3: 10000 | D3: 12000 | E3: 12000 | F3: 15000 | G3: 15000 | H3: 9000 | I3: 9000 | J3: 12000 | K3: 12000 | L3: 14000 | M3: 12000 | N3: 10000 | O3: =SUM(C3:N3) | P3: =AVERAGE(C3:N3)
A4: Teneur | B4: oz/t | C4: 0.223 | D4: 0.225 | E4: 0.198 | F4: 0.185 | G4: 0.185 | H4: 0.223 | I4: 0.321 | J4: 0.311 | K4: 0.255 | L4: 0.286 | M4: 0.296 | N4: 0.223 | P4: =AVERAGE(C4:N4)
A5: Production réalisée | B5: oz | C5: =C3*C4 | D5: =D3*D4 | E5: =E3*E4 | F5: =F3*F4 | G5: =G3*G4 | H5: =H3*H4 | I5: =I3*I4 | J5: =J3*J4 | ... N5: =N3*N4 | O5: =SUM(C5:N5) | P5: =P3*P4
A6: Chiffre d'affaires réalisé | B6: USD | H6: =SUM(C5:H5)*H2 | N6: =SUM(I5:N5)*N2 | O6: =SUM(C6:N6) | P6: =O6/12
A7: Redevance minière (5%) | B7: USD | H7: =H6*5% | N7: =N6*5% | O7: =SUM(C7:N7) | P7: =O7/12
O8: =O7-'2) Exportations mensuelles'!O7
O9: =O8/'2) Exportations mensuelles'!O7

Sheet 11_04_Contrat_d_4
C1: Janvier | D1: Février | E1: Mars | F1: Avril | G1: Mai | H1: Juin | I1: Juillet | J1: Août | K1: Septembre | L1: Octobre | M1: Novembre | N1: Décembre | O1: Total | P1: Moyenne
A2: Cours | B2: USD/oz | C2: 1000 | D2: 1100 | E2: 1400 | F2: 1050 | G2: 900 | H2: 800 | I2: 850 | J2: 1300 | K2: 1600 | L2: 1700 | M2: 1800 | N2: 2000 | P2: =AVERAGE(C2:N2)
A3: Minerai extrait | B3: t | C3: 10000 | D3: 12000 | E3: 12000 | F3: 15000 | G3: 15000 | H3: 9000 | I3: 9000 | J3: 12000 | K3: 12000 | L3: 14000 | M3: 12000 | N3: 10000 | O3: =SUM(C3:N3) | P3: =AVERAGE(C3:N3)
A4: Teneur | B4: oz/t | C4: 0.223 | D4: 0.225 | E4: 0.198 | F4: 0.185 | G4: 0.185 | H4: 0.223 | I4: 0.321 | J4: 0.311 | K4: 0.255 | L4: 0.286 | M4: 0.296 | N4: 0.223 | P4: =AVERAGE(C4:N4)
A5: Production réalisée | B5: oz | C5: =C3*C4 | D5: =D3*D4 | E5: =E3*E4 | F5: =F3*F4 | G5: =G3*G4 | H5: =H3*H4 | I5: =I3*I4 | J5: =J3*J4 | ... N5: =N3*N4 | O5: =SUM(C5:N5) | P5: =P3*P4
A6: Chiffre d'affaires réalisé | B6: USD | N6: =SUM(C5:N5)*H2 | O6: =SUM(C6:N6) | P6: =O6/12
A7: Redevance minière (5%) | B7: USD | N7: =N6*5% | O7: =SUM(C7:N7) | P7: =O7/12
O8: =O7-'2) Exportations mensuelles'!O7
O9: =O8/'2) Exportations mensuelles'!O7

Sheet 12_04_Contrat_d_1
A1: 1) Situation initiale
A3: BILAN
A4: Actif | D4: Passif
A5: Immobilisations | C5: =SUM(C6:C7) | D5: Capitaux propres | F5: 3000
A6: – Terrain | C6: 3000
A7: – Équipements | C7: 7000
A8: Stock | C8: 1000 | D8: Dettes | F8: 8000
A9: Total Actif | C9: =C5+C8 | D9: Total Passif | F9: =F5+F8
A11: COMPTE DE RESULTAT
A12: Charges | D12: Produits
A13: Coûts de production | C13: =C14+C21 | D13: Chiffre d'affaires | F13: =100*50
A14: – Charges d'exploitation | C14: =SUM(C15:C17)
A15: –– Intrants | C15: 2000
A16: –– Amortisements | B16: 0.05 | C16: =B16*C7
A17: –– Taxes | C17: =SUM(C18:C20)
A18: ––– Redevances superficiaires | B18: 0.01 | C18: =C6*B18
A19: ––– Redevances minières | B19: 0.05 | C19: =F13*B19
A20: ––– Droits de douane | B20: 0.075 | C20: =C15*B20
A21: – Charges finnacières | B21: 0.05 | C21: =F8*B21
A22: Profit | C22: =F13-C13
A23: – Impôt sur les sociétés | B23: 0.3 | C23: =C22*B23
A24: – Profit après impôt | C24: =C22-C23
A25: – Dividendes | B25: 0.5 | C25: =C24*B25
A26: – Réserves | B26: 0.5 | C26: =C24*B26
A27: Total Charges | C27: =C13+C22 | D27: Total Produits | F27: =F13

Sheet 12_04_Contrat_d_2
A1: 2) Sous-capitalisation
A3: BILAN
A4: Actif | D4: Passif
A5: Immobilisations | C5: =SUM(C6:C7) | D5: Capitaux propres | F5: 1000
A6: – Terrain | C6: 3000
A7: – Équipements | C7: 7000
A8: Stock | C8: 1000 | D8: Dettes | F8: 10000
A9: Total Actif | C9: =C5+C8 | D9: Total Passif | F9: =F5+F8
A11: COMPTE DE RESULTAT
A12: Charges | D12: Produits
A13: Coûts de production | C13: =C14+C21 | D13: Chiffre d'affaires | F13: =100*50
A14: – Charges d'exploitation | C14: =SUM(C15:C17)
A15: –– Intrants | C15: 2000
A16: –– Amortisements | B16: 0.05 | C16: =B16*C7
A17: –– Taxes | C17: =SUM(C18:C20)
A18: ––– Redevances superficiaires | B18: 0.01 | C18: =C6*B18
A19: ––– Redevances minières | B19: 0.05 | C19: =F13*B19
A20: ––– Droits de douane | B20: 0.075 | C20: =C15*B20
A21: – Charges finnacières | B21: 0.05 | C21: =F8*B21
A22: Profit | C22: =F13-C13
A23: – Impôt sur les sociétés | B23: 0.3 | C23: =C22*B23
A24: – Profit après impôt | C24: =C22-C23
A25: – Dividendes | B25: 0.5 | C25: =C24*B25
A26: – Réserves | B26: 0.5 | C26: =C24*B26
A27: Total Charges | C27: =C13+C22 | D27: Total Produits | F27: =F13

Sheet 12_04_Contrat_d_3
A1: 3) Manipulation des coûts
A3: BILAN
A4: Actif | D4: Passif
A5: Immobilisations | C5: =SUM(C6:C7) | D5: Capitaux propres | F5: 1000
A6: – Terrain | C6: 3000
A7: – Équipements | C7: 12000
A8: Stock | C8: 1000 | D8: Dettes | F8: 15000
A9: Total Actif | C9: =C5+C8 | D9: Total Passif | F9: =F5+F8
A11: COMPTE DE RESULTAT
A12: Charges | D12: Produits
A13: Coûts de production | C13: =C14+C21 | D13: Chiffre d'affaires | F13: =100*50
A14: – Charges d'exploitation | C14: =SUM(C15:C17)
A15: –– Intrants | C15: 2800
A16: –– Amortisements | B16: 0.05 | C16: =B16*C7
A17: –– Taxes | C17: =SUM(C18:C20)
A18: ––– Redevances superficiaires | B18: 0.01 | C18: =C6*B18
A19: ––– Redevances minières | B19: 0.05 | C19: =F13*B19
A20: ––– Droits de douane | B20: 0.075 | C20: =C15*B20
A21: – Charges finnacières | B21: 0.05 | C21: =F8*B21
A22: Profit | C22: =F13-C13
A23: – Impôt sur les sociétés | B23: 0.3 | C23: =C22*B23
A24: – Profit après impôt | C24: =C22-C23
A25: – Dividendes | B25: 0.5 | C25: =C24*B25
A26: – Réserves | B26: 0.5 | C26: =C24*B26
A27: Total Charges | C27: =C13+C22 | D27: Total Produits | F27: =F13

Sheet 12_04_Contrat_d_4
A1: 4) Contrat de couverture
A3: BILAN
A4: Actif | D4: Passif
A5: Immobilisations | C5: =SUM(C6:C7) | D5: Capitaux propres | F5: 3000
A6: – Terrain | C6: 3000
A7: – Équipements | C7: 7000
A8: Stock | C8: 1000 | D8: Dettes | F8: 8000
A9: Total Actif | C9: =C5+C8 | D9: Total Passif | F9: =F5+F8
A11: COMPTE DE RESULTAT
A12: Charges | D12: Produits
A13: Coûts de production | C13: =C14+C21 | D13: Chiffre d'affaires | F13: =100*30
A14: – Charges d'exploitation | C14: =SUM(C15:C17)
A15: –– Intrants | C15: 2000
A16: –– Amortisements | B16: 0.05 | C16: =B16*C7
A17: –– Taxes | C17: =SUM(C18:C20)
A18: ––– Redevances superficiaires | B18: 0.01 | C18: =C6*B18
A19: ––– Redevances minières | B19: 0.05 | C19: =F13*B19
A20: ––– Droits de douane | B20: 0.075 | C20: =C15*B20
A21: – Charges finnacières | B21: 0.05 | C21: =F8*B21
A22: Profit | C22: =F13-C13
A23: – Impôt sur les sociétés | B23: 0.3 | C23: 0
A24: – Profit après impôt | C24: =C22-C23
A25: – Dividendes | B25: 0.5 | C25: 0
A26: – Réserves | B26: 0.5 | C26: 0
A27: Total Charges | C27: =C13+C22 | D27: Total Produits | F27: =F13

Sheet 13_05_Manipulat_1
C1: Janvier | D1: Février | E1: Mars | F1: Avril | G1: Mai | H1: Juin | I1: Juillet | J1: Août | K1: Septembre | L1: Octobre | M1: Novembre | N1: Décembre | O1: Total | P1: Moyenne
A2: Cours | B2: USD/oz | C2: 1000 | D2: 1100 | E2: 1400 | F2: 1050 | G2: 900 | H2: 800 | I2: 850 | J2: 1300 | K2: 1600 | L2: 1700 | M2: 1800 | N2: 2000 | P2: =AVERAGE(C2:N2)
A3: Minerai extrait | B3: t | C3: 10000 | D3: 12000 | E3: 12000 | F3: 15000 | G3: 15000 | H3: 9000 | I3: 9000 | J3: 12000 | K3: 12000 | L3: 14000 | M3: 12000 | N3: 10000 | O3: =SUM(C3:N3) | P3: =AVERAGE(C3:N3)
A4: Teneur | B4: oz/t | C4: 0.223 | D4: 0.225 | E4: 0.198 | F4: 0.185 | G4: 0.185 | H4: 0.223 | I4: 0.321 | J4: 0.311 | K4: 0.255 | L4: 0.286 | M4: 0.296 | N4: 0.223 | P4: =AVERAGE(C4:N4)
A5: Production réalisée | B5: oz | C5: =C3*C4 | D5: =D3*D4 | E5: =E3*E4 | F5: =F3*F4 | G5: =G3*G4 | H5: =H3*H4 | I5: =I3*I4 | J5: =J3*J4 | ... N5: =N3*N4 | O5: =SUM(C5:N5) | P5: =P3*P4

Sheet 13_05_Manipulat_2
C1: Janvier | D1: Février | E1: Mars | F1: Avril | G1: Mai | H1: Juin | I1: Juillet | J1: Août | K1: Septembre | L1: Octobre | M1: Novembre | N1: Décembre | O1: Total | P1: Moyenne
A2: Cours | B2: USD/oz | C2: 1000 | D2: 1100 | E2: 1400 | F2: 1050 | G2: 900 | H2: 800 | I2: 850 | J2: 1300 | K2: 1600 | L2: 1700 | M2: 1800 | N2: 2000 | P2: =AVERAGE(C2:N2)
A3: Minerai extrait | B3: t | C3: 10000 | D3: 12000 | E3: 12000 | F3: 15000 | G3: 15000 | H3: 9000 | I3: 9000 | J3: 12000 | K3: 12000 | L3: 14000 | M3: 12000 | N3: 10000 | O3: =SUM(C3:N3) | P3: =AVERAGE(C3:N3)
A4: Teneur | B4: oz/t | C4: 0.223 | D4: 0.225 | E4: 0.198 | F4: 0.185 | G4: 0.185 | H4: 0.223 | I4: 0.321 | J4: 0.311 | K4: 0.255 | L4: 0.286 | M4: 0.296 | N4: 0.223 | P4: =AVERAGE(C4:N4)
A5: Production réalisée | B5: oz | C5: =C3*C4 | D5: =D3*D4 | E5: =E3*E4 | F5: =F3*F4 | G5: =G3*G4 | H5: =H3*H4 | I5: =I3*I4 | J5: =J3*J4 | ... N5: =N3*N4 | O5: =SUM(C5:N5) | P5: =P3*P4
A6: Chiffre d'affaires réalisé | B6: USD | C6: =C5*C2 | D6: =D5*D2 | E6: =E5*E2 | F6: =F5*F2 | G6: =G5*G2 | H6: =H5*H2 | I6: =I5*I2 | J6: =J5*J2 | ... N6: =N5*N2 | O6: =SUM(C6:N6) | P6: =P2*P5
A7: Redevance minière (5%) | B7: USD | C7: =C6*5% | D7: =D6*5% | E7: =E6*5% | F7: =F6*5% | G7: =G6*5% | H7: =H6*5% | I7: =I6*5% | J7: =J6*5% | ... N7: =N6*5% | O7: =SUM(C7:N7) | P7: =AVERAGE(C7:N7)

Sheet 13_05_Manipulat_3
C1: Janvier | D1: Février | E1: Mars | F1: Avril | G1: Mai | H1: Juin | I1: Juillet | J1: Août | K1: Septembre | L1: Octobre | M1: Novembre | N1: Décembre | O1: Total | P1: Moyenne
A2: Cours | B2: USD/oz | C2: 1000 | D2: 1100 | E2: 1400 | F2: 1050 | G2: 900 | H2: 800 | I2: 850 | J2: 1300 | K2: 1600 | L2: 1700 | M2: 1800 | N2: 2000 | P2: =AVERAGE(C2:N2)
A3: Minerai extrait | B3: t | C3: 10000 | D3: 12000 | E3: 12000 | F3: 15000 | G3: 15000 | H3: 9000 | I3: 9000 | J3: 12000 | K3: 12000 | L3: 14000 | M3: 12000 | N3: 10000 | O3: =SUM(C3:N3) | P3: =AVERAGE(C3:N3)
A4: Teneur | B4: oz/t | C4: 0.223 | D4: 0.225 | E4: 0.198 | F4: 0.185 | G4: 0.185 | H4: 0.223 | I4: 0.321 | J4: 0.311 | K4: 0.255 | L4: 0.286 | M4: 0.296 | N4: 0.223 | P4: =AVERAGE(C4:N4)
A5: Production réalisée | B5: oz | C5: =C3*C4 | D5: =D3*D4 | E5: =E3*E4 | F5: =F3*F4 | G5: =G3*G4 | H5: =H3*H4 | I5: =I3*I4 | J5: =J3*J4 | ... N5: =N3*N4 | O5: =SUM(C5:N5) | P5: =P3*P4
A6: Chiffre d'affaires réalisé | B6: USD | H6: =SUM(C5:H5)*H2 | N6: =SUM(I5:N5)*N2 | O6: =SUM(C6:N6) | P6: =O6/12
A7: Redevance minière (5%) | B7: USD | H7: =H6*5% | N7: =N6*5% | O7: =SUM(C7:N7) | P7: =O7/12
O8: =O7-'2) Exportations mensuelles'!O7
O9: =O8/'2) Exportations mensuelles'!O7

Sheet 13_05_Manipulat_4
C1: Janvier | D1: Février | E1: Mars | F1: Avril | G1: Mai | H1: Juin | I1: Juillet | J1: Août | K1: Septembre | L1: Octobre | M1: Novembre | N1: Décembre | O1: Total | P1: Moyenne
A2: Cours | B2: USD/oz | C2: 1000 | D2: 1100 | E2: 1400 | F2: 1050 | G2: 900 | H2: 800 | I2: 850 | J2: 1300 | K2: 1600 | L2: 1700 | M2: 1800 | N2: 2000 | P2: =AVERAGE(C2:N2)
A3: Minerai extrait | B3: t | C3: 10000 | D3: 12000 | E3: 12000 | F3: 15000 | G3: 15000 | H3: 9000 | I3: 9000 | J3: 12000 | K3: 12000 | L3: 14000 | M3: 12000 | N3: 10000 | O3: =SUM(C3:N3) | P3: =AVERAGE(C3:N3)
A4: Teneur | B4: oz/t | C4: 0.223 | D4: 0.225 | E4: 0.198 | F4: 0.185 | G4: 0.185 | H4: 0.223 | I4: 0.321 | J4: 0.311 | K4: 0.255 | L4: 0.286 | M4: 0.296 | N4: 0.223 | P4: =AVERAGE(C4:N4)
A5: Production réalisée | B5: oz | C5: =C3*C4 | D5: =D3*D4 | E5: =E3*E4 | F5: =F3*F4 | G5: =G3*G4 | H5: =H3*H4 | I5: =I3*I4 | J5: =J3*J4 | ... N5: =N3*N4 | O5: =SUM(C5:N5) | P5: =P3*P4
A6: Chiffre d'affaires réalisé | B6: USD | N6: =SUM(C5:N5)*H2 | O6: =SUM(C6:N6) | P6: =O6/12
A7: Redevance minière (5%) | B7: USD | N7: =N6*5% | O7: =SUM(C7:N7) | P7: =O7/12
O8: =O7-'2) Exportations mensuelles'!O7
O9: =O8/'2) Exportations mensuelles'!O7

Sheet 13_05_Manipulat_5
C1: Janvier | D1: Février | E1: Mars | F1: Avril | G1: Mai | H1: Juin | I1: Juillet | J1: Août | K1: Septembre | L1: Octobre | M1: Novembre | N1: Décembre | O1: Total | P1: Moyenne
A2: Cours | B2: USD/oz | C2: 1000 | D2: 1100 | E2: 1400 | F2: 1050 | G2: 900 | H2: 800 | I2: 850 | J2: 1300 | K2: 1600 | L2: 1700 | M2: 1800 | N2: 2000 | P2: =AVERAGE(C2:N2)
A3: Minerai extrait | B3: t | C3: 10000 | D3: 12000 | E3: 12000 | F3: 15000 | G3: 15000 | H3: 9000 | I3: 9000 | J3: 12000 | K3: 12000 | L3: 14000 | M3: 12000 | N3: 10000 | O3: =SUM(C3:N3) | P3: =AVERAGE(C3:N3)
A4: Teneur | B4: oz/t | C4: 0.223 | D4: 0.225 | E4: 0.198 | F4: 0.185 | G4: 0.185 | H4: 0.223 | I4: 0.321 | J4: 0.311 | K4: 0.255 | L4: 0.286 | M4: 0.296 | N4: 0.223 | P4: =AVERAGE(C4:N4)
A5: Production réalisée | B5: oz | C5: =C3*$F$4 | D5: =D3*$F$4 | E5: =E3*$F$4 | F5: =F3*$F$4 | G5: =G3*$F$4 | H5: =H3*$F$4 | I5: =I3*$F$4 | J5: =J3*$F$4 | ... N5: =N3*$F$4 | O5: =SUM(C5:N5) | P5: =P3*P4
A6: Chiffre d'affaires réalisé | B6: USD | C6: =C5*C2 | D6: =D5*D2 | E6: =E5*E2 | F6: =F5*F2 | G6: =G5*G2 | H6: =H5*H2 | I6: =I5*I2 | J6: =J5*J2 | ... N6: =N5*N2 | O6: =SUM(C6:N6) | P6: =O6/12
A7: Redevance minière (5%) | B7: USD | C7: =C6*5% | D7: =D6*5% | E7: =E6*5% | F7: =F6*5% | G7: =G6*5% | H7: =H6*5% | I7: =I6*5% | J7: =J6*5% | ... N7: =N6*5% | O7: =SUM(C7:N7) | P7: =O7/12
O8: =O7-'2) Exportations mensuelles'!O7
O9: =O8/'2) Exportations mensuelles'!O7
